Workbook

Sheet 彙整總表
C4: 年份 | D4: 2023 | E4: 2024 | F4: 2025 | G4: 2026 | H4: 2027 | I4: 2028 | J4: 2029 | K4: 2030 | L4: 2031 | M4: 2032 | N4: 2033 | O4: 2034 | P4: 2035 | Q4: 2036 | R4: 2037 | S4: 2038 | T4: 2039 | U4: 2040 | V4: 2041 | W4: 2042
C5: 預估發電度數
B6: 表 62 | D6: =ABS('表 62_滾算紀錄3'!D40) | E6: =ABS('表 62_滾算紀錄3'!E40) | F6: =ABS('表 62_滾算紀錄3'!F40) | G6: =ABS('表 62_滾算紀錄3'!G40) | H6: =ABS('表 62_滾算紀錄3'!H40) | I6: =ABS('表 62_滾算紀錄3'!I40) | J6: =ABS('表 62_滾算紀錄3'!J40) | K6: =ABS('表 62_滾算紀錄3'!K40) | ... W6: =ABS('表 62_滾算紀錄3'!W40)
B7: 表 62 | D7: =ABS('表 62_滾算紀錄2'!D40) | E7: =ABS('表 62_滾算紀錄2'!E40) | F7: =ABS('表 62_滾算紀錄2'!F40) | G7: =ABS('表 62_滾算紀錄2'!G40) | H7: =ABS('表 62_滾算紀錄2'!H40) | I7: =ABS('表 62_滾算紀錄2'!I40) | J7: =ABS('表 62_滾算紀錄2'!J40) | K7: =ABS('表 62_滾算紀錄2'!K40) | ... W7: =ABS('表 62_滾算紀錄2'!W40)
B8: 表 62 | D8: =ABS('表 62_滾算紀錄4'!D40) | E8: =ABS('表 62_滾算紀錄4'!E40) | F8: =ABS('表 62_滾算紀錄4'!F40) | G8: =ABS('表 62_滾算紀錄4'!G40) | H8: =ABS('表 62_滾算紀錄4'!H40) | I8: =ABS('表 62_滾算紀錄4'!I40) | J8: =ABS('表 62_滾算紀錄4'!J40) | K8: =ABS('表 62_滾算紀錄4'!K40) | ... W8: =ABS('表 62_滾算紀錄4'!W40)
B9: 表 62 | D9: =ABS('表 62_滾算紀錄6'!D40) | E9: =ABS('表 62_滾算紀錄6'!E40) | F9: =ABS('表 62_滾算紀錄6'!F40) | G9: =ABS('表 62_滾算紀錄6'!G40) | H9: =ABS('表 62_滾算紀錄6'!H40) | I9: =ABS('表 62_滾算紀錄6'!I40) | J9: =ABS('表 62_滾算紀錄6'!J40) | K9: =ABS('表 62_滾算紀錄6'!K40) | ... W9: =ABS('表 62_滾算紀錄6'!W40)
C10: 預估發電度數/年總計 | D10: =SUM(D6:D9) | E10: =SUM(E6:E9) | F10: =SUM(F6:F9) | G10: =SUM(G6:G9) | H10: =SUM(H6:H9) | I10: =SUM(I6:I9) | J10: =SUM(J6:J9) | K10: =SUM(K6:K9) | ... W10: =SUM(W6:W9)
C11: 預估收入 | D11: 2023 | E11: 2024 | F11: 2025 | G11: 2026 | H11: 2027 | I11: 2028 | J11: 2029 | K11: 2030 | L11: 2031 | M11: 2032 | N11: 2033 | O11: 2034 | P11: 2035 | Q11: 2036 | R11: 2037 | S11: 2038 | T11: 2039 | U11: 2040 | V11: 2041 | W11: 2042
B12: 表 62 | D12: =ABS('表 62_滾算紀錄3'!D41) | E12: =ABS('表 62_滾算紀錄3'!E41) | F12: =ABS('表 62_滾算紀錄3'!F41) | G12: =ABS('表 62_滾算紀錄3'!G41) | H12: =ABS('表 62_滾算紀錄3'!H41) | I12: =ABS('表 62_滾算紀錄3'!I41) | J12: =ABS('表 62_滾算紀錄3'!J41) | K12: =ABS('表 62_滾算紀錄3'!K41) | ... W12: =ABS('表 62_滾算紀錄3'!W41)
B13: 表 62 | D13: =ABS('表 62_滾算紀錄2'!D41) | E13: =ABS('表 62_滾算紀錄2'!E41) | F13: =ABS('表 62_滾算紀錄2'!F41) | G13: =ABS('表 62_滾算紀錄2'!G41) | H13: =ABS('表 62_滾算紀錄2'!H41) | I13: =ABS('表 62_滾算紀錄2'!I41) | J13: =ABS('表 62_滾算紀錄2'!J41) | K13: =ABS('表 62_滾算紀錄2'!K41) | ... W13: =ABS('表 62_滾算紀錄2'!W41)
B14: 表 62 | D14: =ABS('表 62_滾算紀錄4'!D41) | E14: =ABS('表 62_滾算紀錄4'!E41) | F14: =ABS('表 62_滾算紀錄4'!F41) | G14: =ABS('表 62_滾算紀錄4'!G41) | H14: =ABS('表 62_滾算紀錄4'!H41) | I14: =ABS('表 62_滾算紀錄4'!I41) | J14: =ABS('表 62_滾算紀錄4'!J41) | K14: =ABS('表 62_滾算紀錄4'!K41) | ... W14: =ABS('表 62_滾算紀錄4'!W41)
B15: 表 62 | D15: =ABS('表 62_滾算紀錄6'!D41) | E15: =ABS('表 62_滾算紀錄6'!E41) | F15: =ABS('表 62_滾算紀錄6'!F41) | G15: =ABS('表 62_滾算紀錄6'!G41) | H15: =ABS('表 62_滾算紀錄6'!H41) | I15: =ABS('表 62_滾算紀錄6'!I41) | J15: =ABS('表 62_滾算紀錄6'!J41) | K15: =ABS('表 62_滾算紀錄6'!K41) | ... W15: =ABS('表 62_滾算紀錄6'!W41)
C16: 預估收入/年總計 | D16: =SUM(D12:D15) | E16: =SUM(E12:E15) | F16: =SUM(F12:F15) | G16: =SUM(G12:G15) | H16: =SUM(H12:H15) | I16: =SUM(I12:I15) | J16: =SUM(J12:J15) | K16: =SUM(K12:K15) | ... W16: =SUM(W12:W15)
C17: 租金 | D17: 2023 | E17: 2024 | F17: 2025 | G17: 2026 | H17: 2027 | I17: 2028 | J17: 2029 | K17: 2030 | L17: 2031 | M17: 2032 | N17: 2033 | O17: 2034 | P17: 2035 | Q17: 2036 | R17: 2037 | S17: 2038 | T17: 2039 | U17: 2040 | V17: 2041 | W17: 2042
B18: 表 62 | D18: =ABS('表 62_滾算紀錄3'!D45) | E18: =ABS('表 62_滾算紀錄3'!E45) | F18: =ABS('表 62_滾算紀錄3'!F45) | G18: =ABS('表 62_滾算紀錄3'!G45) | H18: =ABS('表 62_滾算紀錄3'!H45) | I18: =ABS('表 62_滾算紀錄3'!I45) | J18: =ABS('表 62_滾算紀錄3'!J45) | K18: =ABS('表 62_滾算紀錄3'!K45) | ... W18: =ABS('表 62_滾算紀錄3'!W45)
B19: 表 62 | D19: =ABS('表 62_滾算紀錄2'!D45) | E19: =ABS('表 62_滾算紀錄2'!E45) | F19: =ABS('表 62_滾算紀錄2'!F45) | G19: =ABS('表 62_滾算紀錄2'!G45) | H19: =ABS('表 62_滾算紀錄2'!H45) | I19: =ABS('表 62_滾算紀錄2'!I45) | J19: =ABS('表 62_滾算紀錄2'!J45) | K19: =ABS('表 62_滾算紀錄2'!K45) | ... W19: =ABS('表 62_滾算紀錄2'!W45)
B20: 表 62 | D20: =ABS('表 62_滾算紀錄4'!D45) | E20: =ABS('表 62_滾算紀錄4'!E45) | F20: =ABS('表 62_滾算紀錄4'!F45) | G20: =ABS('表 62_滾算紀錄4'!G45) | H20: =ABS('表 62_滾算紀錄4'!H45) | I20: =ABS('表 62_滾算紀錄4'!I45) | J20: =ABS('表 62_滾算紀錄4'!J45) | K20: =ABS('表 62_滾算紀錄4'!K45) | ... W20: =ABS('表 62_滾算紀錄4'!W45)
B21: 表 62 | D21: =ABS('表 62_滾算紀錄6'!D45) | E21: =ABS('表 62_滾算紀錄6'!E45) | F21: =ABS('表 62_滾算紀錄6'!F45) | G21: =ABS('表 62_滾算紀錄6'!G45) | H21: =ABS('表 62_滾算紀錄6'!H45) | I21: =ABS('表 62_滾算紀錄6'!I45) | J21: =ABS('表 62_滾算紀錄6'!J45) | K21: =ABS('表 62_滾算紀錄6'!K45) | ... W21: =ABS('表 62_滾算紀錄6'!W45)
C22: 租金/年總計 | D22: =SUM(D18:D21) | E22: =SUM(E18:E21) | F22: =SUM(F18:F21) | G22: =SUM(G18:G21) | H22: =SUM(H18:H21) | I22: =SUM(I18:I21) | J22: =SUM(J18:J21) | K22: =SUM(K18:K21) | ... W22: =SUM(W18:W21)
C23: 運維 | D23: 2023 | E23: 2024 | F23: 2025 | G23: 2026 | H23: 2027 | I23: 2028 | J23: 2029 | K23: 2030 | L23: 2031 | M23: 2032 | N23: 2033 | O23: 2034 | P23: 2035 | Q23: 2036 | R23: 2037 | S23: 2038 | T23: 2039 | U23: 2040 | V23: 2041 | W23: 2042
B24: 表 62 | D24: =ABS('表 62_滾算紀錄3'!D48) | E24: =ABS('表 62_滾算紀錄3'!E48) | F24: =ABS('表 62_滾算紀錄3'!F48) | G24: =ABS('表 62_滾算紀錄3'!G48) | H24: =ABS('表 62_滾算紀錄3'!H48) | I24: =ABS('表 62_滾算紀錄3'!I48) | J24: =ABS('表 62_滾算紀錄3'!J48) | K24: =ABS('表 62_滾算紀錄3'!K48) | ... W24: =ABS('表 62_滾算紀錄3'!W48)
B25: 表 62 | D25: =ABS('表 62_滾算紀錄2'!D48) | E25: =ABS('表 62_滾算紀錄2'!E48) | F25: =ABS('表 62_滾算紀錄2'!F48) | G25: =ABS('表 62_滾算紀錄2'!G48) | H25: =ABS('表 62_滾算紀錄2'!H48) | I25: =ABS('表 62_滾算紀錄2'!I48) | J25: =ABS('表 62_滾算紀錄2'!J48) | K25: =ABS('表 62_滾算紀錄2'!K48) | ... W25: =ABS('表 62_滾算紀錄2'!W48)
B26: 表 62 | D26: =ABS('表 62_滾算紀錄4'!D48) | E26: =ABS('表 62_滾算紀錄4'!E48) | F26: =ABS('表 62_滾算紀錄4'!F48) | G26: =ABS('表 62_滾算紀錄4'!G48) | H26: =ABS('表 62_滾算紀錄4'!H48) | I26: =ABS('表 62_滾算紀錄4'!I48) | J26: =ABS('表 62_滾算紀錄4'!J48) | K26: =ABS('表 62_滾算紀錄4'!K48) | ... W26: =ABS('表 62_滾算紀錄4'!W48)
B27: 表 62 | D27: =ABS('表 62_滾算紀錄6'!D48) | E27: =ABS('表 62_滾算紀錄6'!E48) | F27: =ABS('表 62_滾算紀錄6'!F48) | G27: =ABS('表 62_滾算紀錄6'!G48) | H27: =ABS('表 62_滾算紀錄6'!H48) | I27: =ABS('表 62_滾算紀錄6'!I48) | J27: =ABS('表 62_滾算紀錄6'!J48) | K27: =ABS('表 62_滾算紀錄6'!K48) | ... W27: =ABS('表 62_滾算紀錄6'!W48)
C28: 運維/年總計 | D28: =SUM(D24:D27) | E28: =SUM(E24:E27) | F28: =SUM(F24:F27) | G28: =SUM(G24:G27) | H28: =SUM(H24:H27) | I28: =SUM(I24:I27) | J28: =SUM(J24:J27) | K28: =SUM(K24:K27) | ... W28: =SUM(W24:W27)
C29: 保險 | D29: 2023 | E29: 2024 | F29: 2025 | G29: 2026 | H29: 2027 | I29: 2028 | J29: 2029 | K29: 2030 | L29: 2031 | M29: 2032 | N29: 2033 | O29: 2034 | P29: 2035 | Q29: 2036 | R29: 2037 | S29: 2038 | T29: 2039 | U29: 2040 | V29: 2041 | W29: 2042
B30: 表 62 | D30: =ABS('表 62_滾算紀錄3'!D49) | E30: =ABS('表 62_滾算紀錄3'!E49) | F30: =ABS('表 62_滾算紀錄3'!F49) | G30: =ABS('表 62_滾算紀錄3'!G49) | H30: =ABS('表 62_滾算紀錄3'!H49) | I30: =ABS('表 62_滾算紀錄3'!I49) | J30: =ABS('表 62_滾算紀錄3'!J49) | K30: =ABS('表 62_滾算紀錄3'!K49) | ... W30: =ABS('表 62_滾算紀錄3'!W49)
B31: 表 62 | D31: =ABS('表 62_滾算紀錄2'!D49) | E31: =ABS('表 62_滾算紀錄2'!E49) | F31: =ABS('表 62_滾算紀錄2'!F49) | G31: =ABS('表 62_滾算紀錄2'!G49) | H31: =ABS('表 62_滾算紀錄2'!H49) | I31: =ABS('表 62_滾算紀錄2'!I49) | J31: =ABS('表 62_滾算紀錄2'!J49) | K31: =ABS('表 62_滾算紀錄2'!K49) | ... W31: =ABS('表 62_滾算紀錄2'!W49)
B32: 表 62 | D32: =ABS('表 62_滾算紀錄4'!D49) | E32: =ABS('表 62_滾算紀錄4'!E49) | F32: =ABS('表 62_滾算紀錄4'!F49) | G32: =ABS('表 62_滾算紀錄4'!G49) | H32: =ABS('表 62_滾算紀錄4'!H49) | I32: =ABS('表 62_滾算紀錄4'!I49) | J32: =ABS('表 62_滾算紀錄4'!J49) | K32: =ABS('表 62_滾算紀錄4'!K49) | ... W32: =ABS('表 62_滾算紀錄4'!W49)
B33: 表 62 | D33: =ABS('表 62_滾算紀錄6'!D49) | E33: =ABS('表 62_滾算紀錄6'!E49) | F33: =ABS('表 62_滾算紀錄6'!F49) | G33: =ABS('表 62_滾算紀錄6'!G49) | H33: =ABS('表 62_滾算紀錄6'!H49) | I33: =ABS('表 62_滾算紀錄6'!I49) | J33: =ABS('表 62_滾算紀錄6'!J49) | K33: =ABS('表 62_滾算紀錄6'!K49) | ... W33: =ABS('表 62_滾算紀錄6'!W49)
C34: 保險/年總計 | D34: =SUM(D30:D33) | E34: =SUM(E30:E33) | F34: =SUM(F30:F33) | G34: =SUM(G30:G33) | H34: =SUM(H30:H33) | I34: =SUM(I30:I33) | J34: =SUM(J30:J33) | K34: =SUM(K30:K33) | ... W34: =SUM(W30:W33)
C35: 模組回收費 | D35: 2023 | E35: 2024 | F35: 2025 | G35: 2026 | H35: 2027 | I35: 2028 | J35: 2029 | K35: 2030 | L35: 2031 | M35: 2032 | N35: 2033 | O35: 2034 | P35: 2035 | Q35: 2036 | R35: 2037 | S35: 2038 | T35: 2039 | U35: 2040 | V35: 2041 | W35: 2042
B36: 表 62 | D36: =ABS('表 62_滾算紀錄3'!D50) | E36: =ABS('表 62_滾算紀錄3'!E50) | F36: =ABS('表 62_滾算紀錄3'!F50) | G36: =ABS('表 62_滾算紀錄3'!G50) | H36: =ABS('表 62_滾算紀錄3'!H50) | I36: =ABS('表 62_滾算紀錄3'!I50) | J36: =ABS('表 62_滾算紀錄3'!J50) | K36: =ABS('表 62_滾算紀錄3'!K50) | ... W36: =ABS('表 62_滾算紀錄3'!W50)
B37: 表 62 | D37: =ABS('表 62_滾算紀錄2'!D50) | E37: =ABS('表 62_滾算紀錄2'!E50) | F37: =ABS('表 62_滾算紀錄2'!F50) | G37: =ABS('表 62_滾算紀錄2'!G50) | H37: =ABS('表 62_滾算紀錄2'!H50) | I37: =ABS('表 62_滾算紀錄2'!I50) | J37: =ABS('表 62_滾算紀錄2'!J50) | K37: =ABS('表 62_滾算紀錄2'!K50) | ... W37: =ABS('表 62_滾算紀錄2'!W50)
B38: 表 62 | D38: =ABS('表 62_滾算紀錄4'!D50) | E38: =ABS('表 62_滾算紀錄4'!E50) | F38: =ABS('表 62_滾算紀錄4'!F50) | G38: =ABS('表 62_滾算紀錄4'!G50) | H38: =ABS('表 62_滾算紀錄4'!H50) | I38: =ABS('表 62_滾算紀錄4'!I50) | J38: =ABS('表 62_滾算紀錄4'!J50) | K38: =ABS('表 62_滾算紀錄4'!K50) | ... W38: =ABS('表 62_滾算紀錄4'!W50)
B39: 表 62 | D39: =ABS('表 62_滾算紀錄6'!D50) | E39: =ABS('表 62_滾算紀錄6'!E50) | F39: =ABS('表 62_滾算紀錄6'!F50) | G39: =ABS('表 62_滾算紀錄6'!G50) | H39: =ABS('表 62_滾算紀錄6'!H50) | I39: =ABS('表 62_滾算紀錄6'!I50) | J39: =ABS('表 62_滾算紀錄6'!J50) | K39: =ABS('表 62_滾算紀錄6'!K50) | ... W39: =ABS('表 62_滾算紀錄6'!W50)
C40: 模組回收費/年總計 | D40: =SUM(D36:D39) | E40: =SUM(E36:E39) | F40: =SUM(F36:F39) | G40: =SUM(G36:G39) | H40: =SUM(H36:H39) | I40: =SUM(I36:I39) | J40: =SUM(J36:J39) | K40: =SUM(K36:K39) | ... W40: =SUM(W36:W39)
C41: 所得稅 | D41: 2023 | E41: 2024 | F41: 2025 | G41: 2026 | H41: 2027 | I41: 2028 | J41: 2029 | K41: 2030 | L41: 2031 | M41: 2032 | N41: 2033 | O41: 2034 | P41: 2035 | Q41: 2036 | R41: 2037 | S41: 2038 | T41: 2039 | U41: 2040 | V41: 2041 | W41: 2042
B42: 表 62 | D42: =ABS('表 62_滾算紀錄3'!D54) | E42: =ABS('表 62_滾算紀錄3'!E54) | F42: =ABS('表 62_滾算紀錄3'!F54) | G42: =ABS('表 62_滾算紀錄3'!G54) | H42: =ABS('表 62_滾算紀錄3'!H54) | I42: =ABS('表 62_滾算紀錄3'!I54) | J42: =ABS('表 62_滾算紀錄3'!J54) | K42: =ABS('表 62_滾算紀錄3'!K54) | ... W42: =ABS('表 62_滾算紀錄3'!W54)
B43: 表 62 | D43: =ABS('表 62_滾算紀錄2'!D54) | E43: =ABS('表 62_滾算紀錄2'!E54) | F43: =ABS('表 62_滾算紀錄2'!F54) | G43: =ABS('表 62_滾算紀錄2'!G54) | H43: =ABS('表 62_滾算紀錄2'!H54) | I43: =ABS('表 62_滾算紀錄2'!I54) | J43: =ABS('表 62_滾算紀錄2'!J54) | K43: =ABS('表 62_滾算紀錄2'!K54) | ... W43: =ABS('表 62_滾算紀錄2'!W54)
...

Sheet 表 62_滾算紀錄3
B1: 電站基本資料
B2: 電站名稱 | C2: 淡江大學-財務模擬案場 | D2: - | E2: -
B3: 電站壽命 | C3: 20 | D3: - | E3: -
B4: 建置量(kWp) | C4: 436.1 | D4: - | E4: - | M4: 滾算紀錄編號: 3
B5: 起始年度 | C5: 2023 | D5: 結束年度 | E5: 2042 | M5: 第2次滾算摘要
M6: 價金: 28000
B7: 綜合損益表 | M7: 專案IRR: 4.98
B8: 收入 | M8: 權益法IRR: 13.18
B9: 收支項目 | C9: 相關參數 | D9: 參數數值 | E9: 年限 | M9: 利潤率: 20.00%
B10: 電費收入 | C10: 年度AC併網總發電量 | D10: 547002 | E10: 20 | M10: 第2次滾算，減少 1000 元 - 現金模式，每次減少 1000 元
C11: 首年衰退率 | D11: 0.01
C12: 次年衰退率 | D12: 0.004
C13: 躉售費率(FIT) | D13: 3.7152
B14: 支出
B15: 收支項目 | C15: 相關參數 | D15: 參數數值 | E15: 攤提年限
B16: 設備費用(價金) | C16: 每kWp設備成本 | D16: 28000 | E16: 20
C17: 信邦利潤率 | D17: 0.2
C18: 開發費 | D18: 2000
B19: 租金費用 | C19: 租金計算方式 (1=固定攤提/2=電費抽成) | D19: 1 | E19: 0
C20: 【方式1參數】租金總額 | D20: 5804025 | E20: 20
C21: 【方式2參數】抽成比率 | D21: 0 | E21: 0
B22: 運維費用 | C22: 每kw運維成本 | D22: 400 | E22: 20
B23: 保險費用 | C23: 占整體設備費用比例 | D23: 0.003 | E23: 20
B24: 模組回收費用 | C24: 每kw模組回收成本 | D24: 1000 | E24: 10
B25: 利息費用 | C25: 銀行利率 | D25: 0.025595 | E25: 0
B26: 所得稅 | C26: 所得稅率 | D26: 0.2 | E26: 0
B29: 現金流量表
B30: 金流項目 | C30: 相關參數 | D30: 參數數值
B31: 貸款成數 | C31: 占總設備費用比例 | D31: 0.8
B32: 貸款還款 | C32: 攤還期數 | D32: 15
B33: 現金股利 | C33: 股利比率 | D33: 0.9
B34: 年底減資 | C34: 攤還期數 | D34: 4
C37: 年份 | D37: 2023 | E37: 2024 | F37: 2025 | G37: 2026 | H37: 2027 | I37: 2028 | J37: 2029 | K37: 2030 | L37: 2031 | M37: 2032 | N37: 2033 | O37: 2034 | P37: 2035 | Q37: 2036 | R37: 2037 | S37: 2038 | T37: 2039 | U37: 2040 | V37: 2041 | W37: 2042
B38: 0
B39: (Unit : Currency) | C39: 0 | D39: 1 | E39: 2 | F39: 3 | G39: 4 | H39: 5 | I39: 6 | J39: 7 | K39: 8 | L39: 9 | M39: 10 | N39: 11 | O39: 12 | P39: 13 | Q39: 14 | R39: 15 | S39: 16 | T39: 17 | U39: 18 | V39: 19 | W39: 20
B40: 發電度數(KWH) | C40: 0 | D40: =$D$10*0.99 | E40: =$D$10*0.986 | F40: =$D$10*0.982 | G40: =$D$10*0.978 | H40: =$D$10*0.974 | I40: =$D$10*0.97 | J40: =$D$10*0.966 | K40: =$D$10*0.962 | L40: =$D$10*0.958 | M40: =$D$10*0.954 | N40: =$D$10*0.95 | O40: =$D$10*0.946 | P40: =$D$10*0.942 | Q40: =$D$10*0.938 | R40: =$D$10*0.934 | S40: =$D$10*0.93 | T40: =$D$10*0.926 | U40: =$D$10*0.922 | V40: =$D$10*0.918 | W40: =$D$10*0.914
B41: Inflow : 電費收入 | C41: - | D41: =D40*$D$13 | E41: =E40*$D$13 | F41: =F40*$D$13 | G41: =G40*$D$13 | H41: =H40*$D$13 | I41: =I40*$D$13 | J41: =J40*$D$13 | K41: =K40*$D$13 | ... W41: =W40*$D$13
B42: Inflow : 政府補助 | C42: - | G42: - | H42: - | I42: - | J42: - | K42: - | L42: - | M42: - | N42: - | O42: - | P42: - | Q42: - | R42: - | S42: - | T42: - | U42: - | V42: - | W42: -
B43: Inflow : 銀行借款
B44: Outflow : 設備費用 | C44: =-(D16/(1-D17)+D18)*C4
...

Sheet 表 62_滾算紀錄2
B1: 電站基本資料
B2: 電站名稱 | C2: 淡江大學-財務模擬案場 | D2: - | E2: -
B3: 電站壽命 | C3: 20 | D3: - | E3: -
B4: 建置量(kWp) | C4: 436.1 | D4: - | E4: - | M4: 滾算紀錄編號: 2
B5: 起始年度 | C5: 2023 | D5: 結束年度 | E5: 2042 | M5: 第1次滾算摘要
M6: 價金: 29000
B7: 綜合損益表 | M7: 專案IRR: 4.63
B8: 收入 | M8: 權益法IRR: 11.74
B9: 收支項目 | C9: 相關參數 | D9: 參數數值 | E9: 年限 | M9: 利潤率: 20.00%
B10: 電費收入 | C10: 年度AC併網總發電量 | D10: 547002 | E10: 20 | M10: 第1次滾算，減少 1000 元 - 現金模式，每次減少 1000 元
C11: 首年衰退率 | D11: 0.01
C12: 次年衰退率 | D12: 0.004
C13: 躉售費率(FIT) | D13: 3.7152
B14: 支出
B15: 收支項目 | C15: 相關參數 | D15: 參數數值 | E15: 攤提年限
B16: 設備費用(價金) | C16: 每kWp設備成本 | D16: 29000 | E16: 20
C17: 信邦利潤率 | D17: 0.2
C18: 開發費 | D18: 2000
B19: 租金費用 | C19: 租金計算方式 (1=固定攤提/2=電費抽成) | D19: 1 | E19: 0
C20: 【方式1參數】租金總額 | D20: 5804025 | E20: 20
C21: 【方式2參數】抽成比率 | D21: 0 | E21: 0
B22: 運維費用 | C22: 每kw運維成本 | D22: 400 | E22: 20
B23: 保險費用 | C23: 占整體設備費用比例 | D23: 0.003 | E23: 20
B24: 模組回收費用 | C24: 每kw模組回收成本 | D24: 1000 | E24: 10
B25: 利息費用 | C25: 銀行利率 | D25: 0.025595 | E25: 0
B26: 所得稅 | C26: 所得稅率 | D26: 0.2 | E26: 0
B29: 現金流量表
B30: 金流項目 | C30: 相關參數 | D30: 參數數值
B31: 貸款成數 | C31: 占總設備費用比例 | D31: 0.8
B32: 貸款還款 | C32: 攤還期數 | D32: 15
B33: 現金股利 | C33: 股利比率 | D33: 0.9
B34: 年底減資 | C34: 攤還期數 | D34: 4
C37: 年份 | D37: 2023 | E37: 2024 | F37: 2025 | G37: 2026 | H37: 2027 | I37: 2028 | J37: 2029 | K37: 2030 | L37: 2031 | M37: 2032 | N37: 2033 | O37: 2034 | P37: 2035 | Q37: 2036 | R37: 2037 | S37: 2038 | T37: 2039 | U37: 2040 | V37: 2041 | W37: 2042
B38: 0
B39: (Unit : Currency) | C39: 0 | D39: 1 | E39: 2 | F39: 3 | G39: 4 | H39: 5 | I39: 6 | J39: 7 | K39: 8 | L39: 9 | M39: 10 | N39: 11 | O39: 12 | P39: 13 | Q39: 14 | R39: 15 | S39: 16 | T39: 17 | U39: 18 | V39: 19 | W39: 20
B40: 發電度數(KWH) | C40: 0 | D40: =$D$10*0.99 | E40: =$D$10*0.986 | F40: =$D$10*0.982 | G40: =$D$10*0.978 | H40: =$D$10*0.974 | I40: =$D$10*0.97 | J40: =$D$10*0.966 | K40: =$D$10*0.962 | L40: =$D$10*0.958 | M40: =$D$10*0.954 | N40: =$D$10*0.95 | O40: =$D$10*0.946 | P40: =$D$10*0.942 | Q40: =$D$10*0.938 | R40: =$D$10*0.934 | S40: =$D$10*0.93 | T40: =$D$10*0.926 | U40: =$D$10*0.922 | V40: =$D$10*0.918 | W40: =$D$10*0.914
B41: Inflow : 電費收入 | C41: - | D41: =D40*$D$13 | E41: =E40*$D$13 | F41: =F40*$D$13 | G41: =G40*$D$13 | H41: =H40*$D$13 | I41: =I40*$D$13 | J41: =J40*$D$13 | K41: =K40*$D$13 | ... W41: =W40*$D$13
B42: Inflow : 政府補助 | C42: - | G42: - | H42: - | I42: - | J42: - | K42: - | L42: - | M42: - | N42: - | O42: - | P42: - | Q42: - | R42: - | S42: - | T42: - | U42: - | V42: - | W42: -
B43: Inflow : 銀行借款
B44: Outflow : 設備費用 | C44: =-(D16/(1-D17)+D18)*C4
...

Sheet 表 62_滾算紀錄4
B1: 電站基本資料
B2: 電站名稱 | C2: 淡江大學-財務模擬案場 | D2: - | E2: -
B3: 電站壽命 | C3: 20 | D3: - | E3: -
B4: 建置量(kWp) | C4: 436.1 | D4: - | E4: - | M4: 滾算紀錄編號: 4
B5: 起始年度 | C5: 2023 | D5: 結束年度 | E5: 2042 | M5: 第3次滾算摘要
M6: 價金: 27000
B7: 綜合損益表 | M7: 專案IRR: 5.35
B8: 收入 | M8: 權益法IRR: 14.77
B9: 收支項目 | C9: 相關參數 | D9: 參數數值 | E9: 年限 | M9: 利潤率: 20.00%
B10: 電費收入 | C10: 年度AC併網總發電量 | D10: 547002 | E10: 20 | M10: 第3次滾算，減少 1000 元 - 現金模式，每次減少 1000 元
C11: 首年衰退率 | D11: 0.01
C12: 次年衰退率 | D12: 0.004
C13: 躉售費率(FIT) | D13: 3.7152
B14: 支出
B15: 收支項目 | C15: 相關參數 | D15: 參數數值 | E15: 攤提年限
B16: 設備費用(價金) | C16: 每kWp設備成本 | D16: 27000 | E16: 20
C17: 信邦利潤率 | D17: 0.2
C18: 開發費 | D18: 2000
B19: 租金費用 | C19: 租金計算方式 (1=固定攤提/2=電費抽成) | D19: 1 | E19: 0
C20: 【方式1參數】租金總額 | D20: 5804025 | E20: 20
C21: 【方式2參數】抽成比率 | D21: 0 | E21: 0
B22: 運維費用 | C22: 每kw運維成本 | D22: 400 | E22: 20
B23: 保險費用 | C23: 占整體設備費用比例 | D23: 0.003 | E23: 20
B24: 模組回收費用 | C24: 每kw模組回收成本 | D24: 1000 | E24: 10
B25: 利息費用 | C25: 銀行利率 | D25: 0.025595 | E25: 0
B26: 所得稅 | C26: 所得稅率 | D26: 0.2 | E26: 0
B29: 現金流量表
B30: 金流項目 | C30: 相關參數 | D30: 參數數值
B31: 貸款成數 | C31: 占總設備費用比例 | D31: 0.8
B32: 貸款還款 | C32: 攤還期數 | D32: 15
B33: 現金股利 | C33: 股利比率 | D33: 0.9
B34: 年底減資 | C34: 攤還期數 | D34: 4
C37: 年份 | D37: 2023 | E37: 2024 | F37: 2025 | G37: 2026 | H37: 2027 | I37: 2028 | J37: 2029 | K37: 2030 | L37: 2031 | M37: 2032 | N37: 2033 | O37: 2034 | P37: 2035 | Q37: 2036 | R37: 2037 | S37: 2038 | T37: 2039 | U37: 2040 | V37: 2041 | W37: 2042
B38: 0
B39: (Unit : Currency) | C39: 0 | D39: 1 | E39: 2 | F39: 3 | G39: 4 | H39: 5 | I39: 6 | J39: 7 | K39: 8 | L39: 9 | M39: 10 | N39: 11 | O39: 12 | P39: 13 | Q39: 14 | R39: 15 | S39: 16 | T39: 17 | U39: 18 | V39: 19 | W39: 20
B40: 發電度數(KWH) | C40: 0 | D40: =$D$10*0.99 | E40: =$D$10*0.986 | F40: =$D$10*0.982 | G40: =$D$10*0.978 | H40: =$D$10*0.974 | I40: =$D$10*0.97 | J40: =$D$10*0.966 | K40: =$D$10*0.962 | L40: =$D$10*0.958 | M40: =$D$10*0.954 | N40: =$D$10*0.95 | O40: =$D$10*0.946 | P40: =$D$10*0.942 | Q40: =$D$10*0.938 | R40: =$D$10*0.934 | S40: =$D$10*0.93 | T40: =$D$10*0.926 | U40: =$D$10*0.922 | V40: =$D$10*0.918 | W40: =$D$10*0.914
B41: Inflow : 電費收入 | C41: - | D41: =D40*$D$13 | E41: =E40*$D$13 | F41: =F40*$D$13 | G41: =G40*$D$13 | H41: =H40*$D$13 | I41: =I40*$D$13 | J41: =J40*$D$13 | K41: =K40*$D$13 | ... W41: =W40*$D$13
B42: Inflow : 政府補助 | C42: - | G42: - | H42: - | I42: - | J42: - | K42: - | L42: - | M42: - | N42: - | O42: - | P42: - | Q42: - | R42: - | S42: - | T42: - | U42: - | V42: - | W42: -
B43: Inflow : 銀行借款
B44: Outflow : 設備費用 | C44: =-(D16/(1-D17)+D18)*C4
...

Sheet 表 62_滾算紀錄6
B1: 電站基本資料
B2: 電站名稱 | C2: 淡江大學-財務模擬案場 | D2: - | E2: -
B3: 電站壽命 | C3: 20 | D3: - | E3: -
B4: 建置量(kWp) | C4: 436.1 | D4: - | E4: - | M4: 滾算紀錄編號: 6
B5: 起始年度 | C5: 2023 | D5: 結束年度 | E5: 2042 | M5: 第5次滾算摘要
M6: 價金: 25000
B7: 綜合損益表 | M7: 專案IRR: 6.15
B8: 收入 | M8: 權益法IRR: 18.54
B9: 收支項目 | C9: 相關參數 | D9: 參數數值 | E9: 年限 | M9: 利潤率: 20.00%
B10: 電費收入 | C10: 年度AC併網總發電量 | D10: 547002 | E10: 20 | M10: 第5次滾算，減少 1000 元 - 現金模式，每次減少 1000 元
C11: 首年衰退率 | D11: 0.01
C12: 次年衰退率 | D12: 0.004
C13: 躉售費率(FIT) | D13: 3.7152
B14: 支出
B15: 收支項目 | C15: 相關參數 | D15: 參數數值 | E15: 攤提年限
B16: 設備費用(價金) | C16: 每kWp設備成本 | D16: 25000 | E16: 20
C17: 信邦利潤率 | D17: 0.2
C18: 開發費 | D18: 2000
B19: 租金費用 | C19: 租金計算方式 (1=固定攤提/2=電費抽成) | D19: 1 | E19: 0
C20: 【方式1參數】租金總額 | D20: 5804025 | E20: 20
C21: 【方式2參數】抽成比率 | D21: 0 | E21: 0
B22: 運維費用 | C22: 每kw運維成本 | D22: 400 | E22: 20
B23: 保險費用 | C23: 占整體設備費用比例 | D23: 0.003 | E23: 20
B24: 模組回收費用 | C24: 每kw模組回收成本 | D24: 1000 | E24: 10
B25: 利息費用 | C25: 銀行利率 | D25: 0.025595 | E25: 0
B26: 所得稅 | C26: 所得稅率 | D26: 0.2 | E26: 0
B29: 現金流量表
B30: 金流項目 | C30: 相關參數 | D30: 參數數值
B31: 貸款成數 | C31: 占總設備費用比例 | D31: 0.8
B32: 貸款還款 | C32: 攤還期數 | D32: 15
B33: 現金股利 | C33: 股利比率 | D33: 0.9
B34: 年底減資 | C34: 攤還期數 | D34: 4
C37: 年份 | D37: 2023 | E37: 2024 | F37: 2025 | G37: 2026 | H37: 2027 | I37: 2028 | J37: 2029 | K37: 2030 | L37: 2031 | M37: 2032 | N37: 2033 | O37: 2034 | P37: 2035 | Q37: 2036 | R37: 2037 | S37: 2038 | T37: 2039 | U37: 2040 | V37: 2041 | W37: 2042
B38: 0
B39: (Unit : Currency) | C39: 0 | D39: 1 | E39: 2 | F39: 3 | G39: 4 | H39: 5 | I39: 6 | J39: 7 | K39: 8 | L39: 9 | M39: 10 | N39: 11 | O39: 12 | P39: 13 | Q39: 14 | R39: 15 | S39: 16 | T39: 17 | U39: 18 | V39: 19 | W39: 20
B40: 發電度數(KWH) | C40: 0 | D40: =$D$10*0.99 | E40: =$D$10*0.986 | F40: =$D$10*0.982 | G40: =$D$10*0.978 | H40: =$D$10*0.974 | I40: =$D$10*0.97 | J40: =$D$10*0.966 | K40: =$D$10*0.962 | L40: =$D$10*0.958 | M40: =$D$10*0.954 | N40: =$D$10*0.95 | O40: =$D$10*0.946 | P40: =$D$10*0.942 | Q40: =$D$10*0.938 | R40: =$D$10*0.934 | S40: =$D$10*0.93 | T40: =$D$10*0.926 | U40: =$D$10*0.922 | V40: =$D$10*0.918 | W40: =$D$10*0.914
B41: Inflow : 電費收入 | C41: - | D41: =D40*$D$13 | E41: =E40*$D$13 | F41: =F40*$D$13 | G41: =G40*$D$13 | H41: =H40*$D$13 | I41: =I40*$D$13 | J41: =J40*$D$13 | K41: =K40*$D$13 | ... W41: =W40*$D$13
B42: Inflow : 政府補助 | C42: - | G42: - | H42: - | I42: - | J42: - | K42: - | L42: - | M42: - | N42: - | O42: - | P42: - | Q42: - | R42: - | S42: - | T42: - | U42: - | V42: - | W42: -
B43: Inflow : 銀行借款
B44: Outflow : 設備費用 | C44: =-(D16/(1-D17)+D18)*C4
...
