Workbook

Sheet 多站彙整
C4: 年份 | D4: 2023 | E4: 2024 | F4: 2025 | G4: 2026 | H4: 2027 | I4: 2028 | J4: 2029 | K4: 2030 | L4: 2031 | M4: 2032 | N4: 2033 | O4: 2034 | P4: 2035 | Q4: 2036 | R4: 2037 | S4: 2038 | T4: 2039 | U4: 2040 | V4: 2041 | W4: 2042
C5: 預估發電度數
B6: 表 105 | D6: =ABS('表 105_滾算紀錄1'!D40) | E6: =ABS('表 105_滾算紀錄1'!E40) | F6: =ABS('表 105_滾算紀錄1'!F40) | G6: =ABS('表 105_滾算紀錄1'!G40) | H6: =ABS('表 105_滾算紀錄1'!H40) | I6: =ABS('表 105_滾算紀錄1'!I40) | J6: =ABS('表 105_滾算紀錄1'!J40) | K6: =ABS('表 105_滾算紀錄1'!K40) | ... W6: =ABS('表 105_滾算紀錄1'!W40)
B7: 表 105 | D7: =ABS('表 105_滾算紀錄2'!D40) | E7: =ABS('表 105_滾算紀錄2'!E40) | F7: =ABS('表 105_滾算紀錄2'!F40) | G7: =ABS('表 105_滾算紀錄2'!G40) | H7: =ABS('表 105_滾算紀錄2'!H40) | I7: =ABS('表 105_滾算紀錄2'!I40) | J7: =ABS('表 105_滾算紀錄2'!J40) | K7: =ABS('表 105_滾算紀錄2'!K40) | ... W7: =ABS('表 105_滾算紀錄2'!W40)
B8: 表 105 | D8: =ABS('表 105_滾算紀錄3'!D40) | E8: =ABS('表 105_滾算紀錄3'!E40) | F8: =ABS('表 105_滾算紀錄3'!F40) | G8: =ABS('表 105_滾算紀錄3'!G40) | H8: =ABS('表 105_滾算紀錄3'!H40) | I8: =ABS('表 105_滾算紀錄3'!I40) | J8: =ABS('表 105_滾算紀錄3'!J40) | K8: =ABS('表 105_滾算紀錄3'!K40) | ... W8: =ABS('表 105_滾算紀錄3'!W40)
C9: 預估發電度數/年總計 | D9: =SUM(D6:D8) | E9: =SUM(E6:E8) | F9: =SUM(F6:F8) | G9: =SUM(G6:G8) | H9: =SUM(H6:H8) | I9: =SUM(I6:I8) | J9: =SUM(J6:J8) | K9: =SUM(K6:K8) | ... W9: =SUM(W6:W8)
C10: 預估收入 | D10: 2023 | E10: 2024 | F10: 2025 | G10: 2026 | H10: 2027 | I10: 2028 | J10: 2029 | K10: 2030 | L10: 2031 | M10: 2032 | N10: 2033 | O10: 2034 | P10: 2035 | Q10: 2036 | R10: 2037 | S10: 2038 | T10: 2039 | U10: 2040 | V10: 2041 | W10: 2042
B11: 表 105 | D11: =ABS('表 105_滾算紀錄1'!D41) | E11: =ABS('表 105_滾算紀錄1'!E41) | F11: =ABS('表 105_滾算紀錄1'!F41) | G11: =ABS('表 105_滾算紀錄1'!G41) | H11: =ABS('表 105_滾算紀錄1'!H41) | I11: =ABS('表 105_滾算紀錄1'!I41) | J11: =ABS('表 105_滾算紀錄1'!J41) | K11: =ABS('表 105_滾算紀錄1'!K41) | ... W11: =ABS('表 105_滾算紀錄1'!W41)
B12: 表 105 | D12: =ABS('表 105_滾算紀錄2'!D41) | E12: =ABS('表 105_滾算紀錄2'!E41) | F12: =ABS('表 105_滾算紀錄2'!F41) | G12: =ABS('表 105_滾算紀錄2'!G41) | H12: =ABS('表 105_滾算紀錄2'!H41) | I12: =ABS('表 105_滾算紀錄2'!I41) | J12: =ABS('表 105_滾算紀錄2'!J41) | K12: =ABS('表 105_滾算紀錄2'!K41) | ... W12: =ABS('表 105_滾算紀錄2'!W41)
B13: 表 105 | D13: =ABS('表 105_滾算紀錄3'!D41) | E13: =ABS('表 105_滾算紀錄3'!E41) | F13: =ABS('表 105_滾算紀錄3'!F41) | G13: =ABS('表 105_滾算紀錄3'!G41) | H13: =ABS('表 105_滾算紀錄3'!H41) | I13: =ABS('表 105_滾算紀錄3'!I41) | J13: =ABS('表 105_滾算紀錄3'!J41) | K13: =ABS('表 105_滾算紀錄3'!K41) | ... W13: =ABS('表 105_滾算紀錄3'!W41)
C14: 預估收入/年總計 | D14: =SUM(D11:D13) | E14: =SUM(E11:E13) | F14: =SUM(F11:F13) | G14: =SUM(G11:G13) | H14: =SUM(H11:H13) | I14: =SUM(I11:I13) | J14: =SUM(J11:J13) | K14: =SUM(K11:K13) | ... W14: =SUM(W11:W13)
C15: 租金 | D15: 2023 | E15: 2024 | F15: 2025 | G15: 2026 | H15: 2027 | I15: 2028 | J15: 2029 | K15: 2030 | L15: 2031 | M15: 2032 | N15: 2033 | O15: 2034 | P15: 2035 | Q15: 2036 | R15: 2037 | S15: 2038 | T15: 2039 | U15: 2040 | V15: 2041 | W15: 2042
B16: 表 105 | D16: =ABS('表 105_滾算紀錄1'!D45) | E16: =ABS('表 105_滾算紀錄1'!E45) | F16: =ABS('表 105_滾算紀錄1'!F45) | G16: =ABS('表 105_滾算紀錄1'!G45) | H16: =ABS('表 105_滾算紀錄1'!H45) | I16: =ABS('表 105_滾算紀錄1'!I45) | J16: =ABS('表 105_滾算紀錄1'!J45) | K16: =ABS('表 105_滾算紀錄1'!K45) | ... W16: =ABS('表 105_滾算紀錄1'!W45)
B17: 表 105 | D17: =ABS('表 105_滾算紀錄2'!D45) | E17: =ABS('表 105_滾算紀錄2'!E45) | F17: =ABS('表 105_滾算紀錄2'!F45) | G17: =ABS('表 105_滾算紀錄2'!G45) | H17: =ABS('表 105_滾算紀錄2'!H45) | I17: =ABS('表 105_滾算紀錄2'!I45) | J17: =ABS('表 105_滾算紀錄2'!J45) | K17: =ABS('表 105_滾算紀錄2'!K45) | ... W17: =ABS('表 105_滾算紀錄2'!W45)
B18: 表 105 | D18: =ABS('表 105_滾算紀錄3'!D45) | E18: =ABS('表 105_滾算紀錄3'!E45) | F18: =ABS('表 105_滾算紀錄3'!F45) | G18: =ABS('表 105_滾算紀錄3'!G45) | H18: =ABS('表 105_滾算紀錄3'!H45) | I18: =ABS('表 105_滾算紀錄3'!I45) | J18: =ABS('表 105_滾算紀錄3'!J45) | K18: =ABS('表 105_滾算紀錄3'!K45) | ... W18: =ABS('表 105_滾算紀錄3'!W45)
C19: 租金/年總計 | D19: =SUM(D16:D18) | E19: =SUM(E16:E18) | F19: =SUM(F16:F18) | G19: =SUM(G16:G18) | H19: =SUM(H16:H18) | I19: =SUM(I16:I18) | J19: =SUM(J16:J18) | K19: =SUM(K16:K18) | ... W19: =SUM(W16:W18)
C20: 運維 | D20: 2023 | E20: 2024 | F20: 2025 | G20: 2026 | H20: 2027 | I20: 2028 | J20: 2029 | K20: 2030 | L20: 2031 | M20: 2032 | N20: 2033 | O20: 2034 | P20: 2035 | Q20: 2036 | R20: 2037 | S20: 2038 | T20: 2039 | U20: 2040 | V20: 2041 | W20: 2042
B21: 表 105 | D21: =ABS('表 105_滾算紀錄1'!D48) | E21: =ABS('表 105_滾算紀錄1'!E48) | F21: =ABS('表 105_滾算紀錄1'!F48) | G21: =ABS('表 105_滾算紀錄1'!G48) | H21: =ABS('表 105_滾算紀錄1'!H48) | I21: =ABS('表 105_滾算紀錄1'!I48) | J21: =ABS('表 105_滾算紀錄1'!J48) | K21: =ABS('表 105_滾算紀錄1'!K48) | ... W21: =ABS('表 105_滾算紀錄1'!W48)
B22: 表 105 | D22: =ABS('表 105_滾算紀錄2'!D48) | E22: =ABS('表 105_滾算紀錄2'!E48) | F22: =ABS('表 105_滾算紀錄2'!F48) | G22: =ABS('表 105_滾算紀錄2'!G48) | H22: =ABS('表 105_滾算紀錄2'!H48) | I22: =ABS('表 105_滾算紀錄2'!I48) | J22: =ABS('表 105_滾算紀錄2'!J48) | K22: =ABS('表 105_滾算紀錄2'!K48) | ... W22: =ABS('表 105_滾算紀錄2'!W48)
B23: 表 105 | D23: =ABS('表 105_滾算紀錄3'!D48) | E23: =ABS('表 105_滾算紀錄3'!E48) | F23: =ABS('表 105_滾算紀錄3'!F48) | G23: =ABS('表 105_滾算紀錄3'!G48) | H23: =ABS('表 105_滾算紀錄3'!H48) | I23: =ABS('表 105_滾算紀錄3'!I48) | J23: =ABS('表 105_滾算紀錄3'!J48) | K23: =ABS('表 105_滾算紀錄3'!K48) | ... W23: =ABS('表 105_滾算紀錄3'!W48)
C24: 運維/年總計 | D24: =SUM(D21:D23) | E24: =SUM(E21:E23) | F24: =SUM(F21:F23) | G24: =SUM(G21:G23) | H24: =SUM(H21:H23) | I24: =SUM(I21:I23) | J24: =SUM(J21:J23) | K24: =SUM(K21:K23) | ... W24: =SUM(W21:W23)
C25: 保險 | D25: 2023 | E25: 2024 | F25: 2025 | G25: 2026 | H25: 2027 | I25: 2028 | J25: 2029 | K25: 2030 | L25: 2031 | M25: 2032 | N25: 2033 | O25: 2034 | P25: 2035 | Q25: 2036 | R25: 2037 | S25: 2038 | T25: 2039 | U25: 2040 | V25: 2041 | W25: 2042
B26: 表 105 | D26: =ABS('表 105_滾算紀錄1'!D49) | E26: =ABS('表 105_滾算紀錄1'!E49) | F26: =ABS('表 105_滾算紀錄1'!F49) | G26: =ABS('表 105_滾算紀錄1'!G49) | H26: =ABS('表 105_滾算紀錄1'!H49) | I26: =ABS('表 105_滾算紀錄1'!I49) | J26: =ABS('表 105_滾算紀錄1'!J49) | K26: =ABS('表 105_滾算紀錄1'!K49) | ... W26: =ABS('表 105_滾算紀錄1'!W49)
B27: 表 105 | D27: =ABS('表 105_滾算紀錄2'!D49) | E27: =ABS('表 105_滾算紀錄2'!E49) | F27: =ABS('表 105_滾算紀錄2'!F49) | G27: =ABS('表 105_滾算紀錄2'!G49) | H27: =ABS('表 105_滾算紀錄2'!H49) | I27: =ABS('表 105_滾算紀錄2'!I49) | J27: =ABS('表 105_滾算紀錄2'!J49) | K27: =ABS('表 105_滾算紀錄2'!K49) | ... W27: =ABS('表 105_滾算紀錄2'!W49)
B28: 表 105 | D28: =ABS('表 105_滾算紀錄3'!D49) | E28: =ABS('表 105_滾算紀錄3'!E49) | F28: =ABS('表 105_滾算紀錄3'!F49) | G28: =ABS('表 105_滾算紀錄3'!G49) | H28: =ABS('表 105_滾算紀錄3'!H49) | I28: =ABS('表 105_滾算紀錄3'!I49) | J28: =ABS('表 105_滾算紀錄3'!J49) | K28: =ABS('表 105_滾算紀錄3'!K49) | ... W28: =ABS('表 105_滾算紀錄3'!W49)
C29: 保險/年總計 | D29: =SUM(D26:D28) | E29: =SUM(E26:E28) | F29: =SUM(F26:F28) | G29: =SUM(G26:G28) | H29: =SUM(H26:H28) | I29: =SUM(I26:I28) | J29: =SUM(J26:J28) | K29: =SUM(K26:K28) | ... W29: =SUM(W26:W28)
C30: 模組回收費 | D30: 2023 | E30: 2024 | F30: 2025 | G30: 2026 | H30: 2027 | I30: 2028 | J30: 2029 | K30: 2030 | L30: 2031 | M30: 2032 | N30: 2033 | O30: 2034 | P30: 2035 | Q30: 2036 | R30: 2037 | S30: 2038 | T30: 2039 | U30: 2040 | V30: 2041 | W30: 2042
B31: 表 105 | D31: =ABS('表 105_滾算紀錄1'!D50) | E31: =ABS('表 105_滾算紀錄1'!E50) | F31: =ABS('表 105_滾算紀錄1'!F50) | G31: =ABS('表 105_滾算紀錄1'!G50) | H31: =ABS('表 105_滾算紀錄1'!H50) | I31: =ABS('表 105_滾算紀錄1'!I50) | J31: =ABS('表 105_滾算紀錄1'!J50) | K31: =ABS('表 105_滾算紀錄1'!K50) | ... W31: =ABS('表 105_滾算紀錄1'!W50)
B32: 表 105 | D32: =ABS('表 105_滾算紀錄2'!D50) | E32: =ABS('表 105_滾算紀錄2'!E50) | F32: =ABS('表 105_滾算紀錄2'!F50) | G32: =ABS('表 105_滾算紀錄2'!G50) | H32: =ABS('表 105_滾算紀錄2'!H50) | I32: =ABS('表 105_滾算紀錄2'!I50) | J32: =ABS('表 105_滾算紀錄2'!J50) | K32: =ABS('表 105_滾算紀錄2'!K50) | ... W32: =ABS('表 105_滾算紀錄2'!W50)
B33: 表 105 | D33: =ABS('表 105_滾算紀錄3'!D50) | E33: =ABS('表 105_滾算紀錄3'!E50) | F33: =ABS('表 105_滾算紀錄3'!F50) | G33: =ABS('表 105_滾算紀錄3'!G50) | H33: =ABS('表 105_滾算紀錄3'!H50) | I33: =ABS('表 105_滾算紀錄3'!I50) | J33: =ABS('表 105_滾算紀錄3'!J50) | K33: =ABS('表 105_滾算紀錄3'!K50) | ... W33: =ABS('表 105_滾算紀錄3'!W50)
C34: 模組回收費/年總計 | D34: =SUM(D31:D33) | E34: =SUM(E31:E33) | F34: =SUM(F31:F33) | G34: =SUM(G31:G33) | H34: =SUM(H31:H33) | I34: =SUM(I31:I33) | J34: =SUM(J31:J33) | K34: =SUM(K31:K33) | ... W34: =SUM(W31:W33)
C35: 所得稅 | D35: 2023 | E35: 2024 | F35: 2025 | G35: 2026 | H35: 2027 | I35: 2028 | J35: 2029 | K35: 2030 | L35: 2031 | M35: 2032 | N35: 2033 | O35: 2034 | P35: 2035 | Q35: 2036 | R35: 2037 | S35: 2038 | T35: 2039 | U35: 2040 | V35: 2041 | W35: 2042
B36: 表 105 | D36: =ABS('表 105_滾算紀錄1'!D54) | E36: =ABS('表 105_滾算紀錄1'!E54) | F36: =ABS('表 105_滾算紀錄1'!F54) | G36: =ABS('表 105_滾算紀錄1'!G54) | H36: =ABS('表 105_滾算紀錄1'!H54) | I36: =ABS('表 105_滾算紀錄1'!I54) | J36: =ABS('表 105_滾算紀錄1'!J54) | K36: =ABS('表 105_滾算紀錄1'!K54) | ... W36: =ABS('表 105_滾算紀錄1'!W54)
B37: 表 105 | D37: =ABS('表 105_滾算紀錄2'!D54) | E37: =ABS('表 105_滾算紀錄2'!E54) | F37: =ABS('表 105_滾算紀錄2'!F54) | G37: =ABS('表 105_滾算紀錄2'!G54) | H37: =ABS('表 105_滾算紀錄2'!H54) | I37: =ABS('表 105_滾算紀錄2'!I54) | J37: =ABS('表 105_滾算紀錄2'!J54) | K37: =ABS('表 105_滾算紀錄2'!K54) | ... W37: =ABS('表 105_滾算紀錄2'!W54)
B38: 表 105 | D38: =ABS('表 105_滾算紀錄3'!D54) | E38: =ABS('表 105_滾算紀錄3'!E54) | F38: =ABS('表 105_滾算紀錄3'!F54) | G38: =ABS('表 105_滾算紀錄3'!G54) | H38: =ABS('表 105_滾算紀錄3'!H54) | I38: =ABS('表 105_滾算紀錄3'!I54) | J38: =ABS('表 105_滾算紀錄3'!J54) | K38: =ABS('表 105_滾算紀錄3'!K54) | ... W38: =ABS('表 105_滾算紀錄3'!W54)
C39: 所得稅/年總計 | D39: =SUM(D36:D38) | E39: =SUM(E36:E38) | F39: =SUM(F36:F38) | G39: =SUM(G36:G38) | H39: =SUM(H36:H38) | I39: =SUM(I36:I38) | J39: =SUM(J36:J38) | K39: =SUM(K36:K38) | ... W39: =SUM(W36:W38)
C40: 設備折舊 | D40: 2023 | E40: 2024 | F40: 2025 | G40: 2026 | H40: 2027 | I40: 2028 | J40: 2029 | K40: 2030 | L40: 2031 | M40: 2032 | N40: 2033 | O40: 2034 | P40: 2035 | Q40: 2036 | R40: 2037 | S40: 2038 | T40: 2039 | U40: 2040 | V40: 2041 | W40: 2042
B41: 表 105 | D41: =ABS('表 105_滾算紀錄1'!D67) | E41: =ABS('表 105_滾算紀錄1'!E67) | F41: =ABS('表 105_滾算紀錄1'!F67) | G41: =ABS('表 105_滾算紀錄1'!G67) | H41: =ABS('表 105_滾算紀錄1'!H67) | I41: =ABS('表 105_滾算紀錄1'!I67) | J41: =ABS('表 105_滾算紀錄1'!J67) | K41: =ABS('表 105_滾算紀錄1'!K67) | ... W41: =ABS('表 105_滾算紀錄1'!W67)
B42: 表 105 | D42: =ABS('表 105_滾算紀錄2'!D67) | E42: =ABS('表 105_滾算紀錄2'!E67) | F42: =ABS('表 105_滾算紀錄2'!F67) | G42: =ABS('表 105_滾算紀錄2'!G67) | H42: =ABS('表 105_滾算紀錄2'!H67) | I42: =ABS('表 105_滾算紀錄2'!I67) | J42: =ABS('表 105_滾算紀錄2'!J67) | K42: =ABS('表 105_滾算紀錄2'!K67) | ... W42: =ABS('表 105_滾算紀錄2'!W67)
B43: 表 105 | D43: =ABS('表 105_滾算紀錄3'!D67) | E43: =ABS('表 105_滾算紀錄3'!E67) | F43: =ABS('表 105_滾算紀錄3'!F67) | G43: =ABS('表 105_滾算紀錄3'!G67) | H43: =ABS('表 105_滾算紀錄3'!H67) | I43: =ABS('表 105_滾算紀錄3'!I67) | J43: =ABS('表 105_滾算紀錄3'!J67) | K43: =ABS('表 105_滾算紀錄3'!K67) | ... W43: =ABS('表 105_滾算紀錄3'!W67)
...

Sheet 表 105_滾算紀錄1
B1: 電站基本資料 | P1: =1-D11 | Q1: =P1-$D12 | R1: =Q1-$D12 | S1: =R1-$D12 | T1: =S1-$D12 | U1: =T1-$D12 | V1: =U1-$D12 | W1: =V1-$D12 | X1: =W1-$D12 | ... AI1: =AH1-$D12
B2: 電站名稱 | C2: 淡江大學-財務模擬案場 | D2: - | E2: -
B3: 電站壽命 | C3: 20 | D3: - | E3: -
B4: 建置量(kWp) | C4: 436.1 | D4: - | E4: - | M4: 滾算紀錄編號: 1
B5: 起始年度 | C5: 2023 | D5: 結束年度 | E5: 2042 | M5: 初始價金摘要
M6: 價金: 35000
B7: 綜合損益表 | M7: 專案IRR: 1.54
B8: 收入 | M8: 權益法IRR: 1.27
B9: 收支項目 | C9: 相關參數 | D9: 參數數值 | E9: 年限 | M9: 利潤率: 30.00%
B10: 電費收入 | C10: 年度AC併網總發電量 | D10: 547002 | E10: 20 | M10: 初始價金 - 現金模式，每次減少 1000 元
C11: 首年衰退率 | D11: 0.01
C12: 次年衰退率 | D12: 0.004
C13: 躉售費率(FIT) | D13: 3.7152
B14: 支出
B15: 收支項目 | C15: 相關參數 | D15: 參數數值 | E15: 攤提年限
B16: 設備費用(價金) | C16: 每kWp設備成本 | D16: 35000 | E16: 20
C17: 信邦利潤率 | D17: 0.3
C18: 開發費 | D18: 3000
B19: 租金費用 | C19: 租金計算方式 (1=固定攤提/2=電費抽成) | D19: 1 | E19: 0
C20: 【方式1參數】租金總額 | D20: 290201 | E20: 20
C21: 【方式2參數】抽成比率 | D21: 0 | E21: 0
B22: 運維費用 | C22: 每kw運維成本 | D22: 400 | E22: 20
B23: 保險費用 | C23: 占整體設備費用比例 | D23: 0.003 | E23: 20
B24: 模組回收費用 | C24: 每kw模組回收成本 | D24: 1000 | E24: 10
B25: 利息費用 | C25: 銀行利率 | D25: 0.025595 | E25: 0
B26: 所得稅 | C26: 所得稅率 | D26: 0.2 | E26: 0
B29: 現金流量表
B30: 金流項目 | C30: 相關參數 | D30: 參數數值
B31: 貸款成數 | C31: 占總設備費用比例 | D31: 0.8
B32: 貸款還款 | C32: 攤還期數 | D32: 15
B33: 現金股利 | C33: 股利比率 | D33: 0.9
B34: 年底減資 | C34: 攤還期數 | D34: 4
C37: 年份 | D37: 2023 | E37: 2024 | F37: 2025 | G37: 2026 | H37: 2027 | I37: 2028 | J37: 2029 | K37: 2030 | L37: 2031 | M37: 2032 | N37: 2033 | O37: 2034 | P37: 2035 | Q37: 2036 | R37: 2037 | S37: 2038 | T37: 2039 | U37: 2040 | V37: 2041 | W37: 2042
B38: 0
B39: (Unit : Currency) | C39: 0 | D39: 1 | E39: 2 | F39: 3 | G39: 4 | H39: 5 | I39: 6 | J39: 7 | K39: 8 | L39: 9 | M39: 10 | N39: 11 | O39: 12 | P39: 13 | Q39: 14 | R39: 15 | S39: 16 | T39: 17 | U39: 18 | V39: 19 | W39: 20
B40: 發電度數(KWH) | C40: 0 | D40: =$D$10*P1 | E40: =$D$10*Q1 | F40: =$D$10*R1 | G40: =$D$10*S1 | H40: =$D$10*T1 | I40: =$D$10*U1 | J40: =$D$10*V1 | K40: =$D$10*W1 | ... W40: =$D$10*AI1
B41: Inflow : 電費收入 | C41: - | D41: =D40*$D$13 | E41: =E40*$D$13 | F41: =F40*$D$13 | G41: =G40*$D$13 | H41: =H40*$D$13 | I41: =I40*$D$13 | J41: =J40*$D$13 | K41: =K40*$D$13 | ... W41: =W40*$D$13
B42: Inflow : 政府補助 | C42: - | G42: - | H42: - | I42: - | J42: - | K42: - | L42: - | M42: - | N42: - | O42: - | P42: - | Q42: - | R42: - | S42: - | T42: - | U42: - | V42: - | W42: -
B43: Inflow : 銀行借款
B44: Outflow : 設備費用 | C44: =-(D16/(1-D17)+D18)*C4
...

Sheet 表 105_滾算紀錄2
B1: 電站基本資料 | P1: =1-D11 | Q1: =P1-$D12 | R1: =Q1-$D12 | S1: =R1-$D12 | T1: =S1-$D12 | U1: =T1-$D12 | V1: =U1-$D12 | W1: =V1-$D12 | X1: =W1-$D12 | ... AI1: =AH1-$D12
B2: 電站名稱 | C2: 淡江大學-財務模擬案場 | D2: - | E2: -
B3: 電站壽命 | C3: 20 | D3: - | E3: -
B4: 建置量(kWp) | C4: 436.1 | D4: - | E4: - | M4: 滾算紀錄編號: 2
B5: 起始年度 | C5: 2023 | D5: 結束年度 | E5: 2042 | M5: 第1次滾算摘要
M6: 價金: 34000
B7: 綜合損益表 | M7: 專案IRR: 1.78
B8: 收入 | M8: 權益法IRR: 1.99
B9: 收支項目 | C9: 相關參數 | D9: 參數數值 | E9: 年限 | M9: 利潤率: 30.00%
B10: 電費收入 | C10: 年度AC併網總發電量 | D10: 547002 | E10: 20 | M10: 第1次滾算，減少 1000 元 - 現金模式，每次減少 1000 元
C11: 首年衰退率 | D11: 0.01
C12: 次年衰退率 | D12: 0.004
C13: 躉售費率(FIT) | D13: 3.7152
B14: 支出
B15: 收支項目 | C15: 相關參數 | D15: 參數數值 | E15: 攤提年限
B16: 設備費用(價金) | C16: 每kWp設備成本 | D16: 34000 | E16: 20
C17: 信邦利潤率 | D17: 0.3
C18: 開發費 | D18: 3000
B19: 租金費用 | C19: 租金計算方式 (1=固定攤提/2=電費抽成) | D19: 1 | E19: 0
C20: 【方式1參數】租金總額 | D20: 290201 | E20: 20
C21: 【方式2參數】抽成比率 | D21: 0 | E21: 0
B22: 運維費用 | C22: 每kw運維成本 | D22: 400 | E22: 20
B23: 保險費用 | C23: 占整體設備費用比例 | D23: 0.003 | E23: 20
B24: 模組回收費用 | C24: 每kw模組回收成本 | D24: 1000 | E24: 10
B25: 利息費用 | C25: 銀行利率 | D25: 0.025595 | E25: 0
B26: 所得稅 | C26: 所得稅率 | D26: 0.2 | E26: 0
B29: 現金流量表
B30: 金流項目 | C30: 相關參數 | D30: 參數數值
B31: 貸款成數 | C31: 占總設備費用比例 | D31: 0.8
B32: 貸款還款 | C32: 攤還期數 | D32: 15
B33: 現金股利 | C33: 股利比率 | D33: 0.9
B34: 年底減資 | C34: 攤還期數 | D34: 4
C37: 年份 | D37: 2023 | E37: 2024 | F37: 2025 | G37: 2026 | H37: 2027 | I37: 2028 | J37: 2029 | K37: 2030 | L37: 2031 | M37: 2032 | N37: 2033 | O37: 2034 | P37: 2035 | Q37: 2036 | R37: 2037 | S37: 2038 | T37: 2039 | U37: 2040 | V37: 2041 | W37: 2042
B38: 0
B39: (Unit : Currency) | C39: 0 | D39: 1 | E39: 2 | F39: 3 | G39: 4 | H39: 5 | I39: 6 | J39: 7 | K39: 8 | L39: 9 | M39: 10 | N39: 11 | O39: 12 | P39: 13 | Q39: 14 | R39: 15 | S39: 16 | T39: 17 | U39: 18 | V39: 19 | W39: 20
B40: 發電度數(KWH) | C40: 0 | D40: =$D$10*P1 | E40: =$D$10*Q1 | F40: =$D$10*R1 | G40: =$D$10*S1 | H40: =$D$10*T1 | I40: =$D$10*U1 | J40: =$D$10*V1 | K40: =$D$10*W1 | ... W40: =$D$10*AI1
B41: Inflow : 電費收入 | C41: - | D41: =D40*$D$13 | E41: =E40*$D$13 | F41: =F40*$D$13 | G41: =G40*$D$13 | H41: =H40*$D$13 | I41: =I40*$D$13 | J41: =J40*$D$13 | K41: =K40*$D$13 | ... W41: =W40*$D$13
B42: Inflow : 政府補助 | C42: - | G42: - | H42: - | I42: - | J42: - | K42: - | L42: - | M42: - | N42: - | O42: - | P42: - | Q42: - | R42: - | S42: - | T42: - | U42: - | V42: - | W42: -
B43: Inflow : 銀行借款
B44: Outflow : 設備費用 | C44: =-(D16/(1-D17)+D18)*C4
...

Sheet 表 105_滾算紀錄3
B1: 電站基本資料 | P1: =1-D11 | Q1: =P1-$D12 | R1: =Q1-$D12 | S1: =R1-$D12 | T1: =S1-$D12 | U1: =T1-$D12 | V1: =U1-$D12 | W1: =V1-$D12 | X1: =W1-$D12 | ... AI1: =AH1-$D12
B2: 電站名稱 | C2: 淡江大學-財務模擬案場 | D2: - | E2: -
B3: 電站壽命 | C3: 20 | D3: - | E3: -
B4: 建置量(kWp) | C4: 436.1 | D4: - | E4: - | M4: 滾算紀錄編號: 3
B5: 起始年度 | C5: 2023 | D5: 結束年度 | E5: 2042 | M5: 第2次滾算摘要
M6: 價金: 33000
B7: 綜合損益表 | M7: 專案IRR: 2.03
B8: 收入 | M8: 權益法IRR: 2.75
B9: 收支項目 | C9: 相關參數 | D9: 參數數值 | E9: 年限 | M9: 利潤率: 30.00%
B10: 電費收入 | C10: 年度AC併網總發電量 | D10: 547002 | E10: 20 | M10: 第2次滾算，減少 1000 元 - 現金模式，每次減少 1000 元
C11: 首年衰退率 | D11: 0.01
C12: 次年衰退率 | D12: 0.004
C13: 躉售費率(FIT) | D13: 3.7152
B14: 支出
B15: 收支項目 | C15: 相關參數 | D15: 參數數值 | E15: 攤提年限
B16: 設備費用(價金) | C16: 每kWp設備成本 | D16: 33000 | E16: 20
C17: 信邦利潤率 | D17: 0.3
C18: 開發費 | D18: 3000
B19: 租金費用 | C19: 租金計算方式 (1=固定攤提/2=電費抽成) | D19: 1 | E19: 0
C20: 【方式1參數】租金總額 | D20: 290201 | E20: 20
C21: 【方式2參數】抽成比率 | D21: 0 | E21: 0
B22: 運維費用 | C22: 每kw運維成本 | D22: 400 | E22: 20
B23: 保險費用 | C23: 占整體設備費用比例 | D23: 0.003 | E23: 20
B24: 模組回收費用 | C24: 每kw模組回收成本 | D24: 1000 | E24: 10
B25: 利息費用 | C25: 銀行利率 | D25: 0.025595 | E25: 0
B26: 所得稅 | C26: 所得稅率 | D26: 0.2 | E26: 0
B29: 現金流量表
B30: 金流項目 | C30: 相關參數 | D30: 參數數值
B31: 貸款成數 | C31: 占總設備費用比例 | D31: 0.8
B32: 貸款還款 | C32: 攤還期數 | D32: 15
B33: 現金股利 | C33: 股利比率 | D33: 0.9
B34: 年底減資 | C34: 攤還期數 | D34: 4
C37: 年份 | D37: 2023 | E37: 2024 | F37: 2025 | G37: 2026 | H37: 2027 | I37: 2028 | J37: 2029 | K37: 2030 | L37: 2031 | M37: 2032 | N37: 2033 | O37: 2034 | P37: 2035 | Q37: 2036 | R37: 2037 | S37: 2038 | T37: 2039 | U37: 2040 | V37: 2041 | W37: 2042
B38: 0
B39: (Unit : Currency) | C39: 0 | D39: 1 | E39: 2 | F39: 3 | G39: 4 | H39: 5 | I39: 6 | J39: 7 | K39: 8 | L39: 9 | M39: 10 | N39: 11 | O39: 12 | P39: 13 | Q39: 14 | R39: 15 | S39: 16 | T39: 17 | U39: 18 | V39: 19 | W39: 20
B40: 發電度數(KWH) | C40: 0 | D40: =$D$10*P1 | E40: =$D$10*Q1 | F40: =$D$10*R1 | G40: =$D$10*S1 | H40: =$D$10*T1 | I40: =$D$10*U1 | J40: =$D$10*V1 | K40: =$D$10*W1 | ... W40: =$D$10*AI1
B41: Inflow : 電費收入 | C41: - | D41: =D40*$D$13 | E41: =E40*$D$13 | F41: =F40*$D$13 | G41: =G40*$D$13 | H41: =H40*$D$13 | I41: =I40*$D$13 | J41: =J40*$D$13 | K41: =K40*$D$13 | ... W41: =W40*$D$13
B42: Inflow : 政府補助 | C42: - | G42: - | H42: - | I42: - | J42: - | K42: - | L42: - | M42: - | N42: - | O42: - | P42: - | Q42: - | R42: - | S42: - | T42: - | U42: - | V42: - | W42: -
B43: Inflow : 銀行借款
B44: Outflow : 設備費用 | C44: =-(D16/(1-D17)+D18)*C4
...
