Workbook
Name ret_tlt0: #REF!
Name ss: #REF!
Name Table0: 發電!$U$7:$AE$23
Name ret_tlt0: #REF!
Name ss: #REF!
Name ret_tlt0: #REF!
Name ss: #REF!
Name ret_tlt0: #REF!
Name ss: #REF!
Name ret_tlt0: #REF!
Name ss: #REF!
Name ret_tlt0: #REF!
Name ss: #REF!
Name ret_tlt0: #REF!
Name ss: #REF!
Name ret_tlt0: #REF!
Name ss: #REF!
Name ret_tlt0: #REF!
Name ss: #REF!
Name ret_tlt0: #REF!
Name ss: #REF!
Name ret_tlt0: #REF!
Name ret_tlt0: #REF!
Name ss: #REF!
Name ret_tlt0: #REF!
Name ret_tlt0: #REF!
Name ret_tlt0: #REF!
Name ss: #REF!
Name ret_tlt0: #REF!
Name ss: #REF!
Name ret_tlt0: #REF!

Sheet 等效
A1: Parameters for Tilted Solar Panels:
A3: =Q5 | B3: Jan | C3: Feb | D3: Mar | E3: Apr | F3: May | G3: Jun | H3: Jul | I3: Aug | J3: Sep | K3: Oct | L3: Nov | M3: Dec | N3: Annual | Q3: 請貼這→
A4: =R5 | N4: Average | Q4: LAT | R4: LON | S4: PARAMETER | T4: JAN | U4: FEB | V4: MAR | W4: APR | X4: MAY | Y4: JUN | Z4: JUL | AA4: AUG | AB4: SEP | AC4: OCT | AD4: NOV | AE4: DEC | AF4: ANN
A5: =SUBSTITUTE(S5,P5,"") | B5: =T5 | C5: =U5 | D5: =V5 | E5: =W5 | F5: =X5 | G5: =Y5 | H5: =Z5 | I5: =AA5 | ... N5: =AF5 | P5: ALLSKY_SFC_ | S5: ALLSKY_SFC_SW_DNI
A6: =SUBSTITUTE(S6,P6,"") | B6: =T6 | C6: =U6 | D6: =V6 | E6: =W6 | F6: =X6 | G6: =Y6 | H6: =Z6 | I6: =AA6 | ... N6: =AF6 | P6: ALLSKY_SFC_ | S6: ALLSKY_SFC_SW_DWN
A7: =SUBSTITUTE(S7,P7,"") | B7: =T7 | C7: =U7 | D7: =V7 | E7: =W7 | F7: =X7 | G7: =Y7 | H7: =Z7 | I7: =AA7 | ... N7: =AF7 | P7: ALLSKY_SFC_ | S7: ALLSKY_SFC_SW_DIFF
A8: =SUBSTITUTE(S8,P8,"") | B8: =T8 | C8: =U8 | D8: =V8 | E8: =W8 | F8: =X8 | G8: =Y8 | H8: =Z8 | I8: =AA8 | ... N8: =AF8 | P8: SI_EF_TILTED_SURFACE_ | S8: SI_EF_TILTED_SURFACE_HORIZONTAL
A9: =SUBSTITUTE(S9,P9,"") | B9: =T9 | C9: =U9 | D9: =V9 | E9: =W9 | F9: =X9 | G9: =Y9 | H9: =Z9 | I9: =AA9 | ... N9: =AF9 | P9: SI_EF_TILTED_SURFACE_ | S9: SI_EF_TILTED_SURFACE_LAT_MINUS15
A10: =SUBSTITUTE(S10,P10,"") | B10: =T10 | C10: =U10 | D10: =V10 | E10: =W10 | F10: =X10 | G10: =Y10 | H10: =Z10 | I10: =AA10 | ... N10: =AF10 | P10: SI_EF_TILTED_SURFACE_ | S10: SI_EF_TILTED_SURFACE_LATITUDE
A11: =SUBSTITUTE(S11,P11,"") | B11: =T11 | C11: =U11 | D11: =V11 | E11: =W11 | F11: =X11 | G11: =Y11 | H11: =Z11 | I11: =AA11 | ... N11: =AF11 | P11: SI_EF_TILTED_SURFACE_ | S11: SI_EF_TILTED_SURFACE_LAT_PLUS15
A12: =SUBSTITUTE(S12,P12,"") | B12: =T12 | C12: =U12 | D12: =V12 | E12: =W12 | F12: =X12 | G12: =Y12 | H12: =Z12 | I12: =AA12 | ... N12: =AF12 | P12: SI_EF_TILTED_SURFACE_ | S12: SI_EF_TILTED_SURFACE_VERTICAL
A13: =SUBSTITUTE(S13,P13,"") | B13: =T13 | C13: =U13 | D13: =V13 | E13: =W13 | F13: =X13 | G13: =Y13 | H13: =Z13 | I13: =AA13 | ... N13: =AF13 | P13: SI_EF_TILTED_SURFACE_ | S13: SI_EF_TILTED_SURFACE_OPTIMAL
A14: =SUBSTITUTE(S14,P14,"") | B14: =T14 | C14: =U14 | D14: =V14 | E14: =W14 | F14: =X14 | G14: =Y14 | H14: =Z14 | I14: =AA14 | ... N14: =AF14 | P14: SI_EF_TILTED_SURFACE_ | S14: SI_EF_TILTED_SURFACE_OPTIMAL_ANG
A15: =SUBSTITUTE(S15,P15,"") | B15: =T15 | C15: =U15 | D15: =V15 | E15: =W15 | F15: =X15 | G15: =Y15 | H15: =Z15 | I15: =AA15 | ... N15: =AF15 | P15: SI_EF_TILTED_SURFACE_ | S15: SI_EF_TILTED_SURFACE_OPTIMAL_ANG_ORT
A16: NOTE: Diffuse radiation, direct normal radiation and tilted surface radiation are not calculated when the clearness index (K) is below 0.3 or above 0.8.
P17: Location: Latitude | S17: Parameter(s):
A18: https://eosweb.larc.nasa.gov/cgi-bin/sse/grid.cgi?email=skip@larc.nasa.gov | P18: Longitude 120.8254 | S18: ALLSKY_SFC_SW_DNI | T18: 全天面短波向下直接法向輻照度 (kW-hr/m^2/day)
P19: Location: Latitude 24.5648 Longitude | S19: ALLSKY_SFC_SW_DWN | T19: 全天面短波下行輻照度 (kW-hr/m^2/day)
A20: https://power.larc.nasa.gov/data-access-viewer/ | E20: NEW | P20: =SUBSTITUTE(S3,P17,"") | S20: ALLSKY_SFC_SW_DIFF | T20: 全天表面短波漫射輻照度 (kW-hr/m^2/day)
S21: SI_EF_TILTED_SURFACE_HORIZONTAL | T21: 赤道面向水平面的太陽輻照度（kW-hr/m^2/day）
S22: SI_EF_TILTED_SURFACE_LAT_MINUS15 | T22: 赤道面向緯度減 15 傾斜的太陽輻照度 (kW-hr/m^2/day)
S23: SI_EF_TILTED_SURFACE_LATITUDE | T23: 赤道面向緯度傾斜的太陽輻照度（kW-hr/m^2/day）
S24: SI_EF_TILTED_SURFACE_LAT_PLUS15 | T24: 面向赤道緯度加上 15 傾斜度的太陽輻照度（kW-hr/m^2/day）
S25: SI_EF_TILTED_SURFACE_VERTICAL | T25: 面向赤道垂直表面的太陽輻照度（kW-hr/m^2/day）
S26: SI_EF_TILTED_SURFACE_OPTIMAL | T26: 太陽輻照度最佳 (kW-hr/m^2/day)
S27: SI_EF_TILTED_SURFACE_OPTIMAL_ANG | T27: 太陽輻照度最佳角度（度）
S28: SI_EF_TILTED_SURFACE_OPTIMAL_ANG_ORT | T28: 太陽輻照度傾斜表面方向（N/S 方向）

Sheet 費率
C2: 苗栗為分界
B3: 屋 | C3: 北 | D3: 111年 | E3: 上 | F3: 下 | H3: 躉售費率 | L3: 本案適用級距 | M3: 本案適用費率欄位(行) | P3: 本案適用級距欄位(列)
B4: 頂 | D4: 1-<20 kW | E4: =E10*1.15 | F4: =F10*1.15 | H4: =INDEX(D3:F6,P4,M4) | L4: =IF(#REF!="屋頂",IF(#REF!<20,費率!D4,IF(#REF!<100,費率!D5,費率!D6)),0) | M4: =MATCH(#REF!,費率!D3:F3,0) | P4: =MATCH(L4,D3:D6,0)
B5: 型 | D5: 20-<100 kW | E5: =E11*1.15 | F5: =F11*1.15 | J5: 合併計算
D6: 100-<500kW | E6: =E12*1.15 | F6: =F12*1.15 | J6: =IF(#REF!="屋頂",IF(#REF!="否",IF(L11=7,H10,IF(L11=1,H4)),IF(L11=7,H20,IF(L11=1,H17))),IF(L11=7,H27,IF(L11=1,H24)))
L7: 本案適用級距 | M7: 本案適用費率欄位(行) | P7: 本案適用級距欄位(列)
C8: 苗栗為分界 | J8: 實際費率看回收頁 | L8: =IF(#REF!="屋頂",IF(#REF!<20,費率!D10,IF(#REF!<100,費率!D11,費率!D12)),0) | M8: =MATCH(#REF!,費率!D9:F9,0) | P8: =MATCH(L8,D9:D12,0)
B9: 屋 | C9: 南 | D9: 111年 | E9: 上 | F9: 下 | H9: 躉售費率
B10: 頂 | D10: 1-<20 kW | E10: 5.8952 | F10: 5.7848 | H10: =INDEX(D9:F12,P8,M8) | L10: 選用費率
B11: 型 | D11: 20-<100 kW | E11: 4.5549 | F11: 4.4538 | L11: =MATCH(#REF!,費率!C3:C19,0)
D12: 100-<500kW | E12: 4.097 | F12: 3.9666
J13: 無合併計算
J14: =IF(L11=7,H10,IF(L11=1,H4))
C15: 苗栗為分界
B16: 屋 | C16: 北 | D16: 111年 | E16: 上 | F16: 下 | H16: 躉售費率 | L16: 本案適用級距 | M16: 本案適用費率欄位(行) | P16: 本案適用級距欄位(列)
B17: 頂 | D17: 500 kW↑ | E17: =E19*1.15 | F17: =F19*1.15 | H17: =INDEX(D16:F17,P17,M17) | L17: =IF(#REF!="屋頂",IF(#REF!="是",D17,0),0) | M17: =MATCH(#REF!,費率!D16:F16,0) | P17: =MATCH(L17,D16:D17,0)
B18: 型 | C18: 南 | D18: 111年 | E18: 上 | F18: 下 | L18: 本案適用級距 | M18: 本案適用費率欄位(行) | P18: 本案適用級距欄位(列)
D19: 500 kW↑ | E19: 4.1122 | F19: 3.9727 | H19: 躉售費率 | L19: =IF(#REF!="屋頂",IF(#REF!="是",D19,0),0) | M19: =MATCH(#REF!,費率!D18:F18,0) | P19: =MATCH(L19,D18:D19,0)
D20: 合併 | H20: =INDEX(D18:F19,P19,M19)
C22: 苗栗為分界
B23: 地 | C23: 北 | D23: 111年 | E23: 上 | F23: 下 | H23: 躉售費率 | L23: 本案適用級距 | M23: 本案適用費率欄位(行) | P23: 本案適用級距欄位(列)
B24: 面 | D24: 1 kW↑ | E24: =E26*1.15 | F24: =F26*1.15 | H24: =INDEX(D23:F24,P24,M24) | L24: =IF(#REF!="屋頂",0,D24) | M24: =MATCH(#REF!,費率!D23:F23,0) | P24: =MATCH(L24,D23:D24,0)
B25: 型 | C25: 南 | D25: 111年 | E25: 上 | F25: 下 | L25: 本案適用級距 | M25: 本案適用費率欄位(行) | P25: 本案適用級距欄位(列)
D26: 1 kW↑ | E26: 4.0031 | F26: 3.868 | H26: 躉售費率 | L26: =IF(#REF!="屋頂",0,D26) | M26: =MATCH(#REF!,費率!D25:F25,0) | P26: =MATCH(L26,D25:D26,0)
H27: =INDEX(D25:F26,P26,M26)
C31: 高效能模組(元/度)
C32: 屋頂型 | D32: 1-<20 kW | E32: 0.3471
D33: 20-<100 kW | E33: 0.2672
D34: 100-<500kW | E34: 0.238
D35: 500 kW↑ | E35: 0.2384
C37: 地面型 | D37: 1 kW↑ | E37: 0.2321

Sheet 發電
C2: 安裝總容量 | D2: =#REF! | E2: kW
C3: 設計傾角 | D3: SW_DWN | E3: 度
U4: 說明 | V4: 水平面總輻射量 | W4: 水平面散射輻射量 | X4: 環境溫度 | Y4: 入射採光面上 的總輻射量 | Z4: 陣列輸出的 有效能量 | AA4: 併網電量 | AB4: 系統效率PR值 | AC4: 等效日照 | AD4: 有效日照
C5: 1 | D5: 2 | E5: 3 | F5: 4 | G5: 5 | H5: 6 | I5: 7 | J5: 8 | K5: 9 | L5: 10 | M5: 11 | N5: 12 | O5: 13 | P5: 14
C6: 系統PR值 | D6: =AB22
C8: 發電量評估 | D8: 一月 | E8: 二月 | F8: 三月 | G8: 四月 | H8: 五月 | I8: 六月 | J8: 七月 | K8: 八月 | L8: 九月 | M8: 十月 | N8: 十一月 | O8: 十二月 | P8: 每年 總發電量 (度/每年) | Q8: 每年 每KW總發電量 (度/KW/每年) | S8: 有效日照 | V8: GlobHor | W8: DiffHor | X8: T_Amb | Y8: GlobInc | Z8: EArray | AA8: E_Grid | AB8: PR | AC8: Yr | AD8: Yf
C9: AC 併網總發電量 (度/月) | S9: =Q9/365 | V9: kWh/m² | W9: kWh/m² | X9: °C | Y9: kWh/m² | Z9: kWh | AA9: kWh | AB9: ratio | AC9: kWh/m²/day | AD9: kWh/kWp/day
U10: 1月
U11: 2月
L12: 衰退率 | M12: 首年 | N12: 0.01 | U12: 3月
C13: 手動計算值 | M13: 第2-25年 | N13: 0.004 | U13: 4月
U14: 5月
C15: 模組衰減率(年) | D15: 0.004 | L15: 衰退率 | M15: 年 | N15: 遞減% | O15: 模組瓦數(W) | U15: 6月
C16: 發電量計算 | D16: 年發電量(KWH) | F16: 年躉電收入(NTD) | H16: 累計躉電收入(NTD) | L16: 0 | M16: 0 | N16: 1 | O16: 550 | U16: 7月
C17: 第1年 | J17: =N17 | L17: =$N$12 | M17: 1 | N17: =N16-L17 | O17: =$O$16*N17 | U17: 8月
C18: 第2年 | J18: =N18 | L18: =$N$13 | M18: 2 | N18: =N17-L18 | O18: =$O$16*N18 | U18: 9月
C19: 第3年 | J19: =N19 | L19: =$N$13 | M19: 3 | N19: =N18-L19 | O19: =$O$16*N19 | U19: 10月
C20: 第4年 | J20: =N20 | L20: =$N$13 | M20: 4 | N20: =N19-L20 | O20: =$O$16*N20 | U20: 11月
C21: 第5年 | J21: =N21 | L21: =$N$13 | M21: 5 | N21: =N20-L21 | O21: =$O$16*N21 | U21: 12月
C22: 第6年 | J22: =N22 | L22: =$N$13 | M22: 6 | N22: =N21-L22 | O22: =$O$16*N22 | U22: 年
C23: 第7年 | J23: =N23 | L23: =$N$13 | M23: 7 | N23: =N22-L23 | O23: =$O$16*N23
C24: 第8年 | J24: =N24 | L24: =$N$13 | M24: 8 | N24: =N23-L24 | O24: =$O$16*N24
C25: 第9年 | J25: =N25 | L25: =$N$13 | M25: 9 | N25: =N24-L25 | O25: =$O$16*N25
C26: 第10年 | J26: =N26 | L26: =$N$13 | M26: 10 | N26: =N25-L26 | O26: =$O$16*N26
C27: 第11年 | J27: =N27 | L27: =$N$13 | M27: 11 | N27: =N26-L27 | O27: =$O$16*N27
C28: 第12年 | J28: =N28 | L28: =$N$13 | M28: 12 | N28: =N27-L28 | O28: =$O$16*N28
C29: 第13年 | J29: =N29 | L29: =$N$13 | M29: 13 | N29: =N28-L29 | O29: =$O$16*N29
C30: 第14年 | J30: =N30 | L30: =$N$13 | M30: 14 | N30: =N29-L30 | O30: =$O$16*N30
C31: 第15年 | J31: =N31 | L31: =$N$13 | M31: 15 | N31: =N30-L31 | O31: =$O$16*N31
C32: 第16年 | J32: =N32 | L32: =$N$13 | M32: 16 | N32: =N31-L32 | O32: =$O$16*N32
C33: 第17年 | J33: =N33 | L33: =$N$13 | M33: 17 | N33: =N32-L33 | O33: =$O$16*N33
C34: 第18年 | J34: =N34 | L34: =$N$13 | M34: 18 | N34: =N33-L34 | O34: =$O$16*N34
... C36: 第20年 | J36: =N36 | L36: =$N$13 | M36: 20 | N36: =N35-L36 | O36: =$O$16*N36
L37: =$N$13 | M37: 21 | N37: =N36-L37 | O37: =$O$16*N37
C38: 平均值 | L38: =$N$13 | M38: 22 | N38: =N37-L38 | O38: =$O$16*N38
L39: =$N$13 | M39: 23 | N39: =N38-L39 | O39: =$O$16*N39
L40: =$N$13 | M40: 24 | N40: =N39-L40 | O40: =$O$16*N40
L41: =$N$13 | M41: 25 | N41: =N40-L41 | O41: =$O$16*N41

Sheet 成本
B2: =#REF! | D2: =#REF! | E2: kW系統設置成本分析 | F2: 工程利潤 (未稅售價-未稅成本) /未稅售價 | H2: =($M$175-$O$175)/$M$175 | J2: 實際利潤 (未稅售價-未稅成本) /未稅售價 | L2: =($M$175-$P$175)/$M$175
B4: 編號 | C4: 名 稱 | F4: 業務報價用 (單價NTD) | G4: 業務 倍率 | H4: PM buffer (單價NTD) | I4: PM 倍率 | J4: 實際單價 (NTD) | K4: 數量 | L4: 單位 | M4: 業務報價 (NTD) | N4: PM buffer (NTD) | O4: 預估成本 (NTD) | P4: 實際報價 | Q4: 備 註
B5: 模組及逆變器
B6: 1 | C6: DCPV | F6: =H6*G6 | G6: 1.2 | H6: =I6*J6 | I6: 1.05 | J6: =模組!E3*模組!D3*#REF! | K6: =#REF! | L6: 片 | M6: =F6*K6 | N6: =H6*K6 | O6: =J6*K6
B7: 2 | C7: Micro Inverter | F7: =H7*G7 | G7: 1.7 | H7: =I7*J7 | I7: 1.05 | J7: =微逆變!E3*#REF! | K7: 0 | L7: 台 | M7: =F7*K7 | N7: =H7*K7 | O7: =J7*K7 | T7: 含inverter加工及配件
B8: 3 | C8: String Iinverter | F8: =H8*G8 | G8: 1.2 | H8: =I8*J8 | I8: 1.05 | J8: =逆變!F8 | K8: 0 | L8: 式 | M8: =F8*K8 | N8: =H8*K8 | O8: =J8*K8 | T8: x 牌 x 台 x KW; x 牌 x 台 x KW
B9: 4 | C9: 獨立Iinverter | F9: =H9*G9 | G9: 1.05 | H9: =I9*J9 | I9: 1.05 | J9: ='(獨)逆變'!F3 | K9: 0 | L9: 台 | M9: =F9*K9 | N9: =H9*K9 | O9: =J9*K9 | T9: x 牌 x 台 x KW; x 牌 x 台 x KW
L10: 小計 | M10: =SUM(M6:M9) | N10: =SUM(N6:N9) | O10: =SUM(O6:O9)
L11: 平均1KW(未稅) | M11: =M10/$D$2 | N11: =N10/$D$2 | O11: =O10/$D$2
B12: 文件&行政
B13: 1 | C13: 市電躉售併聯申請 | F13: =H13*G13 | G13: 1.2 | H13: =I13*J13 | I13: 1.05 | J13: =IF(D2<100,行政!D20,行政!D3)*0+行政!D3 | L13: 式 | M13: =F13*K13 | N13: =H13*K13 | O13: =J13*K13 | Q13: 單期500~2MW $86000/式 | T13: 工程圖說需有甲級蓋章
B14: 2 | C14: 結構技師簽證 | F14: =H14*G14 | G14: 1.2 | H14: =I14*J14 | I14: 1.05 | J14: =行政!D7*0+D2*80 | L14: 式 | M14: =F14*K14 | N14: =H14*K14 | O14: =J14*K14 | Q14: 80/kW | T14: 含結構計算及完竣表
B15: 3 | C15: 電機技師簽證費(100KW以上需要) | F15: =H15*G15 | G15: 1.2 | H15: =I15*J15 | I15: 1.05 | J15: =IF(D2<500,行政!D54,行政!D54+IF((D2-500)<500,行政!D54,IF((D2-500)<=1000,行政!D56,IF((D2-500)<=1500,行政!D57,IF((D2-500)<=2000,行政!D58)))))*0+行政!D11 | L15: 式 | M15: =F15*K15 | N15: =H15*K15 | O15: =J15*K15
B16: 4 | C16: 電機技師簽證費(APS簽證) | F16: =H16*G16 | G16: 1.05 | H16: =I16*J16 | I16: 1.05 | J16: =行政!D55 | L16: 式 | M16: =F16*K16 | N16: =H16*K16 | O16: =J16*K16 | T16: 100kW↓
B17: 5 | C17: 太陽光電乙級技術士簽證 | F17: =H17*G17 | G17: 1.2 | H17: =I17*J17 | I17: 1.05 | J17: =行政!D65 | L17: 式 | M17: =F17*K17 | N17: =H17*K17 | O17: =J17*K17 | T17: 100kW↓
F18: =H18*G18 | G18: 1.05 | H18: =I18*J18 | I18: 1.05 | L18: 式 | M18: =F18*K18 | N18: =H18*K18 | O18: =J18*K18
L19: 小計 | M19: =SUM(M13:M17) | N19: =SUM(N13:N17) | O19: =SUM(O13:O18)
L20: 平均1KW(未稅) | M20: =M19/$D$2 | N20: =N19/$D$2 | O20: =O19/$D$2
B21: 設計監造
B22: 1 | C22: 系統設計監造及設計費 | F22: =H22*G22 | G22: 1.05 | H22: =I22*J22 | I22: 1.05 | J22: 50000 | K22: 0 | L22: 式 | M22: =F22*K22 | N22: =H22*K22 | O22: 0 | T22: sinbon監造, sinbon設計電力系統(結構圖繪製,電力圖繪製)
B23: 2 | C23: 開發費 | F23: =H23*G23 | G23: 1 | H23: =I23*J23 | I23: 1 | J23: 3000 | K23: 0 | L23: KW | M23: =F23*K23 | N23: =H23*K23 | O23: =J23*K23
L24: 小計 | M24: =SUM(M22:M23) | N24: =SUM(N22:N23) | O24: =SUM(O22:O23)
L25: 平均1KW(未稅) | M25: =M24/$D$2 | N25: =N24/$D$2 | O25: =O24/$D$2
B26: 鋼料結構工程
B27: 1 | C27: 材料費用: H型鋼 | F27: =H27*G27 | G27: 1.05 | H27: =I27*J27 | I27: 1.05 | J27: =鋼構!D3*1.4*1.4*1.1 | K27: 0 | L27: KG | M27: =F27*K27 | N27: =H27*K27 | O27: =J27*K27 | P27: 1.4*1.4*1.1 | T27: (規格)
B28: 2 | C28: 材料費用: C型鋼 | F28: =H28*G28 | G28: 1.05 | H28: =I28*J28 | I28: 1.05 | J28: =鋼構!F3*1.4*1.4*1.1 | K28: 0 | L28: KG | M28: =F28*K28 | N28: =H28*K28 | O28: =J28*K28 | P28: 1.4*1.4*1.1 | T28: (規格)
B29: 3 | C29: 材料費用: 熱浸鍍鋅費用 | F29: =H29*G29 | G29: 1.05 | H29: =I29*J29 | I29: 1.05 | J29: =鋼構!H3*1.1 | K29: 0 | L29: KG | M29: =F29*K29 | N29: =H29*K29 | O29: =J29*K29 | P29: *1.1 | T29: 噴砂噴漆 $8/kg
B30: 4 | C30: 材料費用: 五金配件+人工 | F30: =H30*G30 | G30: 1.05 | H30: =I30*J30 | I30: 1.05 | J30: =鋼構!J3 | K30: 0 | L30: KG | M30: =F30*K30 | N30: =H30*K30 | O30: =J30*K30 | T30: 葉23，尚25；耐17
B31: 5 | C31: 材料費用: 水泥基礎 | F31: =H31*G31 | G31: 1.05 | H31: =I31*J31 | I31: 1.05 | J31: =鋼構!L3 | L31: 柱 | M31: =F31*K31 | N31: =H31*K31 | O31: =J31*K31 | T31: 葉老闆
B32: 6 | C32: 材料費用: 吊運費 | F32: =H32*G32 | G32: 1.05 | H32: =I32*J32 | I32: 1.05 | J32: =鋼構!N3 | K32: 0 | L32: KG | M32: =F32*K32 | N32: =H32*K32 | O32: =J32*K32
B33: 7 | C33: 材料費用: 管理費 | F33: =H33*G33 | G33: 1.05 | H33: =I33*J33 | I33: 1.05 | J33: =(O27+O28+O29+O30+O31+O32)*0.08 | K33: 1 | L33: 式 | M33: =F33*K33 | N33: =H33*K33 | O33: =J33*K33
B34: 8 | C34: 材料費用: 膨脹螺栓(與樓板結合) | F34: =H34*G34 | G34: 1.05 | H34: =I34*J34 | I34: 1.05 | J34: 0 | K34: 0 | L34: 式 | M34: =F34*K34 | N34: =H34*K34 | O34: =J34*K34
B35: 9 | C35: 材料費用: 白鐵花紋板 | F35: =H35*G35 | G35: 1.05 | H35: =I35*J35 | I35: 1.05 | J35: 0 | K35: 0 | L35: 式 | M35: =F35*K35 | N35: =H35*K35 | O35: =J35*K35
B36: 10 | C36: 材料費用: 維修走道 (鋼構用) | F36: =H36*G36 | G36: 1.05 | H36: =I36*J36 | I36: 1.05 | J36: =500*1.2 | K36: 0 | L36: 張 | M36: =F36*K36 | N36: =H36*K36 | O36: =J36*K36 | P36: 1.2 | T36: 400x2400mm/張 $500
B37: 11 | C37: 爬梯+護籠 | F37: =H37*G37 | G37: 1.05 | H37: =I37*J37 | I37: 1.05 | J37: =材料!E32*1.2 | K37: 0 | L37: 米 | M37: =F37*K37 | N37: =H37*K37 | O37: =J37*K37 | P37: 1.2 | T37: 中苗，金明案發包價
B38: 12 | C38: 既設烤漆_清板 0.52T(盛餘) | F38: =H38*G38 | G38: 1.05 | H38: =I38*J38 | I38: 1.05 | J38: =材料!E15*1.15*1.2 | K38: 0 | L38: 坪 | M38: =F38*K38 | N38: =H38*K38 | O38: =J38*K38 | P38: 1.2 | T38: 1坪=3.3平方公尺，含Z或口型鋼
B39: 13 | C39: 新設烤漆_清板 0.52T(盛餘) | F39: =H39*G39 | G39: 1.05 | H39: =I39*J39 | I39: 1.05 | J39: =材料!E14*1.2 | K39: 0 | L39: 坪 | M39: =F39*K39 | N39: =H39*K39 | O39: =J39*K39 | P39: 1.2 | T39: 1坪=3.3平方公尺
B40: 14 | C40: 新設烤漆_雙層鋼板 0.52T(盛餘) | F40: =H40*G40 | G40: 1.05 | H40: =I40*J40 | I40: 1.05 | J40: =材料!E16*1.2 | K40: 0 | L40: 坪 | M40: =F40*K40 | N40: =H40*K40 | O40: =J40*K40 | P40: 1.2 | T40: 業界也稱「三明治板」
B41: 15 | C41: 不鏽鋼水槽(0.4T) | F41: =H41*G41 | G41: 1.05 | H41: =I41*J41 | I41: 1.05 | J41: =材料!E37*1.2 | K41: 0 | L41: 米 | M41: =F41*K41 | N41: =H41*K41 | O41: =J41*K41 | P41: 1.2
B42: 16 | C42: 收邊 烤漆鋁鋅板 | F42: =H42*G42 | G42: 1.05 | H42: =I42*J42 | I42: 1.05 | J42: =材料!E41*1.2 | K42: 0 | L42: 米 | M42: =F42*K42 | N42: =H42*K42 | O42: =J42*K42 | P42: 1.2
...

Sheet 報價
C2: =成本!D2 | D2: KW交流太陽能光電板發電系統 | L2: =C2 | M2: KW交流太陽能光電板發電系統
B3: 編號 | C3: 名稱 | D3: 數量 | E3: 單位 | F3: 小計 | G3: 備註 | K3: 編號 | L3: 名稱 | M3: 數量 | N3: 單位 | O3: 小計 | P3: 備註
B4: 1 | C4: 太陽能模組 | D4: =成本!K6 | E4: 片 | F4: =成本!M6 | K4: 1 | L4: =C4 | M4: =D4 | N4: 片 | O4: 9168000 | P4: 20年保固
B5: 2 | C5: 逆變器 | D5: 1 | E5: 式 | F5: =成本!M8 | K5: 2 | L5: =C5 | M5: =D5 | N5: 式 | O5: 2375000 | P5: 20年保固
B6: 3 | C6: 市電躉售併聯申請 | D6: 1 | E6: 式 | F6: =成本!M13 | K6: 3 | L6: =C6 | M6: =D6 | N6: 式 | O6: 168000 | P6: 台電、能源局、建管。
B7: 4 | C7: 結構技師簽證 | D7: 1 | E7: 式 | F7: =成本!M14 | K7: 4 | L7: =C7 | M7: =D7 | N7: 式 | O7: 80000
B8: 5 | C8: 電機技師簽證費 | D8: 1 | E8: 式 | F8: =成本!M15 | K8: 5 | L8: =C8 | M8: =D8 | N8: 式 | O8: =F8 | P8: 100kW以上，含系統衝擊分析。
B9: 6 | C9: 太陽光電乙級技術士簽證 | D9: 1 | E9: 式 | F9: =成本!M17 | K9: 6 | L9: =C9 | M9: =D9 | N9: 式 | O9: 8000 | P9: 100kW以下。
B10: 7 | C10: 太陽能系統監造及設計費用 | D10: 1 | E10: 式 | F10: =成本!M23 | K10: 7 | L10: =C10 | M10: =D10 | N10: 式 | O10: =F10
B11: 8 | C11: 鋼料結構工程 | D11: 1 | E11: 式 | F11: =成本!M43+成本!M47 | K11: 8 | L11: =C11 | M11: =D11 | N11: 式 | O11: =F11
B12: 9 | C12: 鋁合金結構工程 | D12: 1 | E12: 式 | F12: =成本!M65+成本!M70 | K12: 9 | L12: =C12 | M12: =D12 | N12: 式 | O12: 8816000 | P12: 含支架以及維修步道。
B13: 10 | C13: 水泥基座工程 | D13: 1 | E13: 式 | F13: =成本!M76+成本!M79 | K13: 10 | L13: =C13 | M13: =D13 | N13: 式 | O13: 1152000
B14: 11 | C14: 防水工程 | D14: 1 | E14: 式 | F14: =成本!M94+成本!M98 | K14: 11 | L14: =C14 | M14: =D14 | N14: 式 | O14: =F14
B15: 12 | C15: 系統監控工程 | D15: 1 | E15: 式 | F15: =成本!M115+成本!M118 | K15: 12 | L15: =C15 | M15: =D15 | N15: 式 | O15: 450000 | P15: 含監控箱體、錶頭、⽇照計、模組溫度計。
B16: 13 | C16: 太陽能系統配線工程 | D16: 1 | E16: 式 | F16: =成本!M137+成本!M147+成本!M152 | K16: 13 | L16: =C16 | M16: =D16 | N16: 式 | O16: 13380000 | P16: 含工帶料。 交流電纜線(太平洋/華新麗華)、太陽能專用直流線、金屬軟管、RSG管、PVC管、網路線、太陽能鋁線槽。 管線配置工程、動力管配線工程、配電盤設備安裝工程、監控安裝工程、太陽能系統測試工程。
B17: 14 | C17: 運輸及吊掛工程 | D17: 1 | E17: 式 | F17: =成本!M167 | K17: 14 | L17: =C17 | M17: =D17 | N17: 式 | O17: 80000
B18: 15 | C18: 台電審查作業費、線補費 | D18: 1 | E18: 式 | F18: =成本!M172 | K18: 15 | L18: =C18 | M18: =D18 | N18: 式 | O18: =F18 | P18: 實質審查後，實支實付。
B20: 小計 | F20: =SUM(F4:F19) | K20: 小計 | O20: =SUM(O4:O19) | Q20: =IF(O20<F20,"錯誤","OK") | R20: 調整後利潤 | S20: =(O20-成本!O175)/O20
B21: 稅金5％ | F21: =F20*0.05 | K21: 稅金5％ | O21: =O20*0.05
B22: 總計 | F22: =F21+F20 | K22: 總計 | O22: =SUM(O20:O21)
B23: 平均1kw（未稅） | F23: =F20/#REF! | K23: 平均1kW（未稅） | O23: =O20/#REF!
B24: 平均1kw（含稅） | F24: =F22/#REF! | K24: 平均1kW（含稅） | O24: =O22/#REF!
B25: 運維 | K25: 運維
B26: 1 | C26: 系統維運 | D26: =C2 | E26: kW | F26: =D26*400*20 | K26: 1 | L26: 系統維運 | M26: =D26 | N26: kW | O26: =F26 | P26: 400kW/年，共計20年。 含清洗巡檢線上監控等運維服務。
B27: 其他 | K27: 其他
B28: 1 | C28: 保險費 | D28: 參考: 造價0.3% 由業主自行投保。 | K28: 1 | L28: 保險費 | M28: =D28
B29: 2 | C29: 模組回收費 | D29: =C2 | E29: kW | F29: =D29*1000 | K29: 2 | L29: 模組回收費 | M29: =D29 | N29: kW | O29: =F29 | P29: 1000kW/元，由環保署分10年徵收。

Sheet IRR (樂觀2%)
B2: 重資打包賣價 | C2: =Z28
C4: 年份 | D4: 2020 | E4: 2021 | F4: 2022 | G4: 2023 | H4: 2024 | I4: 2025 | J4: 2026 | K4: 2027 | L4: 2028 | M4: 2029 | N4: 2030 | O4: 2031 | P4: 2032 | Q4: 2033 | R4: 2034 | S4: 2035 | T4: 2036 | U4: 2037 | V4: 2038 | W4: 2039
B5: 案場名 | C5: 預估發電度數 | AD5: 發電度數
B6: =#REF! | D6: =#REF! | E6: =#REF! | F6: =#REF! | G6: =#REF! | H6: =#REF! | I6: =#REF! | J6: =#REF! | K6: =#REF! | ... W6: =#REF! | Z6: =SUM(D6:Y6) | AD6: 賣價
C7: 發電度數 總計 | D7: =SUM(D6:D6) | E7: =SUM(E6:E6) | F7: =SUM(F6:F6) | G7: =SUM(G6:G6) | H7: =SUM(H6:H6) | I7: =SUM(I6:I6) | J7: =SUM(J6:J6) | K7: =SUM(K6:K6) | ... X7: =SUM(X6:X6) | Z7: =SUM(D7:Y7) | AA7: =IF(ROUND((#REF!-'IRR (樂觀2%)'!Z7),0)=0,"correct", "error")
B8: 案場名 | C8: 預估收入 | D8: 2020 | E8: 2021 | F8: 2022 | G8: 2023 | H8: 2024 | I8: 2025 | J8: 2026 | K8: 2027 | L8: 2028 | M8: 2029 | N8: 2030 | O8: 2031 | P8: 2032 | Q8: 2033 | R8: 2034 | S8: 2035 | T8: 2036 | U8: 2037 | V8: 2038 | W8: 2039 | X8: 2040
B9: =#REF! | D9: =#REF! | E9: =#REF! | F9: =#REF! | G9: =#REF! | H9: =#REF! | I9: =#REF! | J9: =#REF! | K9: =#REF! | ... W9: =#REF! | Z9: =SUM(D9:Y9)
C10: 預估收入 總計 | D10: =SUM(D9:D9) | E10: =SUM(E9:E9) | F10: =SUM(F9:F9) | G10: =SUM(G9:G9) | H10: =SUM(H9:H9) | I10: =SUM(I9:I9) | J10: =SUM(J9:J9) | K10: =SUM(K9:K9) | ... X10: =SUM(X9:X9) | Z10: =SUM(D10:Y10) | AA10: =IF(ROUND((#REF!-'IRR (樂觀2%)'!Z10),0)=0,"correct", "error")
B11: 案場名 | C11: 租金/年 | D11: 2020 | E11: 2021 | F11: 2022 | G11: 2023 | H11: 2024 | I11: 2025 | J11: 2026 | K11: 2027 | L11: 2028 | M11: 2029 | N11: 2030 | O11: 2031 | P11: 2032 | Q11: 2033 | R11: 2034 | S11: 2035 | T11: 2036 | U11: 2037 | V11: 2038 | W11: 2039 | X11: 2040
B12: =#REF! | D12: =#REF! | E12: =#REF! | F12: =#REF! | G12: =#REF! | H12: =#REF! | I12: =#REF! | J12: =#REF! | K12: =#REF! | ... W12: =#REF! | Z12: =SUM(D12:Y12)
C13: 租金/年 總計 | D13: =SUM(D12:D12) | E13: =SUM(E12:E12) | F13: =SUM(F12:F12) | G13: =SUM(G12:G12) | H13: =SUM(H12:H12) | I13: =SUM(I12:I12) | J13: =SUM(J12:J12) | K13: =SUM(K12:K12) | ... X13: =SUM(X12:X12) | Z13: =SUM(D13:Y13) | AA13: =IF(ROUND((#REF!-'IRR (樂觀2%)'!Z13),0)=0,"correct", "error")
B14: 案場名 | C14: 運維/年 | D14: 2020 | E14: 2021 | F14: 2022 | G14: 2023 | H14: 2024 | I14: 2025 | J14: 2026 | K14: 2027 | L14: 2028 | M14: 2029 | N14: 2030 | O14: 2031 | P14: 2032 | Q14: 2033 | R14: 2034 | S14: 2035 | T14: 2036 | U14: 2037 | V14: 2038 | W14: 2039 | X14: 2040
B15: =#REF! | D15: =#REF! | E15: =#REF! | F15: =#REF! | G15: =#REF! | H15: =#REF! | I15: =#REF! | J15: =#REF! | K15: =#REF! | ... W15: =#REF! | Z15: =SUM(D15:Y15)
C16: 運維/年 總計 | D16: =SUM(D15:D15) | E16: =SUM(E15:E15) | F16: =SUM(F15:F15) | G16: =SUM(G15:G15) | H16: =SUM(H15:H15) | I16: =SUM(I15:I15) | J16: =SUM(J15:J15) | K16: =SUM(K15:K15) | ... X16: =SUM(X15:X15) | Z16: =SUM(D16:Y16) | AA16: =IF(ROUND((#REF!-'IRR (樂觀2%)'!Z16),0)=0,"correct", "error")
B17: 案場名 | C17: 保險/年 | D17: 2020 | E17: 2021 | F17: 2022 | G17: 2023 | H17: 2024 | I17: 2025 | J17: 2026 | K17: 2027 | L17: 2028 | M17: 2029 | N17: 2030 | O17: 2031 | P17: 2032 | Q17: 2033 | R17: 2034 | S17: 2035 | T17: 2036 | U17: 2037 | V17: 2038 | W17: 2039 | X17: 2040
B18: =#REF! | D18: =#REF! | E18: =#REF! | F18: =#REF! | G18: =#REF! | H18: =#REF! | I18: =#REF! | J18: =#REF! | K18: =#REF! | ... W18: =#REF! | Z18: =SUM(D18:Y18)
C19: 保險/年 總計 | D19: =SUM(D18:D18) | E19: =SUM(E18:E18) | F19: =SUM(F18:F18) | G19: =SUM(G18:G18) | H19: =SUM(H18:H18) | I19: =SUM(I18:I18) | J19: =SUM(J18:J18) | K19: =SUM(K18:K18) | ... X19: =SUM(X18:X18) | Z19: =SUM(D19:Y19) | AA19: =IF(ROUND((#REF!-'IRR (樂觀2%)'!Z19),0)=0,"correct", "error")
B20: 案場名 | C20: 模組回收費/年 | D20: 2020 | E20: 2021 | F20: 2022 | G20: 2023 | H20: 2024 | I20: 2025 | J20: 2026 | K20: 2027 | L20: 2028 | M20: 2029 | N20: 2030 | O20: 2031 | P20: 2032 | Q20: 2033 | R20: 2034 | S20: 2035 | T20: 2036 | U20: 2037 | V20: 2038 | W20: 2039 | X20: 2040
B21: =#REF! | D21: =#REF! | E21: =#REF! | F21: =#REF! | G21: =#REF! | H21: =#REF! | I21: =#REF! | J21: =#REF! | K21: =#REF! | ... W21: =#REF! | Z21: =SUM(D21:Y21)
C22: 模組回收費/年 總計 | D22: =SUM(D21:D21) | E22: =SUM(E21:E21) | F22: =SUM(F21:F21) | G22: =SUM(G21:G21) | H22: =SUM(H21:H21) | I22: =SUM(I21:I21) | J22: =SUM(J21:J21) | K22: =SUM(K21:K21) | ... X22: =SUM(X21:X21) | Z22: =SUM(D22:Y22) | AA22: =IF(ROUND((#REF!-'IRR (樂觀2%)'!Z22),0)=0,"correct", "error")
B23: 案場名 | C23: 所得稅/年 | D23: 2020 | E23: 2021 | F23: 2022 | G23: 2023 | H23: 2024 | I23: 2025 | J23: 2026 | K23: 2027 | L23: 2028 | M23: 2029 | N23: 2030 | O23: 2031 | P23: 2032 | Q23: 2033 | R23: 2034 | S23: 2035 | T23: 2036 | U23: 2037 | V23: 2038 | W23: 2039 | X23: 2040
B24: =#REF! | D24: =#REF! | E24: =#REF! | F24: =#REF! | G24: =#REF! | H24: =#REF! | I24: =#REF! | J24: =#REF! | K24: =#REF! | ... W24: =#REF! | Z24: =SUM(D24:Y24)
C25: 所得稅/年 總計 | D25: =SUM(D24:D24) | E25: =SUM(E24:E24) | F25: =SUM(F24:F24) | G25: =SUM(G24:G24) | H25: =SUM(H24:H24) | I25: =SUM(I24:I24) | J25: =SUM(J24:J24) | K25: =SUM(K24:K24) | ... X25: =SUM(X24:X24) | Z25: =SUM(D25:Y25) | AA25: =IF(ROUND((#REF!-'IRR (樂觀2%)'!Z25),0)=0,"correct", "error")
B26: 案場名 | C26: 設備折舊/年 | D26: 2020 | E26: 2021 | F26: 2022 | G26: 2023 | H26: 2024 | I26: 2025 | J26: 2026 | K26: 2027 | L26: 2028 | M26: 2029 | N26: 2030 | O26: 2031 | P26: 2032 | Q26: 2033 | R26: 2034 | S26: 2035 | T26: 2036 | U26: 2037 | V26: 2038 | W26: 2039 | X26: 2040
B27: =#REF! | D27: =#REF! | E27: =#REF! | F27: =#REF! | G27: =#REF! | H27: =#REF! | I27: =#REF! | J27: =#REF! | K27: =#REF! | ... W27: =#REF! | Z27: =SUM(D27:Y27) | AA27: =IF(ROUND((Z27-#REF!),0)=0,"correct", "error")
C28: 設備折舊/年 總計 | D28: =SUM(D27:D27) | E28: =SUM(E27:E27) | F28: =SUM(F27:F27) | G28: =SUM(G27:G27) | H28: =SUM(H27:H27) | I28: =SUM(I27:I27) | J28: =SUM(J27:J27) | K28: =SUM(K27:K27) | ... X28: =SUM(X27:X27) | Z28: =SUM(D28:Y28) | AA28: =IF(ROUND((#REF!-'IRR (樂觀2%)'!Z28),0)=0,"correct", "error")
C30: 年份 | D30: 2020 | E30: 2021 | F30: 2022 | G30: 2023 | H30: 2024 | I30: 2025 | J30: 2026 | K30: 2027 | L30: 2028 | M30: 2029 | N30: 2030 | O30: 2031 | P30: 2032 | Q30: 2033 | R30: 2034 | S30: 2035 | T30: 2036 | U30: 2037 | V30: 2038 | W30: 2039
B31: 0 | F31: 手動計算值 | T31: 償還年限
B32: (Unit : Currency) | C32: 0 | D32: 1 | E32: 2 | F32: 3 | G32: 4 | H32: 5 | I32: 6 | J32: 7 | K32: 8 | L32: 9 | M32: 10 | N32: 11 | O32: 12 | P32: 13 | Q32: 14 | R32: 15 | S32: 16 | T32: 17 | U32: 18 | V32: 19 | W32: 20
B33: 發電度數(KWH) | C33: 0 | D33: =D7 | E33: =E7 | F33: =F7 | G33: =G7 | H33: =H7 | I33: =I7 | J33: =J7 | K33: =K7 | ... X33: =X7 | Z33: =SUM(D33:Y33) | AA33: =IF(ROUND((Z33-Z7),0)=0,"correct", "error")
B34: Inflow : 電費收入 | C34: - | D34: =D10 | E34: =E10 | F34: =F10 | G34: =G10 | H34: =H10 | I34: =I10 | J34: =J10 | K34: =K10 | ... X34: =X10 | Z34: =SUM(D34:Y34) | AA34: =IF(ROUND((Z34-Z10),0)=0,"correct", "error")
B35: Inflow : 政府補助 | C35: - | F35: 0 | G35: - | H35: - | I35: - | J35: - | K35: - | L35: - | M35: - | N35: - | O35: - | P35: - | Q35: - | R35: - | S35: - | T35: - | U35: - | V35: - | W35: -
B36: Inflow : 銀行借款
B37: Outflow : 設備費用 | C37: =-C2 | F37: - | G37: - | H37: - | I37: - | J37: - | K37: - | L37: - | M37: - | N37: - | O37: - | P37: - | Q37: - | R37: - | S37: - | T37: - | U37: - | V37: - | W37: -
B38: Outflow : 設備放置區域租金 | C38: - | D38: =-D13 | E38: =-E13 | F38: =-F13 | G38: =-G13 | H38: =-H13 | I38: =-I13 | J38: =-J13 | K38: =-K13 | ... X38: =-X13 | Z38: =SUM(D38:Y38) | AA38: =IF(ROUND((Z38+Z13),0)=0,"correct", "error")
B39: Outflow : 返還借款 | C39: 0 | V39: 0 | W39: 0 | Z39: =SUM(D39:Y39)
B40: Outflow : 利息費用 | C40: - | Z40: =SUM(D40:Y40)
B41: Outflow : 維運費 | C41: - | D41: =-D16 | E41: =-E16 | F41: =-F16 | G41: =-G16 | H41: =-H16 | I41: =-I16 | J41: =-J16 | K41: =-K16 | ... X41: =-X16 | Z41: =SUM(D41:Y41) | AA41: =IF(ROUND((Z41+Z16),0)=0,"correct", "error")
B42: Outflow : 保險費 | C42: - | D42: =-D19 | E42: =-E19 | F42: =-F19 | G42: =-G19 | H42: =-H19 | I42: =-I19 | J42: =-J19 | K42: =-K19 | ... X42: =-X19 | Z42: =SUM(D42:Y42) | AA42: =IF(ROUND((Z42+Z19),0)=0,"correct", "error")
B43: Outflow : 模組回收費 | D43: =-D22 | E43: =-E22 | F43: =-F22 | G43: =-G22 | H43: =-H22 | I43: =-I22 | J43: =-J22 | K43: =-K22 | ... X43: =-X22 | Z43: =SUM(D43:Y43) | AA43: =IF(ROUND((Z22+Z43),0)=0,"correct", "error")
...

Sheet 滾算紀錄單(總紀錄)
A1: 價金每KW | B1: 專案法IRR | C1: 權益法IRR | D1: 信邦利潤率 | E1: 信邦利潤 | F1: 每kw信邦利潤 | G1: 開發費 | H1: 備註
A2: 30000 | B2: 4.29 | C2: 10.43 | D2: 0.2 | E2: 2398550 | F2: 5500 | G2: 2000 | H2: 初始價金 - 現金模式，每次減少 500 元，邊界值 25000 元
A3: 29500 | B3: 4.46 | C3: 11.07 | D3: 0.2 | E3: 2344037.5 | F3: 5375 | G3: 2000 | H3: 第1次滾算，減少 500 元 - 現金模式，每次減少 500 元
A4: 29000 | B4: 4.63 | C4: 11.74 | D4: 0.2 | E4: 2289525 | F4: 5250 | G4: 2000 | H4: 第2次滾算，減少 500 元 - 現金模式，每次減少 500 元
A5: 28500 | B5: 4.8 | C5: 12.44 | D5: 0.2 | E5: 2235012.5 | F5: 5125 | G5: 2000 | H5: 第3次滾算，減少 500 元 - 現金模式，每次減少 500 元
A6: 28000 | B6: 4.98 | C6: 13.18 | D6: 0.2 | E6: 2180500 | F6: 5000 | G6: 2000 | H6: 第4次滾算，減少 500 元 - 現金模式，每次減少 500 元
A7: 27500 | B7: 5.16 | C7: 13.95 | D7: 0.2 | E7: 2125987.5 | F7: 4875 | G7: 2000 | H7: 第5次滾算，減少 500 元 - 現金模式，每次減少 500 元
A8: 27000 | B8: 5.35 | C8: 14.77 | D8: 0.2 | E8: 2071475 | F8: 4750 | G8: 2000 | H8: 第6次滾算，減少 500 元 - 現金模式，每次減少 500 元
A9: 26500 | B9: 5.54 | C9: 15.63 | D9: 0.2 | E9: 2016962.5 | F9: 4625 | G9: 2000 | H9: 第7次滾算，減少 500 元 - 現金模式，每次減少 500 元
A10: 26000 | B10: 5.74 | C10: 16.54 | D10: 0.2 | E10: 1962450 | F10: 4500 | G10: 2000 | H10: 第8次滾算，減少 500 元 - 現金模式，每次減少 500 元
A11: 25500 | B11: 5.94 | C11: 17.51 | D11: 0.2 | E11: 1907937.5 | F11: 4375 | G11: 2000 | H11: 第9次滾算，減少 500 元 - 現金模式，每次減少 500 元
A12: 25000 | B12: 6.15 | C12: 18.54 | D12: 0.2 | E12: 1853425 | F12: 4250 | G12: 2000 | H12: 第10次滾算，減少 500 元 - 現金模式，每次減少 500 元

Sheet 滾算紀錄單(使用者記錄)
A1: 價金每KW | B1: 專案法IRR | C1: 權益法IRR | D1: 信邦利潤率 | E1: 信邦利潤 | F1: 每kw信邦利潤 | G1: 開發費 | H1: 備註

Sheet 滾算紀錄1
B1: 電站基本資料
B2: 電站名稱 | C2: 淡江大學-財務模擬案場 | D2: - | E2: -
B3: 電站壽命 | C3: 20 | D3: - | E3: -
B4: 建置量(kWp) | C4: 436.1 | D4: - | E4: -
B5: 起始年度 | C5: 2020 | D5: 結束年度 | E5: 2039 | M5: 初始價金摘要
M6: 初始價金: 30000
B7: 綜合損益表 | M7: 專案IRR: 4.29
B8: 收入 | M8: 權益法IRR: 10.43
B9: 收支項目 | C9: 相關參數 | D9: 參數數值 | E9: 年限 | M9: 利潤率: 20.00%
B10: 電費收入 | C10: 年度AC併網總發電量 | D10: 547002 | E10: 20 | M10: 基準價金 - 滾算起始點
C11: 首年衰退率 | D11: 0.01
C12: 次年衰退率 | D12: 0.004
C13: 躉售費率(FIT) | D13: 3.7152
B14: 支出
B15: 收支項目 | C15: 相關參數 | D15: 參數數值 | E15: 攤提年限
B16: 設備費用(價金) | C16: 每kWp設備成本 | D16: 30000 | E16: 20
C17: 信邦利潤率 | D17: 0.2
C18: 開發費 | D18: 2000
B19: 租金費用 | C19: 租金計算方式 (1=固定攤提/2=電費抽成) | D19: 1 | E19: 0
C20: 【方式1參數】租金總額 | D20: 5804025 | E20: 20
C21: 【方式2參數】抽成比率 | D21: 0 | E21: 0
B22: 運維費用 | C22: 每kw運維成本 | D22: 400 | E22: 20
B23: 保險費用 | C23: 占整體設備費用比例 | D23: 0.003 | E23: 20
B24: 模組回收費用 | C24: 每kw模組回收成本 | D24: 1000 | E24: 10
B25: 利息費用 | C25: 銀行利率 | D25: 0.025595 | E25: 0
B26: 所得稅 | C26: 所得稅率 | D26: 0.2 | E26: 0
B29: 現金流量表
B30: 金流項目 | C30: 相關參數 | D30: 參數數值
B31: 貸款成數 | C31: 占總設備費用比例 | D31: 0.8
B32: 貸款還款 | C32: 攤還期數 | D32: 15
B33: 現金股利 | C33: 股利比率 | D33: 0.9
B34: 年底減資 | C34: 攤還期數 | D34: 4
C37: 年份 | D37: 2020 | E37: 2021 | F37: 2022 | G37: 2023 | H37: 2024 | I37: 2025 | J37: 2026 | K37: 2027 | L37: 2028 | M37: 2029 | N37: 2030 | O37: 2031 | P37: 2032 | Q37: 2033 | R37: 2034 | S37: 2035 | T37: 2036 | U37: 2037 | V37: 2038 | W37: 2039
B38: 0 | F38: 手動計算值 | T38: 償還年限
B39: (Unit : Currency) | C39: 0 | D39: 1 | E39: 2 | F39: 3 | G39: 4 | H39: 5 | I39: 6 | J39: 7 | K39: 8 | L39: 9 | M39: 10 | N39: 11 | O39: 12 | P39: 13 | Q39: 14 | R39: 15 | S39: 16 | T39: 17 | U39: 18 | V39: 19 | W39: 20
B40: 發電度數(KWH) | C40: 0 | D40: =#REF! | E40: =#REF! | F40: =#REF! | G40: =#REF! | H40: =#REF! | I40: =#REF! | J40: =#REF! | K40: =#REF! | ... W40: =#REF!
B41: Inflow : 電費收入 | C41: - | D41: =#REF! | E41: =#REF! | F41: =#REF! | G41: =#REF! | H41: =#REF! | I41: =#REF! | J41: =#REF! | K41: =#REF! | ... W41: =#REF!
B42: Inflow : 政府補助 | C42: - | F42: 0 | G42: - | H42: - | I42: - | J42: - | K42: - | L42: - | M42: - | N42: - | O42: - | P42: - | Q42: - | R42: - | S42: - | T42: - | U42: - | V42: - | W42: -
B43: Inflow : 銀行借款
B44: Outflow : 設備費用 | C44: =-#REF! | F44: - | G44: - | H44: - | I44: - | J44: - | K44: - | L44: - | M44: - | N44: - | O44: - | P44: - | Q44: - | R44: - | S44: - | T44: - | U44: - | V44: - | W44: -
...

Sheet IRR (保守3%)
B2: 重資打包賣價 | C2: =Z28
C4: 年份 | D4: 2020 | E4: 2021 | F4: 2022 | G4: 2023 | H4: 2024 | I4: 2025 | J4: 2026 | K4: 2027 | L4: 2028 | M4: 2029 | N4: 2030 | O4: 2031 | P4: 2032 | Q4: 2033 | R4: 2034 | S4: 2035 | T4: 2036 | U4: 2037 | V4: 2038 | W4: 2039
B5: 案場名 | C5: 預估發電度數 | AD5: 發電度數
B6: =#REF! | D6: =#REF! | E6: =#REF! | F6: =#REF! | G6: =#REF! | H6: =#REF! | I6: =#REF! | J6: =#REF! | K6: =#REF! | ... W6: =#REF! | Z6: =SUM(D6:Y6) | AD6: 賣價
C7: 發電度數 總計 | D7: =SUM(D6:D6) | E7: =SUM(E6:E6) | F7: =SUM(F6:F6) | G7: =SUM(G6:G6) | H7: =SUM(H6:H6) | I7: =SUM(I6:I6) | J7: =SUM(J6:J6) | K7: =SUM(K6:K6) | ... X7: =SUM(X6:X6) | Z7: =SUM(D7:Y7) | AA7: =IF(ROUND((#REF!-'IRR (保守3%)'!Z7),0)=0,"correct", "error")
B8: 案場名 | C8: 預估收入 | D8: 2020 | E8: 2021 | F8: 2022 | G8: 2023 | H8: 2024 | I8: 2025 | J8: 2026 | K8: 2027 | L8: 2028 | M8: 2029 | N8: 2030 | O8: 2031 | P8: 2032 | Q8: 2033 | R8: 2034 | S8: 2035 | T8: 2036 | U8: 2037 | V8: 2038 | W8: 2039 | X8: 2040
B9: =#REF! | D9: =#REF! | E9: =#REF! | F9: =#REF! | G9: =#REF! | H9: =#REF! | I9: =#REF! | J9: =#REF! | K9: =#REF! | ... W9: =#REF! | Z9: =SUM(D9:Y9)
C10: 預估收入 總計 | D10: =SUM(D9:D9) | E10: =SUM(E9:E9) | F10: =SUM(F9:F9) | G10: =SUM(G9:G9) | H10: =SUM(H9:H9) | I10: =SUM(I9:I9) | J10: =SUM(J9:J9) | K10: =SUM(K9:K9) | ... X10: =SUM(X9:X9) | Z10: =SUM(D10:Y10) | AA10: =IF(ROUND((#REF!-'IRR (保守3%)'!Z10),0)=0,"correct", "error")
B11: 案場名 | C11: 租金/年 | D11: 2020 | E11: 2021 | F11: 2022 | G11: 2023 | H11: 2024 | I11: 2025 | J11: 2026 | K11: 2027 | L11: 2028 | M11: 2029 | N11: 2030 | O11: 2031 | P11: 2032 | Q11: 2033 | R11: 2034 | S11: 2035 | T11: 2036 | U11: 2037 | V11: 2038 | W11: 2039 | X11: 2040
B12: =#REF! | D12: =#REF! | E12: =#REF! | F12: =#REF! | G12: =#REF! | H12: =#REF! | I12: =#REF! | J12: =#REF! | K12: =#REF! | ... W12: =#REF! | Z12: =SUM(D12:Y12)
C13: 租金/年 總計 | D13: =SUM(D12:D12) | E13: =SUM(E12:E12) | F13: =SUM(F12:F12) | G13: =SUM(G12:G12) | H13: =SUM(H12:H12) | I13: =SUM(I12:I12) | J13: =SUM(J12:J12) | K13: =SUM(K12:K12) | ... X13: =SUM(X12:X12) | Z13: =SUM(D13:Y13) | AA13: =IF(ROUND((#REF!-'IRR (保守3%)'!Z13),0)=0,"correct", "error")
B14: 案場名 | C14: 運維/年 | D14: 2020 | E14: 2021 | F14: 2022 | G14: 2023 | H14: 2024 | I14: 2025 | J14: 2026 | K14: 2027 | L14: 2028 | M14: 2029 | N14: 2030 | O14: 2031 | P14: 2032 | Q14: 2033 | R14: 2034 | S14: 2035 | T14: 2036 | U14: 2037 | V14: 2038 | W14: 2039 | X14: 2040
B15: =#REF! | D15: =#REF! | E15: =#REF! | F15: =#REF! | G15: =#REF! | H15: =#REF! | I15: =#REF! | J15: =#REF! | K15: =#REF! | ... W15: =#REF! | Z15: =SUM(D15:Y15)
C16: 運維/年 總計 | D16: =SUM(D15:D15) | E16: =SUM(E15:E15) | F16: =SUM(F15:F15) | G16: =SUM(G15:G15) | H16: =SUM(H15:H15) | I16: =SUM(I15:I15) | J16: =SUM(J15:J15) | K16: =SUM(K15:K15) | ... X16: =SUM(X15:X15) | Z16: =SUM(D16:Y16) | AA16: =IF(ROUND((#REF!-'IRR (保守3%)'!Z16),0)=0,"correct", "error")
B17: 案場名 | C17: 保險/年 | D17: 2020 | E17: 2021 | F17: 2022 | G17: 2023 | H17: 2024 | I17: 2025 | J17: 2026 | K17: 2027 | L17: 2028 | M17: 2029 | N17: 2030 | O17: 2031 | P17: 2032 | Q17: 2033 | R17: 2034 | S17: 2035 | T17: 2036 | U17: 2037 | V17: 2038 | W17: 2039 | X17: 2040
B18: =#REF! | D18: =#REF! | E18: =#REF! | F18: =#REF! | G18: =#REF! | H18: =#REF! | I18: =#REF! | J18: =#REF! | K18: =#REF! | ... W18: =#REF! | Z18: =SUM(D18:Y18)
C19: 保險/年 總計 | D19: =SUM(D18:D18) | E19: =SUM(E18:E18) | F19: =SUM(F18:F18) | G19: =SUM(G18:G18) | H19: =SUM(H18:H18) | I19: =SUM(I18:I18) | J19: =SUM(J18:J18) | K19: =SUM(K18:K18) | ... X19: =SUM(X18:X18) | Z19: =SUM(D19:Y19) | AA19: =IF(ROUND((#REF!-'IRR (保守3%)'!Z19),0)=0,"correct", "error")
B20: 案場名 | C20: 模組回收費/年 | D20: 2020 | E20: 2021 | F20: 2022 | G20: 2023 | H20: 2024 | I20: 2025 | J20: 2026 | K20: 2027 | L20: 2028 | M20: 2029 | N20: 2030 | O20: 2031 | P20: 2032 | Q20: 2033 | R20: 2034 | S20: 2035 | T20: 2036 | U20: 2037 | V20: 2038 | W20: 2039 | X20: 2040
B21: =#REF! | D21: =#REF! | E21: =#REF! | F21: =#REF! | G21: =#REF! | H21: =#REF! | I21: =#REF! | J21: =#REF! | K21: =#REF! | ... W21: =#REF! | Z21: =SUM(D21:Y21)
C22: 模組回收費/年 總計 | D22: =SUM(D21:D21) | E22: =SUM(E21:E21) | F22: =SUM(F21:F21) | G22: =SUM(G21:G21) | H22: =SUM(H21:H21) | I22: =SUM(I21:I21) | J22: =SUM(J21:J21) | K22: =SUM(K21:K21) | ... X22: =SUM(X21:X21) | Z22: =SUM(D22:Y22) | AA22: =IF(ROUND((#REF!-'IRR (保守3%)'!Z22),0)=0,"correct", "error")
B23: 案場名 | C23: 所得稅/年 | D23: 2020 | E23: 2021 | F23: 2022 | G23: 2023 | H23: 2024 | I23: 2025 | J23: 2026 | K23: 2027 | L23: 2028 | M23: 2029 | N23: 2030 | O23: 2031 | P23: 2032 | Q23: 2033 | R23: 2034 | S23: 2035 | T23: 2036 | U23: 2037 | V23: 2038 | W23: 2039 | X23: 2040
B24: =#REF! | D24: =#REF! | E24: =#REF! | F24: =#REF! | G24: =#REF! | H24: =#REF! | I24: =#REF! | J24: =#REF! | K24: =#REF! | ... W24: =#REF! | Z24: =SUM(D24:Y24)
C25: 所得稅/年 總計 | D25: =SUM(D24:D24) | E25: =SUM(E24:E24) | F25: =SUM(F24:F24) | G25: =SUM(G24:G24) | H25: =SUM(H24:H24) | I25: =SUM(I24:I24) | J25: =SUM(J24:J24) | K25: =SUM(K24:K24) | ... X25: =SUM(X24:X24) | Z25: =SUM(D25:Y25) | AA25: =IF(ROUND((#REF!-'IRR (保守3%)'!Z25),0)=0,"correct", "error")
B26: 案場名 | C26: 設備折舊/年 | D26: 2020 | E26: 2021 | F26: 2022 | G26: 2023 | H26: 2024 | I26: 2025 | J26: 2026 | K26: 2027 | L26: 2028 | M26: 2029 | N26: 2030 | O26: 2031 | P26: 2032 | Q26: 2033 | R26: 2034 | S26: 2035 | T26: 2036 | U26: 2037 | V26: 2038 | W26: 2039 | X26: 2040
B27: =#REF! | D27: =#REF! | E27: =#REF! | F27: =#REF! | G27: =#REF! | H27: =#REF! | I27: =#REF! | J27: =#REF! | K27: =#REF! | ... W27: =#REF! | Z27: =SUM(D27:Y27) | AA27: =IF(ROUND((Z27-#REF!),0)=0,"correct", "error")
C28: 設備折舊/年 總計 | D28: =SUM(D27:D27) | E28: =SUM(E27:E27) | F28: =SUM(F27:F27) | G28: =SUM(G27:G27) | H28: =SUM(H27:H27) | I28: =SUM(I27:I27) | J28: =SUM(J27:J27) | K28: =SUM(K27:K27) | ... X28: =SUM(X27:X27) | Z28: =SUM(D28:Y28) | AA28: =IF(ROUND((#REF!-'IRR (保守3%)'!Z28),0)=0,"correct", "error")
C30: 年份 | D30: 2020 | E30: 2021 | F30: 2022 | G30: 2023 | H30: 2024 | I30: 2025 | J30: 2026 | K30: 2027 | L30: 2028 | M30: 2029 | N30: 2030 | O30: 2031 | P30: 2032 | Q30: 2033 | R30: 2034 | S30: 2035 | T30: 2036 | U30: 2037 | V30: 2038 | W30: 2039
B31: 0 | F31: 手動計算值 | T31: 償還年限
B32: (Unit : Currency) | C32: 0 | D32: 1 | E32: 2 | F32: 3 | G32: 4 | H32: 5 | I32: 6 | J32: 7 | K32: 8 | L32: 9 | M32: 10 | N32: 11 | O32: 12 | P32: 13 | Q32: 14 | R32: 15 | S32: 16 | T32: 17 | U32: 18 | V32: 19 | W32: 20
B33: 發電度數(KWH) | C33: 0 | D33: =D7 | E33: =E7 | F33: =F7 | G33: =G7 | H33: =H7 | I33: =I7 | J33: =J7 | K33: =K7 | ... X33: =X7 | Z33: =SUM(D33:Y33) | AA33: =IF(ROUND((Z33-Z7),0)=0,"correct", "error")
B34: Inflow : 電費收入 | C34: - | D34: =D10 | E34: =E10 | F34: =F10 | G34: =G10 | H34: =H10 | I34: =I10 | J34: =J10 | K34: =K10 | ... X34: =X10 | Z34: =SUM(D34:Y34) | AA34: =IF(ROUND((Z34-Z10),0)=0,"correct", "error")
B35: Inflow : 政府補助 | C35: - | F35: 0 | G35: - | H35: - | I35: - | J35: - | K35: - | L35: - | M35: - | N35: - | O35: - | P35: - | Q35: - | R35: - | S35: - | T35: - | U35: - | V35: - | W35: -
B36: Inflow : 銀行借款
B37: Outflow : 設備費用 | C37: =-C2 | F37: - | G37: - | H37: - | I37: - | J37: - | K37: - | L37: - | M37: - | N37: - | O37: - | P37: - | Q37: - | R37: - | S37: - | T37: - | U37: - | V37: - | W37: -
B38: Outflow : 設備放置區域租金 | C38: - | D38: =-D13 | E38: =-E13 | F38: =-F13 | G38: =-G13 | H38: =-H13 | I38: =-I13 | J38: =-J13 | K38: =-K13 | ... X38: =-X13 | Z38: =SUM(D38:Y38) | AA38: =IF(ROUND((Z38+Z13),0)=0,"correct", "error")
B39: Outflow : 返還借款 | C39: 0 | V39: 0 | W39: 0 | Z39: =SUM(D39:Y39)
B40: Outflow : 利息費用 | C40: - | Z40: =SUM(D40:Y40)
B41: Outflow : 維運費 | C41: - | D41: =-D16 | E41: =-E16 | F41: =-F16 | G41: =-G16 | H41: =-H16 | I41: =-I16 | J41: =-J16 | K41: =-K16 | ... X41: =-X16 | Z41: =SUM(D41:Y41) | AA41: =IF(ROUND((Z41+Z16),0)=0,"correct", "error")
B42: Outflow : 保險費 | C42: - | D42: =-D19 | E42: =-E19 | F42: =-F19 | G42: =-G19 | H42: =-H19 | I42: =-I19 | J42: =-J19 | K42: =-K19 | ... X42: =-X19 | Z42: =SUM(D42:Y42) | AA42: =IF(ROUND((Z42+Z19),0)=0,"correct", "error")
B43: Outflow : 模組回收費 | D43: =-D22 | E43: =-E22 | F43: =-F22 | G43: =-G22 | H43: =-H22 | I43: =-I22 | J43: =-J22 | K43: =-K22 | ... X43: =-X22 | Z43: =SUM(D43:Y43) | AA43: =IF(ROUND((Z22+Z43),0)=0,"correct", "error")
...

Sheet 比例
B2: 工程項目圓餅圖
Q4: =SUM(Q6:Q15)
B5: 項目 | C5: 成本比例 | I5: 項目 | J5: 業務報價比例 | P5: 項目 | Q5: 利潤比例
B6: =#REF! | C6: =#REF!/#REF! | I6: =#REF! | J6: =#REF!/#REF! | P6: =#REF! | Q6: =(#REF!-#REF!)/#REF!
B7: =#REF! | C7: =#REF!/#REF! | I7: =#REF! | J7: =#REF!/#REF! | P7: =#REF! | Q7: =(#REF!-#REF!)/#REF!
B8: =#REF! | C8: =(#REF!+#REF!+#REF!+#REF!)/#REF! | I8: =#REF! | J8: =(#REF!+#REF!+#REF!+#REF!)/#REF! | P8: =#REF! | Q8: =((#REF!-#REF!)+(#REF!-#REF!)+(#REF!-#REF!)+(#REF!-#REF!))/#REF!
B9: =#REF! | C9: =(#REF!+#REF!)/#REF! | I9: =#REF! | J9: =(#REF!+#REF!)/#REF! | P9: =#REF! | Q9: =((#REF!-#REF!)+(#REF!-#REF!))/#REF!
B10: =#REF! | C10: =(#REF!+#REF!)/#REF! | I10: =#REF! | J10: =(#REF!+#REF!)/#REF! | P10: =#REF! | Q10: =((#REF!-#REF!)+(#REF!-#REF!))/#REF!
B11: =#REF! | C11: =(#REF!+#REF!+#REF!)/#REF! | I11: =#REF! | J11: =(#REF!+#REF!+#REF!)/#REF! | P11: =#REF! | Q11: =((#REF!-#REF!)+(#REF!-#REF!)+(#REF!-#REF!))/#REF!
B12: =#REF! | C12: =(#REF!+#REF!)/#REF! | I12: =#REF! | J12: =(#REF!+#REF!)/#REF! | P12: =#REF! | Q12: =((#REF!-#REF!)+(#REF!-#REF!))/#REF!
B13: =#REF! | C13: =(#REF!)/#REF! | I13: =#REF! | J13: =(#REF!)/#REF! | P13: =#REF! | Q13: =(#REF!-#REF!)/#REF!
B14: =#REF! | C14: =(#REF!)/#REF! | I14: =#REF! | J14: =(#REF!)/#REF! | P14: =#REF! | Q14: =(#REF!-#REF!)/#REF!
B15: =#REF! | C15: =#REF!/#REF! | I15: =#REF! | J15: =#REF!/#REF! | P15: =#REF! | Q15: =(#REF!-#REF!)/#REF!

Sheet 台電
B1: =B11
B2: 選用廠商 | C2: 規格 | D2: 報價(台幣/KW)
B3: =B14 | C3: =C14 | D3: =D14
B5: =B19
B6: 選用廠商 | C6: 規格 | D6: 報價(台幣/案) | F6: 選用廠商 | G6: 規格 | H6: 報價(台幣/KW)
B7: =B23 | C7: =C23 | D7: =D23 | F7: - | G7: 內線 | H7: 0
B11: 併網工程費用
B12: 廠商 | C12: 規格 | D12: 報價(台幣/KW) | E12: 報價時間 | F12: NOTE | G12: 聯絡人 | H12: 聯絡方式 | I12: Email
B13: 台電 | C13: 50-100 | D13: 1050 | F13: 50KW以下免費(屋頂型)
B14: 台電 | C14: 100-500 | D14: 1470 | F14: 50KW以下免費(屋頂型)
B15: 台電 | C15: 50-2000 | D15: 630 | F15: 50KW以下免費，高壓線補費(屋頂型)；110/03/29內線須確認既有線路是否需加強電力網(該電號併接的台電線路為分界，3年↑X、3年↓O、須實質審查)
B16: 台電 | C16: 地面型 | D16: 2100 | F16: 22.8kV↓配電、110.05.06 草案
B17: 台電 | D17: 1400 | F17: 69kV↑配電、110.05.06 草案
B19: 併網審查作業費
B20: 廠商 | C20: 規格 | D20: 報價(台幣/案) | E20: 報價時間 | F20: NOTE | G20: 聯絡人 | H20: 聯絡方式 | I20: Email
B21: 台電 | C21: 併接外線69KV以上 | D21: 340000 | F21: 中華民國99年1/18日,經授能字09920080510
B22: 台電 | C22: 併接外線22.8KV | D22: 85000 | F22: 中華民國99年1/18日,經授能字09920080510
B23: 台電 | C23: 併接外線11.4KV | D23: 85000 | F23: 中華民國99年1/18日,經授能字09920080510
B24: 台電 | C24: 併接低壓 | D24: 18000 | F24: 中華民國109年4/6日,電輸供部規字第10980340751號 惟辦理第一次展延時收取
B28: 代辦升壓設備(1+2或1+3)
B29: 廠商 | C29: 規格 | D29: 報價(台幣/kW/km) | E29: 報價時間 | F29: NOTE | G29: 聯絡人 | H29: 聯絡方式 | I29: Email
B30: 台電 | C30: 升壓設備 | D30: 2880元/kw*裝置容量 | E30: 1 | F30: 中華民國107年7月2日電配售部配字第1078066359
B31: 台電 | C31: 配電線路(架空) | D31: 803元/Kw*km | E31: 2 | F31: 中華民國107年7月2日電配售部配字第1078066359
B32: 台電 | C32: 配電線路(地下) | D32: 2484元/kW*km | E32: 3 | F32: 中華民國107年7月2日電配售部配字第1078066359

Sheet 行政
B1: 市電躉售併聯申請
B2: 選用廠商 | C2: 規格 | D2: 報價(台幣/案)
B3: =B42 | C3: 1-99kWp *1案 100-499kWp *2案 | D3: =D41+D42*2
B5: 結構技師
B6: 選用廠商 | C6: 規格 | D6: 報價(台幣/案)
B7: =B50 | C7: =C50 | D7: =80*#REF! | E7: 80/kW
B9: 電機技師(100KW以上案件需要)
B10: 選用廠商 | C10: 規格(KW) | D10: 報價(台幣/案)
B11: =B54 | C11: =C54 | D11: =D54
B14: 市電躉售併聯申請
B15: 廠商 | C15: 規格 | D15: 報價(台幣/案) | E15: 報價時間 | F15: NOTE | G15: 聯絡人 | H15: 聯絡方式 | I15: Email | J15: 備註
B16: 原生 | C16: 10kW左右 | D16: 20000 | E16: 2020/4月 | F16: 所有公家文件申請行政流程 (特別價) | G16: 湯學薇 | J16: 第三型
B17: 原生 | C17: 100kW以下 | D17: 30000 | E17: 2018/5月 | F17: 所有公家文件申請行政流程
B18: 原生 | C18: 100kW以上 | D18: 33000 | E18: 2018/5月 | F18: 所有公家文件申請行政流程
B19: 原生 | C19: 500-2MW | D19: 86000 | E19: 2020/8月 | F19: 所有公家文件申請行政流程 (特別價)
B20: 辰欣豪亦 | C20: 20kW以下 | D20: 40000 | E20: 2021/8月 | F20: 所有公家文件申請行政流程 *台電審查 *縣市政府 *顧問服務 | G20: 李佳玲 | I20: 自用不躉售案件 以9折計算
B21: 辰欣豪亦 | C21: 21-99kW | E21: 2021/8月 | G21: 李佳玲
B22: 辰欣豪亦 | C22: 100-199kW | D22: 45000 | E22: 2021/8月 | G22: 李佳玲
B23: 辰欣豪亦 | C23: 200-299kW | E23: 2021/8月 | G23: 李佳玲
B24: 辰欣豪亦 | C24: 300-399kW | E24: 2021/8月 | G24: 李佳玲
B25: 辰欣豪亦 | C25: 400-499kW | E25: 2021/8月 | G25: 李佳玲
B26: 辰欣豪亦 | C26: 500-999kW | D26: 70000 | E26: 2021/8月 | G26: 李佳玲
B27: 辰欣豪亦 | C27: 1000-1499kW | D27: 95000 | E27: 2021/8月 | G27: 李佳玲
B28: 辰欣豪亦 | C28: 1500-1999kW | D28: 150000 | E28: 2021/8月 | G28: 李佳玲
B29: 辰欣豪亦 | C29: 10MW以下 | D29: 500000 | E29: 2021/8月 | F29: 所有公家文件申請行政流程 *籌設前置 *電業籌設 *施工許可 *免雜項執照 *設備認定 *電業執照 | G29: 李佳玲 | I29: 每案籌設以一期為限， 施工許可申請依據籌設許可函核定內容為準 | J29: 第二型
B30: 辰欣豪亦 | C30: 11-30MW | D30: 800000 | E30: 2021/8月 | G30: 李佳玲
B31: 辰欣豪亦 | C31: 31-50MW | D31: 1000000 | E31: 2021/8月 | G31: 李佳玲
B32: 辰欣豪亦 | C32: 51MW以上 | D32: 另行報價 | E32: 2021/8月 | G32: 李佳玲
B33: 辰欣豪亦 | C33: 10MW以下 | D33: 750000 | E33: 2021/8月 | G33: 李佳玲 | J33: 第一型
B34: 辰欣豪亦 | C34: 11-20MW | D34: 850000 | E34: 2021/8月 | G34: 李佳玲
B35: 辰欣豪亦 | C35: 21-40MW | D35: 1050000 | E35: 2021/8月 | G35: 李佳玲
B36: 辰欣豪亦 | C36: 41-60MW | D36: 1250000 | E36: 2021/8月 | G36: 李佳玲
B37: 辰欣豪亦 | C37: 61-80MW | D37: 1450000 | E37: 2021/8月 | G37: 李佳玲
B38: 辰欣豪亦 | C38: 81-100MW | D38: 1650000 | E38: 2021/8月 | G38: 李佳玲
B39: 辰欣豪亦 | C39: 101MW以上 | D39: 另行報價 | E39: 2021/8月 | G39: 李佳玲
B40: 日鴻 | C40: 20kW以下 | D40: 45000 | E40: 2022/4月 | F40: 所有公家文件申請行政流程 *台電審查(含台電送審四大圖說繪製) *縣市政府 | G40: 黃永政 | J40: 第三型
B41: 友樂晴 | C41: 1-99kWp | D41: 35000 | E41: 20221109 | F41: 所有公家文件申請行政流程 *同一場址分多期送件，視為多案，依各案容量所屬級距分別報價 *同一場址分兩期以上送件，可折扣 *報價包含電器承裝業及太陽光電乙級技術士簽證 *不含圖說修正及設備修改 *不含任何技師簽證費用及政府規費 | G41: 湯學薇 | H41: 02-23038861 | I41: neomy@yolothink.com | J41: 第三型
B42: 友樂晴 | C42: 100-499kWp | D42: 45000 | E42: 2221109
C43: 500-999kWp | D43: 55000 | E43: 20221109
C44: 1000-1999kWp | D44: 75000 | E44: 20221109
...

Sheet 材料
B2: 品名 | C2: 廠商 | D2: 規格 | E2: 報價(台幣/pc) | F2: 報價時間 | G2: NOTE | H2: 聯絡人 | I2: 聯絡方式
B3: 花紋鐵板 | C3: 唐絹 | D3: 白鐵 4呎 x 8呎 t=3mm | E3: 5600 | F3: 2016/3月 | G3: 報價未含材切費用(120 x 243cm)，材切每刀500元 | H3: 彭小姐 | I3: 037230032
B4: 菱型網 | C4: 久恩 | D4: 熱浸 4呎 x 8呎 t=6mm | E4: 1620 | F4: 2017/5月 | G4: 報價未含材切費用(120 x 243cm)，材切每刀60元 | H4: 劉經理 | I4: 073737800
B5: 菱型網 | C5: 久恩 | D5: 白鐵 4呎 x 8呎 t=6mm | E5: 4800 | F5: 2017/5月 | G5: 報價未含材切費用(120 x 243cm)，材切每刀60元 | H5: 劉經理 | I5: 073737800
B7: 品名 | C7: 廠商 | D7: 規格 | E7: 報價(台幣/坪) | F7: 報價時間 | G7: NOTE | H7: 聯絡人 | I7: 聯絡方式
B8: 鐵皮浪板 | C8: 尚鴻 | D8: 不銹鋼+烤漆_清板 0.47 | E8: 3200 | F8: 2020/4月 | G8: 不銹鋼(白鐵)清板0.47+烤漆 (含工帶料) | H8: 黃世昕 | I8: 0916107569
B9: 鐵皮浪板 | C9: 盛貿 | D9: 不銹鋼_清板 | E9: 2500 | F9: 2020/4月 | G9: 不銹鋼(白鐵)清板 (含工帶料) | H9: 林浩興 | I9: 0933526557
B10: 鐵皮浪板 | C10: 龍耀 | D10: 不銹鋼_清板 0.5 | E10: 2500 | F10: 2020/4月 | G10: 不銹鋼(白鐵)清板0.5 (含工帶料) | H10: 邱耀德 | I10: 0912607906
B11: 鐵皮浪板 | C11: 尚鴻 | D11: 不銹鋼_清板 0.47 | E11: 2800 | F11: 2020/4月 | G11: 不銹鋼(白鐵)清板0.47 (含工帶料) | H11: 黃世昕 | I11: 0916107569
B12: 鐵皮浪板 | C12: 志貿 | D12: 不銹鋼_清板 0.5 | E12: 2800 | F12: 2019/6月 | G12: 不銹鋼(白鐵)清板0.5 (含工帶料) | H12: 廖彥傑 | I12: 0958159909
B13: 鐵皮浪板 | C13: 志貿 | D13: 烤漆_清板0.6 | E13: 1900 | F13: 2019/6月 | G13: 清板0.6 (含工帶料) 盛餘清板0.5(1200)、三明治0.5(2500)→華鋼 | H13: 廖彥傑 | I13: 0958159909
B14: 鐵皮浪板 | C14: 宏勝 | D14: 烤漆_清板 0.52(盛餘) | E14: 1600 | F14: 2018/1月 | G14: 盛餘清板0.52 (含工帶料) | H14: 葉老闆 | I14: 0973124524
B15: 鐵皮浪板 | C15: 宏勝 | D15: 烤漆_清板 0.52(盛餘) + Z或口型鋼 | E15: 1800 | F15: 2018/1月 | G15: 盛餘清板0.52+Z或口型鋼 (含工帶料) | H15: 葉老闆 | I15: 0973124524
B16: 鐵皮浪板 | C16: 宏勝 | D16: 烤漆_雙層鋼板 0.5(盛餘) | E16: 1850 | F16: 2019/10月 | G16: 0.5商標雙層盛於浪板 (含工帶料) | H16: 葉老闆 | I16: 0973124524
B17: 鐵皮浪板 | C17: 尚鴻 | D17: 烤漆_雙層鋼板 0.5 | E17: 1980 | F17: 2019/10月 | G17: 750五溝雙層鋼板 (含工帶料) | H17: 黃世昕 | I17: 0916107569
B18: 鐵皮浪板 | C18: 盛貿 | D18: 烤漆_雙層鋼板 | E18: 2000 | F18: 2019/10月 | G18: 三合一浪板 (含工帶料) | H18: 林浩興 | I18: 0933526557
B19: 鐵皮浪板 | C19: 門泰 | D19: 烤漆_雙層鋼板 | E19: 1800 | F19: 2019/10月 | G19: 烤漆四合一 (含工帶料) | H19: 范光星 | I19: 0937020326
... B21: 鐵皮浪板 | C21: 立岑 | D21: 烤漆_三明治板 0.52(燁輝) | E21: 3250 | F21: 2018/1月 | G21: 外層板:燁輝0.52PE烤漆 中層:5cm玻璃棉+1.6mmZ型鐵 內層:凱景0.42PE烤漆美式板 含工帶料，不含清運(清板:170/坪、防火板620/坪) | H21: 楊文雄 | I21: 0955788037
B22: 鐵皮浪板 | C22: 華鋼 | D22: 盛餘清板0.5 | F22: 2018/6月 | G22: 盛餘清板0.5 (含工帶料，修邊280(米/元)，美福介紹) | H22: 李天助 | I22: 0932399844
B23: 鐵皮浪板 | C23: 華鋼 | D23: 三明治0.5 | F23: 2018/6月 | G23: 三明治0.5 (含工帶料，修邊280(米/元)，美福介紹) | H23: 李天助 | I23: 0932399844
B25: 品名 | C25: 廠商 | D25: 規格 | E25: 報價(台幣/米) | F25: 報價時間 | G25: NOTE | H25: 聯絡人 | I25: 聯絡方式
B26: 防水膠帶 | C26: 3M | D26: 寬3cm | E26: 100 | F26: 2018/7月 | G26: 寬3cm x 長1600cm一捲，原材料 寬60cm x 長1600cm一捲
B27: 防水膠帶412 | C27: 金勇貿 | D27: 厚0.5mmx寬3cm | E27: 18 | F27: 2018/7月 | G27: 厚0.5mmx寬3cm x 長20m，每寬120元，可客製化裁切 | H27: 李先生 | I27: 0980111379
B28: 防水膠帶5032 | C28: 金勇貿 | D28: 厚2mmx寬3cm | E28: 33 | F28: 2018/7月 | G28: 厚2mmx寬3cm x 長10m，每寬110元，可客製化裁切 | H28: 李先生 | I28: 0980111379
B29: 結構膠帶2204 | C29: 3M | D29: 寬4cm | E29: 38 | G29: 寬4cm x 長2500cm一捲 | H29: 邱先生 | I29: 0935052022
B31: 品名 | C31: 廠商 | D31: 規格 | E31: 報價(台幣/米) | F31: 報價時間 | G31: NOTE | H31: 聯絡人 | I31: 聯絡方式
B32: 爬梯 | C32: 中苗鐵工廠 | D32: 不鏽鋼爬梯+護籠 | E32: 3500 | F32: 2018/12月 | G32: 含工帶料 | H32: 羅老闆 | I32: 0932617006
B34: 品名 | C34: 廠商 | D34: 規格 | E34: 報價(台幣/米) | F34: 報價時間 | G34: NOTE | H34: 聯絡人 | I34: 聯絡方式
B35: 不鏽鋼水槽 | C35: 華鋼 | D35: 0.5t | E35: 700 | F35: 2018/6月 | G35: 含工帶料，美福介紹 | H35: 李天助 | I35: 0932399844
B36: 不鏽鋼水槽 | C36: 華鋼 | D36: 1t | E36: 1600 | F36: 2018/6月 | G36: 含工帶料，美福介紹 | H36: 李天助 | I36: 0932399844
B37: 不鏽鋼水槽 | C37: 宏勝 | D37: 0.4t | E37: 1000 | F37: 2019/10月 | G37: 含工帶料 | H37: 葉老闆 | I37: 0973124524
B38: 不鏽鋼水槽 | C38: 尚鴻 | D38: 0.5t | E38: 1000 | F38: 2019/10月 | G38: 含工帶料 | H38: 黃世昕 | I38: 0916107569
B40: 品名 | C40: 廠商 | D40: 規格 | E40: 報價(台幣/米) | F40: 報價時間 | G40: NOTE | H40: 聯絡人 | I40: 聯絡方式
B41: 收邊 烤漆鋁鋅板 | C41: 宏勝 | D41: 0.5 | E41: 300 | F41: 2019/10月 | G41: 含工帶料 | H41: 葉老闆 | I41: 0973124524
B42: 收邊 烤漆鋁鋅板 | C42: 尚鴻 | D42: 0.5 | E42: 300 | F42: 2019/10月 | G42: 含工帶料 | H42: 黃世昕 | I42: 0916107569
B43: 收邊 烤漆鋁鋅板 | C43: 門泰 | E43: 300 | F43: 2019/10月 | G43: 含工帶料 | H43: 范光星 | I43: 0937020326
B44: 收邊 烤漆鋁鋅板 | C44: 聖貿 | E44: 300 | F44: 2019/10月 | G44: 含工帶料 | H44: 林浩興 | I44: 0933526557
B45: 收邊 不鏽鋼板 | C45: 聖貿 | E45: 700 | F45: 2020/4月 | G45: 含工帶料 | H45: 林浩興 | I45: 0933526557
B46: 收邊 烤漆不鏽鋼板 | C46: 聖貿 | E46: 800 | F46: 2020/4月 | G46: 含工帶料 | H46: 林浩興 | I46: 0933526557

Sheet 監控
B1: 監控收集器 | F1: 環控設備
B2: 選用廠商 | C2: 規格 | D2: 報價(台幣/台) | F2: 選用廠商 | G2: 規格 | H2: 報價(台幣/式)
B3: =B14 | C3: =C14 | D3: =D14 | F3: =IF(成本!D2<=100,B29,IF(成本!D2>100,B30,)) | G3: =IF(成本!D2<=100,C29,IF(成本!D2>100,C30,)) | H3: =IF(成本!D2<=100,D29,IF(成本!D2>100,D30))*0+D29+D30*2
B5: 數據收集盒 | F5: 雲端系統
B6: 選用廠商 | C6: 規格 | D6: 報價(台幣/台) | F6: 選用廠商 | G6: 規格 | H6: 報價(台幣/年)
B7: =B22 | C7: =C22 | D7: =D22 | F7: =B45 | G7: =C45 | H7: =D43+D44+D45
B10: 監控收集器
B11: 廠商 | C11: 規格 | D11: 報價(台幣/台) | E11: KW | F11: 報價時間 | G11: NOTE | H11: 聯絡人 | I11: 聯絡方式 | J11: Email
B12: Solarbridge | C12: PowerManerger | D12: 12000 | G12: 含雲端系統,無專人監控(由Sinbon專人監控) | H12: 蘇育志 | I12: 0936-185841 / 03-5980288-1370 | J12: jeffery.su@bigsun-energy.com
B13: APS | C13: ECU | D13: 7500 | H13: 業務
B14: APS | C14: ECUR | D14: =100*#REF! | F14: 2020/1月 | G14: 100/USD，保固3年，90台QS1用一台ECU-R | H14: 麗芳
B15: 古瑞瓦特 | C15: 監控模組 | D15: 1500 | F15: 2021/10月 | G15: 7台以內INV，(一支對一台INV) | H15: 郭曜誠 | I15: 0975-515-112
B16: 古瑞瓦特 | C16: 數據收集器 | D16: 15000 | F16: 2021/10月 | G16: 32台INV，拉RS-485線路 | H16: 郭曜誠 | I16: 0975-515-112
B17: 新望 | C17: V1000+ | D17: 5000 | F17: 2022/3月 | G17: 外接資料蒐集器-含電源組，一年保固 / 無延保方案 | H17: 郭曜誠 | I17: 0975-515-112
B18: 新望 | C18: V1000L | D18: 8000 | F18: 2022/3月 | G18: 外接資料蒐集器-含電源組，一年保固 / 無延保方案 | H18: 郭曜誠 | I18: 0975-515-112
B20: 數據收集盒
B21: BIG SUN | C21: iPVBox智慧盒 | D21: 15800 | F21: 2018/4月 | G21: iPVBox-2102 智慧盒 (5年保固) | H21: 蘇育志 | I21: 0936-185841 / 03-5980288-1370 | J21: jeffery.su@bigsun-energy.com
B22: 沅碁雲 | C22: Logger | D22: 35000 | E22: 2MW以下 | F22: 2020/10月 | G22: logger保固一年含現場安裝費(線材不含)；Logger $14000/台；雲端系統 | H22: 王振城 | I22: 0928-225-333 | J22: max@sunedge.com.tw
B23: 沅碁雲 | C23: Logger | D23: 25000 | E23: 2MW以下 | F23: 2020/10月 | G23: logger保固一年含現場安裝費(線材不含)；Logger $14000/台；雲端系統+Dreams系統 | H23: 王振城 | I23: 0928-225-333 | J23: max@sunedge.com.tw
B24: 三惟 | C24: Logger | D24: 31500 | E24: 499kW以下 | F24: 2020/4月 | G24: logger保固一年不含現場安裝費(線材不含) | H24: 朱育龍 | I24: 02-6620-8358 / 0928-765206 | J24: Adam-chew@sunware.com.tw
B25: 慧景 | C25: Logger | D25: 25000 | E25: - | F25: 2022/3月 | G25: logger保固五年(工業等級)；範圍25~40台裝置(基本30台)；型號：pt-2020 (2port) | H25: 詹前鋒 | I25: 0989-434-128 | J25: max@thingnario.com
B26: 慧景 | C26: Logger | D26: 28000 | E26: - | F26: 2022/3月 | G26: logger保固五年(工業等級)；範圍25~40台裝置(基本30台)；型號：pt-4020 (4port) | H26: 詹前鋒 | I26: 0989-434-128 | J26: max@thingnario.com
B28: 環控設備
B29: 沅碁 | C29: 環控設備 | D29: 52300 | E29: 100KW以下 | F29: 2018/2月 | G29: 含溫度(5300)+日照(28500)+CT、交流錶頭(18500) | H29: 王振城 | I29: 0928-225-333 | J29: max@sunedge.com.tw
B30: 沅碁 | C30: 環控設備 | D30: 55000 | E30: 499KW | F30: 2018/7月 | G30: 含溫度、日照(43000)+CT、交流錶頭(12000) | H30: 王振城 | I30: 0928-225-333 | J30: max@sunedge.com.tw
B31: 綠世界 | C31: 環控設備 | D31: 44600 | E31: 100KW以下 | F31: 2018/2月 | G31: 含溫度(4900)+日照(19400)+CT(600*3)+交流錶頭(6600)+安裝費(2500)+箱體(9400) | H31: 蘇育志 | I31: 0936-185841 / 03-5980288-1370
B32: 綠世界 | C32: 環控設備 | D32: 51200 | E32: 100KW以上 | F32: 2018/2月 | G32: 含溫度(4900)+日照(19400)+CT(2800*3)+交流錶頭(6600)+安裝費(2500)+箱體(9400) | H32: 蘇育志 | I32: 0936-185841 / 03-5980288-1370
B33: 三惟 | C33: 環控設備 | D33: 43500 | E33: 499KW | F33: 2020/4月 | G33: 含溫度(1500)+日照(22000)+CT(2800*3)+交流錶頭(6600)+箱體(8000) | H33: 朱育龍 | I33: 02-6620-8358 / 0928-765206 | J33: Adam-chew@sunware.com.tw
B34: 三惟 | C34: 環控設備 | D34: 40900 | E34: 100KW | F34: 2021/8月 | G34: 含溫度(2000)+日照(19500)+CT(2800*3)+交流錶頭(5000)+箱體(6000) | H34: 朱育龍 | I34: 02-6620-8358 / 0928-765206 | J34: Adam-chew@sunware.com.tw
B35: 慧景(紘銘) | C35: 環控設備 | D35: 40700 | E35: - | F35: 2022/4月 | G35: 含溫度(5150)+日照(22350)+箱體(13200) | H35: 詹前鋒 | I35: 0989-434-128 | J35: max@thingnario.com
B37: 雲端系統
B38: 廠商 | C38: 規格 | D38: 報價(台幣/年) | E38: KW | F38: 報價時間 | G38: NOTE | H38: 聯絡人 | I38: 聯絡方式 | J38: Email | K38: 報價(台幣)
B39: BIG SUN | C39: 雲端IPV系統 | D39: 900 | E39: 20KW以下 | F39: 2018/4月 | G39: 5年期滿後每案每年1000元 | H39: 蘇育志 | I39: 0936-185841 / 03-5980288-1370 | J39: jeffery.su@bigsun-energy.com | K39: 25000
B40: BIG SUN | C40: 雲端IPV系統 | D40: 1600 | E40: 21-100KW | F40: 2018/4月 | G40: 5年期滿後每案每年1000元 | H40: 蘇育志 | I40: 0936-185841 / 03-5980288-1370 | J40: jeffery.su@bigsun-energy.com
B41: BIG SUN | C41: 雲端IPV系統 | D41: 2000 | E41: 101-499KW | F41: 2018/4月 | G41: 5年期滿後每案每年1000元 | H41: 蘇育志 | I41: 0936-185841 / 03-5980288-1370 | J41: jeffery.su@bigsun-energy.com
B42: BIG SUN | C42: 雲端IPV系統 | D42: 3000 | E42: 499-999KW | F42: 2018/4月 | G42: 5年期滿後每案每年1000元 | H42: 蘇育志 | I42: 0936-185841 / 03-5980288-1370 | J42: jeffery.su@bigsun-energy.com
B43: 沅碁 | C43: 沅碁網站監控 | D43: 4000 | E43: 100KW以下 | F43: 2020/10月 | G43: 含專人監控,五年一個package | H43: 王振城 | I43: 0928-225-333 | J43: max@sunedge.com.tw
B44: 沅碁 | C44: 沅碁網站監控 | D44: 7000 | E44: 101-300KW | F44: 2020/10月 | H44: 王振城 | I44: 0928-225-333 | J44: max@sunedge.com.tw
B45: 沅碁 | C45: 沅碁網站監控 | D45: 12000 | E45: 301-499KW | F45: 2020/10月 | H45: 王振城 | I45: 0928-225-333 | J45: max@sunedge.com.tw
B46: 沅碁 | C46: 沅碁網站監控 | D46: 16000 | E46: 500~1MW | F46: 2020/10月 | H46: 王振城 | I46: 0928-225-333 | J46: max@sunedge.com.tw
...

Sheet 監控 (2)
B1: 數據收集盒
B2: 慧景 | C2: Logger | D2: 25000 | E2: - | F2: 2022/3月 | G2: logger保固五年(工業等級)；範圍25~40台裝置(基本30台)；型號：pt-2020 (2port) | H2: 詹前鋒 | I2: 0989-434-128 | J2: max@thingnario.com
B3: 慧景 | C3: Logger | D3: 28000 | E3: - | F3: 2022/3月 | G3: logger保固五年(工業等級)；範圍25~40台裝置(基本30台)；型號：pt-4020 (4port) | H3: 詹前鋒 | I3: 0989-434-128 | J3: max@thingnario.com
B5: 環控設備
B6: 慧景(紘銘) | C6: 環控設備 | D6: 38100 | E6: - | F6: 2022/3月 | G6: 含溫度(2300)+日照(19500)+交流錶頭(5700)+箱體(10600)、不含CT | H6: 詹前鋒 | I6: 0989-434-128 | J6: max@thingnario.com
B7: 慧景(紘銘) | C7: 環控設備 | D7: 40700 | E7: - | F7: 2022/4月 | G7: 含溫度(5150)+日照(22350)+箱體(13200) | H7: 詹前鋒 | I7: 0989-434-128 | J7: max@thingnario.com
B9: 雲端系統
B10: 廠商 | C10: 規格 | D10: 報價(台幣/年) | E10: KW | F10: 報價時間 | G10: NOTE | H10: 聯絡人 | I10: 聯絡方式 | J10: Email | K10: 報價(台幣)
B11: 慧景 | C11: 慧景網站監控 | D11: =K11/5 | E11: 100kW以下 | F11: 2022/3月 | G11: 五年一個package，共5年 (無專人監控，提供一套系統平臺，供維運及管理電站) | H11: 詹前鋒 | I11: 0989-434-128 | J11: max@thingnario.com | K11: 25000
B12: 慧景 | C12: 慧景網站監控 | D12: =K12/5 | E12: 99~249kW | F12: 2022/3月 | H12: 詹前鋒 | I12: 0989-434-128 | J12: max@thingnario.com | K12: 35000
B13: 慧景 | C13: 慧景網站監控 | D13: =K13/5 | E13: 249~499kW | F13: 2022/3月 | H13: 詹前鋒 | I13: 0989-434-128 | J13: max@thingnario.com | K13: 45000
B14: 慧景 | C14: 慧景網站監控 | D14: =K14/5 | E14: 499~999kW | F14: 2022/3月 | H14: 詹前鋒 | I14: 0989-434-128 | J14: max@thingnario.com | K14: 60000
B15: 慧景 | C15: 慧景網站監控 | D15: =K15/20 | E15: 99kW以下 | F15: 2022/3月 | G15: 五年一個package，共20年 (無專人監控，提供一套系統平臺，供維運及管理電站) | H15: 詹前鋒 | I15: 0989-434-128 | J15: max@thingnario.com | K15: =K11*4
B16: 慧景 | C16: 慧景網站監控 | D16: =K16/20 | E16: 99~249kW | F16: 2022/3月 | H16: 詹前鋒 | I16: 0989-434-128 | J16: max@thingnario.com | K16: =K12*4
B17: 慧景 | C17: 慧景網站監控 | D17: =K17/20 | E17: 249~499kW | F17: 2022/3月 | H17: 詹前鋒 | I17: 0989-434-128 | J17: max@thingnario.com | K17: =K13*4
B18: 慧景 | C18: 慧景網站監控 | D18: =K18/20 | E18: 499~999kW | F18: 2022/3月 | H18: 詹前鋒 | I18: 0989-434-128 | J18: max@thingnario.com | K18: =K14*4
B19: 慧景 | C19: 慧景網站監控 | D19: =K19/20 | E19: 99kW以下 | F19: 2022/3月 | G19: 二十年一個package，共20年 (無專人監控，提供一套系統平臺，供維運及管理電站) | H19: 詹前鋒 | I19: 0989-434-128 | J19: max@thingnario.com | K19: =K15*L19 | L19: 0.95
B20: 慧景 | C20: 慧景網站監控 | D20: =K20/20 | E20: 99~249kW | F20: 2022/3月 | H20: 詹前鋒 | I20: 0989-434-128 | J20: max@thingnario.com | K20: =K16*L19 | L20: 0.95
B21: 慧景 | C21: 慧景網站監控 | D21: =K21/20 | E21: 249~499kW | F21: 2022/3月 | H21: 詹前鋒 | I21: 0989-434-128 | J21: max@thingnario.com | K21: =K17*L19 | L21: 0.95
B22: 慧景 | C22: 慧景網站監控 | D22: =K22/20 | E22: 499~999kW | F22: 2022/3月 | H22: 詹前鋒 | I22: 0989-434-128 | J22: max@thingnario.com | K22: =K18*L19 | L22: 0.95
B24: Dreams系統 | C24: 同一廠址總裝置容量500kW以上時，須裝設遙控監視設備並接受台電安全調度(110.08.05)
B25: 廠商 | C25: 規格 | D25: 報價(台幣) | E25: KW | F25: 報價時間 | G25: NOTE | H25: 聯絡人 | I25: 聯絡方式 | J25: Email
B26: 慧景 | C26: 慧景網站監控 | D26: 35000 | E26: 500~1MW | F26: 2021/8月 | G26: 5年 | H26: 詹前鋒 | I26: 0937-099-803 | J26: max@thingnario.com
B27: 慧景 | C27: 慧景網站監控 | D27: 41000 | E27: 500~1MW | F27: 2021/8月 | G27: 5年+SIM卡 | H27: 詹前鋒 | I27: 0937-099-803 | J27: max@thingnario.com
B28: 慧景 | C28: 慧景網站監控 | D28: 200000 | E28: 500~1MW | F28: 2021/8月 | G28: 20年 | H28: 詹前鋒 | I28: 0937-099-803 | J28: max@thingnario.com
B29: 慧景 | C29: 慧景網站監控 | D29: 224000 | E29: 500~1MW | F29: 2021/8月 | G29: 20年+SIM卡 | H29: 詹前鋒 | I29: 0937-099-803 | J29: max@thingnario.com
B30: 慧景 | C30: 慧景網站監控 | D30: 72000 | E30: 1~2MW | F30: 2021/8月 | G30: 5年+SIM卡 | H30: 詹前鋒 | I30: 0937-099-803 | J30: max@thingnario.com
B31: 慧景 | C31: 慧景網站監控 | D31: 288000 | E31: 1~2MW | F31: 2021/8月 | G31: 20年+SIM卡 | H31: 詹前鋒 | I31: 0937-099-803 | J31: max@thingnario.com
B33: 雲端系統+Dreams系統 | D33: 同一廠址總裝置容量500kW以上時，須裝設遙控監視設備並接受台電安全調度(110.08.05)
B34: 廠商 | C34: 規格 | D34: 報價(台幣/年)*20年 | E34: KW | F34: 報價時間 | G34: NOTE | H34: 聯絡人 | I34: 聯絡方式 | J34: Email | K34: 報價(台幣)
B35: 慧景 | C35: 慧景網站監控 | D35: =D22 | E35: 499~999kW | F35: 2022/3月 | G35: 二十年一個package；無SIM卡；含硬體(logger) | H35: 詹前鋒 | I35: 0989-434-128 | J35: max@thingnario.com | K35: =K22
B36: 慧景 | C36: 慧景網站監控 | D36: 224000 | E36: 500~1MW | F36: 2021/8月 | G36: 20年+SIM卡 | H36: 詹前鋒 | I36: 0989-434-128 | J36: max@thingnario.com | K36: =R23
B37: 慧景 | C37: 慧景網站監控 | D37: 10 / kW | E37: 1~80MW | F37: 2022/3月 | G37: 二十年一個package；無SIM卡；純軟體不含硬體(logger)，1MW->$10,000/年(1/kw->$10/年) | H37: 詹前鋒 | I37: 0989-434-128 | J37: max@thingnario.com | K37: -
B38: 慧景 | C38: 慧景網站監控 | D38: 288000 | E38: 1~2MW | F38: 2021/8月 | G38: 20年+SIM卡 | H38: 詹前鋒 | I38: 0937-099-803 | J38: max@thingnario.com
D40: 一電站拆一二期，且總建置超過500kW
D41: ～ 499kW 採級距報價 ， 二期 就採用每kW 純軟體的收費 1.2NT /每月 ； kW*1.2*單月；前提一二期INV位置相同，可共用Logger；如INV不同區域，無法共用Logger，則須額外加購Logger
D42: (二十年一個package)
D45: 備註
D46: 1.SIM卡 $6000(5年)=$1200(1年)=$100(1個月) for Dreams(1G)
D47: 2.報價內含了logger (軟硬體皆含)
...

Sheet 監控 (3)
B1: 監控收集器 | F1: 環控設備
B2: 選用廠商 | C2: 規格 | D2: 報價(台幣/台) | F2: 選用廠商 | G2: 規格 | H2: 報價(台幣/式)
B3: =B14 | C3: =C14 | D3: =D14 | F3: =IF(#REF!<=100,B24,IF(#REF!>100,B25,)) | G3: =IF(#REF!<=100,C24,IF(#REF!>100,C25,)) | H3: =IF(#REF!<=100,D24,IF(#REF!>100,D25))
B5: 數據收集盒 | F5: 雲端系統
B6: 選用廠商 | C6: 規格 | D6: 報價(台幣/台) | F6: 選用廠商 | G6: 規格 | H6: 報價(台幣/年)
B7: =B18 | C7: =C18 | D7: =D18 | F7: =B39 | G7: =C39 | H7: =D39
B10: 監控收集器
B11: 廠商 | C11: 規格 | D11: 報價(台幣/台) | E11: KW | F11: 報價時間 | G11: NOTE | H11: 聯絡人 | I11: 聯絡方式 | J11: Email
B12: Solarbridge | C12: PowerManerger | D12: 12000 | G12: 含雲端系統,無專人監控(由Sinbon專人監控) | H12: 蘇育志 | I12: 0936-185841 / 03-5980288-1370 | J12: jeffery.su@bigsun-energy.com
B13: APS | C13: ECU | D13: 7500 | H13: 業務
B14: APS | C14: ECUR | D14: =100*#REF! | F14: 2020/1月 | G14: 100/USD，保固3年，90台QS1用一台ECU-R | H14: 麗芳
B16: 數據收集盒
B17: BIG SUN | C17: iPVBox智慧盒 | D17: 15800 | F17: 2018/4月 | G17: iPVBox-2102 智慧盒 (5年保固) | H17: 蘇育志 | I17: 0936-185841 / 03-5980288-1370 | J17: jeffery.su@bigsun-energy.com
B18: 沅碁雲 | C18: Logger | D18: 35000 | E18: 2MW以下 | F18: 2020/10月 | G18: logger保固一年含現場安裝費(線材不含)；Logger $14000/台；雲端系統 | H18: 王振城 | I18: 0928-225-333 | J18: max@sunedge.com.tw
B19: 沅碁雲 | C19: Logger | D19: 25000 | E19: 2MW以下 | F19: 2020/10月 | G19: logger保固一年含現場安裝費(線材不含)；Logger $14000/台；雲端系統+Dreams系統 | H19: 王振城 | I19: 0928-225-333 | J19: max@sunedge.com.tw
