Workbook

Sheet 多站彙整
C4: 年份 | D4: 2020 | E4: 2021 | F4: 2022 | G4: 2023 | H4: 2024 | I4: 2025 | J4: 2026 | K4: 2027 | L4: 2028 | M4: 2029 | N4: 2030 | O4: 2031 | P4: 2032 | Q4: 2033 | R4: 2034 | S4: 2035 | T4: 2036 | U4: 2037 | V4: 2038 | W4: 2039
C5: 預估發電度數
B6: 淡江大學 | D6: =ROUND(ABS(淡江大學_p2!D40),0) -> 541532 | E6: =ROUND(ABS(淡江大學_p2!E40),0) -> 539344 | F6: =ROUND(ABS(淡江大學_p2!F40),0) -> 537156 | G6: =ROUND(ABS(淡江大學_p2!G40),0) -> 534968 | H6: =ROUND(ABS(淡江大學_p2!H40),0) -> 532780 | I6: =ROUND(ABS(淡江大學_p2!I40),0) -> 530592 | J6: =ROUND(ABS(淡江大學_p2!J40),0) -> 528404 | K6: =ROUND(ABS(淡江大學_p2!K40),0) -> 526216 | ... W6: =ROUND(ABS(淡江大學_p2!W40),0) -> 499960
B7: 淡江大學 | D7: =ROUND(ABS(淡江大學_p5!D40),0) -> 541532 | E7: =ROUND(ABS(淡江大學_p5!E40),0) -> 539344 | F7: =ROUND(ABS(淡江大學_p5!F40),0) -> 537156 | G7: =ROUND(ABS(淡江大學_p5!G40),0) -> 534968 | H7: =ROUND(ABS(淡江大學_p5!H40),0) -> 532780 | I7: =ROUND(ABS(淡江大學_p5!I40),0) -> 530592 | J7: =ROUND(ABS(淡江大學_p5!J40),0) -> 528404 | K7: =ROUND(ABS(淡江大學_p5!K40),0) -> 526216 | ... W7: =ROUND(ABS(淡江大學_p5!W40),0) -> 499960
B8: 淡江大學 | D8: =ROUND(ABS(淡江大學_p3!D40),0) -> 541532 | E8: =ROUND(ABS(淡江大學_p3!E40),0) -> 539344 | F8: =ROUND(ABS(淡江大學_p3!F40),0) -> 537156 | G8: =ROUND(ABS(淡江大學_p3!G40),0) -> 534968 | H8: =ROUND(ABS(淡江大學_p3!H40),0) -> 532780 | I8: =ROUND(ABS(淡江大學_p3!I40),0) -> 530592 | J8: =ROUND(ABS(淡江大學_p3!J40),0) -> 528404 | K8: =ROUND(ABS(淡江大學_p3!K40),0) -> 526216 | ... W8: =ROUND(ABS(淡江大學_p3!W40),0) -> 499960
B9: 淡江大學 | D9: =ROUND(ABS(淡江大學_p4!D40),0) -> 541532 | E9: =ROUND(ABS(淡江大學_p4!E40),0) -> 539344 | F9: =ROUND(ABS(淡江大學_p4!F40),0) -> 537156 | G9: =ROUND(ABS(淡江大學_p4!G40),0) -> 534968 | H9: =ROUND(ABS(淡江大學_p4!H40),0) -> 532780 | I9: =ROUND(ABS(淡江大學_p4!I40),0) -> 530592 | J9: =ROUND(ABS(淡江大學_p4!J40),0) -> 528404 | K9: =ROUND(ABS(淡江大學_p4!K40),0) -> 526216 | ... W9: =ROUND(ABS(淡江大學_p4!W40),0) -> 499960
C10: 預估發電度數/年總計 | D10: =SUM(D6:D9) -> 2166128 | E10: =SUM(E6:E9) -> 2157376 | F10: =SUM(F6:F9) -> 2148624 | G10: =SUM(G6:G9) -> 2139872 | H10: =SUM(H6:H9) -> 2131120 | I10: =SUM(I6:I9) -> 2122368 | J10: =SUM(J6:J9) -> 2113616 | K10: =SUM(K6:K9) -> 2104864 | ... W10: =SUM(W6:W9) -> 1999840
C11: 年份 | D11: 2020 | E11: 2021 | F11: 2022 | G11: 2023 | H11: 2024 | I11: 2025 | J11: 2026 | K11: 2027 | L11: 2028 | M11: 2029 | N11: 2030 | O11: 2031 | P11: 2032 | Q11: 2033 | R11: 2034 | S11: 2035 | T11: 2036 | U11: 2037 | V11: 2038 | W11: 2039
C12: 預估收入
B13: 淡江大學 | D13: =ROUND(ABS(淡江大學_p2!D41),0) -> 2166128 | E13: =ROUND(ABS(淡江大學_p2!E41),0) -> 2157376 | F13: =ROUND(ABS(淡江大學_p2!F41),0) -> 2148624 | G13: =ROUND(ABS(淡江大學_p2!G41),0) -> 2139872 | H13: =ROUND(ABS(淡江大學_p2!H41),0) -> 2131120 | I13: =ROUND(ABS(淡江大學_p2!I41),0) -> 2122368 | J13: =ROUND(ABS(淡江大學_p2!J41),0) -> 2113616 | K13: =ROUND(ABS(淡江大學_p2!K41),0) -> 2104864 | ... W13: =ROUND(ABS(淡江大學_p2!W41),0) -> 1999839
B14: 淡江大學 | D14: =ROUND(ABS(淡江大學_p5!D41),0) -> 2166128 | E14: =ROUND(ABS(淡江大學_p5!E41),0) -> 2157376 | F14: =ROUND(ABS(淡江大學_p5!F41),0) -> 2148624 | G14: =ROUND(ABS(淡江大學_p5!G41),0) -> 2139872 | H14: =ROUND(ABS(淡江大學_p5!H41),0) -> 2131120 | I14: =ROUND(ABS(淡江大學_p5!I41),0) -> 2122368 | J14: =ROUND(ABS(淡江大學_p5!J41),0) -> 2113616 | K14: =ROUND(ABS(淡江大學_p5!K41),0) -> 2104864 | ... W14: =ROUND(ABS(淡江大學_p5!W41),0) -> 1999839
B15: 淡江大學 | D15: =ROUND(ABS(淡江大學_p3!D41),0) -> 2166128 | E15: =ROUND(ABS(淡江大學_p3!E41),0) -> 2157376 | F15: =ROUND(ABS(淡江大學_p3!F41),0) -> 2148624 | G15: =ROUND(ABS(淡江大學_p3!G41),0) -> 2139872 | H15: =ROUND(ABS(淡江大學_p3!H41),0) -> 2131120 | I15: =ROUND(ABS(淡江大學_p3!I41),0) -> 2122368 | J15: =ROUND(ABS(淡江大學_p3!J41),0) -> 2113616 | K15: =ROUND(ABS(淡江大學_p3!K41),0) -> 2104864 | ... W15: =ROUND(ABS(淡江大學_p3!W41),0) -> 1999839
B16: 淡江大學 | D16: =ROUND(ABS(淡江大學_p4!D41),0) -> 2166128 | E16: =ROUND(ABS(淡江大學_p4!E41),0) -> 2157376 | F16: =ROUND(ABS(淡江大學_p4!F41),0) -> 2148624 | G16: =ROUND(ABS(淡江大學_p4!G41),0) -> 2139872 | H16: =ROUND(ABS(淡江大學_p4!H41),0) -> 2131120 | I16: =ROUND(ABS(淡江大學_p4!I41),0) -> 2122368 | J16: =ROUND(ABS(淡江大學_p4!J41),0) -> 2113616 | K16: =ROUND(ABS(淡江大學_p4!K41),0) -> 2104864 | ... W16: =ROUND(ABS(淡江大學_p4!W41),0) -> 1999839
C17: 預估收入/年總計 | D17: =SUM(D13:D16) -> 8664512 | E17: =SUM(E13:E16) -> 8629504 | F17: =SUM(F13:F16) -> 8594496 | G17: =SUM(G13:G16) -> 8559488 | H17: =SUM(H13:H16) -> 8524480 | I17: =SUM(I13:I16) -> 8489472 | J17: =SUM(J13:J16) -> 8454464 | K17: =SUM(K13:K16) -> 8419456 | ... W17: =SUM(W13:W16) -> 7999356
C18: 年份 | D18: 2020 | E18: 2021 | F18: 2022 | G18: 2023 | H18: 2024 | I18: 2025 | J18: 2026 | K18: 2027 | L18: 2028 | M18: 2029 | N18: 2030 | O18: 2031 | P18: 2032 | Q18: 2033 | R18: 2034 | S18: 2035 | T18: 2036 | U18: 2037 | V18: 2038 | W18: 2039
C19: 租金
B20: 淡江大學 | D20: =ROUND(ABS(淡江大學_p2!D45),0) -> 290201 | E20: =ROUND(ABS(淡江大學_p2!E45),0) -> 290201 | F20: =ROUND(ABS(淡江大學_p2!F45),0) -> 290201 | G20: =ROUND(ABS(淡江大學_p2!G45),0) -> 290201 | H20: =ROUND(ABS(淡江大學_p2!H45),0) -> 290201 | I20: =ROUND(ABS(淡江大學_p2!I45),0) -> 290201 | J20: =ROUND(ABS(淡江大學_p2!J45),0) -> 290201 | K20: =ROUND(ABS(淡江大學_p2!K45),0) -> 290201 | ... W20: =ROUND(ABS(淡江大學_p2!W45),0) -> 290201
B21: 淡江大學 | D21: =ROUND(ABS(淡江大學_p5!D45),0) -> 290201 | E21: =ROUND(ABS(淡江大學_p5!E45),0) -> 290201 | F21: =ROUND(ABS(淡江大學_p5!F45),0) -> 290201 | G21: =ROUND(ABS(淡江大學_p5!G45),0) -> 290201 | H21: =ROUND(ABS(淡江大學_p5!H45),0) -> 290201 | I21: =ROUND(ABS(淡江大學_p5!I45),0) -> 290201 | J21: =ROUND(ABS(淡江大學_p5!J45),0) -> 290201 | K21: =ROUND(ABS(淡江大學_p5!K45),0) -> 290201 | ... W21: =ROUND(ABS(淡江大學_p5!W45),0) -> 290201
B22: 淡江大學 | D22: =ROUND(ABS(淡江大學_p3!D45),0) -> 290201 | E22: =ROUND(ABS(淡江大學_p3!E45),0) -> 290201 | F22: =ROUND(ABS(淡江大學_p3!F45),0) -> 290201 | G22: =ROUND(ABS(淡江大學_p3!G45),0) -> 290201 | H22: =ROUND(ABS(淡江大學_p3!H45),0) -> 290201 | I22: =ROUND(ABS(淡江大學_p3!I45),0) -> 290201 | J22: =ROUND(ABS(淡江大學_p3!J45),0) -> 290201 | K22: =ROUND(ABS(淡江大學_p3!K45),0) -> 290201 | ... W22: =ROUND(ABS(淡江大學_p3!W45),0) -> 290201
B23: 淡江大學 | D23: =ROUND(ABS(淡江大學_p4!D45),0) -> 290201 | E23: =ROUND(ABS(淡江大學_p4!E45),0) -> 290201 | F23: =ROUND(ABS(淡江大學_p4!F45),0) -> 290201 | G23: =ROUND(ABS(淡江大學_p4!G45),0) -> 290201 | H23: =ROUND(ABS(淡江大學_p4!H45),0) -> 290201 | I23: =ROUND(ABS(淡江大學_p4!I45),0) -> 290201 | J23: =ROUND(ABS(淡江大學_p4!J45),0) -> 290201 | K23: =ROUND(ABS(淡江大學_p4!K45),0) -> 290201 | ... W23: =ROUND(ABS(淡江大學_p4!W45),0) -> 290201
C24: 租金/年總計 | D24: =SUM(D20:D23) -> 1160804 | E24: =SUM(E20:E23) -> 1160804 | F24: =SUM(F20:F23) -> 1160804 | G24: =SUM(G20:G23) -> 1160804 | H24: =SUM(H20:H23) -> 1160804 | I24: =SUM(I20:I23) -> 1160804 | J24: =SUM(J20:J23) -> 1160804 | K24: =SUM(K20:K23) -> 1160804 | ... W24: =SUM(W20:W23) -> 1160804
C25: 年份 | D25: 2020 | E25: 2021 | F25: 2022 | G25: 2023 | H25: 2024 | I25: 2025 | J25: 2026 | K25: 2027 | L25: 2028 | M25: 2029 | N25: 2030 | O25: 2031 | P25: 2032 | Q25: 2033 | R25: 2034 | S25: 2035 | T25: 2036 | U25: 2037 | V25: 2038 | W25: 2039
C26: 運維
B27: 淡江大學 | D27: =ROUND(ABS(淡江大學_p2!D48),0) -> 174440 | E27: =ROUND(ABS(淡江大學_p2!E48),0) -> 174440 | F27: =ROUND(ABS(淡江大學_p2!F48),0) -> 174440 | G27: =ROUND(ABS(淡江大學_p2!G48),0) -> 174440 | H27: =ROUND(ABS(淡江大學_p2!H48),0) -> 174440 | I27: =ROUND(ABS(淡江大學_p2!I48),0) -> 174440 | J27: =ROUND(ABS(淡江大學_p2!J48),0) -> 174440 | K27: =ROUND(ABS(淡江大學_p2!K48),0) -> 174440 | ... W27: =ROUND(ABS(淡江大學_p2!W48),0) -> 174440
B28: 淡江大學 | D28: =ROUND(ABS(淡江大學_p5!D48),0) -> 174440 | E28: =ROUND(ABS(淡江大學_p5!E48),0) -> 174440 | F28: =ROUND(ABS(淡江大學_p5!F48),0) -> 174440 | G28: =ROUND(ABS(淡江大學_p5!G48),0) -> 174440 | H28: =ROUND(ABS(淡江大學_p5!H48),0) -> 174440 | I28: =ROUND(ABS(淡江大學_p5!I48),0) -> 174440 | J28: =ROUND(ABS(淡江大學_p5!J48),0) -> 174440 | K28: =ROUND(ABS(淡江大學_p5!K48),0) -> 174440 | ... W28: =ROUND(ABS(淡江大學_p5!W48),0) -> 174440
B29: 淡江大學 | D29: =ROUND(ABS(淡江大學_p3!D48),0) -> 174440 | E29: =ROUND(ABS(淡江大學_p3!E48),0) -> 174440 | F29: =ROUND(ABS(淡江大學_p3!F48),0) -> 174440 | G29: =ROUND(ABS(淡江大學_p3!G48),0) -> 174440 | H29: =ROUND(ABS(淡江大學_p3!H48),0) -> 174440 | I29: =ROUND(ABS(淡江大學_p3!I48),0) -> 174440 | J29: =ROUND(ABS(淡江大學_p3!J48),0) -> 174440 | K29: =ROUND(ABS(淡江大學_p3!K48),0) -> 174440 | ... W29: =ROUND(ABS(淡江大學_p3!W48),0) -> 174440
B30: 淡江大學 | D30: =ROUND(ABS(淡江大學_p4!D48),0) -> 174440 | E30: =ROUND(ABS(淡江大學_p4!E48),0) -> 174440 | F30: =ROUND(ABS(淡江大學_p4!F48),0) -> 174440 | G30: =ROUND(ABS(淡江大學_p4!G48),0) -> 174440 | H30: =ROUND(ABS(淡江大學_p4!H48),0) -> 174440 | I30: =ROUND(ABS(淡江大學_p4!I48),0) -> 174440 | J30: =ROUND(ABS(淡江大學_p4!J48),0) -> 174440 | K30: =ROUND(ABS(淡江大學_p4!K48),0) -> 174440 | ... W30: =ROUND(ABS(淡江大學_p4!W48),0) -> 174440
C31: 運維/年總計 | D31: =SUM(D27:D30) -> 697760 | E31: =SUM(E27:E30) -> 697760 | F31: =SUM(F27:F30) -> 697760 | G31: =SUM(G27:G30) -> 697760 | H31: =SUM(H27:H30) -> 697760 | I31: =SUM(I27:I30) -> 697760 | J31: =SUM(J27:J30) -> 697760 | K31: =SUM(K27:K30) -> 697760 | ... W31: =SUM(W27:W30) -> 697760
C32: 年份 | D32: 2020 | E32: 2021 | F32: 2022 | G32: 2023 | H32: 2024 | I32: 2025 | J32: 2026 | K32: 2027 | L32: 2028 | M32: 2029 | N32: 2030 | O32: 2031 | P32: 2032 | Q32: 2033 | R32: 2034 | S32: 2035 | T32: 2036 | U32: 2037 | V32: 2038 | W32: 2039
C33: 保險
B34: 淡江大學 | D34: =ROUND(ABS(淡江大學_p2!D49),0) -> 43174 | E34: =ROUND(ABS(淡江大學_p2!E49),0) -> 43174 | F34: =ROUND(ABS(淡江大學_p2!F49),0) -> 43174 | G34: =ROUND(ABS(淡江大學_p2!G49),0) -> 43174 | H34: =ROUND(ABS(淡江大學_p2!H49),0) -> 43174 | I34: =ROUND(ABS(淡江大學_p2!I49),0) -> 43174 | J34: =ROUND(ABS(淡江大學_p2!J49),0) -> 43174 | K34: =ROUND(ABS(淡江大學_p2!K49),0) -> 43174 | ... W34: =ROUND(ABS(淡江大學_p2!W49),0) -> 43174
B35: 淡江大學 | D35: =ROUND(ABS(淡江大學_p5!D49),0) -> 35324 | E35: =ROUND(ABS(淡江大學_p5!E49),0) -> 35324 | F35: =ROUND(ABS(淡江大學_p5!F49),0) -> 35324 | G35: =ROUND(ABS(淡江大學_p5!G49),0) -> 35324 | H35: =ROUND(ABS(淡江大學_p5!H49),0) -> 35324 | I35: =ROUND(ABS(淡江大學_p5!I49),0) -> 35324 | J35: =ROUND(ABS(淡江大學_p5!J49),0) -> 35324 | K35: =ROUND(ABS(淡江大學_p5!K49),0) -> 35324 | ... W35: =ROUND(ABS(淡江大學_p5!W49),0) -> 35324
B36: 淡江大學 | D36: =ROUND(ABS(淡江大學_p3!D49),0) -> 40557 | E36: =ROUND(ABS(淡江大學_p3!E49),0) -> 40557 | F36: =ROUND(ABS(淡江大學_p3!F49),0) -> 40557 | G36: =ROUND(ABS(淡江大學_p3!G49),0) -> 40557 | H36: =ROUND(ABS(淡江大學_p3!H49),0) -> 40557 | I36: =ROUND(ABS(淡江大學_p3!I49),0) -> 40557 | J36: =ROUND(ABS(淡江大學_p3!J49),0) -> 40557 | K36: =ROUND(ABS(淡江大學_p3!K49),0) -> 40557 | ... W36: =ROUND(ABS(淡江大學_p3!W49),0) -> 40557
B37: 淡江大學 | D37: =ROUND(ABS(淡江大學_p4!D49),0) -> 37941 | E37: =ROUND(ABS(淡江大學_p4!E49),0) -> 37941 | F37: =ROUND(ABS(淡江大學_p4!F49),0) -> 37941 | G37: =ROUND(ABS(淡江大學_p4!G49),0) -> 37941 | H37: =ROUND(ABS(淡江大學_p4!H49),0) -> 37941 | I37: =ROUND(ABS(淡江大學_p4!I49),0) -> 37941 | J37: =ROUND(ABS(淡江大學_p4!J49),0) -> 37941 | K37: =ROUND(ABS(淡江大學_p4!K49),0) -> 37941 | ... W37: =ROUND(ABS(淡江大學_p4!W49),0) -> 37941
C38: 保險/年總計 | D38: =SUM(D34:D37) -> 156996 | E38: =SUM(E34:E37) -> 156996 | F38: =SUM(F34:F37) -> 156996 | G38: =SUM(G34:G37) -> 156996 | H38: =SUM(H34:H37) -> 156996 | I38: =SUM(I34:I37) -> 156996 | J38: =SUM(J34:J37) -> 156996 | K38: =SUM(K34:K37) -> 156996 | ... W38: =SUM(W34:W37) -> 156996
C39: 年份 | D39: 2020 | E39: 2021 | F39: 2022 | G39: 2023 | H39: 2024 | I39: 2025 | J39: 2026 | K39: 2027 | L39: 2028 | M39: 2029 | N39: 2030 | O39: 2031 | P39: 2032 | Q39: 2033 | R39: 2034 | S39: 2035 | T39: 2036 | U39: 2037 | V39: 2038 | W39: 2039
C40: 模組回收費
B41: 淡江大學 | D41: =ROUND(ABS(淡江大學_p2!D50),0) -> 43610 | E41: =ROUND(ABS(淡江大學_p2!E50),0) -> 43610 | F41: =ROUND(ABS(淡江大學_p2!F50),0) -> 43610 | G41: =ROUND(ABS(淡江大學_p2!G50),0) -> 43610 | H41: =ROUND(ABS(淡江大學_p2!H50),0) -> 43610 | I41: =ROUND(ABS(淡江大學_p2!I50),0) -> 43610 | J41: =ROUND(ABS(淡江大學_p2!J50),0) -> 43610 | K41: =ROUND(ABS(淡江大學_p2!K50),0) -> 43610 | ... W41: =ROUND(ABS(淡江大學_p2!W50),0) -> 0
B42: 淡江大學 | D42: =ROUND(ABS(淡江大學_p5!D50),0) -> 43610 | E42: =ROUND(ABS(淡江大學_p5!E50),0) -> 43610 | F42: =ROUND(ABS(淡江大學_p5!F50),0) -> 43610 | G42: =ROUND(ABS(淡江大學_p5!G50),0) -> 43610 | H42: =ROUND(ABS(淡江大學_p5!H50),0) -> 43610 | I42: =ROUND(ABS(淡江大學_p5!I50),0) -> 43610 | J42: =ROUND(ABS(淡江大學_p5!J50),0) -> 43610 | K42: =ROUND(ABS(淡江大學_p5!K50),0) -> 43610 | ... W42: =ROUND(ABS(淡江大學_p5!W50),0) -> 0
B43: 淡江大學 | D43: =ROUND(ABS(淡江大學_p3!D50),0) -> 43610 | E43: =ROUND(ABS(淡江大學_p3!E50),0) -> 43610 | F43: =ROUND(ABS(淡江大學_p3!F50),0) -> 43610 | G43: =ROUND(ABS(淡江大學_p3!G50),0) -> 43610 | H43: =ROUND(ABS(淡江大學_p3!H50),0) -> 43610 | I43: =ROUND(ABS(淡江大學_p3!I50),0) -> 43610 | J43: =ROUND(ABS(淡江大學_p3!J50),0) -> 43610 | K43: =ROUND(ABS(淡江大學_p3!K50),0) -> 43610 | ... W43: =ROUND(ABS(淡江大學_p3!W50),0) -> 0
...

Sheet 淡江大學_p2
B1: 電站基本資料 | F1: 說明 | P1: =1-D11 -> 0.99 | Q1: =P1-$D12 -> 0.986 | R1: =Q1-$D12 -> 0.982 | S1: =R1-$D12 -> 0.978 | T1: =S1-$D12 -> 0.974 | U1: =T1-$D12 -> 0.97 | V1: =U1-$D12 -> 0.966 | W1: =V1-$D12 -> 0.962 | X1: =W1-$D12 -> 0.958 | ... AI1: =AH1-$D12 -> 0.914
B2: 電站名稱 | C2: 淡江大學 | D2: - | E2: - | F2: 填入本案場名稱
B3: 電站壽命 | C3: 20 | D3: - | E3: - | F3: 預設 20 年，代表財務評估年期。若合約年限不同可依實際情況修改
B4: 建置量(kWp) | C4: 436.1 | D4: - | E4: - | F4: 填入裝置容量（kWp），通常由設計圖面或報價書取得 | M4: 情境編號: 2
B5: 起始年度 | C5: 2020 | D5: 結束年度 | E5: 2039 | F5: 填入電站預計掛表的西元年份（例：2025）。結束年度會自動計算 | M5: 第1次滾算摘要
M6: 價金: 33000
B7: 綜合損益表 | M7: 專案IRR: 3.16
B8: 收入 | M8: 權益法IRR: 6.19
B9: 收支項目 | C9: 相關參數 | D9: 參數數值 | E9: 年限 | F9: 說明 | M9: 利潤率: 30.00%
B10: 電費收入 | C10: 年度AC併網總發電量 | D10: 547002 | E10: 20 | F10: 預估年發電量（kWh），通常來自 PVsyst 模擬或估算：裝置容量 × 年日照時數 × 系統效率 | M10: 第1次滾算，減少 2000 元 - 現金模式，每次減少 2000 元
C11: 首年衰退率 | D11: 0.01 | F11: 第一年發電衰退比率，請填小數（例：1% → 填 0.01）。一般首年衰退約 1~2%(請參考模組規格書)
C12: 次年衰退率 | D12: 0.004 | F12: 第二年起每年固定衰退比率，請填小數（例：0.4% → 填 0.004）。一般約 0.4~0.7%(請參考模組規格書)
C13: 躉售費率(FIT) / 綠電費率 | D13: 4 | F13: 與台電簽訂的躉購費率或綠電合約費率，單位：元/度。請參考台電公告或合約內容
B14: 支出
B15: 收支項目 | C15: 相關參數 | D15: 參數數值 | E15: 攤提年限 | F15: 說明
B16: 設備費用(價金) | C16: 每kWp設備成本 | D16: 33000 | E16: 20 | F16: 每峰瓩設備成本（元/kWp），包含模組、逆變器、支架等硬體，不含工程施工費
C17: 信邦利潤率(ex:20%填0.2) | D17: 0.3 | F17: 公司在設備費用上加計的利潤比率，請填小數（例：20% → 填 0.2）
C18: 開發費 | D18: 2000 | F18: 前期開發費用（元），含可行性評估、申請規費、地主溝通等。若無則填 0
B19: 租金費用 | C19: 租金計算方式 | D19: 1 | E19: 20 | F19: 填 1 = 固定年租金（需填方式1參數）；填 2 = 依電費收入抽成（需填方式2參數）
C20: 【方式1參數】每年相同價格 | D20: 290201 | E20: 20 | F20: 租金計算方式選「1」時填寫，固定年租金金額（元/年），套用至整個電站壽命期
C21: 【方式2參數】抽成比率 | D21: 0 | E21: 20 | F21: 租金計算方式選「2」時填寫，請填小數（例：10% → 填 0.1）。租金 = 當年電費收入 × 抽成比率
B22: 運維費用 | C22: 每kw運維成本 | D22: 400 | E22: 20 | F22: 每峰瓩每年運維費用（元/kWp/年），含清洗、巡檢、維修等。
B23: 保險費用 | C23: 占整體設備費用比例 | D23: 0.003 | E23: 20 | F23: 保險費佔設備總費用比率，填小數（例：0.3% → 填 0.003）。預設 0.003，可依投保條件調整
B24: 模組回收費用 | C24: 每kw模組回收成本 | D24: 1000 | E24: 10 | F24: 每峰瓩模組廢棄回收費用（元/kWp），於第 1~10 年計提（攤提 10 年）。
B25: 利息費用 | C25: 銀行利率 | D25: 0.0256 | E25: 20 | F25: 向銀行貸款的年利率，填小數（例：2.56% → 填 0.0256）。請依銀行核准利率填入
B26: 所得稅 | C26: 所得稅率 | D26: 0.2 | E26: 20 | F26: 公司所得稅率，填小數（例：20% → 填 0.2）。預設 0.2，通常不需更改
B29: 現金流量表
B30: 金流項目 | C30: 相關參數 | D30: 參數數值 | F30: 說明
B31: 貸款成數 | C31: 占總設備費用比例 | D31: 0.8 | F31: 貸款佔設備總費用比例，填小數（例：80% → 填 0.8）。預設 0.8 代表貸八成、自備二成
B32: 貸款還款 | C32: 攤還期數 | D32: 15 | F32: 貸款還款年數（年）。預設 15 年，代表分 15 年平均攤還本金
B33: 現金股利 | C33: 股利比率 | D33: 0.9 | F33: 稅後現金流中分配給股東的比例，填小數（例：90% → 填 0.9）
B34: 年底減資 | C34: 攤還期數 | D34: 4 | F34: 年底減資返還股東的年數。預設 4 年，代表 倒數 4 年進行減資，加速資金返還
C37: 年份 | D37: 2020 | E37: 2021 | F37: 2022 | G37: 2023 | H37: 2024 | I37: 2025 | J37: 2026 | K37: 2027 | L37: 2028 | M37: 2029 | N37: 2030 | O37: 2031 | P37: 2032 | Q37: 2033 | R37: 2034 | S37: 2035 | T37: 2036 | U37: 2037 | V37: 2038 | W37: 2039
B38: 0
B39: (Unit : Currency) | C39: 0 | D39: 1 | E39: 2 | F39: 3 | G39: 4 | H39: 5 | I39: 6 | J39: 7 | K39: 8 | L39: 9 | M39: 10 | N39: 11 | O39: 12 | P39: 13 | Q39: 14 | R39: 15 | S39: 16 | T39: 17 | U39: 18 | V39: 19 | W39: 20
B40: 發電度數(KWH) | C40: 0 | D40: =$D$10*P1 -> 541531.98 | E40: =$D$10*Q1 -> 539343.97 | F40: =$D$10*R1 -> 537155.96 | G40: =$D$10*S1 -> 534967.96 | H40: =$D$10*T1 -> 532779.95 | I40: =$D$10*U1 -> 530591.94 | J40: =$D$10*V1 -> 528403.93 | K40: =$D$10*W1 -> 526215.92 | ... W40: =$D$10*AI1 -> 499959.83
B41: Inflow : 電費收入 | C41: - | D41: =D40*$D$13 -> 2166127.9 | E41: =E40*$D$13 -> 2157375.9 | F41: =F40*$D$13 -> 2148623.9 | G41: =G40*$D$13 -> 2139871.8 | H41: =H40*$D$13 -> 2131119.8 | I41: =I40*$D$13 -> 2122367.8 | J41: =J40*$D$13 -> 2113615.7 | K41: =K40*$D$13 -> 2104863.7 | ... W41: =W40*$D$13 -> 1999839.3
B42: Inflow : 政府補助 | C42: - | G42: - | H42: - | I42: - | J42: - | K42: - | L42: - | M42: - | N42: - | O42: - | P42: - | Q42: - | R42: - | S42: - | T42: - | U42: - | V42: - | W42: -
B43: Inflow : 銀行借款
B44: Outflow : 設備費用 | C44: =-(D16/(1-D17)+D18)*C4 -> -21431200
...

Sheet 淡江大學_p5
B1: 電站基本資料 | F1: 說明 | P1: =1-D11 -> 0.99 | Q1: =P1-$D12 -> 0.986 | R1: =Q1-$D12 -> 0.982 | S1: =R1-$D12 -> 0.978 | T1: =S1-$D12 -> 0.974 | U1: =T1-$D12 -> 0.97 | V1: =U1-$D12 -> 0.966 | W1: =V1-$D12 -> 0.962 | X1: =W1-$D12 -> 0.958 | ... AI1: =AH1-$D12 -> 0.914
B2: 電站名稱 | C2: 淡江大學 | D2: - | E2: - | F2: 填入本案場名稱
B3: 電站壽命 | C3: 20 | D3: - | E3: - | F3: 預設 20 年，代表財務評估年期。若合約年限不同可依實際情況修改
B4: 建置量(kWp) | C4: 436.1 | D4: - | E4: - | F4: 填入裝置容量（kWp），通常由設計圖面或報價書取得 | M4: 情境編號: 5
B5: 起始年度 | C5: 2020 | D5: 結束年度 | E5: 2039 | F5: 填入電站預計掛表的西元年份（例：2025）。結束年度會自動計算 | M5: 第4次滾算摘要
M6: 價金: 27000
B7: 綜合損益表 | M7: 專案IRR: 5.11
B8: 收入 | M8: 權益法IRR: 13.45
B9: 收支項目 | C9: 相關參數 | D9: 參數數值 | E9: 年限 | F9: 說明 | M9: 利潤率: 30.00%
B10: 電費收入 | C10: 年度AC併網總發電量 | D10: 547002 | E10: 20 | F10: 預估年發電量（kWh），通常來自 PVsyst 模擬或估算：裝置容量 × 年日照時數 × 系統效率 | M10: 第4次滾算，減少 2000 元 - 現金模式，每次減少 2000 元
C11: 首年衰退率 | D11: 0.01 | F11: 第一年發電衰退比率，請填小數（例：1% → 填 0.01）。一般首年衰退約 1~2%(請參考模組規格書)
C12: 次年衰退率 | D12: 0.004 | F12: 第二年起每年固定衰退比率，請填小數（例：0.4% → 填 0.004）。一般約 0.4~0.7%(請參考模組規格書)
C13: 躉售費率(FIT) / 綠電費率 | D13: 4 | F13: 與台電簽訂的躉購費率或綠電合約費率，單位：元/度。請參考台電公告或合約內容
B14: 支出
B15: 收支項目 | C15: 相關參數 | D15: 參數數值 | E15: 攤提年限 | F15: 說明
B16: 設備費用(價金) | C16: 每kWp設備成本 | D16: 27000 | E16: 20 | F16: 每峰瓩設備成本（元/kWp），包含模組、逆變器、支架等硬體，不含工程施工費
C17: 信邦利潤率(ex:20%填0.2) | D17: 0.3 | F17: 公司在設備費用上加計的利潤比率，請填小數（例：20% → 填 0.2）
C18: 開發費 | D18: 2000 | F18: 前期開發費用（元），含可行性評估、申請規費、地主溝通等。若無則填 0
B19: 租金費用 | C19: 租金計算方式 | D19: 1 | E19: 20 | F19: 填 1 = 固定年租金（需填方式1參數）；填 2 = 依電費收入抽成（需填方式2參數）
C20: 【方式1參數】每年相同價格 | D20: 290201 | E20: 20 | F20: 租金計算方式選「1」時填寫，固定年租金金額（元/年），套用至整個電站壽命期
C21: 【方式2參數】抽成比率 | D21: 0 | E21: 20 | F21: 租金計算方式選「2」時填寫，請填小數（例：10% → 填 0.1）。租金 = 當年電費收入 × 抽成比率
B22: 運維費用 | C22: 每kw運維成本 | D22: 400 | E22: 20 | F22: 每峰瓩每年運維費用（元/kWp/年），含清洗、巡檢、維修等。
B23: 保險費用 | C23: 占整體設備費用比例 | D23: 0.003 | E23: 20 | F23: 保險費佔設備總費用比率，填小數（例：0.3% → 填 0.003）。預設 0.003，可依投保條件調整
B24: 模組回收費用 | C24: 每kw模組回收成本 | D24: 1000 | E24: 10 | F24: 每峰瓩模組廢棄回收費用（元/kWp），於第 1~10 年計提（攤提 10 年）。
B25: 利息費用 | C25: 銀行利率 | D25: 0.0256 | E25: 20 | F25: 向銀行貸款的年利率，填小數（例：2.56% → 填 0.0256）。請依銀行核准利率填入
B26: 所得稅 | C26: 所得稅率 | D26: 0.2 | E26: 20 | F26: 公司所得稅率，填小數（例：20% → 填 0.2）。預設 0.2，通常不需更改
B29: 現金流量表
B30: 金流項目 | C30: 相關參數 | D30: 參數數值 | F30: 說明
B31: 貸款成數 | C31: 占總設備費用比例 | D31: 0.8 | F31: 貸款佔設備總費用比例，填小數（例：80% → 填 0.8）。預設 0.8 代表貸八成、自備二成
B32: 貸款還款 | C32: 攤還期數 | D32: 15 | F32: 貸款還款年數（年）。預設 15 年，代表分 15 年平均攤還本金
B33: 現金股利 | C33: 股利比率 | D33: 0.9 | F33: 稅後現金流中分配給股東的比例，填小數（例：90% → 填 0.9）
B34: 年底減資 | C34: 攤還期數 | D34: 4 | F34: 年底減資返還股東的年數。預設 4 年，代表 倒數 4 年進行減資，加速資金返還
C37: 年份 | D37: 2020 | E37: 2021 | F37: 2022 | G37: 2023 | H37: 2024 | I37: 2025 | J37: 2026 | K37: 2027 | L37: 2028 | M37: 2029 | N37: 2030 | O37: 2031 | P37: 2032 | Q37: 2033 | R37: 2034 | S37: 2035 | T37: 2036 | U37: 2037 | V37: 2038 | W37: 2039
B38: 0
B39: (Unit : Currency) | C39: 0 | D39: 1 | E39: 2 | F39: 3 | G39: 4 | H39: 5 | I39: 6 | J39: 7 | K39: 8 | L39: 9 | M39: 10 | N39: 11 | O39: 12 | P39: 13 | Q39: 14 | R39: 15 | S39: 16 | T39: 17 | U39: 18 | V39: 19 | W39: 20
B40: 發電度數(KWH) | C40: 0 | D40: =$D$10*P1 -> 541531.98 | E40: =$D$10*Q1 -> 539343.97 | F40: =$D$10*R1 -> 537155.96 | G40: =$D$10*S1 -> 534967.96 | H40: =$D$10*T1 -> 532779.95 | I40: =$D$10*U1 -> 530591.94 | J40: =$D$10*V1 -> 528403.93 | K40: =$D$10*W1 -> 526215.92 | ... W40: =$D$10*AI1 -> 499959.83
B41: Inflow : 電費收入 | C41: - | D41: =D40*$D$13 -> 2166127.9 | E41: =E40*$D$13 -> 2157375.9 | F41: =F40*$D$13 -> 2148623.9 | G41: =G40*$D$13 -> 2139871.8 | H41: =H40*$D$13 -> 2131119.8 | I41: =I40*$D$13 -> 2122367.8 | J41: =J40*$D$13 -> 2113615.7 | K41: =K40*$D$13 -> 2104863.7 | ... W41: =W40*$D$13 -> 1999839.3
B42: Inflow : 政府補助 | C42: - | G42: - | H42: - | I42: - | J42: - | K42: - | L42: - | M42: - | N42: - | O42: - | P42: - | Q42: - | R42: - | S42: - | T42: - | U42: - | V42: - | W42: -
B43: Inflow : 銀行借款
B44: Outflow : 設備費用 | C44: =-(D16/(1-D17)+D18)*C4 -> -17693200
...

Sheet 淡江大學_p3
B1: 電站基本資料 | F1: 說明 | P1: =1-D11 -> 0.99 | Q1: =P1-$D12 -> 0.986 | R1: =Q1-$D12 -> 0.982 | S1: =R1-$D12 -> 0.978 | T1: =S1-$D12 -> 0.974 | U1: =T1-$D12 -> 0.97 | V1: =U1-$D12 -> 0.966 | W1: =V1-$D12 -> 0.962 | X1: =W1-$D12 -> 0.958 | ... AI1: =AH1-$D12 -> 0.914
B2: 電站名稱 | C2: 淡江大學 | D2: - | E2: - | F2: 填入本案場名稱
B3: 電站壽命 | C3: 20 | D3: - | E3: - | F3: 預設 20 年，代表財務評估年期。若合約年限不同可依實際情況修改
B4: 建置量(kWp) | C4: 436.1 | D4: - | E4: - | F4: 填入裝置容量（kWp），通常由設計圖面或報價書取得 | M4: 情境編號: 3
B5: 起始年度 | C5: 2020 | D5: 結束年度 | E5: 2039 | F5: 填入電站預計掛表的西元年份（例：2025）。結束年度會自動計算 | M5: 第2次滾算摘要
M6: 價金: 31000
B7: 綜合損益表 | M7: 專案IRR: 3.75
B8: 收入 | M8: 權益法IRR: 8.21
B9: 收支項目 | C9: 相關參數 | D9: 參數數值 | E9: 年限 | F9: 說明 | M9: 利潤率: 30.00%
B10: 電費收入 | C10: 年度AC併網總發電量 | D10: 547002 | E10: 20 | F10: 預估年發電量（kWh），通常來自 PVsyst 模擬或估算：裝置容量 × 年日照時數 × 系統效率 | M10: 第2次滾算，減少 2000 元 - 現金模式，每次減少 2000 元
C11: 首年衰退率 | D11: 0.01 | F11: 第一年發電衰退比率，請填小數（例：1% → 填 0.01）。一般首年衰退約 1~2%(請參考模組規格書)
C12: 次年衰退率 | D12: 0.004 | F12: 第二年起每年固定衰退比率，請填小數（例：0.4% → 填 0.004）。一般約 0.4~0.7%(請參考模組規格書)
C13: 躉售費率(FIT) / 綠電費率 | D13: 4 | F13: 與台電簽訂的躉購費率或綠電合約費率，單位：元/度。請參考台電公告或合約內容
B14: 支出
B15: 收支項目 | C15: 相關參數 | D15: 參數數值 | E15: 攤提年限 | F15: 說明
B16: 設備費用(價金) | C16: 每kWp設備成本 | D16: 31000 | E16: 20 | F16: 每峰瓩設備成本（元/kWp），包含模組、逆變器、支架等硬體，不含工程施工費
C17: 信邦利潤率(ex:20%填0.2) | D17: 0.3 | F17: 公司在設備費用上加計的利潤比率，請填小數（例：20% → 填 0.2）
C18: 開發費 | D18: 2000 | F18: 前期開發費用（元），含可行性評估、申請規費、地主溝通等。若無則填 0
B19: 租金費用 | C19: 租金計算方式 | D19: 1 | E19: 20 | F19: 填 1 = 固定年租金（需填方式1參數）；填 2 = 依電費收入抽成（需填方式2參數）
C20: 【方式1參數】每年相同價格 | D20: 290201 | E20: 20 | F20: 租金計算方式選「1」時填寫，固定年租金金額（元/年），套用至整個電站壽命期
C21: 【方式2參數】抽成比率 | D21: 0 | E21: 20 | F21: 租金計算方式選「2」時填寫，請填小數（例：10% → 填 0.1）。租金 = 當年電費收入 × 抽成比率
B22: 運維費用 | C22: 每kw運維成本 | D22: 400 | E22: 20 | F22: 每峰瓩每年運維費用（元/kWp/年），含清洗、巡檢、維修等。
B23: 保險費用 | C23: 占整體設備費用比例 | D23: 0.003 | E23: 20 | F23: 保險費佔設備總費用比率，填小數（例：0.3% → 填 0.003）。預設 0.003，可依投保條件調整
B24: 模組回收費用 | C24: 每kw模組回收成本 | D24: 1000 | E24: 10 | F24: 每峰瓩模組廢棄回收費用（元/kWp），於第 1~10 年計提（攤提 10 年）。
B25: 利息費用 | C25: 銀行利率 | D25: 0.0256 | E25: 20 | F25: 向銀行貸款的年利率，填小數（例：2.56% → 填 0.0256）。請依銀行核准利率填入
B26: 所得稅 | C26: 所得稅率 | D26: 0.2 | E26: 20 | F26: 公司所得稅率，填小數（例：20% → 填 0.2）。預設 0.2，通常不需更改
B29: 現金流量表
B30: 金流項目 | C30: 相關參數 | D30: 參數數值 | F30: 說明
B31: 貸款成數 | C31: 占總設備費用比例 | D31: 0.8 | F31: 貸款佔設備總費用比例，填小數（例：80% → 填 0.8）。預設 0.8 代表貸八成、自備二成
B32: 貸款還款 | C32: 攤還期數 | D32: 15 | F32: 貸款還款年數（年）。預設 15 年，代表分 15 年平均攤還本金
B33: 現金股利 | C33: 股利比率 | D33: 0.9 | F33: 稅後現金流中分配給股東的比例，填小數（例：90% → 填 0.9）
B34: 年底減資 | C34: 攤還期數 | D34: 4 | F34: 年底減資返還股東的年數。預設 4 年，代表 倒數 4 年進行減資，加速資金返還
C37: 年份 | D37: 2020 | E37: 2021 | F37: 2022 | G37: 2023 | H37: 2024 | I37: 2025 | J37: 2026 | K37: 2027 | L37: 2028 | M37: 2029 | N37: 2030 | O37: 2031 | P37: 2032 | Q37: 2033 | R37: 2034 | S37: 2035 | T37: 2036 | U37: 2037 | V37: 2038 | W37: 2039
B38: 0
B39: (Unit : Currency) | C39: 0 | D39: 1 | E39: 2 | F39: 3 | G39: 4 | H39: 5 | I39: 6 | J39: 7 | K39: 8 | L39: 9 | M39: 10 | N39: 11 | O39: 12 | P39: 13 | Q39: 14 | R39: 15 | S39: 16 | T39: 17 | U39: 18 | V39: 19 | W39: 20
B40: 發電度數(KWH) | C40: 0 | D40: =$D$10*P1 -> 541531.98 | E40: =$D$10*Q1 -> 539343.97 | F40: =$D$10*R1 -> 537155.96 | G40: =$D$10*S1 -> 534967.96 | H40: =$D$10*T1 -> 532779.95 | I40: =$D$10*U1 -> 530591.94 | J40: =$D$10*V1 -> 528403.93 | K40: =$D$10*W1 -> 526215.92 | ... W40: =$D$10*AI1 -> 499959.83
B41: Inflow : 電費收入 | C41: - | D41: =D40*$D$13 -> 2166127.9 | E41: =E40*$D$13 -> 2157375.9 | F41: =F40*$D$13 -> 2148623.9 | G41: =G40*$D$13 -> 2139871.8 | H41: =H40*$D$13 -> 2131119.8 | I41: =I40*$D$13 -> 2122367.8 | J41: =J40*$D$13 -> 2113615.7 | K41: =K40*$D$13 -> 2104863.7 | ... W41: =W40*$D$13 -> 1999839.3
B42: Inflow : 政府補助 | C42: - | G42: - | H42: - | I42: - | J42: - | K42: - | L42: - | M42: - | N42: - | O42: - | P42: - | Q42: - | R42: - | S42: - | T42: - | U42: - | V42: - | W42: -
B43: Inflow : 銀行借款
B44: Outflow : 設備費用 | C44: =-(D16/(1-D17)+D18)*C4 -> -20185200
...

Sheet 淡江大學_p4
B1: 電站基本資料 | F1: 說明 | P1: =1-D11 -> 0.99 | Q1: =P1-$D12 -> 0.986 | R1: =Q1-$D12 -> 0.982 | S1: =R1-$D12 -> 0.978 | T1: =S1-$D12 -> 0.974 | U1: =T1-$D12 -> 0.97 | V1: =U1-$D12 -> 0.966 | W1: =V1-$D12 -> 0.962 | X1: =W1-$D12 -> 0.958 | ... AI1: =AH1-$D12 -> 0.914
B2: 電站名稱 | C2: 淡江大學 | D2: - | E2: - | F2: 填入本案場名稱
B3: 電站壽命 | C3: 20 | D3: - | E3: - | F3: 預設 20 年，代表財務評估年期。若合約年限不同可依實際情況修改
B4: 建置量(kWp) | C4: 436.1 | D4: - | E4: - | F4: 填入裝置容量（kWp），通常由設計圖面或報價書取得 | M4: 情境編號: 4
B5: 起始年度 | C5: 2020 | D5: 結束年度 | E5: 2039 | F5: 填入電站預計掛表的西元年份（例：2025）。結束年度會自動計算 | M5: 第3次滾算摘要
M6: 價金: 29000
B7: 綜合損益表 | M7: 專案IRR: 4.39
B8: 收入 | M8: 權益法IRR: 10.59
B9: 收支項目 | C9: 相關參數 | D9: 參數數值 | E9: 年限 | F9: 說明 | M9: 利潤率: 30.00%
B10: 電費收入 | C10: 年度AC併網總發電量 | D10: 547002 | E10: 20 | F10: 預估年發電量（kWh），通常來自 PVsyst 模擬或估算：裝置容量 × 年日照時數 × 系統效率 | M10: 第3次滾算，減少 2000 元 - 現金模式，每次減少 2000 元
C11: 首年衰退率 | D11: 0.01 | F11: 第一年發電衰退比率，請填小數（例：1% → 填 0.01）。一般首年衰退約 1~2%(請參考模組規格書)
C12: 次年衰退率 | D12: 0.004 | F12: 第二年起每年固定衰退比率，請填小數（例：0.4% → 填 0.004）。一般約 0.4~0.7%(請參考模組規格書)
C13: 躉售費率(FIT) / 綠電費率 | D13: 4 | F13: 與台電簽訂的躉購費率或綠電合約費率，單位：元/度。請參考台電公告或合約內容
B14: 支出
B15: 收支項目 | C15: 相關參數 | D15: 參數數值 | E15: 攤提年限 | F15: 說明
B16: 設備費用(價金) | C16: 每kWp設備成本 | D16: 29000 | E16: 20 | F16: 每峰瓩設備成本（元/kWp），包含模組、逆變器、支架等硬體，不含工程施工費
C17: 信邦利潤率(ex:20%填0.2) | D17: 0.3 | F17: 公司在設備費用上加計的利潤比率，請填小數（例：20% → 填 0.2）
C18: 開發費 | D18: 2000 | F18: 前期開發費用（元），含可行性評估、申請規費、地主溝通等。若無則填 0
B19: 租金費用 | C19: 租金計算方式 | D19: 1 | E19: 20 | F19: 填 1 = 固定年租金（需填方式1參數）；填 2 = 依電費收入抽成（需填方式2參數）
C20: 【方式1參數】每年相同價格 | D20: 290201 | E20: 20 | F20: 租金計算方式選「1」時填寫，固定年租金金額（元/年），套用至整個電站壽命期
C21: 【方式2參數】抽成比率 | D21: 0 | E21: 20 | F21: 租金計算方式選「2」時填寫，請填小數（例：10% → 填 0.1）。租金 = 當年電費收入 × 抽成比率
B22: 運維費用 | C22: 每kw運維成本 | D22: 400 | E22: 20 | F22: 每峰瓩每年運維費用（元/kWp/年），含清洗、巡檢、維修等。
B23: 保險費用 | C23: 占整體設備費用比例 | D23: 0.003 | E23: 20 | F23: 保險費佔設備總費用比率，填小數（例：0.3% → 填 0.003）。預設 0.003，可依投保條件調整
B24: 模組回收費用 | C24: 每kw模組回收成本 | D24: 1000 | E24: 10 | F24: 每峰瓩模組廢棄回收費用（元/kWp），於第 1~10 年計提（攤提 10 年）。
B25: 利息費用 | C25: 銀行利率 | D25: 0.0256 | E25: 20 | F25: 向銀行貸款的年利率，填小數（例：2.56% → 填 0.0256）。請依銀行核准利率填入
B26: 所得稅 | C26: 所得稅率 | D26: 0.2 | E26: 20 | F26: 公司所得稅率，填小數（例：20% → 填 0.2）。預設 0.2，通常不需更改
B29: 現金流量表
B30: 金流項目 | C30: 相關參數 | D30: 參數數值 | F30: 說明
B31: 貸款成數 | C31: 占總設備費用比例 | D31: 0.8 | F31: 貸款佔設備總費用比例，填小數（例：80% → 填 0.8）。預設 0.8 代表貸八成、自備二成
B32: 貸款還款 | C32: 攤還期數 | D32: 15 | F32: 貸款還款年數（年）。預設 15 年，代表分 15 年平均攤還本金
B33: 現金股利 | C33: 股利比率 | D33: 0.9 | F33: 稅後現金流中分配給股東的比例，填小數（例：90% → 填 0.9）
B34: 年底減資 | C34: 攤還期數 | D34: 4 | F34: 年底減資返還股東的年數。預設 4 年，代表 倒數 4 年進行減資，加速資金返還
C37: 年份 | D37: 2020 | E37: 2021 | F37: 2022 | G37: 2023 | H37: 2024 | I37: 2025 | J37: 2026 | K37: 2027 | L37: 2028 | M37: 2029 | N37: 2030 | O37: 2031 | P37: 2032 | Q37: 2033 | R37: 2034 | S37: 2035 | T37: 2036 | U37: 2037 | V37: 2038 | W37: 2039
B38: 0
B39: (Unit : Currency) | C39: 0 | D39: 1 | E39: 2 | F39: 3 | G39: 4 | H39: 5 | I39: 6 | J39: 7 | K39: 8 | L39: 9 | M39: 10 | N39: 11 | O39: 12 | P39: 13 | Q39: 14 | R39: 15 | S39: 16 | T39: 17 | U39: 18 | V39: 19 | W39: 20
B40: 發電度數(KWH) | C40: 0 | D40: =$D$10*P1 -> 541531.98 | E40: =$D$10*Q1 -> 539343.97 | F40: =$D$10*R1 -> 537155.96 | G40: =$D$10*S1 -> 534967.96 | H40: =$D$10*T1 -> 532779.95 | I40: =$D$10*U1 -> 530591.94 | J40: =$D$10*V1 -> 528403.93 | K40: =$D$10*W1 -> 526215.92 | ... W40: =$D$10*AI1 -> 499959.83
B41: Inflow : 電費收入 | C41: - | D41: =D40*$D$13 -> 2166127.9 | E41: =E40*$D$13 -> 2157375.9 | F41: =F40*$D$13 -> 2148623.9 | G41: =G40*$D$13 -> 2139871.8 | H41: =H40*$D$13 -> 2131119.8 | I41: =I40*$D$13 -> 2122367.8 | J41: =J40*$D$13 -> 2113615.7 | K41: =K40*$D$13 -> 2104863.7 | ... W41: =W40*$D$13 -> 1999839.3
B42: Inflow : 政府補助 | C42: - | G42: - | H42: - | I42: - | J42: - | K42: - | L42: - | M42: - | N42: - | O42: - | P42: - | Q42: - | R42: - | S42: - | T42: - | U42: - | V42: - | W42: -
B43: Inflow : 銀行借款
B44: Outflow : 設備費用 | C44: =-(D16/(1-D17)+D18)*C4 -> -18939200
...
