Workbook

Sheet 多站彙整
C4: 年份 | D4: 2020 | E4: 2021 | F4: 2022 | G4: 2023 | H4: 2024 | I4: 2025 | J4: 2026 | K4: 2027 | L4: 2028 | M4: 2029 | N4: 2030 | O4: 2031 | P4: 2032 | Q4: 2033 | R4: 2034 | S4: 2035 | T4: 2036 | U4: 2037 | V4: 2038 | W4: 2039
C5: 預估發電度數
B6: 淡江大學 | D6: =ROUND(ABS(淡江大學_p8!D40),0) -> 541532 | E6: =ROUND(ABS(淡江大學_p8!E40),0) -> 539344 | F6: =ROUND(ABS(淡江大學_p8!F40),0) -> 537156 | G6: =ROUND(ABS(淡江大學_p8!G40),0) -> 534968 | H6: =ROUND(ABS(淡江大學_p8!H40),0) -> 532780 | I6: =ROUND(ABS(淡江大學_p8!I40),0) -> 530592 | J6: =ROUND(ABS(淡江大學_p8!J40),0) -> 528404 | K6: =ROUND(ABS(淡江大學_p8!K40),0) -> 526216 | ... W6: =ROUND(ABS(淡江大學_p8!W40),0) -> 499960
B7: 淡江大學 | D7: =ROUND(ABS(淡江大學_p7!D40),0) -> 541532 | E7: =ROUND(ABS(淡江大學_p7!E40),0) -> 539344 | F7: =ROUND(ABS(淡江大學_p7!F40),0) -> 537156 | G7: =ROUND(ABS(淡江大學_p7!G40),0) -> 534968 | H7: =ROUND(ABS(淡江大學_p7!H40),0) -> 532780 | I7: =ROUND(ABS(淡江大學_p7!I40),0) -> 530592 | J7: =ROUND(ABS(淡江大學_p7!J40),0) -> 528404 | K7: =ROUND(ABS(淡江大學_p7!K40),0) -> 526216 | ... W7: =ROUND(ABS(淡江大學_p7!W40),0) -> 499960
B8: 淡江大學 | D8: =ROUND(ABS(淡江大學_p5!D40),0) -> 541532 | E8: =ROUND(ABS(淡江大學_p5!E40),0) -> 539344 | F8: =ROUND(ABS(淡江大學_p5!F40),0) -> 537156 | G8: =ROUND(ABS(淡江大學_p5!G40),0) -> 534968 | H8: =ROUND(ABS(淡江大學_p5!H40),0) -> 532780 | I8: =ROUND(ABS(淡江大學_p5!I40),0) -> 530592 | J8: =ROUND(ABS(淡江大學_p5!J40),0) -> 528404 | K8: =ROUND(ABS(淡江大學_p5!K40),0) -> 526216 | ... W8: =ROUND(ABS(淡江大學_p5!W40),0) -> 499960
B9: 淡江大學 | D9: =ROUND(ABS(淡江大學_p4!D40),0) -> 541532 | E9: =ROUND(ABS(淡江大學_p4!E40),0) -> 539344 | F9: =ROUND(ABS(淡江大學_p4!F40),0) -> 537156 | G9: =ROUND(ABS(淡江大學_p4!G40),0) -> 534968 | H9: =ROUND(ABS(淡江大學_p4!H40),0) -> 532780 | I9: =ROUND(ABS(淡江大學_p4!I40),0) -> 530592 | J9: =ROUND(ABS(淡江大學_p4!J40),0) -> 528404 | K9: =ROUND(ABS(淡江大學_p4!K40),0) -> 526216 | ... W9: =ROUND(ABS(淡江大學_p4!W40),0) -> 499960
B10: 淡江大學 | D10: =ROUND(ABS(淡江大學_p3!D40),0) -> 541532 | E10: =ROUND(ABS(淡江大學_p3!E40),0) -> 539344 | F10: =ROUND(ABS(淡江大學_p3!F40),0) -> 537156 | G10: =ROUND(ABS(淡江大學_p3!G40),0) -> 534968 | H10: =ROUND(ABS(淡江大學_p3!H40),0) -> 532780 | I10: =ROUND(ABS(淡江大學_p3!I40),0) -> 530592 | J10: =ROUND(ABS(淡江大學_p3!J40),0) -> 528404 | K10: =ROUND(ABS(淡江大學_p3!K40),0) -> 526216 | ... W10: =ROUND(ABS(淡江大學_p3!W40),0) -> 499960
B11: 淡江大學 | D11: =ROUND(ABS(淡江大學_p6!D40),0) -> 541532 | E11: =ROUND(ABS(淡江大學_p6!E40),0) -> 539344 | F11: =ROUND(ABS(淡江大學_p6!F40),0) -> 537156 | G11: =ROUND(ABS(淡江大學_p6!G40),0) -> 534968 | H11: =ROUND(ABS(淡江大學_p6!H40),0) -> 532780 | I11: =ROUND(ABS(淡江大學_p6!I40),0) -> 530592 | J11: =ROUND(ABS(淡江大學_p6!J40),0) -> 528404 | K11: =ROUND(ABS(淡江大學_p6!K40),0) -> 526216 | ... W11: =ROUND(ABS(淡江大學_p6!W40),0) -> 499960
C12: 預估發電度數/年總計 | D12: =SUM(D6:D11) -> 3249192 | E12: =SUM(E6:E11) -> 3236064 | F12: =SUM(F6:F11) -> 3222936 | G12: =SUM(G6:G11) -> 3209808 | H12: =SUM(H6:H11) -> 3196680 | I12: =SUM(I6:I11) -> 3183552 | J12: =SUM(J6:J11) -> 3170424 | K12: =SUM(K6:K11) -> 3157296 | ... W12: =SUM(W6:W11) -> 2999760
C13: 年份 | D13: 2020 | E13: 2021 | F13: 2022 | G13: 2023 | H13: 2024 | I13: 2025 | J13: 2026 | K13: 2027 | L13: 2028 | M13: 2029 | N13: 2030 | O13: 2031 | P13: 2032 | Q13: 2033 | R13: 2034 | S13: 2035 | T13: 2036 | U13: 2037 | V13: 2038 | W13: 2039
C14: 預估收入
B15: 淡江大學 | D15: =ROUND(ABS(淡江大學_p8!D41),0) -> 2166128 | E15: =ROUND(ABS(淡江大學_p8!E41),0) -> 2157376 | F15: =ROUND(ABS(淡江大學_p8!F41),0) -> 2148624 | G15: =ROUND(ABS(淡江大學_p8!G41),0) -> 2139872 | H15: =ROUND(ABS(淡江大學_p8!H41),0) -> 2131120 | I15: =ROUND(ABS(淡江大學_p8!I41),0) -> 2122368 | J15: =ROUND(ABS(淡江大學_p8!J41),0) -> 2113616 | K15: =ROUND(ABS(淡江大學_p8!K41),0) -> 2104864 | ... W15: =ROUND(ABS(淡江大學_p8!W41),0) -> 1999839
B16: 淡江大學 | D16: =ROUND(ABS(淡江大學_p7!D41),0) -> 2166128 | E16: =ROUND(ABS(淡江大學_p7!E41),0) -> 2157376 | F16: =ROUND(ABS(淡江大學_p7!F41),0) -> 2148624 | G16: =ROUND(ABS(淡江大學_p7!G41),0) -> 2139872 | H16: =ROUND(ABS(淡江大學_p7!H41),0) -> 2131120 | I16: =ROUND(ABS(淡江大學_p7!I41),0) -> 2122368 | J16: =ROUND(ABS(淡江大學_p7!J41),0) -> 2113616 | K16: =ROUND(ABS(淡江大學_p7!K41),0) -> 2104864 | ... W16: =ROUND(ABS(淡江大學_p7!W41),0) -> 1999839
B17: 淡江大學 | D17: =ROUND(ABS(淡江大學_p5!D41),0) -> 2166128 | E17: =ROUND(ABS(淡江大學_p5!E41),0) -> 2157376 | F17: =ROUND(ABS(淡江大學_p5!F41),0) -> 2148624 | G17: =ROUND(ABS(淡江大學_p5!G41),0) -> 2139872 | H17: =ROUND(ABS(淡江大學_p5!H41),0) -> 2131120 | I17: =ROUND(ABS(淡江大學_p5!I41),0) -> 2122368 | J17: =ROUND(ABS(淡江大學_p5!J41),0) -> 2113616 | K17: =ROUND(ABS(淡江大學_p5!K41),0) -> 2104864 | ... W17: =ROUND(ABS(淡江大學_p5!W41),0) -> 1999839
B18: 淡江大學 | D18: =ROUND(ABS(淡江大學_p4!D41),0) -> 2166128 | E18: =ROUND(ABS(淡江大學_p4!E41),0) -> 2157376 | F18: =ROUND(ABS(淡江大學_p4!F41),0) -> 2148624 | G18: =ROUND(ABS(淡江大學_p4!G41),0) -> 2139872 | H18: =ROUND(ABS(淡江大學_p4!H41),0) -> 2131120 | I18: =ROUND(ABS(淡江大學_p4!I41),0) -> 2122368 | J18: =ROUND(ABS(淡江大學_p4!J41),0) -> 2113616 | K18: =ROUND(ABS(淡江大學_p4!K41),0) -> 2104864 | ... W18: =ROUND(ABS(淡江大學_p4!W41),0) -> 1999839
B19: 淡江大學 | D19: =ROUND(ABS(淡江大學_p3!D41),0) -> 2166128 | E19: =ROUND(ABS(淡江大學_p3!E41),0) -> 2157376 | F19: =ROUND(ABS(淡江大學_p3!F41),0) -> 2148624 | G19: =ROUND(ABS(淡江大學_p3!G41),0) -> 2139872 | H19: =ROUND(ABS(淡江大學_p3!H41),0) -> 2131120 | I19: =ROUND(ABS(淡江大學_p3!I41),0) -> 2122368 | J19: =ROUND(ABS(淡江大學_p3!J41),0) -> 2113616 | K19: =ROUND(ABS(淡江大學_p3!K41),0) -> 2104864 | ... W19: =ROUND(ABS(淡江大學_p3!W41),0) -> 1999839
B20: 淡江大學 | D20: =ROUND(ABS(淡江大學_p6!D41),0) -> 2166128 | E20: =ROUND(ABS(淡江大學_p6!E41),0) -> 2157376 | F20: =ROUND(ABS(淡江大學_p6!F41),0) -> 2148624 | G20: =ROUND(ABS(淡江大學_p6!G41),0) -> 2139872 | H20: =ROUND(ABS(淡江大學_p6!H41),0) -> 2131120 | I20: =ROUND(ABS(淡江大學_p6!I41),0) -> 2122368 | J20: =ROUND(ABS(淡江大學_p6!J41),0) -> 2113616 | K20: =ROUND(ABS(淡江大學_p6!K41),0) -> 2104864 | ... W20: =ROUND(ABS(淡江大學_p6!W41),0) -> 1999839
C21: 預估收入/年總計 | D21: =SUM(D15:D20) -> 12996768 | E21: =SUM(E15:E20) -> 12944256 | F21: =SUM(F15:F20) -> 12891744 | G21: =SUM(G15:G20) -> 12839232 | H21: =SUM(H15:H20) -> 12786720 | I21: =SUM(I15:I20) -> 12734208 | J21: =SUM(J15:J20) -> 12681696 | K21: =SUM(K15:K20) -> 12629184 | ... W21: =SUM(W15:W20) -> 11999034
C22: 年份 | D22: 2020 | E22: 2021 | F22: 2022 | G22: 2023 | H22: 2024 | I22: 2025 | J22: 2026 | K22: 2027 | L22: 2028 | M22: 2029 | N22: 2030 | O22: 2031 | P22: 2032 | Q22: 2033 | R22: 2034 | S22: 2035 | T22: 2036 | U22: 2037 | V22: 2038 | W22: 2039
C23: 租金
B24: 淡江大學 | D24: =ROUND(ABS(淡江大學_p8!D45),0) -> 290201 | E24: =ROUND(ABS(淡江大學_p8!E45),0) -> 290201 | F24: =ROUND(ABS(淡江大學_p8!F45),0) -> 290201 | G24: =ROUND(ABS(淡江大學_p8!G45),0) -> 290201 | H24: =ROUND(ABS(淡江大學_p8!H45),0) -> 290201 | I24: =ROUND(ABS(淡江大學_p8!I45),0) -> 290201 | J24: =ROUND(ABS(淡江大學_p8!J45),0) -> 290201 | K24: =ROUND(ABS(淡江大學_p8!K45),0) -> 290201 | ... W24: =ROUND(ABS(淡江大學_p8!W45),0) -> 290201
B25: 淡江大學 | D25: =ROUND(ABS(淡江大學_p7!D45),0) -> 290201 | E25: =ROUND(ABS(淡江大學_p7!E45),0) -> 290201 | F25: =ROUND(ABS(淡江大學_p7!F45),0) -> 290201 | G25: =ROUND(ABS(淡江大學_p7!G45),0) -> 290201 | H25: =ROUND(ABS(淡江大學_p7!H45),0) -> 290201 | I25: =ROUND(ABS(淡江大學_p7!I45),0) -> 290201 | J25: =ROUND(ABS(淡江大學_p7!J45),0) -> 290201 | K25: =ROUND(ABS(淡江大學_p7!K45),0) -> 290201 | ... W25: =ROUND(ABS(淡江大學_p7!W45),0) -> 290201
B26: 淡江大學 | D26: =ROUND(ABS(淡江大學_p5!D45),0) -> 290201 | E26: =ROUND(ABS(淡江大學_p5!E45),0) -> 290201 | F26: =ROUND(ABS(淡江大學_p5!F45),0) -> 290201 | G26: =ROUND(ABS(淡江大學_p5!G45),0) -> 290201 | H26: =ROUND(ABS(淡江大學_p5!H45),0) -> 290201 | I26: =ROUND(ABS(淡江大學_p5!I45),0) -> 290201 | J26: =ROUND(ABS(淡江大學_p5!J45),0) -> 290201 | K26: =ROUND(ABS(淡江大學_p5!K45),0) -> 290201 | ... W26: =ROUND(ABS(淡江大學_p5!W45),0) -> 290201
B27: 淡江大學 | D27: =ROUND(ABS(淡江大學_p4!D45),0) -> 290201 | E27: =ROUND(ABS(淡江大學_p4!E45),0) -> 290201 | F27: =ROUND(ABS(淡江大學_p4!F45),0) -> 290201 | G27: =ROUND(ABS(淡江大學_p4!G45),0) -> 290201 | H27: =ROUND(ABS(淡江大學_p4!H45),0) -> 290201 | I27: =ROUND(ABS(淡江大學_p4!I45),0) -> 290201 | J27: =ROUND(ABS(淡江大學_p4!J45),0) -> 290201 | K27: =ROUND(ABS(淡江大學_p4!K45),0) -> 290201 | ... W27: =ROUND(ABS(淡江大學_p4!W45),0) -> 290201
B28: 淡江大學 | D28: =ROUND(ABS(淡江大學_p3!D45),0) -> 290201 | E28: =ROUND(ABS(淡江大學_p3!E45),0) -> 290201 | F28: =ROUND(ABS(淡江大學_p3!F45),0) -> 290201 | G28: =ROUND(ABS(淡江大學_p3!G45),0) -> 290201 | H28: =ROUND(ABS(淡江大學_p3!H45),0) -> 290201 | I28: =ROUND(ABS(淡江大學_p3!I45),0) -> 290201 | J28: =ROUND(ABS(淡江大學_p3!J45),0) -> 290201 | K28: =ROUND(ABS(淡江大學_p3!K45),0) -> 290201 | ... W28: =ROUND(ABS(淡江大學_p3!W45),0) -> 290201
B29: 淡江大學 | D29: =ROUND(ABS(淡江大學_p6!D45),0) -> 290201 | E29: =ROUND(ABS(淡江大學_p6!E45),0) -> 290201 | F29: =ROUND(ABS(淡江大學_p6!F45),0) -> 290201 | G29: =ROUND(ABS(淡江大學_p6!G45),0) -> 290201 | H29: =ROUND(ABS(淡江大學_p6!H45),0) -> 290201 | I29: =ROUND(ABS(淡江大學_p6!I45),0) -> 290201 | J29: =ROUND(ABS(淡江大學_p6!J45),0) -> 290201 | K29: =ROUND(ABS(淡江大學_p6!K45),0) -> 290201 | ... W29: =ROUND(ABS(淡江大學_p6!W45),0) -> 290201
C30: 租金/年總計 | D30: =SUM(D24:D29) -> 1741206 | E30: =SUM(E24:E29) -> 1741206 | F30: =SUM(F24:F29) -> 1741206 | G30: =SUM(G24:G29) -> 1741206 | H30: =SUM(H24:H29) -> 1741206 | I30: =SUM(I24:I29) -> 1741206 | J30: =SUM(J24:J29) -> 1741206 | K30: =SUM(K24:K29) -> 1741206 | ... W30: =SUM(W24:W29) -> 1741206
C31: 年份 | D31: 2020 | E31: 2021 | F31: 2022 | G31: 2023 | H31: 2024 | I31: 2025 | J31: 2026 | K31: 2027 | L31: 2028 | M31: 2029 | N31: 2030 | O31: 2031 | P31: 2032 | Q31: 2033 | R31: 2034 | S31: 2035 | T31: 2036 | U31: 2037 | V31: 2038 | W31: 2039
C32: 運維
B33: 淡江大學 | D33: =ROUND(ABS(淡江大學_p8!D48),0) -> 174440 | E33: =ROUND(ABS(淡江大學_p8!E48),0) -> 174440 | F33: =ROUND(ABS(淡江大學_p8!F48),0) -> 174440 | G33: =ROUND(ABS(淡江大學_p8!G48),0) -> 174440 | H33: =ROUND(ABS(淡江大學_p8!H48),0) -> 174440 | I33: =ROUND(ABS(淡江大學_p8!I48),0) -> 174440 | J33: =ROUND(ABS(淡江大學_p8!J48),0) -> 174440 | K33: =ROUND(ABS(淡江大學_p8!K48),0) -> 174440 | ... W33: =ROUND(ABS(淡江大學_p8!W48),0) -> 174440
B34: 淡江大學 | D34: =ROUND(ABS(淡江大學_p7!D48),0) -> 174440 | E34: =ROUND(ABS(淡江大學_p7!E48),0) -> 174440 | F34: =ROUND(ABS(淡江大學_p7!F48),0) -> 174440 | G34: =ROUND(ABS(淡江大學_p7!G48),0) -> 174440 | H34: =ROUND(ABS(淡江大學_p7!H48),0) -> 174440 | I34: =ROUND(ABS(淡江大學_p7!I48),0) -> 174440 | J34: =ROUND(ABS(淡江大學_p7!J48),0) -> 174440 | K34: =ROUND(ABS(淡江大學_p7!K48),0) -> 174440 | ... W34: =ROUND(ABS(淡江大學_p7!W48),0) -> 174440
B35: 淡江大學 | D35: =ROUND(ABS(淡江大學_p5!D48),0) -> 174440 | E35: =ROUND(ABS(淡江大學_p5!E48),0) -> 174440 | F35: =ROUND(ABS(淡江大學_p5!F48),0) -> 174440 | G35: =ROUND(ABS(淡江大學_p5!G48),0) -> 174440 | H35: =ROUND(ABS(淡江大學_p5!H48),0) -> 174440 | I35: =ROUND(ABS(淡江大學_p5!I48),0) -> 174440 | J35: =ROUND(ABS(淡江大學_p5!J48),0) -> 174440 | K35: =ROUND(ABS(淡江大學_p5!K48),0) -> 174440 | ... W35: =ROUND(ABS(淡江大學_p5!W48),0) -> 174440
B36: 淡江大學 | D36: =ROUND(ABS(淡江大學_p4!D48),0) -> 174440 | E36: =ROUND(ABS(淡江大學_p4!E48),0) -> 174440 | F36: =ROUND(ABS(淡江大學_p4!F48),0) -> 174440 | G36: =ROUND(ABS(淡江大學_p4!G48),0) -> 174440 | H36: =ROUND(ABS(淡江大學_p4!H48),0) -> 174440 | I36: =ROUND(ABS(淡江大學_p4!I48),0) -> 174440 | J36: =ROUND(ABS(淡江大學_p4!J48),0) -> 174440 | K36: =ROUND(ABS(淡江大學_p4!K48),0) -> 174440 | ... W36: =ROUND(ABS(淡江大學_p4!W48),0) -> 174440
B37: 淡江大學 | D37: =ROUND(ABS(淡江大學_p3!D48),0) -> 174440 | E37: =ROUND(ABS(淡江大學_p3!E48),0) -> 174440 | F37: =ROUND(ABS(淡江大學_p3!F48),0) -> 174440 | G37: =ROUND(ABS(淡江大學_p3!G48),0) -> 174440 | H37: =ROUND(ABS(淡江大學_p3!H48),0) -> 174440 | I37: =ROUND(ABS(淡江大學_p3!I48),0) -> 174440 | J37: =ROUND(ABS(淡江大學_p3!J48),0) -> 174440 | K37: =ROUND(ABS(淡江大學_p3!K48),0) -> 174440 | ... W37: =ROUND(ABS(淡江大學_p3!W48),0) -> 174440
B38: 淡江大學 | D38: =ROUND(ABS(淡江大學_p6!D48),0) -> 174440 | E38: =ROUND(ABS(淡江大學_p6!E48),0) -> 174440 | F38: =ROUND(ABS(淡江大學_p6!F48),0) -> 174440 | G38: =ROUND(ABS(淡江大學_p6!G48),0) -> 174440 | H38: =ROUND(ABS(淡江大學_p6!H48),0) -> 174440 | I38: =ROUND(ABS(淡江大學_p6!I48),0) -> 174440 | J38: =ROUND(ABS(淡江大學_p6!J48),0) -> 174440 | K38: =ROUND(ABS(淡江大學_p6!K48),0) -> 174440 | ... W38: =ROUND(ABS(淡江大學_p6!W48),0) -> 174440
C39: 運維/年總計 | D39: =SUM(D33:D38) -> 1046640 | E39: =SUM(E33:E38) -> 1046640 | F39: =SUM(F33:F38) -> 1046640 | G39: =SUM(G33:G38) -> 1046640 | H39: =SUM(H33:H38) -> 1046640 | I39: =SUM(I33:I38) -> 1046640 | J39: =SUM(J33:J38) -> 1046640 | K39: =SUM(K33:K38) -> 1046640 | ... W39: =SUM(W33:W38) -> 1046640
C40: 年份 | D40: 2020 | E40: 2021 | F40: 2022 | G40: 2023 | H40: 2024 | I40: 2025 | J40: 2026 | K40: 2027 | L40: 2028 | M40: 2029 | N40: 2030 | O40: 2031 | P40: 2032 | Q40: 2033 | R40: 2034 | S40: 2035 | T40: 2036 | U40: 2037 | V40: 2038 | W40: 2039
C41: 保險
B42: 淡江大學 | D42: =ROUND(ABS(淡江大學_p8!D49),0) -> 27474 | E42: =ROUND(ABS(淡江大學_p8!E49),0) -> 27474 | F42: =ROUND(ABS(淡江大學_p8!F49),0) -> 27474 | G42: =ROUND(ABS(淡江大學_p8!G49),0) -> 27474 | H42: =ROUND(ABS(淡江大學_p8!H49),0) -> 27474 | I42: =ROUND(ABS(淡江大學_p8!I49),0) -> 27474 | J42: =ROUND(ABS(淡江大學_p8!J49),0) -> 27474 | K42: =ROUND(ABS(淡江大學_p8!K49),0) -> 27474 | ... W42: =ROUND(ABS(淡江大學_p8!W49),0) -> 27474
B43: 淡江大學 | D43: =ROUND(ABS(淡江大學_p7!D49),0) -> 30091 | E43: =ROUND(ABS(淡江大學_p7!E49),0) -> 30091 | F43: =ROUND(ABS(淡江大學_p7!F49),0) -> 30091 | G43: =ROUND(ABS(淡江大學_p7!G49),0) -> 30091 | H43: =ROUND(ABS(淡江大學_p7!H49),0) -> 30091 | I43: =ROUND(ABS(淡江大學_p7!I49),0) -> 30091 | J43: =ROUND(ABS(淡江大學_p7!J49),0) -> 30091 | K43: =ROUND(ABS(淡江大學_p7!K49),0) -> 30091 | ... W43: =ROUND(ABS(淡江大學_p7!W49),0) -> 30091
...

Sheet 淡江大學_p3
B1: 電站基本資料 | F1: 說明 | P1: =1-D11 -> 0.99 | Q1: =P1-$D12 -> 0.986 | R1: =Q1-$D12 -> 0.982 | S1: =R1-$D12 -> 0.978 | T1: =S1-$D12 -> 0.974 | U1: =T1-$D12 -> 0.97 | V1: =U1-$D12 -> 0.966 | W1: =V1-$D12 -> 0.962 | X1: =W1-$D12 -> 0.958 | ... AI1: =AH1-$D12 -> 0.914
B2: 電站名稱 | C2: 淡江大學 | D2: - | E2: - | F2: 填入本案場名稱
B3: 電站壽命 | C3: 20 | D3: - | E3: - | F3: 預設 20 年，代表財務評估年期。若合約年限不同可依實際情況修改
B4: 建置量(kWp) | C4: 436.1 | D4: - | E4: - | F4: 填入裝置容量（kWp），通常由設計圖面或報價書取得 | M4: 情境編號: 3
B5: 起始年度 | C5: 2020 | D5: 結束年度 | E5: 2039 | F5: 填入電站預計掛表的西元年份（例：2025）。結束年度會自動計算 | M5: 第2次滾算摘要
M6: 價金: 31000
B7: 綜合損益表 | M7: 專案IRR: 3.75
B8: 收入 | M8: 權益法IRR: 8.21
B9: 收支項目 | C9: 相關參數 | D9: 參數數值 | E9: 年限 | F9: 說明 | M9: 利潤率: 30.00%
B10: 電費收入 | C10: 年度AC併網總發電量 | D10: 547002 | E10: 20 | F10: 預估年發電量（kWh），通常來自 PVsyst 模擬或估算：裝置容量 × 年日照時數 × 系統效率 | M10: 第2次滾算，減少 2000 元 - 現金模式，每次減少 2000 元
C11: 首年衰退率 | D11: 0.01 | F11: 第一年發電衰退比率，請填小數（例：1% → 填 0.01）。一般首年衰退約 1~2%(請參考模組規格書)
C12: 次年衰退率 | D12: 0.004 | F12: 第二年起每年固定衰退比率，請填小數（例：0.4% → 填 0.004）。一般約 0.4~0.7%(請參考模組規格書)
C13: 躉售費率(FIT) / 綠電費率 | D13: 4 | F13: 與台電簽訂的躉購費率或綠電合約費率，單位：元/度。請參考台電公告或合約內容
B14: 支出
B15: 收支項目 | C15: 相關參數 | D15: 參數數值 | E15: 攤提年限 | F15: 說明
B16: 設備費用(價金) | C16: 每kWp設備成本 | D16: 31000 | E16: 20 | F16: 每峰瓩設備成本（元/kWp），包含模組、逆變器、支架等硬體，不含工程施工費
C17: 信邦利潤率(ex:20%填0.2) | D17: 0.3 | F17: 公司在設備費用上加計的利潤比率，請填小數（例：20% → 填 0.2）
C18: 開發費 | D18: 2000 | F18: 前期開發費用（元），含可行性評估、申請規費、地主溝通等。若無則填 0
B19: 租金費用 | C19: 租金計算方式 | D19: 1 | E19: 20 | F19: 填 1 = 固定年租金（需填方式1參數）；填 2 = 依電費收入抽成（需填方式2參數）
C20: 【方式1參數】每年相同價格 | D20: 290201 | E20: 20 | F20: 租金計算方式選「1」時填寫，固定年租金金額（元/年），套用至整個電站壽命期
C21: 【方式2參數】抽成比率 | D21: 0 | E21: 20 | F21: 租金計算方式選「2」時填寫，請填小數（例：10% → 填 0.1）。租金 = 當年電費收入 × 抽成比率
B22: 運維費用 | C22: 每kw運維成本 | D22: 400 | E22: 20 | F22: 每峰瓩每年運維費用（元/kWp/年），含清洗、巡檢、維修等。
B23: 保險費用 | C23: 占整體設備費用比例 | D23: 0.003 | E23: 20 | F23: 保險費佔設備總費用比率，填小數（例：0.3% → 填 0.003）。預設 0.003，可依投保條件調整
B24: 模組回收費用 | C24: 每kw模組回收成本 | D24: 1000 | E24: 10 | F24: 每峰瓩模組廢棄回收費用（元/kWp），於第 1~10 年計提（攤提 10 年）。
B25: 利息費用 | C25: 銀行利率 | D25: 0.0256 | E25: 20 | F25: 向銀行貸款的年利率，填小數（例：2.56% → 填 0.0256）。請依銀行核准利率填入
B26: 所得稅 | C26: 所得稅率 | D26: 0.2 | E26: 20 | F26: 公司所得稅率，填小數（例：20% → 填 0.2）。預設 0.2，通常不需更改
B29: 現金流量表
B30: 金流項目 | C30: 相關參數 | D30: 參數數值 | F30: 說明
B31: 貸款成數 | C31: 占總設備費用比例 | D31: 0.8 | F31: 貸款佔設備總費用比例，填小數（例：80% → 填 0.8）。預設 0.8 代表貸八成、自備二成
B32: 貸款還款 | C32: 攤還期數 | D32: 15 | F32: 貸款還款年數（年）。預設 15 年，代表分 15 年平均攤還本金
B33: 現金股利 | C33: 股利比率 | D33: 0.9 | F33: 稅後現金流中分配給股東的比例，填小數（例：90% → 填 0.9）
B34: 年底減資 | C34: 攤還期數 | D34: 4 | F34: 年底減資返還股東的年數。預設 4 年，代表 倒數 4 年進行減資，加速資金返還
C37: 年份 | D37: 2020 | E37: 2021 | F37: 2022 | G37: 2023 | H37: 2024 | I37: 2025 | J37: 2026 | K37: 2027 | L37: 2028 | M37: 2029 | N37: 2030 | O37: 2031 | P37: 2032 | Q37: 2033 | R37: 2034 | S37: 2035 | T37: 2036 | U37: 2037 | V37: 2038 | W37: 2039
B38: 0
B39: (Unit : Currency) | C39: 0 | D39: 1 | E39: 2 | F39: 3 | G39: 4 | H39: 5 | I39: 6 | J39: 7 | K39: 8 | L39: 9 | M39: 10 | N39: 11 | O39: 12 | P39: 13 | Q39: 14 | R39: 15 | S39: 16 | T39: 17 | U39: 18 | V39: 19 | W39: 20
B40: 發電度數(KWH) | C40: 0 | D40: =$D$10*P1 -> 541531.98 | E40: =$D$10*Q1 -> 539343.97 | F40: =$D$10*R1 -> 537155.96 | G40: =$D$10*S1 -> 534967.96 | H40: =$D$10*T1 -> 532779.95 | I40: =$D$10*U1 -> 530591.94 | J40: =$D$10*V1 -> 528403.93 | K40: =$D$10*W1 -> 526215.92 | ... W40: =$D$10*AI1 -> 499959.83
B41: Inflow : 電費收入 | C41: - | D41: =D40*$D$13 -> 2166127.9 | E41: =E40*$D$13 -> 2157375.9 | F41: =F40*$D$13 -> 2148623.9 | G41: =G40*$D$13 -> 2139871.8 | H41: =H40*$D$13 -> 2131119.8 | I41: =I40*$D$13 -> 2122367.8 | J41: =J40*$D$13 -> 2113615.7 | K41: =K40*$D$13 -> 2104863.7 | ... W41: =W40*$D$13 -> 1999839.3
B42: Inflow : 政府補助 | C42: - | G42: - | H42: - | I42: - | J42: - | K42: - | L42: - | M42: - | N42: - | O42: - | P42: - | Q42: - | R42: - | S42: - | T42: - | U42: - | V42: - | W42: -
B43: Inflow : 銀行借款
B44: Outflow : 設備費用 | C44: =-(D16/(1-D17)+D18)*C4 -> -20185200
...

Sheet 淡江大學_p4
B1: 電站基本資料 | F1: 說明 | P1: =1-D11 -> 0.99 | Q1: =P1-$D12 -> 0.986 | R1: =Q1-$D12 -> 0.982 | S1: =R1-$D12 -> 0.978 | T1: =S1-$D12 -> 0.974 | U1: =T1-$D12 -> 0.97 | V1: =U1-$D12 -> 0.966 | W1: =V1-$D12 -> 0.962 | X1: =W1-$D12 -> 0.958 | ... AI1: =AH1-$D12 -> 0.914
B2: 電站名稱 | C2: 淡江大學 | D2: - | E2: - | F2: 填入本案場名稱
B3: 電站壽命 | C3: 20 | D3: - | E3: - | F3: 預設 20 年，代表財務評估年期。若合約年限不同可依實際情況修改
B4: 建置量(kWp) | C4: 436.1 | D4: - | E4: - | F4: 填入裝置容量（kWp），通常由設計圖面或報價書取得 | M4: 情境編號: 4
B5: 起始年度 | C5: 2020 | D5: 結束年度 | E5: 2039 | F5: 填入電站預計掛表的西元年份（例：2025）。結束年度會自動計算 | M5: 第3次滾算摘要
M6: 價金: 29000
B7: 綜合損益表 | M7: 專案IRR: 4.39
B8: 收入 | M8: 權益法IRR: 10.59
B9: 收支項目 | C9: 相關參數 | D9: 參數數值 | E9: 年限 | F9: 說明 | M9: 利潤率: 30.00%
B10: 電費收入 | C10: 年度AC併網總發電量 | D10: 547002 | E10: 20 | F10: 預估年發電量（kWh），通常來自 PVsyst 模擬或估算：裝置容量 × 年日照時數 × 系統效率 | M10: 第3次滾算，減少 2000 元 - 現金模式，每次減少 2000 元
C11: 首年衰退率 | D11: 0.01 | F11: 第一年發電衰退比率，請填小數（例：1% → 填 0.01）。一般首年衰退約 1~2%(請參考模組規格書)
C12: 次年衰退率 | D12: 0.004 | F12: 第二年起每年固定衰退比率，請填小數（例：0.4% → 填 0.004）。一般約 0.4~0.7%(請參考模組規格書)
C13: 躉售費率(FIT) / 綠電費率 | D13: 4 | F13: 與台電簽訂的躉購費率或綠電合約費率，單位：元/度。請參考台電公告或合約內容
B14: 支出
B15: 收支項目 | C15: 相關參數 | D15: 參數數值 | E15: 攤提年限 | F15: 說明
B16: 設備費用(價金) | C16: 每kWp設備成本 | D16: 29000 | E16: 20 | F16: 每峰瓩設備成本（元/kWp），包含模組、逆變器、支架等硬體，不含工程施工費
C17: 信邦利潤率(ex:20%填0.2) | D17: 0.3 | F17: 公司在設備費用上加計的利潤比率，請填小數（例：20% → 填 0.2）
C18: 開發費 | D18: 2000 | F18: 前期開發費用（元），含可行性評估、申請規費、地主溝通等。若無則填 0
B19: 租金費用 | C19: 租金計算方式 | D19: 1 | E19: 20 | F19: 填 1 = 固定年租金（需填方式1參數）；填 2 = 依電費收入抽成（需填方式2參數）
C20: 【方式1參數】每年相同價格 | D20: 290201 | E20: 20 | F20: 租金計算方式選「1」時填寫，固定年租金金額（元/年），套用至整個電站壽命期
C21: 【方式2參數】抽成比率 | D21: 0 | E21: 20 | F21: 租金計算方式選「2」時填寫，請填小數（例：10% → 填 0.1）。租金 = 當年電費收入 × 抽成比率
B22: 運維費用 | C22: 每kw運維成本 | D22: 400 | E22: 20 | F22: 每峰瓩每年運維費用（元/kWp/年），含清洗、巡檢、維修等。
B23: 保險費用 | C23: 占整體設備費用比例 | D23: 0.003 | E23: 20 | F23: 保險費佔設備總費用比率，填小數（例：0.3% → 填 0.003）。預設 0.003，可依投保條件調整
B24: 模組回收費用 | C24: 每kw模組回收成本 | D24: 1000 | E24: 10 | F24: 每峰瓩模組廢棄回收費用（元/kWp），於第 1~10 年計提（攤提 10 年）。
B25: 利息費用 | C25: 銀行利率 | D25: 0.0256 | E25: 20 | F25: 向銀行貸款的年利率，填小數（例：2.56% → 填 0.0256）。請依銀行核准利率填入
B26: 所得稅 | C26: 所得稅率 | D26: 0.2 | E26: 20 | F26: 公司所得稅率，填小數（例：20% → 填 0.2）。預設 0.2，通常不需更改
B29: 現金流量表
B30: 金流項目 | C30: 相關參數 | D30: 參數數值 | F30: 說明
B31: 貸款成數 | C31: 占總設備費用比例 | D31: 0.8 | F31: 貸款佔設備總費用比例，填小數（例：80% → 填 0.8）。預設 0.8 代表貸八成、自備二成
B32: 貸款還款 | C32: 攤還期數 | D32: 15 | F32: 貸款還款年數（年）。預設 15 年，代表分 15 年平均攤還本金
B33: 現金股利 | C33: 股利比率 | D33: 0.9 | F33: 稅後現金流中分配給股東的比例，填小數（例：90% → 填 0.9）
B34: 年底減資 | C34: 攤還期數 | D34: 4 | F34: 年底減資返還股東的年數。預設 4 年，代表 倒數 4 年進行減資，加速資金返還
C37: 年份 | D37: 2020 | E37: 2021 | F37: 2022 | G37: 2023 | H37: 2024 | I37: 2025 | J37: 2026 | K37: 2027 | L37: 2028 | M37: 2029 | N37: 2030 | O37: 2031 | P37: 2032 | Q37: 2033 | R37: 2034 | S37: 2035 | T37: 2036 | U37: 2037 | V37: 2038 | W37: 2039
B38: 0
B39: (Unit : Currency) | C39: 0 | D39: 1 | E39: 2 | F39: 3 | G39: 4 | H39: 5 | I39: 6 | J39: 7 | K39: 8 | L39: 9 | M39: 10 | N39: 11 | O39: 12 | P39: 13 | Q39: 14 | R39: 15 | S39: 16 | T39: 17 | U39: 18 | V39: 19 | W39: 20
B40: 發電度數(KWH) | C40: 0 | D40: =$D$10*P1 -> 541531.98 | E40: =$D$10*Q1 -> 539343.97 | F40: =$D$10*R1 -> 537155.96 | G40: =$D$10*S1 -> 534967.96 | H40: =$D$10*T1 -> 532779.95 | I40: =$D$10*U1 -> 530591.94 | J40: =$D$10*V1 -> 528403.93 | K40: =$D$10*W1 -> 526215.92 | ... W40: =$D$10*AI1 -> 499959.83
B41: Inflow : 電費收入 | C41: - | D41: =D40*$D$13 -> 2166127.9 | E41: =E40*$D$13 -> 2157375.9 | F41: =F40*$D$13 -> 2148623.9 | G41: =G40*$D$13 -> 2139871.8 | H41: =H40*$D$13 -> 2131119.8 | I41: =I40*$D$13 -> 2122367.8 | J41: =J40*$D$13 -> 2113615.7 | K41: =K40*$D$13 -> 2104863.7 | ... W41: =W40*$D$13 -> 1999839.3
B42: Inflow : 政府補助 | C42: - | G42: - | H42: - | I42: - | J42: - | K42: - | L42: - | M42: - | N42: - | O42: - | P42: - | Q42: - | R42: - | S42: - | T42: - | U42: - | V42: - | W42: -
B43: Inflow : 銀行借款
B44: Outflow : 設備費用 | C44: =-(D16/(1-D17)+D18)*C4 -> -18939200
...

Sheet 淡江大學_p5
B1: 電站基本資料 | F1: 說明 | P1: =1-D11 -> 0.99 | Q1: =P1-$D12 -> 0.986 | R1: =Q1-$D12 -> 0.982 | S1: =R1-$D12 -> 0.978 | T1: =S1-$D12 -> 0.974 | U1: =T1-$D12 -> 0.97 | V1: =U1-$D12 -> 0.966 | W1: =V1-$D12 -> 0.962 | X1: =W1-$D12 -> 0.958 | ... AI1: =AH1-$D12 -> 0.914
B2: 電站名稱 | C2: 淡江大學 | D2: - | E2: - | F2: 填入本案場名稱
B3: 電站壽命 | C3: 20 | D3: - | E3: - | F3: 預設 20 年，代表財務評估年期。若合約年限不同可依實際情況修改
B4: 建置量(kWp) | C4: 436.1 | D4: - | E4: - | F4: 填入裝置容量（kWp），通常由設計圖面或報價書取得 | M4: 情境編號: 5
B5: 起始年度 | C5: 2020 | D5: 結束年度 | E5: 2039 | F5: 填入電站預計掛表的西元年份（例：2025）。結束年度會自動計算 | M5: 第4次滾算摘要
M6: 價金: 27000
B7: 綜合損益表 | M7: 專案IRR: 5.11
B8: 收入 | M8: 權益法IRR: 13.45
B9: 收支項目 | C9: 相關參數 | D9: 參數數值 | E9: 年限 | F9: 說明 | M9: 利潤率: 30.00%
B10: 電費收入 | C10: 年度AC併網總發電量 | D10: 547002 | E10: 20 | F10: 預估年發電量（kWh），通常來自 PVsyst 模擬或估算：裝置容量 × 年日照時數 × 系統效率 | M10: 第4次滾算，減少 2000 元 - 現金模式，每次減少 2000 元
C11: 首年衰退率 | D11: 0.01 | F11: 第一年發電衰退比率，請填小數（例：1% → 填 0.01）。一般首年衰退約 1~2%(請參考模組規格書)
C12: 次年衰退率 | D12: 0.004 | F12: 第二年起每年固定衰退比率，請填小數（例：0.4% → 填 0.004）。一般約 0.4~0.7%(請參考模組規格書)
C13: 躉售費率(FIT) / 綠電費率 | D13: 4 | F13: 與台電簽訂的躉購費率或綠電合約費率，單位：元/度。請參考台電公告或合約內容
B14: 支出
B15: 收支項目 | C15: 相關參數 | D15: 參數數值 | E15: 攤提年限 | F15: 說明
B16: 設備費用(價金) | C16: 每kWp設備成本 | D16: 27000 | E16: 20 | F16: 每峰瓩設備成本（元/kWp），包含模組、逆變器、支架等硬體，不含工程施工費
C17: 信邦利潤率(ex:20%填0.2) | D17: 0.3 | F17: 公司在設備費用上加計的利潤比率，請填小數（例：20% → 填 0.2）
C18: 開發費 | D18: 2000 | F18: 前期開發費用（元），含可行性評估、申請規費、地主溝通等。若無則填 0
B19: 租金費用 | C19: 租金計算方式 | D19: 1 | E19: 20 | F19: 填 1 = 固定年租金（需填方式1參數）；填 2 = 依電費收入抽成（需填方式2參數）
C20: 【方式1參數】每年相同價格 | D20: 290201 | E20: 20 | F20: 租金計算方式選「1」時填寫，固定年租金金額（元/年），套用至整個電站壽命期
C21: 【方式2參數】抽成比率 | D21: 0 | E21: 20 | F21: 租金計算方式選「2」時填寫，請填小數（例：10% → 填 0.1）。租金 = 當年電費收入 × 抽成比率
B22: 運維費用 | C22: 每kw運維成本 | D22: 400 | E22: 20 | F22: 每峰瓩每年運維費用（元/kWp/年），含清洗、巡檢、維修等。
B23: 保險費用 | C23: 占整體設備費用比例 | D23: 0.003 | E23: 20 | F23: 保險費佔設備總費用比率，填小數（例：0.3% → 填 0.003）。預設 0.003，可依投保條件調整
B24: 模組回收費用 | C24: 每kw模組回收成本 | D24: 1000 | E24: 10 | F24: 每峰瓩模組廢棄回收費用（元/kWp），於第 1~10 年計提（攤提 10 年）。
B25: 利息費用 | C25: 銀行利率 | D25: 0.0256 | E25: 20 | F25: 向銀行貸款的年利率，填小數（例：2.56% → 填 0.0256）。請依銀行核准利率填入
B26: 所得稅 | C26: 所得稅率 | D26: 0.2 | E26: 20 | F26: 公司所得稅率，填小數（例：20% → 填 0.2）。預設 0.2，通常不需更改
B29: 現金流量表
B30: 金流項目 | C30: 相關參數 | D30: 參數數值 | F30: 說明
B31: 貸款成數 | C31: 占總設備費用比例 | D31: 0.8 | F31: 貸款佔設備總費用比例，填小數（例：80% → 填 0.8）。預設 0.8 代表貸八成、自備二成
B32: 貸款還款 | C32: 攤還期數 | D32: 15 | F32: 貸款還款年數（年）。預設 15 年，代表分 15 年平均攤還本金
B33: 現金股利 | C33: 股利比率 | D33: 0.9 | F33: 稅後現金流中分配給股東的比例，填小數（例：90% → 填 0.9）
B34: 年底減資 | C34: 攤還期數 | D34: 4 | F34: 年底減資返還股東的年數。預設 4 年，代表 倒數 4 年進行減資，加速資金返還
C37: 年份 | D37: 2020 | E37: 2021 | F37: 2022 | G37: 2023 | H37: 2024 | I37: 2025 | J37: 2026 | K37: 2027 | L37: 2028 | M37: 2029 | N37: 2030 | O37: 2031 | P37: 2032 | Q37: 2033 | R37: 2034 | S37: 2035 | T37: 2036 | U37: 2037 | V37: 2038 | W37: 2039
B38: 0
B39: (Unit : Currency) | C39: 0 | D39: 1 | E39: 2 | F39: 3 | G39: 4 | H39: 5 | I39: 6 | J39: 7 | K39: 8 | L39: 9 | M39: 10 | N39: 11 | O39: 12 | P39: 13 | Q39: 14 | R39: 15 | S39: 16 | T39: 17 | U39: 18 | V39: 19 | W39: 20
B40: 發電度數(KWH) | C40: 0 | D40: =$D$10*P1 -> 541531.98 | E40: =$D$10*Q1 -> 539343.97 | F40: =$D$10*R1 -> 537155.96 | G40: =$D$10*S1 -> 534967.96 | H40: =$D$10*T1 -> 532779.95 | I40: =$D$10*U1 -> 530591.94 | J40: =$D$10*V1 -> 528403.93 | K40: =$D$10*W1 -> 526215.92 | ... W40: =$D$10*AI1 -> 499959.83
B41: Inflow : 電費收入 | C41: - | D41: =D40*$D$13 -> 2166127.9 | E41: =E40*$D$13 -> 2157375.9 | F41: =F40*$D$13 -> 2148623.9 | G41: =G40*$D$13 -> 2139871.8 | H41: =H40*$D$13 -> 2131119.8 | I41: =I40*$D$13 -> 2122367.8 | J41: =J40*$D$13 -> 2113615.7 | K41: =K40*$D$13 -> 2104863.7 | ... W41: =W40*$D$13 -> 1999839.3
B42: Inflow : 政府補助 | C42: - | G42: - | H42: - | I42: - | J42: - | K42: - | L42: - | M42: - | N42: - | O42: - | P42: - | Q42: - | R42: - | S42: - | T42: - | U42: - | V42: - | W42: -
B43: Inflow : 銀行借款
B44: Outflow : 設備費用 | C44: =-(D16/(1-D17)+D18)*C4 -> -17693200
...

Sheet 淡江大學_p7
B1: 電站基本資料 | F1: 說明 | P1: =1-D11 -> 0.99 | Q1: =P1-$D12 -> 0.986 | R1: =Q1-$D12 -> 0.982 | S1: =R1-$D12 -> 0.978 | T1: =S1-$D12 -> 0.974 | U1: =T1-$D12 -> 0.97 | V1: =U1-$D12 -> 0.966 | W1: =V1-$D12 -> 0.962 | X1: =W1-$D12 -> 0.958 | ... AI1: =AH1-$D12 -> 0.914
B2: 電站名稱 | C2: 淡江大學 | D2: - | E2: - | F2: 填入本案場名稱
B3: 電站壽命 | C3: 20 | D3: - | E3: - | F3: 預設 20 年，代表財務評估年期。若合約年限不同可依實際情況修改
B4: 建置量(kWp) | C4: 436.1 | D4: - | E4: - | F4: 填入裝置容量（kWp），通常由設計圖面或報價書取得 | M4: 情境編號: 7
B5: 起始年度 | C5: 2020 | D5: 結束年度 | E5: 2039 | F5: 填入電站預計掛表的西元年份（例：2025）。結束年度會自動計算 | M5: 第6次滾算摘要
M6: 價金: 23000
B7: 綜合損益表 | M7: 專案IRR: 6.82
B8: 收入 | M8: 權益法IRR: 21.53
B9: 收支項目 | C9: 相關參數 | D9: 參數數值 | E9: 年限 | F9: 說明 | M9: 利潤率: 30.00%
B10: 電費收入 | C10: 年度AC併網總發電量 | D10: 547002 | E10: 20 | F10: 預估年發電量（kWh），通常來自 PVsyst 模擬或估算：裝置容量 × 年日照時數 × 系統效率 | M10: 第6次滾算，減少 2000 元 - 現金模式，每次減少 2000 元
C11: 首年衰退率 | D11: 0.01 | F11: 第一年發電衰退比率，請填小數（例：1% → 填 0.01）。一般首年衰退約 1~2%(請參考模組規格書)
C12: 次年衰退率 | D12: 0.004 | F12: 第二年起每年固定衰退比率，請填小數（例：0.4% → 填 0.004）。一般約 0.4~0.7%(請參考模組規格書)
C13: 躉售費率(FIT) / 綠電費率 | D13: 4 | F13: 與台電簽訂的躉購費率或綠電合約費率，單位：元/度。請參考台電公告或合約內容
B14: 支出
B15: 收支項目 | C15: 相關參數 | D15: 參數數值 | E15: 攤提年限 | F15: 說明
B16: 設備費用(價金) | C16: 每kWp設備成本 | D16: 23000 | E16: 20 | F16: 每峰瓩設備成本（元/kWp），包含模組、逆變器、支架等硬體，不含工程施工費
C17: 信邦利潤率(ex:20%填0.2) | D17: 0.3 | F17: 公司在設備費用上加計的利潤比率，請填小數（例：20% → 填 0.2）
C18: 開發費 | D18: 2000 | F18: 前期開發費用（元），含可行性評估、申請規費、地主溝通等。若無則填 0
B19: 租金費用 | C19: 租金計算方式 | D19: 1 | E19: 20 | F19: 填 1 = 固定年租金（需填方式1參數）；填 2 = 依電費收入抽成（需填方式2參數）
C20: 【方式1參數】每年相同價格 | D20: 290201 | E20: 20 | F20: 租金計算方式選「1」時填寫，固定年租金金額（元/年），套用至整個電站壽命期
C21: 【方式2參數】抽成比率 | D21: 0 | E21: 20 | F21: 租金計算方式選「2」時填寫，請填小數（例：10% → 填 0.1）。租金 = 當年電費收入 × 抽成比率
B22: 運維費用 | C22: 每kw運維成本 | D22: 400 | E22: 20 | F22: 每峰瓩每年運維費用（元/kWp/年），含清洗、巡檢、維修等。
B23: 保險費用 | C23: 占整體設備費用比例 | D23: 0.003 | E23: 20 | F23: 保險費佔設備總費用比率，填小數（例：0.3% → 填 0.003）。預設 0.003，可依投保條件調整
B24: 模組回收費用 | C24: 每kw模組回收成本 | D24: 1000 | E24: 10 | F24: 每峰瓩模組廢棄回收費用（元/kWp），於第 1~10 年計提（攤提 10 年）。
B25: 利息費用 | C25: 銀行利率 | D25: 0.0256 | E25: 20 | F25: 向銀行貸款的年利率，填小數（例：2.56% → 填 0.0256）。請依銀行核准利率填入
B26: 所得稅 | C26: 所得稅率 | D26: 0.2 | E26: 20 | F26: 公司所得稅率，填小數（例：20% → 填 0.2）。預設 0.2，通常不需更改
B29: 現金流量表
B30: 金流項目 | C30: 相關參數 | D30: 參數數值 | F30: 說明
B31: 貸款成數 | C31: 占總設備費用比例 | D31: 0.8 | F31: 貸款佔設備總費用比例，填小數（例：80% → 填 0.8）。預設 0.8 代表貸八成、自備二成
B32: 貸款還款 | C32: 攤還期數 | D32: 15 | F32: 貸款還款年數（年）。預設 15 年，代表分 15 年平均攤還本金
B33: 現金股利 | C33: 股利比率 | D33: 0.9 | F33: 稅後現金流中分配給股東的比例，填小數（例：90% → 填 0.9）
B34: 年底減資 | C34: 攤還期數 | D34: 4 | F34: 年底減資返還股東的年數。預設 4 年，代表 倒數 4 年進行減資，加速資金返還
C37: 年份 | D37: 2020 | E37: 2021 | F37: 2022 | G37: 2023 | H37: 2024 | I37: 2025 | J37: 2026 | K37: 2027 | L37: 2028 | M37: 2029 | N37: 2030 | O37: 2031 | P37: 2032 | Q37: 2033 | R37: 2034 | S37: 2035 | T37: 2036 | U37: 2037 | V37: 2038 | W37: 2039
B38: 0
B39: (Unit : Currency) | C39: 0 | D39: 1 | E39: 2 | F39: 3 | G39: 4 | H39: 5 | I39: 6 | J39: 7 | K39: 8 | L39: 9 | M39: 10 | N39: 11 | O39: 12 | P39: 13 | Q39: 14 | R39: 15 | S39: 16 | T39: 17 | U39: 18 | V39: 19 | W39: 20
B40: 發電度數(KWH) | C40: 0 | D40: =$D$10*P1 -> 541531.98 | E40: =$D$10*Q1 -> 539343.97 | F40: =$D$10*R1 -> 537155.96 | G40: =$D$10*S1 -> 534967.96 | H40: =$D$10*T1 -> 532779.95 | I40: =$D$10*U1 -> 530591.94 | J40: =$D$10*V1 -> 528403.93 | K40: =$D$10*W1 -> 526215.92 | ... W40: =$D$10*AI1 -> 499959.83
B41: Inflow : 電費收入 | C41: - | D41: =D40*$D$13 -> 2166127.9 | E41: =E40*$D$13 -> 2157375.9 | F41: =F40*$D$13 -> 2148623.9 | G41: =G40*$D$13 -> 2139871.8 | H41: =H40*$D$13 -> 2131119.8 | I41: =I40*$D$13 -> 2122367.8 | J41: =J40*$D$13 -> 2113615.7 | K41: =K40*$D$13 -> 2104863.7 | ... W41: =W40*$D$13 -> 1999839.3
B42: Inflow : 政府補助 | C42: - | G42: - | H42: - | I42: - | J42: - | K42: - | L42: - | M42: - | N42: - | O42: - | P42: - | Q42: - | R42: - | S42: - | T42: - | U42: - | V42: - | W42: -
B43: Inflow : 銀行借款
B44: Outflow : 設備費用 | C44: =-(D16/(1-D17)+D18)*C4 -> -15201200
...

Sheet 淡江大學_p8
B1: 電站基本資料 | F1: 說明 | P1: =1-D11 -> 0.99 | Q1: =P1-$D12 -> 0.986 | R1: =Q1-$D12 -> 0.982 | S1: =R1-$D12 -> 0.978 | T1: =S1-$D12 -> 0.974 | U1: =T1-$D12 -> 0.97 | V1: =U1-$D12 -> 0.966 | W1: =V1-$D12 -> 0.962 | X1: =W1-$D12 -> 0.958 | ... AI1: =AH1-$D12 -> 0.914
B2: 電站名稱 | C2: 淡江大學 | D2: - | E2: - | F2: 填入本案場名稱
B3: 電站壽命 | C3: 20 | D3: - | E3: - | F3: 預設 20 年，代表財務評估年期。若合約年限不同可依實際情況修改
B4: 建置量(kWp) | C4: 436.1 | D4: - | E4: - | F4: 填入裝置容量（kWp），通常由設計圖面或報價書取得 | M4: 情境編號: 8
B5: 起始年度 | C5: 2020 | D5: 結束年度 | E5: 2039 | F5: 填入電站預計掛表的西元年份（例：2025）。結束年度會自動計算 | M5: 第7次滾算摘要
M6: 價金: 21000
B7: 綜合損益表 | M7: 專案IRR: 7.85
B8: 收入 | M8: 權益法IRR: 27.57
B9: 收支項目 | C9: 相關參數 | D9: 參數數值 | E9: 年限 | F9: 說明 | M9: 利潤率: 30.00%
B10: 電費收入 | C10: 年度AC併網總發電量 | D10: 547002 | E10: 20 | F10: 預估年發電量（kWh），通常來自 PVsyst 模擬或估算：裝置容量 × 年日照時數 × 系統效率 | M10: 第7次滾算，減少 2000 元 - 現金模式，每次減少 2000 元
C11: 首年衰退率 | D11: 0.01 | F11: 第一年發電衰退比率，請填小數（例：1% → 填 0.01）。一般首年衰退約 1~2%(請參考模組規格書)
C12: 次年衰退率 | D12: 0.004 | F12: 第二年起每年固定衰退比率，請填小數（例：0.4% → 填 0.004）。一般約 0.4~0.7%(請參考模組規格書)
C13: 躉售費率(FIT) / 綠電費率 | D13: 4 | F13: 與台電簽訂的躉購費率或綠電合約費率，單位：元/度。請參考台電公告或合約內容
B14: 支出
B15: 收支項目 | C15: 相關參數 | D15: 參數數值 | E15: 攤提年限 | F15: 說明
B16: 設備費用(價金) | C16: 每kWp設備成本 | D16: 21000 | E16: 20 | F16: 每峰瓩設備成本（元/kWp），包含模組、逆變器、支架等硬體，不含工程施工費
C17: 信邦利潤率(ex:20%填0.2) | D17: 0.3 | F17: 公司在設備費用上加計的利潤比率，請填小數（例：20% → 填 0.2）
C18: 開發費 | D18: 2000 | F18: 前期開發費用（元），含可行性評估、申請規費、地主溝通等。若無則填 0
B19: 租金費用 | C19: 租金計算方式 | D19: 1 | E19: 20 | F19: 填 1 = 固定年租金（需填方式1參數）；填 2 = 依電費收入抽成（需填方式2參數）
C20: 【方式1參數】每年相同價格 | D20: 290201 | E20: 20 | F20: 租金計算方式選「1」時填寫，固定年租金金額（元/年），套用至整個電站壽命期
C21: 【方式2參數】抽成比率 | D21: 0 | E21: 20 | F21: 租金計算方式選「2」時填寫，請填小數（例：10% → 填 0.1）。租金 = 當年電費收入 × 抽成比率
B22: 運維費用 | C22: 每kw運維成本 | D22: 400 | E22: 20 | F22: 每峰瓩每年運維費用（元/kWp/年），含清洗、巡檢、維修等。
B23: 保險費用 | C23: 占整體設備費用比例 | D23: 0.003 | E23: 20 | F23: 保險費佔設備總費用比率，填小數（例：0.3% → 填 0.003）。預設 0.003，可依投保條件調整
B24: 模組回收費用 | C24: 每kw模組回收成本 | D24: 1000 | E24: 10 | F24: 每峰瓩模組廢棄回收費用（元/kWp），於第 1~10 年計提（攤提 10 年）。
B25: 利息費用 | C25: 銀行利率 | D25: 0.0256 | E25: 20 | F25: 向銀行貸款的年利率，填小數（例：2.56% → 填 0.0256）。請依銀行核准利率填入
B26: 所得稅 | C26: 所得稅率 | D26: 0.2 | E26: 20 | F26: 公司所得稅率，填小數（例：20% → 填 0.2）。預設 0.2，通常不需更改
B29: 現金流量表
B30: 金流項目 | C30: 相關參數 | D30: 參數數值 | F30: 說明
B31: 貸款成數 | C31: 占總設備費用比例 | D31: 0.8 | F31: 貸款佔設備總費用比例，填小數（例：80% → 填 0.8）。預設 0.8 代表貸八成、自備二成
B32: 貸款還款 | C32: 攤還期數 | D32: 15 | F32: 貸款還款年數（年）。預設 15 年，代表分 15 年平均攤還本金
B33: 現金股利 | C33: 股利比率 | D33: 0.9 | F33: 稅後現金流中分配給股東的比例，填小數（例：90% → 填 0.9）
B34: 年底減資 | C34: 攤還期數 | D34: 4 | F34: 年底減資返還股東的年數。預設 4 年，代表 倒數 4 年進行減資，加速資金返還
C37: 年份 | D37: 2020 | E37: 2021 | F37: 2022 | G37: 2023 | H37: 2024 | I37: 2025 | J37: 2026 | K37: 2027 | L37: 2028 | M37: 2029 | N37: 2030 | O37: 2031 | P37: 2032 | Q37: 2033 | R37: 2034 | S37: 2035 | T37: 2036 | U37: 2037 | V37: 2038 | W37: 2039
B38: 0
B39: (Unit : Currency) | C39: 0 | D39: 1 | E39: 2 | F39: 3 | G39: 4 | H39: 5 | I39: 6 | J39: 7 | K39: 8 | L39: 9 | M39: 10 | N39: 11 | O39: 12 | P39: 13 | Q39: 14 | R39: 15 | S39: 16 | T39: 17 | U39: 18 | V39: 19 | W39: 20
B40: 發電度數(KWH) | C40: 0 | D40: =$D$10*P1 -> 541531.98 | E40: =$D$10*Q1 -> 539343.97 | F40: =$D$10*R1 -> 537155.96 | G40: =$D$10*S1 -> 534967.96 | H40: =$D$10*T1 -> 532779.95 | I40: =$D$10*U1 -> 530591.94 | J40: =$D$10*V1 -> 528403.93 | K40: =$D$10*W1 -> 526215.92 | ... W40: =$D$10*AI1 -> 499959.83
B41: Inflow : 電費收入 | C41: - | D41: =D40*$D$13 -> 2166127.9 | E41: =E40*$D$13 -> 2157375.9 | F41: =F40*$D$13 -> 2148623.9 | G41: =G40*$D$13 -> 2139871.8 | H41: =H40*$D$13 -> 2131119.8 | I41: =I40*$D$13 -> 2122367.8 | J41: =J40*$D$13 -> 2113615.7 | K41: =K40*$D$13 -> 2104863.7 | ... W41: =W40*$D$13 -> 1999839.3
B42: Inflow : 政府補助 | C42: - | G42: - | H42: - | I42: - | J42: - | K42: - | L42: - | M42: - | N42: - | O42: - | P42: - | Q42: - | R42: - | S42: - | T42: - | U42: - | V42: - | W42: -
B43: Inflow : 銀行借款
B44: Outflow : 設備費用 | C44: =-(D16/(1-D17)+D18)*C4 -> -13955200
...

Sheet 淡江大學_p6
B1: 電站基本資料 | F1: 說明 | P1: =1-D11 -> 0.99 | Q1: =P1-$D12 -> 0.986 | R1: =Q1-$D12 -> 0.982 | S1: =R1-$D12 -> 0.978 | T1: =S1-$D12 -> 0.974 | U1: =T1-$D12 -> 0.97 | V1: =U1-$D12 -> 0.966 | W1: =V1-$D12 -> 0.962 | X1: =W1-$D12 -> 0.958 | ... AI1: =AH1-$D12 -> 0.914
B2: 電站名稱 | C2: 淡江大學 | D2: - | E2: - | F2: 填入本案場名稱
B3: 電站壽命 | C3: 20 | D3: - | E3: - | F3: 預設 20 年，代表財務評估年期。若合約年限不同可依實際情況修改
B4: 建置量(kWp) | C4: 436.1 | D4: - | E4: - | F4: 填入裝置容量（kWp），通常由設計圖面或報價書取得 | M4: 情境編號: 6
B5: 起始年度 | C5: 2020 | D5: 結束年度 | E5: 2039 | F5: 填入電站預計掛表的西元年份（例：2025）。結束年度會自動計算 | M5: 第5次滾算摘要
M6: 價金: 25000
B7: 綜合損益表 | M7: 專案IRR: 5.91
B8: 收入 | M8: 權益法IRR: 17.0
B9: 收支項目 | C9: 相關參數 | D9: 參數數值 | E9: 年限 | F9: 說明 | M9: 利潤率: 30.00%
B10: 電費收入 | C10: 年度AC併網總發電量 | D10: 547002 | E10: 20 | F10: 預估年發電量（kWh），通常來自 PVsyst 模擬或估算：裝置容量 × 年日照時數 × 系統效率 | M10: 第5次滾算，減少 2000 元 - 現金模式，每次減少 2000 元
C11: 首年衰退率 | D11: 0.01 | F11: 第一年發電衰退比率，請填小數（例：1% → 填 0.01）。一般首年衰退約 1~2%(請參考模組規格書)
C12: 次年衰退率 | D12: 0.004 | F12: 第二年起每年固定衰退比率，請填小數（例：0.4% → 填 0.004）。一般約 0.4~0.7%(請參考模組規格書)
C13: 躉售費率(FIT) / 綠電費率 | D13: 4 | F13: 與台電簽訂的躉購費率或綠電合約費率，單位：元/度。請參考台電公告或合約內容
B14: 支出
B15: 收支項目 | C15: 相關參數 | D15: 參數數值 | E15: 攤提年限 | F15: 說明
B16: 設備費用(價金) | C16: 每kWp設備成本 | D16: 25000 | E16: 20 | F16: 每峰瓩設備成本（元/kWp），包含模組、逆變器、支架等硬體，不含工程施工費
C17: 信邦利潤率(ex:20%填0.2) | D17: 0.3 | F17: 公司在設備費用上加計的利潤比率，請填小數（例：20% → 填 0.2）
C18: 開發費 | D18: 2000 | F18: 前期開發費用（元），含可行性評估、申請規費、地主溝通等。若無則填 0
B19: 租金費用 | C19: 租金計算方式 | D19: 1 | E19: 20 | F19: 填 1 = 固定年租金（需填方式1參數）；填 2 = 依電費收入抽成（需填方式2參數）
C20: 【方式1參數】每年相同價格 | D20: 290201 | E20: 20 | F20: 租金計算方式選「1」時填寫，固定年租金金額（元/年），套用至整個電站壽命期
C21: 【方式2參數】抽成比率 | D21: 0 | E21: 20 | F21: 租金計算方式選「2」時填寫，請填小數（例：10% → 填 0.1）。租金 = 當年電費收入 × 抽成比率
B22: 運維費用 | C22: 每kw運維成本 | D22: 400 | E22: 20 | F22: 每峰瓩每年運維費用（元/kWp/年），含清洗、巡檢、維修等。
B23: 保險費用 | C23: 占整體設備費用比例 | D23: 0.003 | E23: 20 | F23: 保險費佔設備總費用比率，填小數（例：0.3% → 填 0.003）。預設 0.003，可依投保條件調整
B24: 模組回收費用 | C24: 每kw模組回收成本 | D24: 1000 | E24: 10 | F24: 每峰瓩模組廢棄回收費用（元/kWp），於第 1~10 年計提（攤提 10 年）。
B25: 利息費用 | C25: 銀行利率 | D25: 0.0256 | E25: 20 | F25: 向銀行貸款的年利率，填小數（例：2.56% → 填 0.0256）。請依銀行核准利率填入
B26: 所得稅 | C26: 所得稅率 | D26: 0.2 | E26: 20 | F26: 公司所得稅率，填小數（例：20% → 填 0.2）。預設 0.2，通常不需更改
B29: 現金流量表
B30: 金流項目 | C30: 相關參數 | D30: 參數數值 | F30: 說明
B31: 貸款成數 | C31: 占總設備費用比例 | D31: 0.8 | F31: 貸款佔設備總費用比例，填小數（例：80% → 填 0.8）。預設 0.8 代表貸八成、自備二成
B32: 貸款還款 | C32: 攤還期數 | D32: 15 | F32: 貸款還款年數（年）。預設 15 年，代表分 15 年平均攤還本金
B33: 現金股利 | C33: 股利比率 | D33: 0.9 | F33: 稅後現金流中分配給股東的比例，填小數（例：90% → 填 0.9）
B34: 年底減資 | C34: 攤還期數 | D34: 4 | F34: 年底減資返還股東的年數。預設 4 年，代表 倒數 4 年進行減資，加速資金返還
C37: 年份 | D37: 2020 | E37: 2021 | F37: 2022 | G37: 2023 | H37: 2024 | I37: 2025 | J37: 2026 | K37: 2027 | L37: 2028 | M37: 2029 | N37: 2030 | O37: 2031 | P37: 2032 | Q37: 2033 | R37: 2034 | S37: 2035 | T37: 2036 | U37: 2037 | V37: 2038 | W37: 2039
B38: 0
B39: (Unit : Currency) | C39: 0 | D39: 1 | E39: 2 | F39: 3 | G39: 4 | H39: 5 | I39: 6 | J39: 7 | K39: 8 | L39: 9 | M39: 10 | N39: 11 | O39: 12 | P39: 13 | Q39: 14 | R39: 15 | S39: 16 | T39: 17 | U39: 18 | V39: 19 | W39: 20
B40: 發電度數(KWH) | C40: 0 | D40: =$D$10*P1 -> 541531.98 | E40: =$D$10*Q1 -> 539343.97 | F40: =$D$10*R1 -> 537155.96 | G40: =$D$10*S1 -> 534967.96 | H40: =$D$10*T1 -> 532779.95 | I40: =$D$10*U1 -> 530591.94 | J40: =$D$10*V1 -> 528403.93 | K40: =$D$10*W1 -> 526215.92 | ... W40: =$D$10*AI1 -> 499959.83
B41: Inflow : 電費收入 | C41: - | D41: =D40*$D$13 -> 2166127.9 | E41: =E40*$D$13 -> 2157375.9 | F41: =F40*$D$13 -> 2148623.9 | G41: =G40*$D$13 -> 2139871.8 | H41: =H40*$D$13 -> 2131119.8 | I41: =I40*$D$13 -> 2122367.8 | J41: =J40*$D$13 -> 2113615.7 | K41: =K40*$D$13 -> 2104863.7 | ... W41: =W40*$D$13 -> 1999839.3
B42: Inflow : 政府補助 | C42: - | G42: - | H42: - | I42: - | J42: - | K42: - | L42: - | M42: - | N42: - | O42: - | P42: - | Q42: - | R42: - | S42: - | T42: - | U42: - | V42: - | W42: -
B43: Inflow : 銀行借款
B44: Outflow : 設備費用 | C44: =-(D16/(1-D17)+D18)*C4 -> -16447200
...
