Workbook

Sheet 多站彙整
C4: 年份 | D4: 2020 | E4: 2021 | F4: 2022 | G4: 2023 | H4: 2024 | I4: 2025 | J4: 2026 | K4: 2027 | L4: 2028 | M4: 2029 | N4: 2030 | O4: 2031 | P4: 2032 | Q4: 2033 | R4: 2034 | S4: 2035 | T4: 2036 | U4: 2037 | V4: 2038 | W4: 2039
C5: 預估發電度數
B6: 淡江大學 | D6: =ROUND(ABS(淡江大學_p2!D40),0) -> 0 | E6: =ROUND(ABS(淡江大學_p2!E40),0) -> 0 | F6: =ROUND(ABS(淡江大學_p2!F40),0) -> 0 | G6: =ROUND(ABS(淡江大學_p2!G40),0) -> 0 | H6: =ROUND(ABS(淡江大學_p2!H40),0) -> 0 | I6: =ROUND(ABS(淡江大學_p2!I40),0) -> 0 | J6: =ROUND(ABS(淡江大學_p2!J40),0) -> 0 | K6: =ROUND(ABS(淡江大學_p2!K40),0) -> 0 | ... W6: =ROUND(ABS(淡江大學_p2!W40),0) -> 0
B7: 淡江大學 | D7: =ROUND(ABS(淡江大學_p3!D40),0) -> 0 | E7: =ROUND(ABS(淡江大學_p3!E40),0) -> 0 | F7: =ROUND(ABS(淡江大學_p3!F40),0) -> 0 | G7: =ROUND(ABS(淡江大學_p3!G40),0) -> 0 | H7: =ROUND(ABS(淡江大學_p3!H40),0) -> 0 | I7: =ROUND(ABS(淡江大學_p3!I40),0) -> 0 | J7: =ROUND(ABS(淡江大學_p3!J40),0) -> 0 | K7: =ROUND(ABS(淡江大學_p3!K40),0) -> 0 | ... W7: =ROUND(ABS(淡江大學_p3!W40),0) -> 0
C8: 預估發電度數/年總計 | D8: =SUM(D6:D7) -> 0 | E8: =SUM(E6:E7) -> 0 | F8: =SUM(F6:F7) -> 0 | G8: =SUM(G6:G7) -> 0 | H8: =SUM(H6:H7) -> 0 | I8: =SUM(I6:I7) -> 0 | J8: =SUM(J6:J7) -> 0 | K8: =SUM(K6:K7) -> 0 | ... W8: =SUM(W6:W7) -> 0
C9: 年份 | D9: 2020 | E9: 2021 | F9: 2022 | G9: 2023 | H9: 2024 | I9: 2025 | J9: 2026 | K9: 2027 | L9: 2028 | M9: 2029 | N9: 2030 | O9: 2031 | P9: 2032 | Q9: 2033 | R9: 2034 | S9: 2035 | T9: 2036 | U9: 2037 | V9: 2038 | W9: 2039
C10: 預估收入
B11: 淡江大學 | D11: =ROUND(ABS(淡江大學_p2!D41),0) -> 0 | E11: =ROUND(ABS(淡江大學_p2!E41),0) -> 0 | F11: =ROUND(ABS(淡江大學_p2!F41),0) -> 0 | G11: =ROUND(ABS(淡江大學_p2!G41),0) -> 0 | H11: =ROUND(ABS(淡江大學_p2!H41),0) -> 0 | I11: =ROUND(ABS(淡江大學_p2!I41),0) -> 0 | J11: =ROUND(ABS(淡江大學_p2!J41),0) -> 0 | K11: =ROUND(ABS(淡江大學_p2!K41),0) -> 0 | ... W11: =ROUND(ABS(淡江大學_p2!W41),0) -> 0
B12: 淡江大學 | D12: =ROUND(ABS(淡江大學_p3!D41),0) -> 0 | E12: =ROUND(ABS(淡江大學_p3!E41),0) -> 0 | F12: =ROUND(ABS(淡江大學_p3!F41),0) -> 0 | G12: =ROUND(ABS(淡江大學_p3!G41),0) -> 0 | H12: =ROUND(ABS(淡江大學_p3!H41),0) -> 0 | I12: =ROUND(ABS(淡江大學_p3!I41),0) -> 0 | J12: =ROUND(ABS(淡江大學_p3!J41),0) -> 0 | K12: =ROUND(ABS(淡江大學_p3!K41),0) -> 0 | ... W12: =ROUND(ABS(淡江大學_p3!W41),0) -> 0
C13: 預估收入/年總計 | D13: =SUM(D11:D12) -> 0 | E13: =SUM(E11:E12) -> 0 | F13: =SUM(F11:F12) -> 0 | G13: =SUM(G11:G12) -> 0 | H13: =SUM(H11:H12) -> 0 | I13: =SUM(I11:I12) -> 0 | J13: =SUM(J11:J12) -> 0 | K13: =SUM(K11:K12) -> 0 | ... W13: =SUM(W11:W12) -> 0
C14: 年份 | D14: 2020 | E14: 2021 | F14: 2022 | G14: 2023 | H14: 2024 | I14: 2025 | J14: 2026 | K14: 2027 | L14: 2028 | M14: 2029 | N14: 2030 | O14: 2031 | P14: 2032 | Q14: 2033 | R14: 2034 | S14: 2035 | T14: 2036 | U14: 2037 | V14: 2038 | W14: 2039
C15: 租金
B16: 淡江大學 | D16: =ROUND(ABS(淡江大學_p2!D45),0) -> 290201 | E16: =ROUND(ABS(淡江大學_p2!E45),0) -> 290201 | F16: =ROUND(ABS(淡江大學_p2!F45),0) -> 290201 | G16: =ROUND(ABS(淡江大學_p2!G45),0) -> 290201 | H16: =ROUND(ABS(淡江大學_p2!H45),0) -> 290201 | I16: =ROUND(ABS(淡江大學_p2!I45),0) -> 290201 | J16: =ROUND(ABS(淡江大學_p2!J45),0) -> 290201 | K16: =ROUND(ABS(淡江大學_p2!K45),0) -> 290201 | ... W16: =ROUND(ABS(淡江大學_p2!W45),0) -> 290201
B17: 淡江大學 | D17: =ROUND(ABS(淡江大學_p3!D45),0) -> 290201 | E17: =ROUND(ABS(淡江大學_p3!E45),0) -> 290201 | F17: =ROUND(ABS(淡江大學_p3!F45),0) -> 290201 | G17: =ROUND(ABS(淡江大學_p3!G45),0) -> 290201 | H17: =ROUND(ABS(淡江大學_p3!H45),0) -> 290201 | I17: =ROUND(ABS(淡江大學_p3!I45),0) -> 290201 | J17: =ROUND(ABS(淡江大學_p3!J45),0) -> 290201 | K17: =ROUND(ABS(淡江大學_p3!K45),0) -> 290201 | ... W17: =ROUND(ABS(淡江大學_p3!W45),0) -> 290201
C18: 租金/年總計 | D18: =SUM(D16:D17) -> 580402 | E18: =SUM(E16:E17) -> 580402 | F18: =SUM(F16:F17) -> 580402 | G18: =SUM(G16:G17) -> 580402 | H18: =SUM(H16:H17) -> 580402 | I18: =SUM(I16:I17) -> 580402 | J18: =SUM(J16:J17) -> 580402 | K18: =SUM(K16:K17) -> 580402 | ... W18: =SUM(W16:W17) -> 580402
C19: 年份 | D19: 2020 | E19: 2021 | F19: 2022 | G19: 2023 | H19: 2024 | I19: 2025 | J19: 2026 | K19: 2027 | L19: 2028 | M19: 2029 | N19: 2030 | O19: 2031 | P19: 2032 | Q19: 2033 | R19: 2034 | S19: 2035 | T19: 2036 | U19: 2037 | V19: 2038 | W19: 2039
C20: 運維
B21: 淡江大學 | D21: =ROUND(ABS(淡江大學_p2!D48),0) -> 174440 | E21: =ROUND(ABS(淡江大學_p2!E48),0) -> 174440 | F21: =ROUND(ABS(淡江大學_p2!F48),0) -> 174440 | G21: =ROUND(ABS(淡江大學_p2!G48),0) -> 174440 | H21: =ROUND(ABS(淡江大學_p2!H48),0) -> 174440 | I21: =ROUND(ABS(淡江大學_p2!I48),0) -> 174440 | J21: =ROUND(ABS(淡江大學_p2!J48),0) -> 174440 | K21: =ROUND(ABS(淡江大學_p2!K48),0) -> 174440 | ... W21: =ROUND(ABS(淡江大學_p2!W48),0) -> 174440
B22: 淡江大學 | D22: =ROUND(ABS(淡江大學_p3!D48),0) -> 174440 | E22: =ROUND(ABS(淡江大學_p3!E48),0) -> 174440 | F22: =ROUND(ABS(淡江大學_p3!F48),0) -> 174440 | G22: =ROUND(ABS(淡江大學_p3!G48),0) -> 174440 | H22: =ROUND(ABS(淡江大學_p3!H48),0) -> 174440 | I22: =ROUND(ABS(淡江大學_p3!I48),0) -> 174440 | J22: =ROUND(ABS(淡江大學_p3!J48),0) -> 174440 | K22: =ROUND(ABS(淡江大學_p3!K48),0) -> 174440 | ... W22: =ROUND(ABS(淡江大學_p3!W48),0) -> 174440
C23: 運維/年總計 | D23: =SUM(D21:D22) -> 348880 | E23: =SUM(E21:E22) -> 348880 | F23: =SUM(F21:F22) -> 348880 | G23: =SUM(G21:G22) -> 348880 | H23: =SUM(H21:H22) -> 348880 | I23: =SUM(I21:I22) -> 348880 | J23: =SUM(J21:J22) -> 348880 | K23: =SUM(K21:K22) -> 348880 | ... W23: =SUM(W21:W22) -> 348880
C24: 年份 | D24: 2020 | E24: 2021 | F24: 2022 | G24: 2023 | H24: 2024 | I24: 2025 | J24: 2026 | K24: 2027 | L24: 2028 | M24: 2029 | N24: 2030 | O24: 2031 | P24: 2032 | Q24: 2033 | R24: 2034 | S24: 2035 | T24: 2036 | U24: 2037 | V24: 2038 | W24: 2039
C25: 保險
B26: 淡江大學 | D26: =ROUND(ABS(淡江大學_p2!D49),0) -> 43174 | E26: =ROUND(ABS(淡江大學_p2!E49),0) -> 43174 | F26: =ROUND(ABS(淡江大學_p2!F49),0) -> 43174 | G26: =ROUND(ABS(淡江大學_p2!G49),0) -> 43174 | H26: =ROUND(ABS(淡江大學_p2!H49),0) -> 43174 | I26: =ROUND(ABS(淡江大學_p2!I49),0) -> 43174 | J26: =ROUND(ABS(淡江大學_p2!J49),0) -> 43174 | K26: =ROUND(ABS(淡江大學_p2!K49),0) -> 43174 | ... W26: =ROUND(ABS(淡江大學_p2!W49),0) -> 43174
B27: 淡江大學 | D27: =ROUND(ABS(淡江大學_p3!D49),0) -> 40557 | E27: =ROUND(ABS(淡江大學_p3!E49),0) -> 40557 | F27: =ROUND(ABS(淡江大學_p3!F49),0) -> 40557 | G27: =ROUND(ABS(淡江大學_p3!G49),0) -> 40557 | H27: =ROUND(ABS(淡江大學_p3!H49),0) -> 40557 | I27: =ROUND(ABS(淡江大學_p3!I49),0) -> 40557 | J27: =ROUND(ABS(淡江大學_p3!J49),0) -> 40557 | K27: =ROUND(ABS(淡江大學_p3!K49),0) -> 40557 | ... W27: =ROUND(ABS(淡江大學_p3!W49),0) -> 40557
C28: 保險/年總計 | D28: =SUM(D26:D27) -> 83731 | E28: =SUM(E26:E27) -> 83731 | F28: =SUM(F26:F27) -> 83731 | G28: =SUM(G26:G27) -> 83731 | H28: =SUM(H26:H27) -> 83731 | I28: =SUM(I26:I27) -> 83731 | J28: =SUM(J26:J27) -> 83731 | K28: =SUM(K26:K27) -> 83731 | ... W28: =SUM(W26:W27) -> 83731
C29: 年份 | D29: 2020 | E29: 2021 | F29: 2022 | G29: 2023 | H29: 2024 | I29: 2025 | J29: 2026 | K29: 2027 | L29: 2028 | M29: 2029 | N29: 2030 | O29: 2031 | P29: 2032 | Q29: 2033 | R29: 2034 | S29: 2035 | T29: 2036 | U29: 2037 | V29: 2038 | W29: 2039
C30: 模組回收費
B31: 淡江大學 | D31: =ROUND(ABS(淡江大學_p2!D50),0) -> 43610 | E31: =ROUND(ABS(淡江大學_p2!E50),0) -> 43610 | F31: =ROUND(ABS(淡江大學_p2!F50),0) -> 43610 | G31: =ROUND(ABS(淡江大學_p2!G50),0) -> 43610 | H31: =ROUND(ABS(淡江大學_p2!H50),0) -> 43610 | I31: =ROUND(ABS(淡江大學_p2!I50),0) -> 43610 | J31: =ROUND(ABS(淡江大學_p2!J50),0) -> 43610 | K31: =ROUND(ABS(淡江大學_p2!K50),0) -> 43610 | ... W31: =ROUND(ABS(淡江大學_p2!W50),0) -> 0
B32: 淡江大學 | D32: =ROUND(ABS(淡江大學_p3!D50),0) -> 43610 | E32: =ROUND(ABS(淡江大學_p3!E50),0) -> 43610 | F32: =ROUND(ABS(淡江大學_p3!F50),0) -> 43610 | G32: =ROUND(ABS(淡江大學_p3!G50),0) -> 43610 | H32: =ROUND(ABS(淡江大學_p3!H50),0) -> 43610 | I32: =ROUND(ABS(淡江大學_p3!I50),0) -> 43610 | J32: =ROUND(ABS(淡江大學_p3!J50),0) -> 43610 | K32: =ROUND(ABS(淡江大學_p3!K50),0) -> 43610 | ... W32: =ROUND(ABS(淡江大學_p3!W50),0) -> 0
C33: 模組回收費/年總計 | D33: =SUM(D31:D32) -> 87220 | E33: =SUM(E31:E32) -> 87220 | F33: =SUM(F31:F32) -> 87220 | G33: =SUM(G31:G32) -> 87220 | H33: =SUM(H31:H32) -> 87220 | I33: =SUM(I31:I32) -> 87220 | J33: =SUM(J31:J32) -> 87220 | K33: =SUM(K31:K32) -> 87220 | ... W33: =SUM(W31:W32) -> 0
C34: 年份 | D34: 2020 | E34: 2021 | F34: 2022 | G34: 2023 | H34: 2024 | I34: 2025 | J34: 2026 | K34: 2027 | L34: 2028 | M34: 2029 | N34: 2030 | O34: 2031 | P34: 2032 | Q34: 2033 | R34: 2034 | S34: 2035 | T34: 2036 | U34: 2037 | V34: 2038 | W34: 2039
C35: 所得稅
B36: 淡江大學 | D36: =ROUND(ABS(淡江大學_p2!D54),0) -> 0 | E36: =ROUND(ABS(淡江大學_p2!E54),0) -> 0 | F36: =ROUND(ABS(淡江大學_p2!F54),0) -> 0 | G36: =ROUND(ABS(淡江大學_p2!G54),0) -> 0 | H36: =ROUND(ABS(淡江大學_p2!H54),0) -> 0 | I36: =ROUND(ABS(淡江大學_p2!I54),0) -> 0 | J36: =ROUND(ABS(淡江大學_p2!J54),0) -> 0 | K36: =ROUND(ABS(淡江大學_p2!K54),0) -> 0 | ... W36: =ROUND(ABS(淡江大學_p2!W54),0) -> 0
B37: 淡江大學 | D37: =ROUND(ABS(淡江大學_p3!D54),0) -> 0 | E37: =ROUND(ABS(淡江大學_p3!E54),0) -> 0 | F37: =ROUND(ABS(淡江大學_p3!F54),0) -> 0 | G37: =ROUND(ABS(淡江大學_p3!G54),0) -> 0 | H37: =ROUND(ABS(淡江大學_p3!H54),0) -> 0 | I37: =ROUND(ABS(淡江大學_p3!I54),0) -> 0 | J37: =ROUND(ABS(淡江大學_p3!J54),0) -> 0 | K37: =ROUND(ABS(淡江大學_p3!K54),0) -> 0 | ... W37: =ROUND(ABS(淡江大學_p3!W54),0) -> 0
C38: 所得稅/年總計 | D38: =SUM(D36:D37) -> 0 | E38: =SUM(E36:E37) -> 0 | F38: =SUM(F36:F37) -> 0 | G38: =SUM(G36:G37) -> 0 | H38: =SUM(H36:H37) -> 0 | I38: =SUM(I36:I37) -> 0 | J38: =SUM(J36:J37) -> 0 | K38: =SUM(K36:K37) -> 0 | ... W38: =SUM(W36:W37) -> 0
C39: 年份 | D39: 2020 | E39: 2021 | F39: 2022 | G39: 2023 | H39: 2024 | I39: 2025 | J39: 2026 | K39: 2027 | L39: 2028 | M39: 2029 | N39: 2030 | O39: 2031 | P39: 2032 | Q39: 2033 | R39: 2034 | S39: 2035 | T39: 2036 | U39: 2037 | V39: 2038 | W39: 2039
C40: 設備折舊
B41: 淡江大學 | D41: =ROUND(ABS(淡江大學_p2!D67),0) -> 0 | E41: =ROUND(ABS(淡江大學_p2!E67),0) -> 0 | F41: =ROUND(ABS(淡江大學_p2!F67),0) -> 0 | G41: =ROUND(ABS(淡江大學_p2!G67),0) -> 0 | H41: =ROUND(ABS(淡江大學_p2!H67),0) -> 0 | I41: =ROUND(ABS(淡江大學_p2!I67),0) -> 0 | J41: =ROUND(ABS(淡江大學_p2!J67),0) -> 0 | K41: =ROUND(ABS(淡江大學_p2!K67),0) -> 0 | ... W41: =ROUND(ABS(淡江大學_p2!W67),0) -> 0
B42: 淡江大學 | D42: =ROUND(ABS(淡江大學_p3!D67),0) -> 0 | E42: =ROUND(ABS(淡江大學_p3!E67),0) -> 0 | F42: =ROUND(ABS(淡江大學_p3!F67),0) -> 0 | G42: =ROUND(ABS(淡江大學_p3!G67),0) -> 0 | H42: =ROUND(ABS(淡江大學_p3!H67),0) -> 0 | I42: =ROUND(ABS(淡江大學_p3!I67),0) -> 0 | J42: =ROUND(ABS(淡江大學_p3!J67),0) -> 0 | K42: =ROUND(ABS(淡江大學_p3!K67),0) -> 0 | ... W42: =ROUND(ABS(淡江大學_p3!W67),0) -> 0
C43: 設備折舊/年總計 | D43: =SUM(D41:D42) -> 0 | E43: =SUM(E41:E42) -> 0 | F43: =SUM(F41:F42) -> 0 | G43: =SUM(G41:G42) -> 0 | H43: =SUM(H41:H42) -> 0 | I43: =SUM(I41:I42) -> 0 | J43: =SUM(J41:J42) -> 0 | K43: =SUM(K41:K42) -> 0 | ... W43: =SUM(W41:W42) -> 0
...

Sheet 淡江大學_p2
A1: 電站基本資料(請填寫著色處) | E1: 說明 | O1: =1-C11 -> 0.99 | P1: =O1-$C12 -> 0.986 | Q1: =P1-$C12 -> 0.982 | R1: =Q1-$C12 -> 0.978 | S1: =R1-$C12 -> 0.974 | T1: =S1-$C12 -> 0.97 | U1: =T1-$C12 -> 0.966 | V1: =U1-$C12 -> 0.962 | W1: =V1-$C12 -> 0.958 | ... AH1: =AG1-$C12 -> 0.914
A2: 電站名稱 | B2: 淡江大學 | C2: 淡江大學 | D2: - | E2: 填入本案場名稱
A3: 電站壽命 | B3: 20 | C3: 20 | D3: - | E3: 預設 20 年，代表財務評估年期。若合約年限不同可依實際情況修改
A4: 建置量(kWp) | B4: 436.1 | C4: 436.1 | D4: - | E4: 填入裝置容量（kWp），通常由設計圖面或報價書取得 | M4: 情境編號: 2
A5: 起始年度 | B5: 2020 | C5: 2020 | D5: =B5+B3-1 -> 2039 | E5: 2039 | M5: 第1次滾算摘要
M6: 價金: 33000
A7: 綜合損益表(請填寫著色處) | M7: 專案IRR: 2.97
A8: 收入 | M8: 權益法IRR: 5.57
A9: 收支項目 | B9: 相關參數 | C9: 參數數值 | D9: 年限 | E9: 說明 | M9: 利潤率: 30.00%
A10: 電費收入 | B10: 年度AC併網總發電量 | C10: 547002 | D10: 547002 | E10: 20 | M10: 第1次滾算，減少 2000 元 - 現金模式，每次減少 2000 元
B11: 首年衰退率 | C11: 0.01 | E11: 第一年發電衰退比率，請填小數（例：1% → 填 0.01）。一般首年衰退約 1~2%(請參考模組規格書)
B12: 次年衰退率 | C12: 0.004 | E12: 第二年起每年固定衰退比率，請填小數（例：0.4% → 填 0.004）。一般約 0.4~0.7%(請參考模組規格書)
B13: 躉售費率(FIT) / 綠電費率 | C13: 4 | E13: 與台電簽訂的躉購費率或綠電合約費率，單位：元/度。請參考台電公告或合約內容
A14: 支出(請填寫著色處)
A15: 收支項目 | B15: 相關參數 | C15: 參數數值 | D15: 攤提年限 | E15: 說明
A16: 設備費用(價金) | B16: 每kWp設備成本 | C16: 35000 | D16: 33000 | E16: 20
B17: 信邦利潤率(ex:20%填0.2) | C17: 0.3 | E17: 公司在設備費用上加計的利潤比率，請填小數（例：20% → 填 0.2）
B18: 開發費 | C18: 2000 | E18: 前期開發費用（元），含可行性評估、申請規費、地主溝通等。若無則填 0
A19: 租金費用 | B19: 租金計算方式 | C19: 1 | D19: 1 | E19: 0
B20: 【方式1參數】每年相同價格 | C20: 290201 | D20: 290201 | E20: 20
B21: 【方式2參數】抽成比率 | D21: 0 | E21: 0
A22: 運維費用 | B22: 每kw運維成本 | C22: 400 | D22: 400 | E22: 20
A23: 保險費用 | B23: 占整體設備費用比例 | C23: 0.003 | D23: 0.003 | E23: 20
A24: 模組回收費用 | B24: 每kw模組回收成本 | C24: 1000 | D24: 1000 | E24: 10
A25: 利息費用 | B25: 銀行利率 | C25: 0.0256 | D25: 0.0256 | E25: 0
A26: 所得稅 | B26: 所得稅率 | C26: 0.2 | D26: 0.2 | E26: 0
A29: 現金流量表(請填寫著色處)
A30: 金流項目 | B30: 相關參數 | C30: 參數數值 | E30: 說明
A31: 貸款成數 | B31: 占總設備費用比例 | C31: 0.8 | D31: 0.8 | E31: 貸款佔設備總費用比例，填小數（例：80% → 填 0.8）。預設 0.8 代表貸八成、自備二成
A32: 貸款還款 | B32: 攤還期數 | C32: 15 | D32: 15 | E32: 貸款還款年數（年）。預設 15 年，代表分 15 年平均攤還本金
A33: 現金股利 | B33: 股利比率 | C33: 0.9 | D33: 0.9 | E33: 稅後現金流中分配給股東的比例，填小數（例：90% → 填 0.9）
A34: 年底減資 | B34: 攤還期數 | C34: 4 | D34: 4 | E34: 年底減資返還股東的年數。預設 4 年，代表 倒數 4 年進行減資，加速資金返還
D37: 2020 | E37: 2021 | F37: 2022 | G37: 2023 | H37: 2024 | I37: 2025 | J37: 2026 | K37: 2027 | L37: 2028 | M37: 2029 | N37: 2030 | O37: 2031 | P37: 2032 | Q37: 2033 | R37: 2034 | S37: 2035 | T37: 2036 | U37: 2037 | V37: 2038 | W37: 2039
D45: -290201 | E45: -290201 | F45: -290201 | G45: -290201 | H45: -290201 | I45: -290201 | J45: -290201 | K45: -290201 | L45: -290201 | M45: -290201 | N45: -290201 | O45: -290201 | P45: -290201 | Q45: -290201 | R45: -290201 | S45: -290201 | T45: -290201 | U45: -290201 | V45: -290201 | W45: -290201
D48: -174440 | E48: -174440 | F48: -174440 | G48: -174440 | H48: -174440 | I48: -174440 | J48: -174440 | K48: -174440 | L48: -174440 | M48: -174440 | N48: -174440 | O48: -174440 | P48: -174440 | Q48: -174440 | R48: -174440 | S48: -174440 | T48: -174440 | U48: -174440 | V48: -174440 | W48: -174440
D49: -43173.9 | E49: -43173.9 | F49: -43173.9 | G49: -43173.9 | H49: -43173.9 | I49: -43173.9 | J49: -43173.9 | K49: -43173.9 | L49: -43173.9 | M49: -43173.9 | N49: -43173.9 | O49: -43173.9 | P49: -43173.9 | Q49: -43173.9 | R49: -43173.9 | S49: -43173.9 | T49: -43173.9 | U49: -43173.9 | V49: -43173.9 | W49: -43173.9
D50: -43610 | E50: -43610 | F50: -43610 | G50: -43610 | H50: -43610 | I50: -43610 | J50: -43610 | K50: -43610 | L50: -43610 | M50: -43610 | N50: 0 | O50: 0 | P50: 0 | Q50: 0 | R50: 0 | S50: 0 | T50: 0 | U50: 0 | V50: 0 | W50: 0
D54: =D77 -> 0 | E54: =E77 -> 0 | F54: =F77 -> 0 | G54: =G77 -> 0 | H54: =H77 -> 0 | I54: =I77 -> 0 | J54: =J77 -> 0 | K54: =K77 -> 0 | ... W54: =W77 -> 0
D70: 0 | E70: 0 | F70: 0 | G70: 0 | H70: 0 | I70: 0 | J70: 0 | K70: 0 | L70: 0 | M70: 0 | N70: 0 | O70: 0 | P70: 0 | Q70: 0 | R70: 0 | S70: 0 | T70: 0 | U70: 0 | V70: 0 | W70: 0

Sheet 淡江大學_p3
A1: 電站基本資料(請填寫著色處) | E1: 說明 | O1: =1-C11 -> 0.99 | P1: =O1-$C12 -> 0.986 | Q1: =P1-$C12 -> 0.982 | R1: =Q1-$C12 -> 0.978 | S1: =R1-$C12 -> 0.974 | T1: =S1-$C12 -> 0.97 | U1: =T1-$C12 -> 0.966 | V1: =U1-$C12 -> 0.962 | W1: =V1-$C12 -> 0.958 | ... AH1: =AG1-$C12 -> 0.914
A2: 電站名稱 | B2: 淡江大學 | C2: 淡江大學 | D2: - | E2: 填入本案場名稱
A3: 電站壽命 | B3: 20 | C3: 20 | D3: - | E3: 預設 20 年，代表財務評估年期。若合約年限不同可依實際情況修改
A4: 建置量(kWp) | B4: 436.1 | C4: 436.1 | D4: - | E4: 填入裝置容量（kWp），通常由設計圖面或報價書取得 | M4: 情境編號: 3
A5: 起始年度 | B5: 2020 | C5: 2020 | D5: =B5+B3-1 -> 2039 | E5: 2039 | M5: 第2次滾算摘要
M6: 價金: 31000
A7: 綜合損益表(請填寫著色處) | M7: 專案IRR: 3.54
A8: 收入 | M8: 權益法IRR: 7.49
A9: 收支項目 | B9: 相關參數 | C9: 參數數值 | D9: 年限 | E9: 說明 | M9: 利潤率: 30.00%
A10: 電費收入 | B10: 年度AC併網總發電量 | C10: 547002 | D10: 547002 | E10: 20 | M10: 第2次滾算，減少 2000 元 - 現金模式，每次減少 2000 元
B11: 首年衰退率 | C11: 0.01 | E11: 第一年發電衰退比率，請填小數（例：1% → 填 0.01）。一般首年衰退約 1~2%(請參考模組規格書)
B12: 次年衰退率 | C12: 0.004 | E12: 第二年起每年固定衰退比率，請填小數（例：0.4% → 填 0.004）。一般約 0.4~0.7%(請參考模組規格書)
B13: 躉售費率(FIT) / 綠電費率 | C13: 4 | E13: 與台電簽訂的躉購費率或綠電合約費率，單位：元/度。請參考台電公告或合約內容
A14: 支出(請填寫著色處)
A15: 收支項目 | B15: 相關參數 | C15: 參數數值 | D15: 攤提年限 | E15: 說明
A16: 設備費用(價金) | B16: 每kWp設備成本 | C16: 35000 | D16: 31000 | E16: 20
B17: 信邦利潤率(ex:20%填0.2) | C17: 0.3 | E17: 公司在設備費用上加計的利潤比率，請填小數（例：20% → 填 0.2）
B18: 開發費 | C18: 2000 | E18: 前期開發費用（元），含可行性評估、申請規費、地主溝通等。若無則填 0
A19: 租金費用 | B19: 租金計算方式 | C19: 1 | D19: 1 | E19: 0
B20: 【方式1參數】每年相同價格 | C20: 290201 | D20: 290201 | E20: 20
B21: 【方式2參數】抽成比率 | D21: 0 | E21: 0
A22: 運維費用 | B22: 每kw運維成本 | C22: 400 | D22: 400 | E22: 20
A23: 保險費用 | B23: 占整體設備費用比例 | C23: 0.003 | D23: 0.003 | E23: 20
A24: 模組回收費用 | B24: 每kw模組回收成本 | C24: 1000 | D24: 1000 | E24: 10
A25: 利息費用 | B25: 銀行利率 | C25: 0.0256 | D25: 0.0256 | E25: 0
A26: 所得稅 | B26: 所得稅率 | C26: 0.2 | D26: 0.2 | E26: 0
A29: 現金流量表(請填寫著色處)
A30: 金流項目 | B30: 相關參數 | C30: 參數數值 | E30: 說明
A31: 貸款成數 | B31: 占總設備費用比例 | C31: 0.8 | D31: 0.8 | E31: 貸款佔設備總費用比例，填小數（例：80% → 填 0.8）。預設 0.8 代表貸八成、自備二成
A32: 貸款還款 | B32: 攤還期數 | C32: 15 | D32: 15 | E32: 貸款還款年數（年）。預設 15 年，代表分 15 年平均攤還本金
A33: 現金股利 | B33: 股利比率 | C33: 0.9 | D33: 0.9 | E33: 稅後現金流中分配給股東的比例，填小數（例：90% → 填 0.9）
A34: 年底減資 | B34: 攤還期數 | C34: 4 | D34: 4 | E34: 年底減資返還股東的年數。預設 4 年，代表 倒數 4 年進行減資，加速資金返還
D37: 2020 | E37: 2021 | F37: 2022 | G37: 2023 | H37: 2024 | I37: 2025 | J37: 2026 | K37: 2027 | L37: 2028 | M37: 2029 | N37: 2030 | O37: 2031 | P37: 2032 | Q37: 2033 | R37: 2034 | S37: 2035 | T37: 2036 | U37: 2037 | V37: 2038 | W37: 2039
D45: -290201 | E45: -290201 | F45: -290201 | G45: -290201 | H45: -290201 | I45: -290201 | J45: -290201 | K45: -290201 | L45: -290201 | M45: -290201 | N45: -290201 | O45: -290201 | P45: -290201 | Q45: -290201 | R45: -290201 | S45: -290201 | T45: -290201 | U45: -290201 | V45: -290201 | W45: -290201
D48: -174440 | E48: -174440 | F48: -174440 | G48: -174440 | H48: -174440 | I48: -174440 | J48: -174440 | K48: -174440 | L48: -174440 | M48: -174440 | N48: -174440 | O48: -174440 | P48: -174440 | Q48: -174440 | R48: -174440 | S48: -174440 | T48: -174440 | U48: -174440 | V48: -174440 | W48: -174440
D49: -40557.3 | E49: -40557.3 | F49: -40557.3 | G49: -40557.3 | H49: -40557.3 | I49: -40557.3 | J49: -40557.3 | K49: -40557.3 | L49: -40557.3 | M49: -40557.3 | N49: -40557.3 | O49: -40557.3 | P49: -40557.3 | Q49: -40557.3 | R49: -40557.3 | S49: -40557.3 | T49: -40557.3 | U49: -40557.3 | V49: -40557.3 | W49: -40557.3
D50: -43610 | E50: -43610 | F50: -43610 | G50: -43610 | H50: -43610 | I50: -43610 | J50: -43610 | K50: -43610 | L50: -43610 | M50: -43610 | N50: 0 | O50: 0 | P50: 0 | Q50: 0 | R50: 0 | S50: 0 | T50: 0 | U50: 0 | V50: 0 | W50: 0
D54: =D77 -> 0 | E54: =E77 -> 0 | F54: =F77 -> 0 | G54: =G77 -> 0 | H54: =H77 -> 0 | I54: =I77 -> 0 | J54: =J77 -> 0 | K54: =K77 -> 0 | ... W54: =W77 -> 0
D70: 0 | E70: 0 | F70: 0 | G70: 0 | H70: 0 | I70: 0 | J70: 0 | K70: 0 | L70: 0 | M70: 0 | N70: 0 | O70: 0 | P70: 0 | Q70: 0 | R70: 0 | S70: 0 | T70: 0 | U70: 0 | V70: 0 | W70: 0
