Workbook

Sheet 多站彙整
C4: 年份 | D4: 2023 | E4: 2024 | F4: 2025 | G4: 2026 | H4: 2027 | I4: 2028 | J4: 2029 | K4: 2030 | L4: 2031 | M4: 2032 | N4: 2033 | O4: 2034 | P4: 2035 | Q4: 2036 | R4: 2037 | S4: 2038 | T4: 2039 | U4: 2040 | V4: 2041 | W4: 2042
C5: 預估發電度數
B6: 淡江大學-財務模擬案場 | D6: =ROUND(ABS('淡江大學-財務模擬案場_p1'!D40),0) -> 541532 | E6: =ROUND(ABS('淡江大學-財務模擬案場_p1'!E40),0) -> 539344 | F6: =ROUND(ABS('淡江大學-財務模擬案場_p1'!F40),0) -> 537156 | G6: =ROUND(ABS('淡江大學-財務模擬案場_p1'!G40),0) -> 534968 | H6: =ROUND(ABS('淡江大學-財務模擬案場_p1'!H40),0) -> 532780 | I6: =ROUND(ABS('淡江大學-財務模擬案場_p1'!I40),0) -> 530592 | J6: =ROUND(ABS('淡江大學-財務模擬案場_p1'!J40),0) -> 528404 | K6: =ROUND(ABS('淡江大學-財務模擬案場_p1'!K40),0) -> 526216 | ... W6: =ROUND(ABS('淡江大學-財務模擬案場_p1'!W40),0) -> 499960
B7: 淡江大學-財務模擬案場 | D7: =ROUND(ABS('淡江大學-財務模擬案場_p2'!D40),0) -> 541532 | E7: =ROUND(ABS('淡江大學-財務模擬案場_p2'!E40),0) -> 539344 | F7: =ROUND(ABS('淡江大學-財務模擬案場_p2'!F40),0) -> 537156 | G7: =ROUND(ABS('淡江大學-財務模擬案場_p2'!G40),0) -> 534968 | H7: =ROUND(ABS('淡江大學-財務模擬案場_p2'!H40),0) -> 532780 | I7: =ROUND(ABS('淡江大學-財務模擬案場_p2'!I40),0) -> 530592 | J7: =ROUND(ABS('淡江大學-財務模擬案場_p2'!J40),0) -> 528404 | K7: =ROUND(ABS('淡江大學-財務模擬案場_p2'!K40),0) -> 526216 | ... W7: =ROUND(ABS('淡江大學-財務模擬案場_p2'!W40),0) -> 499960
B8: 淡江大學-財務模擬案場 | D8: =ROUND(ABS('淡江大學-財務模擬案場_p3'!D40),0) -> 541532 | E8: =ROUND(ABS('淡江大學-財務模擬案場_p3'!E40),0) -> 539344 | F8: =ROUND(ABS('淡江大學-財務模擬案場_p3'!F40),0) -> 537156 | G8: =ROUND(ABS('淡江大學-財務模擬案場_p3'!G40),0) -> 534968 | H8: =ROUND(ABS('淡江大學-財務模擬案場_p3'!H40),0) -> 532780 | I8: =ROUND(ABS('淡江大學-財務模擬案場_p3'!I40),0) -> 530592 | J8: =ROUND(ABS('淡江大學-財務模擬案場_p3'!J40),0) -> 528404 | K8: =ROUND(ABS('淡江大學-財務模擬案場_p3'!K40),0) -> 526216 | ... W8: =ROUND(ABS('淡江大學-財務模擬案場_p3'!W40),0) -> 499960
C9: 預估發電度數/年總計 | D9: =SUM(D6:D8) -> 1624596 | E9: =SUM(E6:E8) -> 1618032 | F9: =SUM(F6:F8) -> 1611468 | G9: =SUM(G6:G8) -> 1604904 | H9: =SUM(H6:H8) -> 1598340 | I9: =SUM(I6:I8) -> 1591776 | J9: =SUM(J6:J8) -> 1585212 | K9: =SUM(K6:K8) -> 1578648 | ... W9: =SUM(W6:W8) -> 1499880
C10: 年份 | D10: 2023 | E10: 2024 | F10: 2025 | G10: 2026 | H10: 2027 | I10: 2028 | J10: 2029 | K10: 2030 | L10: 2031 | M10: 2032 | N10: 2033 | O10: 2034 | P10: 2035 | Q10: 2036 | R10: 2037 | S10: 2038 | T10: 2039 | U10: 2040 | V10: 2041 | W10: 2042
C11: 預估收入
B12: 淡江大學-財務模擬案場 | D12: =ROUND(ABS('淡江大學-財務模擬案場_p1'!D41),0) -> 2011900 | E12: =ROUND(ABS('淡江大學-財務模擬案場_p1'!E41),0) -> 2003771 | F12: =ROUND(ABS('淡江大學-財務模擬案場_p1'!F41),0) -> 1995642 | G12: =ROUND(ABS('淡江大學-財務模擬案場_p1'!G41),0) -> 1987513 | H12: =ROUND(ABS('淡江大學-財務模擬案場_p1'!H41),0) -> 1979384 | I12: =ROUND(ABS('淡江大學-財務模擬案場_p1'!I41),0) -> 1971255 | J12: =ROUND(ABS('淡江大學-財務模擬案場_p1'!J41),0) -> 1963126 | K12: =ROUND(ABS('淡江大學-財務模擬案場_p1'!K41),0) -> 1954997 | ... W12: =ROUND(ABS('淡江大學-財務模擬案場_p1'!W41),0) -> 1857451
B13: 淡江大學-財務模擬案場 | D13: =ROUND(ABS('淡江大學-財務模擬案場_p2'!D41),0) -> 2011900 | E13: =ROUND(ABS('淡江大學-財務模擬案場_p2'!E41),0) -> 2003771 | F13: =ROUND(ABS('淡江大學-財務模擬案場_p2'!F41),0) -> 1995642 | G13: =ROUND(ABS('淡江大學-財務模擬案場_p2'!G41),0) -> 1987513 | H13: =ROUND(ABS('淡江大學-財務模擬案場_p2'!H41),0) -> 1979384 | I13: =ROUND(ABS('淡江大學-財務模擬案場_p2'!I41),0) -> 1971255 | J13: =ROUND(ABS('淡江大學-財務模擬案場_p2'!J41),0) -> 1963126 | K13: =ROUND(ABS('淡江大學-財務模擬案場_p2'!K41),0) -> 1954997 | ... W13: =ROUND(ABS('淡江大學-財務模擬案場_p2'!W41),0) -> 1857451
B14: 淡江大學-財務模擬案場 | D14: =ROUND(ABS('淡江大學-財務模擬案場_p3'!D41),0) -> 2011900 | E14: =ROUND(ABS('淡江大學-財務模擬案場_p3'!E41),0) -> 2003771 | F14: =ROUND(ABS('淡江大學-財務模擬案場_p3'!F41),0) -> 1995642 | G14: =ROUND(ABS('淡江大學-財務模擬案場_p3'!G41),0) -> 1987513 | H14: =ROUND(ABS('淡江大學-財務模擬案場_p3'!H41),0) -> 1979384 | I14: =ROUND(ABS('淡江大學-財務模擬案場_p3'!I41),0) -> 1971255 | J14: =ROUND(ABS('淡江大學-財務模擬案場_p3'!J41),0) -> 1963126 | K14: =ROUND(ABS('淡江大學-財務模擬案場_p3'!K41),0) -> 1954997 | ... W14: =ROUND(ABS('淡江大學-財務模擬案場_p3'!W41),0) -> 1857451
C15: 預估收入/年總計 | D15: =SUM(D12:D14) -> 6035700 | E15: =SUM(E12:E14) -> 6011313 | F15: =SUM(F12:F14) -> 5986926 | G15: =SUM(G12:G14) -> 5962539 | H15: =SUM(H12:H14) -> 5938152 | I15: =SUM(I12:I14) -> 5913765 | J15: =SUM(J12:J14) -> 5889378 | K15: =SUM(K12:K14) -> 5864991 | ... W15: =SUM(W12:W14) -> 5572353
C16: 年份 | D16: 2023 | E16: 2024 | F16: 2025 | G16: 2026 | H16: 2027 | I16: 2028 | J16: 2029 | K16: 2030 | L16: 2031 | M16: 2032 | N16: 2033 | O16: 2034 | P16: 2035 | Q16: 2036 | R16: 2037 | S16: 2038 | T16: 2039 | U16: 2040 | V16: 2041 | W16: 2042
C17: 租金
B18: 淡江大學-財務模擬案場 | D18: =ROUND(ABS('淡江大學-財務模擬案場_p1'!D45),0) -> 290201 | E18: =ROUND(ABS('淡江大學-財務模擬案場_p1'!E45),0) -> 290201 | F18: =ROUND(ABS('淡江大學-財務模擬案場_p1'!F45),0) -> 290201 | G18: =ROUND(ABS('淡江大學-財務模擬案場_p1'!G45),0) -> 290201 | H18: =ROUND(ABS('淡江大學-財務模擬案場_p1'!H45),0) -> 290201 | I18: =ROUND(ABS('淡江大學-財務模擬案場_p1'!I45),0) -> 290201 | J18: =ROUND(ABS('淡江大學-財務模擬案場_p1'!J45),0) -> 290201 | K18: =ROUND(ABS('淡江大學-財務模擬案場_p1'!K45),0) -> 290201 | ... W18: =ROUND(ABS('淡江大學-財務模擬案場_p1'!W45),0) -> 290201
B19: 淡江大學-財務模擬案場 | D19: =ROUND(ABS('淡江大學-財務模擬案場_p2'!D45),0) -> 290201 | E19: =ROUND(ABS('淡江大學-財務模擬案場_p2'!E45),0) -> 290201 | F19: =ROUND(ABS('淡江大學-財務模擬案場_p2'!F45),0) -> 290201 | G19: =ROUND(ABS('淡江大學-財務模擬案場_p2'!G45),0) -> 290201 | H19: =ROUND(ABS('淡江大學-財務模擬案場_p2'!H45),0) -> 290201 | I19: =ROUND(ABS('淡江大學-財務模擬案場_p2'!I45),0) -> 290201 | J19: =ROUND(ABS('淡江大學-財務模擬案場_p2'!J45),0) -> 290201 | K19: =ROUND(ABS('淡江大學-財務模擬案場_p2'!K45),0) -> 290201 | ... W19: =ROUND(ABS('淡江大學-財務模擬案場_p2'!W45),0) -> 290201
B20: 淡江大學-財務模擬案場 | D20: =ROUND(ABS('淡江大學-財務模擬案場_p3'!D45),0) -> 290201 | E20: =ROUND(ABS('淡江大學-財務模擬案場_p3'!E45),0) -> 290201 | F20: =ROUND(ABS('淡江大學-財務模擬案場_p3'!F45),0) -> 290201 | G20: =ROUND(ABS('淡江大學-財務模擬案場_p3'!G45),0) -> 290201 | H20: =ROUND(ABS('淡江大學-財務模擬案場_p3'!H45),0) -> 290201 | I20: =ROUND(ABS('淡江大學-財務模擬案場_p3'!I45),0) -> 290201 | J20: =ROUND(ABS('淡江大學-財務模擬案場_p3'!J45),0) -> 290201 | K20: =ROUND(ABS('淡江大學-財務模擬案場_p3'!K45),0) -> 290201 | ... W20: =ROUND(ABS('淡江大學-財務模擬案場_p3'!W45),0) -> 290201
C21: 租金/年總計 | D21: =SUM(D18:D20) -> 870603 | E21: =SUM(E18:E20) -> 870603 | F21: =SUM(F18:F20) -> 870603 | G21: =SUM(G18:G20) -> 870603 | H21: =SUM(H18:H20) -> 870603 | I21: =SUM(I18:I20) -> 870603 | J21: =SUM(J18:J20) -> 870603 | K21: =SUM(K18:K20) -> 870603 | ... W21: =SUM(W18:W20) -> 870603
C22: 年份 | D22: 2023 | E22: 2024 | F22: 2025 | G22: 2026 | H22: 2027 | I22: 2028 | J22: 2029 | K22: 2030 | L22: 2031 | M22: 2032 | N22: 2033 | O22: 2034 | P22: 2035 | Q22: 2036 | R22: 2037 | S22: 2038 | T22: 2039 | U22: 2040 | V22: 2041 | W22: 2042
C23: 運維
B24: 淡江大學-財務模擬案場 | D24: =ROUND(ABS('淡江大學-財務模擬案場_p1'!D48),0) -> 174440 | E24: =ROUND(ABS('淡江大學-財務模擬案場_p1'!E48),0) -> 174440 | F24: =ROUND(ABS('淡江大學-財務模擬案場_p1'!F48),0) -> 174440 | G24: =ROUND(ABS('淡江大學-財務模擬案場_p1'!G48),0) -> 174440 | H24: =ROUND(ABS('淡江大學-財務模擬案場_p1'!H48),0) -> 174440 | I24: =ROUND(ABS('淡江大學-財務模擬案場_p1'!I48),0) -> 174440 | J24: =ROUND(ABS('淡江大學-財務模擬案場_p1'!J48),0) -> 174440 | K24: =ROUND(ABS('淡江大學-財務模擬案場_p1'!K48),0) -> 174440 | ... W24: =ROUND(ABS('淡江大學-財務模擬案場_p1'!W48),0) -> 174440
B25: 淡江大學-財務模擬案場 | D25: =ROUND(ABS('淡江大學-財務模擬案場_p2'!D48),0) -> 174440 | E25: =ROUND(ABS('淡江大學-財務模擬案場_p2'!E48),0) -> 174440 | F25: =ROUND(ABS('淡江大學-財務模擬案場_p2'!F48),0) -> 174440 | G25: =ROUND(ABS('淡江大學-財務模擬案場_p2'!G48),0) -> 174440 | H25: =ROUND(ABS('淡江大學-財務模擬案場_p2'!H48),0) -> 174440 | I25: =ROUND(ABS('淡江大學-財務模擬案場_p2'!I48),0) -> 174440 | J25: =ROUND(ABS('淡江大學-財務模擬案場_p2'!J48),0) -> 174440 | K25: =ROUND(ABS('淡江大學-財務模擬案場_p2'!K48),0) -> 174440 | ... W25: =ROUND(ABS('淡江大學-財務模擬案場_p2'!W48),0) -> 174440
B26: 淡江大學-財務模擬案場 | D26: =ROUND(ABS('淡江大學-財務模擬案場_p3'!D48),0) -> 174440 | E26: =ROUND(ABS('淡江大學-財務模擬案場_p3'!E48),0) -> 174440 | F26: =ROUND(ABS('淡江大學-財務模擬案場_p3'!F48),0) -> 174440 | G26: =ROUND(ABS('淡江大學-財務模擬案場_p3'!G48),0) -> 174440 | H26: =ROUND(ABS('淡江大學-財務模擬案場_p3'!H48),0) -> 174440 | I26: =ROUND(ABS('淡江大學-財務模擬案場_p3'!I48),0) -> 174440 | J26: =ROUND(ABS('淡江大學-財務模擬案場_p3'!J48),0) -> 174440 | K26: =ROUND(ABS('淡江大學-財務模擬案場_p3'!K48),0) -> 174440 | ... W26: =ROUND(ABS('淡江大學-財務模擬案場_p3'!W48),0) -> 174440
C27: 運維/年總計 | D27: =SUM(D24:D26) -> 523320 | E27: =SUM(E24:E26) -> 523320 | F27: =SUM(F24:F26) -> 523320 | G27: =SUM(G24:G26) -> 523320 | H27: =SUM(H24:H26) -> 523320 | I27: =SUM(I24:I26) -> 523320 | J27: =SUM(J24:J26) -> 523320 | K27: =SUM(K24:K26) -> 523320 | ... W27: =SUM(W24:W26) -> 523320
C28: 年份 | D28: 2023 | E28: 2024 | F28: 2025 | G28: 2026 | H28: 2027 | I28: 2028 | J28: 2029 | K28: 2030 | L28: 2031 | M28: 2032 | N28: 2033 | O28: 2034 | P28: 2035 | Q28: 2036 | R28: 2037 | S28: 2038 | T28: 2039 | U28: 2040 | V28: 2041 | W28: 2042
C29: 保險
B30: 淡江大學-財務模擬案場 | D30: =ROUND(ABS('淡江大學-財務模擬案場_p1'!D49),0) -> 45791 | E30: =ROUND(ABS('淡江大學-財務模擬案場_p1'!E49),0) -> 45791 | F30: =ROUND(ABS('淡江大學-財務模擬案場_p1'!F49),0) -> 45791 | G30: =ROUND(ABS('淡江大學-財務模擬案場_p1'!G49),0) -> 45791 | H30: =ROUND(ABS('淡江大學-財務模擬案場_p1'!H49),0) -> 45791 | I30: =ROUND(ABS('淡江大學-財務模擬案場_p1'!I49),0) -> 45791 | J30: =ROUND(ABS('淡江大學-財務模擬案場_p1'!J49),0) -> 45791 | K30: =ROUND(ABS('淡江大學-財務模擬案場_p1'!K49),0) -> 45791 | ... W30: =ROUND(ABS('淡江大學-財務模擬案場_p1'!W49),0) -> 45791
B31: 淡江大學-財務模擬案場 | D31: =ROUND(ABS('淡江大學-財務模擬案場_p2'!D49),0) -> 43174 | E31: =ROUND(ABS('淡江大學-財務模擬案場_p2'!E49),0) -> 43174 | F31: =ROUND(ABS('淡江大學-財務模擬案場_p2'!F49),0) -> 43174 | G31: =ROUND(ABS('淡江大學-財務模擬案場_p2'!G49),0) -> 43174 | H31: =ROUND(ABS('淡江大學-財務模擬案場_p2'!H49),0) -> 43174 | I31: =ROUND(ABS('淡江大學-財務模擬案場_p2'!I49),0) -> 43174 | J31: =ROUND(ABS('淡江大學-財務模擬案場_p2'!J49),0) -> 43174 | K31: =ROUND(ABS('淡江大學-財務模擬案場_p2'!K49),0) -> 43174 | ... W31: =ROUND(ABS('淡江大學-財務模擬案場_p2'!W49),0) -> 43174
B32: 淡江大學-財務模擬案場 | D32: =ROUND(ABS('淡江大學-財務模擬案場_p3'!D49),0) -> 40557 | E32: =ROUND(ABS('淡江大學-財務模擬案場_p3'!E49),0) -> 40557 | F32: =ROUND(ABS('淡江大學-財務模擬案場_p3'!F49),0) -> 40557 | G32: =ROUND(ABS('淡江大學-財務模擬案場_p3'!G49),0) -> 40557 | H32: =ROUND(ABS('淡江大學-財務模擬案場_p3'!H49),0) -> 40557 | I32: =ROUND(ABS('淡江大學-財務模擬案場_p3'!I49),0) -> 40557 | J32: =ROUND(ABS('淡江大學-財務模擬案場_p3'!J49),0) -> 40557 | K32: =ROUND(ABS('淡江大學-財務模擬案場_p3'!K49),0) -> 40557 | ... W32: =ROUND(ABS('淡江大學-財務模擬案場_p3'!W49),0) -> 40557
C33: 保險/年總計 | D33: =SUM(D30:D32) -> 129522 | E33: =SUM(E30:E32) -> 129522 | F33: =SUM(F30:F32) -> 129522 | G33: =SUM(G30:G32) -> 129522 | H33: =SUM(H30:H32) -> 129522 | I33: =SUM(I30:I32) -> 129522 | J33: =SUM(J30:J32) -> 129522 | K33: =SUM(K30:K32) -> 129522 | ... W33: =SUM(W30:W32) -> 129522
C34: 年份 | D34: 2023 | E34: 2024 | F34: 2025 | G34: 2026 | H34: 2027 | I34: 2028 | J34: 2029 | K34: 2030 | L34: 2031 | M34: 2032 | N34: 2033 | O34: 2034 | P34: 2035 | Q34: 2036 | R34: 2037 | S34: 2038 | T34: 2039 | U34: 2040 | V34: 2041 | W34: 2042
C35: 模組回收費
B36: 淡江大學-財務模擬案場 | D36: =ROUND(ABS('淡江大學-財務模擬案場_p1'!D50),0) -> 43610 | E36: =ROUND(ABS('淡江大學-財務模擬案場_p1'!E50),0) -> 43610 | F36: =ROUND(ABS('淡江大學-財務模擬案場_p1'!F50),0) -> 43610 | G36: =ROUND(ABS('淡江大學-財務模擬案場_p1'!G50),0) -> 43610 | H36: =ROUND(ABS('淡江大學-財務模擬案場_p1'!H50),0) -> 43610 | I36: =ROUND(ABS('淡江大學-財務模擬案場_p1'!I50),0) -> 43610 | J36: =ROUND(ABS('淡江大學-財務模擬案場_p1'!J50),0) -> 43610 | K36: =ROUND(ABS('淡江大學-財務模擬案場_p1'!K50),0) -> 43610 | ... W36: =ROUND(ABS('淡江大學-財務模擬案場_p1'!W50),0) -> 0
B37: 淡江大學-財務模擬案場 | D37: =ROUND(ABS('淡江大學-財務模擬案場_p2'!D50),0) -> 43610 | E37: =ROUND(ABS('淡江大學-財務模擬案場_p2'!E50),0) -> 43610 | F37: =ROUND(ABS('淡江大學-財務模擬案場_p2'!F50),0) -> 43610 | G37: =ROUND(ABS('淡江大學-財務模擬案場_p2'!G50),0) -> 43610 | H37: =ROUND(ABS('淡江大學-財務模擬案場_p2'!H50),0) -> 43610 | I37: =ROUND(ABS('淡江大學-財務模擬案場_p2'!I50),0) -> 43610 | J37: =ROUND(ABS('淡江大學-財務模擬案場_p2'!J50),0) -> 43610 | K37: =ROUND(ABS('淡江大學-財務模擬案場_p2'!K50),0) -> 43610 | ... W37: =ROUND(ABS('淡江大學-財務模擬案場_p2'!W50),0) -> 0
B38: 淡江大學-財務模擬案場 | D38: =ROUND(ABS('淡江大學-財務模擬案場_p3'!D50),0) -> 43610 | E38: =ROUND(ABS('淡江大學-財務模擬案場_p3'!E50),0) -> 43610 | F38: =ROUND(ABS('淡江大學-財務模擬案場_p3'!F50),0) -> 43610 | G38: =ROUND(ABS('淡江大學-財務模擬案場_p3'!G50),0) -> 43610 | H38: =ROUND(ABS('淡江大學-財務模擬案場_p3'!H50),0) -> 43610 | I38: =ROUND(ABS('淡江大學-財務模擬案場_p3'!I50),0) -> 43610 | J38: =ROUND(ABS('淡江大學-財務模擬案場_p3'!J50),0) -> 43610 | K38: =ROUND(ABS('淡江大學-財務模擬案場_p3'!K50),0) -> 43610 | ... W38: =ROUND(ABS('淡江大學-財務模擬案場_p3'!W50),0) -> 0
C39: 模組回收費/年總計 | D39: =SUM(D36:D38) -> 130830 | E39: =SUM(E36:E38) -> 130830 | F39: =SUM(F36:F38) -> 130830 | G39: =SUM(G36:G38) -> 130830 | H39: =SUM(H36:H38) -> 130830 | I39: =SUM(I36:I38) -> 130830 | J39: =SUM(J36:J38) -> 130830 | K39: =SUM(K36:K38) -> 130830 | ... W39: =SUM(W36:W38) -> 0
C40: 年份 | D40: 2023 | E40: 2024 | F40: 2025 | G40: 2026 | H40: 2027 | I40: 2028 | J40: 2029 | K40: 2030 | L40: 2031 | M40: 2032 | N40: 2033 | O40: 2034 | P40: 2035 | Q40: 2036 | R40: 2037 | S40: 2038 | T40: 2039 | U40: 2040 | V40: 2041 | W40: 2042
C41: 所得稅
B42: 淡江大學-財務模擬案場 | D42: =ROUND(ABS('淡江大學-財務模擬案場_p1'!D54),0) -> 60439 | E42: =ROUND(ABS('淡江大學-財務模擬案場_p1'!E54),0) -> 58813 | F42: =ROUND(ABS('淡江大學-財務模擬案場_p1'!F54),0) -> 57187 | G42: =ROUND(ABS('淡江大學-財務模擬案場_p1'!G54),0) -> 55561 | H42: =ROUND(ABS('淡江大學-財務模擬案場_p1'!H54),0) -> 53936 | I42: =ROUND(ABS('淡江大學-財務模擬案場_p1'!I54),0) -> 52310 | J42: =ROUND(ABS('淡江大學-財務模擬案場_p1'!J54),0) -> 50684 | K42: =ROUND(ABS('淡江大學-財務模擬案場_p1'!K54),0) -> 49058 | ... W42: =ROUND(ABS('淡江大學-財務模擬案場_p1'!W54),0) -> 38271
B43: 淡江大學-財務模擬案場 | D43: =ROUND(ABS('淡江大學-財務模擬案場_p2'!D54),0) -> 73422 | E43: =ROUND(ABS('淡江大學-財務模擬案場_p2'!E54),0) -> 71796 | F43: =ROUND(ABS('淡江大學-財務模擬案場_p2'!F54),0) -> 70170 | G43: =ROUND(ABS('淡江大學-財務模擬案場_p2'!G54),0) -> 68545 | H43: =ROUND(ABS('淡江大學-財務模擬案場_p2'!H54),0) -> 66919 | I43: =ROUND(ABS('淡江大學-財務模擬案場_p2'!I54),0) -> 65293 | J43: =ROUND(ABS('淡江大學-財務模擬案場_p2'!J54),0) -> 63667 | K43: =ROUND(ABS('淡江大學-財務模擬案場_p2'!K54),0) -> 62042 | ... W43: =ROUND(ABS('淡江大學-財務模擬案場_p2'!W54),0) -> 51254
...

Sheet 淡江大學-財務模擬案場_p1
B1: 電站基本資料 | F1: 說明 | P1: =1-D11 -> 0.99 | Q1: =P1-$D12 -> 0.986 | R1: =Q1-$D12 -> 0.982 | S1: =R1-$D12 -> 0.978 | T1: =S1-$D12 -> 0.974 | U1: =T1-$D12 -> 0.97 | V1: =U1-$D12 -> 0.966 | W1: =V1-$D12 -> 0.962 | X1: =W1-$D12 -> 0.958 | ... AI1: =AH1-$D12 -> 0.914
B2: 電站名稱 | C2: 淡江大學-財務模擬案場 | D2: - | E2: - | F2: 填入本案場名稱
B3: 電站壽命 | C3: 20 | D3: - | E3: - | F3: 預設 20 年，代表財務評估年期。若合約年限不同可依實際情況修改
B4: 建置量(kWp) | C4: 436.1 | D4: - | E4: - | F4: 填入裝置容量（kWp），通常由設計圖面或報價書取得 | M4: 情境編號: 1
B5: 起始年度 | C5: 2023 | D5: 結束年度 | E5: 2042 | F5: 填入電站預計掛表的西元年份（例：2025）。結束年度會自動計算 | M5: 初始價金摘要
M6: 價金: 35000
B7: 綜合損益表 | M7: 專案IRR: 1.57
B8: 收入 | M8: 權益法IRR: 1.27
B9: 收支項目 | C9: 相關參數 | D9: 參數數值 | E9: 年限 | F9: 說明 | M9: 利潤率: 30.00%
B10: 電費收入 | C10: 年度AC併網總發電量 | D10: 547002 | E10: 20 | F10: 預估年發電量（kWh），通常來自 PVsyst 模擬或估算：裝置容量 × 年日照時數 × 系統效率 | M10: 初始價金 - 現金模式，每次減少 2000 元
C11: 首年衰退率 | D11: 0.01 | F11: 第一年發電衰退比率，請填小數（例：1% → 填 0.01）。一般首年衰退約 1~2%(請參考模組規格書)
C12: 次年衰退率 | D12: 0.004 | F12: 第二年起每年固定衰退比率，請填小數（例：0.4% → 填 0.004）。一般約 0.4~0.7%(請參考模組規格書)
C13: 躉售費率(FIT) / 綠電費率 | D13: 3.7152 | F13: 與台電簽訂的躉購費率或綠電合約費率，單位：元/度。請參考台電公告或合約內容
B14: 支出
B15: 收支項目 | C15: 相關參數 | D15: 參數數值 | E15: 攤提年限 | F15: 說明
B16: 設備費用(價金) | C16: 每kWp設備成本 | D16: 35000 | E16: 20 | F16: 每峰瓩設備成本（元/kWp），包含模組、逆變器、支架等硬體，不含工程施工費
C17: 信邦利潤率(ex:20%填0.2) | D17: 0.3 | F17: 公司在設備費用上加計的利潤比率，請填小數（例：20% → 填 0.2）
C18: 開發費 | D18: 3000 | F18: 前期開發費用（元），含可行性評估、申請規費、地主溝通等。若無則填 0
B19: 租金費用 | C19: 租金計算方式 | D19: 1 | E19: 0 | F19: 填 1 = 固定年租金（需填方式1參數）；填 2 = 依電費收入抽成（需填方式2參數）
C20: 【方式1參數】每年相同價格 | D20: 290201 | E20: 20 | F20: 租金計算方式選「1」時填寫，固定年租金金額（元/年），套用至整個電站壽命期
C21: 【方式2參數】抽成比率 | D21: 0 | E21: 0 | F21: 租金計算方式選「2」時填寫，請填小數（例：10% → 填 0.1）。租金 = 當年電費收入 × 抽成比率
B22: 運維費用 | C22: 每kw運維成本 | D22: 400 | E22: 20 | F22: 每峰瓩每年運維費用（元/kWp/年），含清洗、巡檢、維修等。
B23: 保險費用 | C23: 占整體設備費用比例 | D23: 0.003 | E23: 20 | F23: 保險費佔設備總費用比率，填小數（例：0.3% → 填 0.003）。預設 0.003，可依投保條件調整
B24: 模組回收費用 | C24: 每kw模組回收成本 | D24: 1000 | E24: 10 | F24: 每峰瓩模組廢棄回收費用（元/kWp），於第 1~10 年計提（攤提 10 年）。
B25: 利息費用 | C25: 銀行利率 | D25: 0.025595 | E25: 0 | F25: 向銀行貸款的年利率，填小數（例：2.56% → 填 0.0256）。請依銀行核准利率填入
B26: 所得稅 | C26: 所得稅率 | D26: 0.2 | E26: 0 | F26: 公司所得稅率，填小數（例：20% → 填 0.2）。預設 0.2，通常不需更改
B29: 現金流量表
B30: 金流項目 | C30: 相關參數 | D30: 參數數值 | F30: 說明
B31: 貸款成數 | C31: 占總設備費用比例 | D31: 0.8 | F31: 貸款佔設備總費用比例，填小數（例：80% → 填 0.8）。預設 0.8 代表貸八成、自備二成
B32: 貸款還款 | C32: 攤還期數 | D32: 15 | F32: 貸款還款年數（年）。預設 15 年，代表分 15 年平均攤還本金
B33: 現金股利 | C33: 股利比率 | D33: 0.9 | F33: 稅後現金流中分配給股東的比例，填小數（例：90% → 填 0.9）
B34: 年底減資 | C34: 攤還期數 | D34: 4 | F34: 年底減資返還股東的年數。預設 4 年，代表 倒數 4 年進行減資，加速資金返還
C37: 年份 | D37: 2023 | E37: 2024 | F37: 2025 | G37: 2026 | H37: 2027 | I37: 2028 | J37: 2029 | K37: 2030 | L37: 2031 | M37: 2032 | N37: 2033 | O37: 2034 | P37: 2035 | Q37: 2036 | R37: 2037 | S37: 2038 | T37: 2039 | U37: 2040 | V37: 2041 | W37: 2042
B38: 0
B39: (Unit : Currency) | C39: 0 | D39: 1 | E39: 2 | F39: 3 | G39: 4 | H39: 5 | I39: 6 | J39: 7 | K39: 8 | L39: 9 | M39: 10 | N39: 11 | O39: 12 | P39: 13 | Q39: 14 | R39: 15 | S39: 16 | T39: 17 | U39: 18 | V39: 19 | W39: 20
B40: 發電度數(KWH) | C40: 0 | D40: =$D$10*P1 -> 541531.98 | E40: =$D$10*Q1 -> 539343.97 | F40: =$D$10*R1 -> 537155.96 | G40: =$D$10*S1 -> 534967.96 | H40: =$D$10*T1 -> 532779.95 | I40: =$D$10*U1 -> 530591.94 | J40: =$D$10*V1 -> 528403.93 | K40: =$D$10*W1 -> 526215.92 | ... W40: =$D$10*AI1 -> 499959.83
B41: Inflow : 電費收入 | C41: - | D41: =D40*$D$13 -> 2011899.6 | E41: =E40*$D$13 -> 2003770.7 | F41: =F40*$D$13 -> 1995641.8 | G41: =G40*$D$13 -> 1987513 | H41: =H40*$D$13 -> 1979384.1 | I41: =I40*$D$13 -> 1971255.2 | J41: =J40*$D$13 -> 1963126.3 | K41: =K40*$D$13 -> 1954997.4 | ... W41: =W40*$D$13 -> 1857450.8
B42: Inflow : 政府補助 | C42: - | G42: - | H42: - | I42: - | J42: - | K42: - | L42: - | M42: - | N42: - | O42: - | P42: - | Q42: - | R42: - | S42: - | T42: - | U42: - | V42: - | W42: -
B43: Inflow : 銀行借款
B44: Outflow : 設備費用 | C44: =-(D16/(1-D17)+D18)*C4 -> -23113300
...

Sheet 淡江大學-財務模擬案場_p2
B1: 電站基本資料 | F1: 說明 | P1: =1-D11 -> 0.99 | Q1: =P1-$D12 -> 0.986 | R1: =Q1-$D12 -> 0.982 | S1: =R1-$D12 -> 0.978 | T1: =S1-$D12 -> 0.974 | U1: =T1-$D12 -> 0.97 | V1: =U1-$D12 -> 0.966 | W1: =V1-$D12 -> 0.962 | X1: =W1-$D12 -> 0.958 | ... AI1: =AH1-$D12 -> 0.914
B2: 電站名稱 | C2: 淡江大學-財務模擬案場 | D2: - | E2: - | F2: 填入本案場名稱
B3: 電站壽命 | C3: 20 | D3: - | E3: - | F3: 預設 20 年，代表財務評估年期。若合約年限不同可依實際情況修改
B4: 建置量(kWp) | C4: 436.1 | D4: - | E4: - | F4: 填入裝置容量（kWp），通常由設計圖面或報價書取得 | M4: 情境編號: 2
B5: 起始年度 | C5: 2023 | D5: 結束年度 | E5: 2042 | F5: 填入電站預計掛表的西元年份（例：2025）。結束年度會自動計算 | M5: 第1次滾算摘要
M6: 價金: 33000
B7: 綜合損益表 | M7: 專案IRR: 2.06
B8: 收入 | M8: 權益法IRR: 2.75
B9: 收支項目 | C9: 相關參數 | D9: 參數數值 | E9: 年限 | F9: 說明 | M9: 利潤率: 30.00%
B10: 電費收入 | C10: 年度AC併網總發電量 | D10: 547002 | E10: 20 | F10: 預估年發電量（kWh），通常來自 PVsyst 模擬或估算：裝置容量 × 年日照時數 × 系統效率 | M10: 第1次滾算，減少 2000 元 - 現金模式，每次減少 2000 元
C11: 首年衰退率 | D11: 0.01 | F11: 第一年發電衰退比率，請填小數（例：1% → 填 0.01）。一般首年衰退約 1~2%(請參考模組規格書)
C12: 次年衰退率 | D12: 0.004 | F12: 第二年起每年固定衰退比率，請填小數（例：0.4% → 填 0.004）。一般約 0.4~0.7%(請參考模組規格書)
C13: 躉售費率(FIT) / 綠電費率 | D13: 3.7152 | F13: 與台電簽訂的躉購費率或綠電合約費率，單位：元/度。請參考台電公告或合約內容
B14: 支出
B15: 收支項目 | C15: 相關參數 | D15: 參數數值 | E15: 攤提年限 | F15: 說明
B16: 設備費用(價金) | C16: 每kWp設備成本 | D16: 33000 | E16: 20 | F16: 每峰瓩設備成本（元/kWp），包含模組、逆變器、支架等硬體，不含工程施工費
C17: 信邦利潤率(ex:20%填0.2) | D17: 0.3 | F17: 公司在設備費用上加計的利潤比率，請填小數（例：20% → 填 0.2）
C18: 開發費 | D18: 3000 | F18: 前期開發費用（元），含可行性評估、申請規費、地主溝通等。若無則填 0
B19: 租金費用 | C19: 租金計算方式 | D19: 1 | E19: 0 | F19: 填 1 = 固定年租金（需填方式1參數）；填 2 = 依電費收入抽成（需填方式2參數）
C20: 【方式1參數】每年相同價格 | D20: 290201 | E20: 20 | F20: 租金計算方式選「1」時填寫，固定年租金金額（元/年），套用至整個電站壽命期
C21: 【方式2參數】抽成比率 | D21: 0 | E21: 0 | F21: 租金計算方式選「2」時填寫，請填小數（例：10% → 填 0.1）。租金 = 當年電費收入 × 抽成比率
B22: 運維費用 | C22: 每kw運維成本 | D22: 400 | E22: 20 | F22: 每峰瓩每年運維費用（元/kWp/年），含清洗、巡檢、維修等。
B23: 保險費用 | C23: 占整體設備費用比例 | D23: 0.003 | E23: 20 | F23: 保險費佔設備總費用比率，填小數（例：0.3% → 填 0.003）。預設 0.003，可依投保條件調整
B24: 模組回收費用 | C24: 每kw模組回收成本 | D24: 1000 | E24: 10 | F24: 每峰瓩模組廢棄回收費用（元/kWp），於第 1~10 年計提（攤提 10 年）。
B25: 利息費用 | C25: 銀行利率 | D25: 0.025595 | E25: 0 | F25: 向銀行貸款的年利率，填小數（例：2.56% → 填 0.0256）。請依銀行核准利率填入
B26: 所得稅 | C26: 所得稅率 | D26: 0.2 | E26: 0 | F26: 公司所得稅率，填小數（例：20% → 填 0.2）。預設 0.2，通常不需更改
B29: 現金流量表
B30: 金流項目 | C30: 相關參數 | D30: 參數數值 | F30: 說明
B31: 貸款成數 | C31: 占總設備費用比例 | D31: 0.8 | F31: 貸款佔設備總費用比例，填小數（例：80% → 填 0.8）。預設 0.8 代表貸八成、自備二成
B32: 貸款還款 | C32: 攤還期數 | D32: 15 | F32: 貸款還款年數（年）。預設 15 年，代表分 15 年平均攤還本金
B33: 現金股利 | C33: 股利比率 | D33: 0.9 | F33: 稅後現金流中分配給股東的比例，填小數（例：90% → 填 0.9）
B34: 年底減資 | C34: 攤還期數 | D34: 4 | F34: 年底減資返還股東的年數。預設 4 年，代表 倒數 4 年進行減資，加速資金返還
C37: 年份 | D37: 2023 | E37: 2024 | F37: 2025 | G37: 2026 | H37: 2027 | I37: 2028 | J37: 2029 | K37: 2030 | L37: 2031 | M37: 2032 | N37: 2033 | O37: 2034 | P37: 2035 | Q37: 2036 | R37: 2037 | S37: 2038 | T37: 2039 | U37: 2040 | V37: 2041 | W37: 2042
B38: 0
B39: (Unit : Currency) | C39: 0 | D39: 1 | E39: 2 | F39: 3 | G39: 4 | H39: 5 | I39: 6 | J39: 7 | K39: 8 | L39: 9 | M39: 10 | N39: 11 | O39: 12 | P39: 13 | Q39: 14 | R39: 15 | S39: 16 | T39: 17 | U39: 18 | V39: 19 | W39: 20
B40: 發電度數(KWH) | C40: 0 | D40: =$D$10*P1 -> 541531.98 | E40: =$D$10*Q1 -> 539343.97 | F40: =$D$10*R1 -> 537155.96 | G40: =$D$10*S1 -> 534967.96 | H40: =$D$10*T1 -> 532779.95 | I40: =$D$10*U1 -> 530591.94 | J40: =$D$10*V1 -> 528403.93 | K40: =$D$10*W1 -> 526215.92 | ... W40: =$D$10*AI1 -> 499959.83
B41: Inflow : 電費收入 | C41: - | D41: =D40*$D$13 -> 2011899.6 | E41: =E40*$D$13 -> 2003770.7 | F41: =F40*$D$13 -> 1995641.8 | G41: =G40*$D$13 -> 1987513 | H41: =H40*$D$13 -> 1979384.1 | I41: =I40*$D$13 -> 1971255.2 | J41: =J40*$D$13 -> 1963126.3 | K41: =K40*$D$13 -> 1954997.4 | ... W41: =W40*$D$13 -> 1857450.8
B42: Inflow : 政府補助 | C42: - | G42: - | H42: - | I42: - | J42: - | K42: - | L42: - | M42: - | N42: - | O42: - | P42: - | Q42: - | R42: - | S42: - | T42: - | U42: - | V42: - | W42: -
B43: Inflow : 銀行借款
B44: Outflow : 設備費用 | C44: =-(D16/(1-D17)+D18)*C4 -> -21867300
...

Sheet 淡江大學-財務模擬案場_p3
B1: 電站基本資料 | F1: 說明 | P1: =1-D11 -> 0.99 | Q1: =P1-$D12 -> 0.986 | R1: =Q1-$D12 -> 0.982 | S1: =R1-$D12 -> 0.978 | T1: =S1-$D12 -> 0.974 | U1: =T1-$D12 -> 0.97 | V1: =U1-$D12 -> 0.966 | W1: =V1-$D12 -> 0.962 | X1: =W1-$D12 -> 0.958 | ... AI1: =AH1-$D12 -> 0.914
B2: 電站名稱 | C2: 淡江大學-財務模擬案場 | D2: - | E2: - | F2: 填入本案場名稱
B3: 電站壽命 | C3: 20 | D3: - | E3: - | F3: 預設 20 年，代表財務評估年期。若合約年限不同可依實際情況修改
B4: 建置量(kWp) | C4: 436.1 | D4: - | E4: - | F4: 填入裝置容量（kWp），通常由設計圖面或報價書取得 | M4: 情境編號: 3
B5: 起始年度 | C5: 2023 | D5: 結束年度 | E5: 2042 | F5: 填入電站預計掛表的西元年份（例：2025）。結束年度會自動計算 | M5: 第2次滾算摘要
M6: 價金: 31000
B7: 綜合損益表 | M7: 專案IRR: 2.6
B8: 收入 | M8: 權益法IRR: 4.43
B9: 收支項目 | C9: 相關參數 | D9: 參數數值 | E9: 年限 | F9: 說明 | M9: 利潤率: 30.00%
B10: 電費收入 | C10: 年度AC併網總發電量 | D10: 547002 | E10: 20 | F10: 預估年發電量（kWh），通常來自 PVsyst 模擬或估算：裝置容量 × 年日照時數 × 系統效率 | M10: 第2次滾算，減少 2000 元 - 現金模式，每次減少 2000 元
C11: 首年衰退率 | D11: 0.01 | F11: 第一年發電衰退比率，請填小數（例：1% → 填 0.01）。一般首年衰退約 1~2%(請參考模組規格書)
C12: 次年衰退率 | D12: 0.004 | F12: 第二年起每年固定衰退比率，請填小數（例：0.4% → 填 0.004）。一般約 0.4~0.7%(請參考模組規格書)
C13: 躉售費率(FIT) / 綠電費率 | D13: 3.7152 | F13: 與台電簽訂的躉購費率或綠電合約費率，單位：元/度。請參考台電公告或合約內容
B14: 支出
B15: 收支項目 | C15: 相關參數 | D15: 參數數值 | E15: 攤提年限 | F15: 說明
B16: 設備費用(價金) | C16: 每kWp設備成本 | D16: 31000 | E16: 20 | F16: 每峰瓩設備成本（元/kWp），包含模組、逆變器、支架等硬體，不含工程施工費
C17: 信邦利潤率(ex:20%填0.2) | D17: 0.3 | F17: 公司在設備費用上加計的利潤比率，請填小數（例：20% → 填 0.2）
C18: 開發費 | D18: 3000 | F18: 前期開發費用（元），含可行性評估、申請規費、地主溝通等。若無則填 0
B19: 租金費用 | C19: 租金計算方式 | D19: 1 | E19: 0 | F19: 填 1 = 固定年租金（需填方式1參數）；填 2 = 依電費收入抽成（需填方式2參數）
C20: 【方式1參數】每年相同價格 | D20: 290201 | E20: 20 | F20: 租金計算方式選「1」時填寫，固定年租金金額（元/年），套用至整個電站壽命期
C21: 【方式2參數】抽成比率 | D21: 0 | E21: 0 | F21: 租金計算方式選「2」時填寫，請填小數（例：10% → 填 0.1）。租金 = 當年電費收入 × 抽成比率
B22: 運維費用 | C22: 每kw運維成本 | D22: 400 | E22: 20 | F22: 每峰瓩每年運維費用（元/kWp/年），含清洗、巡檢、維修等。
B23: 保險費用 | C23: 占整體設備費用比例 | D23: 0.003 | E23: 20 | F23: 保險費佔設備總費用比率，填小數（例：0.3% → 填 0.003）。預設 0.003，可依投保條件調整
B24: 模組回收費用 | C24: 每kw模組回收成本 | D24: 1000 | E24: 10 | F24: 每峰瓩模組廢棄回收費用（元/kWp），於第 1~10 年計提（攤提 10 年）。
B25: 利息費用 | C25: 銀行利率 | D25: 0.025595 | E25: 0 | F25: 向銀行貸款的年利率，填小數（例：2.56% → 填 0.0256）。請依銀行核准利率填入
B26: 所得稅 | C26: 所得稅率 | D26: 0.2 | E26: 0 | F26: 公司所得稅率，填小數（例：20% → 填 0.2）。預設 0.2，通常不需更改
B29: 現金流量表
B30: 金流項目 | C30: 相關參數 | D30: 參數數值 | F30: 說明
B31: 貸款成數 | C31: 占總設備費用比例 | D31: 0.8 | F31: 貸款佔設備總費用比例，填小數（例：80% → 填 0.8）。預設 0.8 代表貸八成、自備二成
B32: 貸款還款 | C32: 攤還期數 | D32: 15 | F32: 貸款還款年數（年）。預設 15 年，代表分 15 年平均攤還本金
B33: 現金股利 | C33: 股利比率 | D33: 0.9 | F33: 稅後現金流中分配給股東的比例，填小數（例：90% → 填 0.9）
B34: 年底減資 | C34: 攤還期數 | D34: 4 | F34: 年底減資返還股東的年數。預設 4 年，代表 倒數 4 年進行減資，加速資金返還
C37: 年份 | D37: 2023 | E37: 2024 | F37: 2025 | G37: 2026 | H37: 2027 | I37: 2028 | J37: 2029 | K37: 2030 | L37: 2031 | M37: 2032 | N37: 2033 | O37: 2034 | P37: 2035 | Q37: 2036 | R37: 2037 | S37: 2038 | T37: 2039 | U37: 2040 | V37: 2041 | W37: 2042
B38: 0
B39: (Unit : Currency) | C39: 0 | D39: 1 | E39: 2 | F39: 3 | G39: 4 | H39: 5 | I39: 6 | J39: 7 | K39: 8 | L39: 9 | M39: 10 | N39: 11 | O39: 12 | P39: 13 | Q39: 14 | R39: 15 | S39: 16 | T39: 17 | U39: 18 | V39: 19 | W39: 20
B40: 發電度數(KWH) | C40: 0 | D40: =$D$10*P1 -> 541531.98 | E40: =$D$10*Q1 -> 539343.97 | F40: =$D$10*R1 -> 537155.96 | G40: =$D$10*S1 -> 534967.96 | H40: =$D$10*T1 -> 532779.95 | I40: =$D$10*U1 -> 530591.94 | J40: =$D$10*V1 -> 528403.93 | K40: =$D$10*W1 -> 526215.92 | ... W40: =$D$10*AI1 -> 499959.83
B41: Inflow : 電費收入 | C41: - | D41: =D40*$D$13 -> 2011899.6 | E41: =E40*$D$13 -> 2003770.7 | F41: =F40*$D$13 -> 1995641.8 | G41: =G40*$D$13 -> 1987513 | H41: =H40*$D$13 -> 1979384.1 | I41: =I40*$D$13 -> 1971255.2 | J41: =J40*$D$13 -> 1963126.3 | K41: =K40*$D$13 -> 1954997.4 | ... W41: =W40*$D$13 -> 1857450.8
B42: Inflow : 政府補助 | C42: - | G42: - | H42: - | I42: - | J42: - | K42: - | L42: - | M42: - | N42: - | O42: - | P42: - | Q42: - | R42: - | S42: - | T42: - | U42: - | V42: - | W42: -
B43: Inflow : 銀行借款
B44: Outflow : 設備費用 | C44: =-(D16/(1-D17)+D18)*C4 -> -20621300
...
