Workbook

Sheet 多站彙整
C4: 年份 | D4: 2020 | E4: 2021 | F4: 2022 | G4: 2023 | H4: 2024 | I4: 2025 | J4: 2026 | K4: 2027 | L4: 2028 | M4: 2029 | N4: 2030 | O4: 2031 | P4: 2032 | Q4: 2033 | R4: 2034 | S4: 2035 | T4: 2036 | U4: 2037 | V4: 2038 | W4: 2039
C5: 預估發電度數
B6: 淡江大學 | D6: =ROUND(ABS(淡江大學_p6_1!D40),0) -> 0 | E6: =ROUND(ABS(淡江大學_p6_1!E40),0) -> 0 | F6: =ROUND(ABS(淡江大學_p6_1!F40),0) -> 0 | G6: =ROUND(ABS(淡江大學_p6_1!G40),0) -> 0 | H6: =ROUND(ABS(淡江大學_p6_1!H40),0) -> 0 | I6: =ROUND(ABS(淡江大學_p6_1!I40),0) -> 0 | J6: =ROUND(ABS(淡江大學_p6_1!J40),0) -> 0 | K6: =ROUND(ABS(淡江大學_p6_1!K40),0) -> 0 | ... W6: =ROUND(ABS(淡江大學_p6_1!W40),0) -> 0
B7: 淡江大學 | D7: =ROUND(ABS(淡江大學_p4_2!D40),0) -> 0 | E7: =ROUND(ABS(淡江大學_p4_2!E40),0) -> 0 | F7: =ROUND(ABS(淡江大學_p4_2!F40),0) -> 0 | G7: =ROUND(ABS(淡江大學_p4_2!G40),0) -> 0 | H7: =ROUND(ABS(淡江大學_p4_2!H40),0) -> 0 | I7: =ROUND(ABS(淡江大學_p4_2!I40),0) -> 0 | J7: =ROUND(ABS(淡江大學_p4_2!J40),0) -> 0 | K7: =ROUND(ABS(淡江大學_p4_2!K40),0) -> 0 | ... W7: =ROUND(ABS(淡江大學_p4_2!W40),0) -> 0
B8: 淡江大學 | D8: =ROUND(ABS(淡江大學_p4_1!D40),0) -> 0 | E8: =ROUND(ABS(淡江大學_p4_1!E40),0) -> 0 | F8: =ROUND(ABS(淡江大學_p4_1!F40),0) -> 0 | G8: =ROUND(ABS(淡江大學_p4_1!G40),0) -> 0 | H8: =ROUND(ABS(淡江大學_p4_1!H40),0) -> 0 | I8: =ROUND(ABS(淡江大學_p4_1!I40),0) -> 0 | J8: =ROUND(ABS(淡江大學_p4_1!J40),0) -> 0 | K8: =ROUND(ABS(淡江大學_p4_1!K40),0) -> 0 | ... W8: =ROUND(ABS(淡江大學_p4_1!W40),0) -> 0
B9: 淡江大學 | D9: =ROUND(ABS(淡江大學_p4!D40),0) -> 0 | E9: =ROUND(ABS(淡江大學_p4!E40),0) -> 0 | F9: =ROUND(ABS(淡江大學_p4!F40),0) -> 0 | G9: =ROUND(ABS(淡江大學_p4!G40),0) -> 0 | H9: =ROUND(ABS(淡江大學_p4!H40),0) -> 0 | I9: =ROUND(ABS(淡江大學_p4!I40),0) -> 0 | J9: =ROUND(ABS(淡江大學_p4!J40),0) -> 0 | K9: =ROUND(ABS(淡江大學_p4!K40),0) -> 0 | ... W9: =ROUND(ABS(淡江大學_p4!W40),0) -> 0
B10: 淡江大學 | D10: =ROUND(ABS(淡江大學_p6!D40),0) -> 0 | E10: =ROUND(ABS(淡江大學_p6!E40),0) -> 0 | F10: =ROUND(ABS(淡江大學_p6!F40),0) -> 0 | G10: =ROUND(ABS(淡江大學_p6!G40),0) -> 0 | H10: =ROUND(ABS(淡江大學_p6!H40),0) -> 0 | I10: =ROUND(ABS(淡江大學_p6!I40),0) -> 0 | J10: =ROUND(ABS(淡江大學_p6!J40),0) -> 0 | K10: =ROUND(ABS(淡江大學_p6!K40),0) -> 0 | ... W10: =ROUND(ABS(淡江大學_p6!W40),0) -> 0
B11: 淡江大學 | D11: =ROUND(ABS(淡江大學_p3!D40),0) -> 0 | E11: =ROUND(ABS(淡江大學_p3!E40),0) -> 0 | F11: =ROUND(ABS(淡江大學_p3!F40),0) -> 0 | G11: =ROUND(ABS(淡江大學_p3!G40),0) -> 0 | H11: =ROUND(ABS(淡江大學_p3!H40),0) -> 0 | I11: =ROUND(ABS(淡江大學_p3!I40),0) -> 0 | J11: =ROUND(ABS(淡江大學_p3!J40),0) -> 0 | K11: =ROUND(ABS(淡江大學_p3!K40),0) -> 0 | ... W11: =ROUND(ABS(淡江大學_p3!W40),0) -> 0
B12: 淡江大學 | D12: =ROUND(ABS(淡江大學_p4_3!D40),0) -> 541532 | E12: =ROUND(ABS(淡江大學_p4_3!E40),0) -> 539344 | F12: =ROUND(ABS(淡江大學_p4_3!F40),0) -> 537156 | G12: =ROUND(ABS(淡江大學_p4_3!G40),0) -> 534968 | H12: =ROUND(ABS(淡江大學_p4_3!H40),0) -> 532780 | I12: =ROUND(ABS(淡江大學_p4_3!I40),0) -> 530592 | J12: =ROUND(ABS(淡江大學_p4_3!J40),0) -> 528404 | K12: =ROUND(ABS(淡江大學_p4_3!K40),0) -> 526216 | ... W12: =ROUND(ABS(淡江大學_p4_3!W40),0) -> 499960
B13: 淡江大學 | D13: =ROUND(ABS(淡江大學_p3_1!D40),0) -> 541532 | E13: =ROUND(ABS(淡江大學_p3_1!E40),0) -> 539344 | F13: =ROUND(ABS(淡江大學_p3_1!F40),0) -> 537156 | G13: =ROUND(ABS(淡江大學_p3_1!G40),0) -> 534968 | H13: =ROUND(ABS(淡江大學_p3_1!H40),0) -> 532780 | I13: =ROUND(ABS(淡江大學_p3_1!I40),0) -> 530592 | J13: =ROUND(ABS(淡江大學_p3_1!J40),0) -> 528404 | K13: =ROUND(ABS(淡江大學_p3_1!K40),0) -> 526216 | ... W13: =ROUND(ABS(淡江大學_p3_1!W40),0) -> 499960
B14: 淡江大學 | D14: =ROUND(ABS(淡江大學_p5!D40),0) -> 541532 | E14: =ROUND(ABS(淡江大學_p5!E40),0) -> 539344 | F14: =ROUND(ABS(淡江大學_p5!F40),0) -> 537156 | G14: =ROUND(ABS(淡江大學_p5!G40),0) -> 534968 | H14: =ROUND(ABS(淡江大學_p5!H40),0) -> 532780 | I14: =ROUND(ABS(淡江大學_p5!I40),0) -> 530592 | J14: =ROUND(ABS(淡江大學_p5!J40),0) -> 528404 | K14: =ROUND(ABS(淡江大學_p5!K40),0) -> 526216 | ... W14: =ROUND(ABS(淡江大學_p5!W40),0) -> 499960
C15: 預估發電度數/年總計 | D15: =SUM(D6:D14) -> 1624596 | E15: =SUM(E6:E14) -> 1618032 | F15: =SUM(F6:F14) -> 1611468 | G15: =SUM(G6:G14) -> 1604904 | H15: =SUM(H6:H14) -> 1598340 | I15: =SUM(I6:I14) -> 1591776 | J15: =SUM(J6:J14) -> 1585212 | K15: =SUM(K6:K14) -> 1578648 | ... W15: =SUM(W6:W14) -> 1499880
C16: 年份 | D16: 2020 | E16: 2021 | F16: 2022 | G16: 2023 | H16: 2024 | I16: 2025 | J16: 2026 | K16: 2027 | L16: 2028 | M16: 2029 | N16: 2030 | O16: 2031 | P16: 2032 | Q16: 2033 | R16: 2034 | S16: 2035 | T16: 2036 | U16: 2037 | V16: 2038 | W16: 2039
C17: 預估收入
B18: 淡江大學 | D18: =ROUND(ABS(淡江大學_p6_1!D41),0) -> 0 | E18: =ROUND(ABS(淡江大學_p6_1!E41),0) -> 0 | F18: =ROUND(ABS(淡江大學_p6_1!F41),0) -> 0 | G18: =ROUND(ABS(淡江大學_p6_1!G41),0) -> 0 | H18: =ROUND(ABS(淡江大學_p6_1!H41),0) -> 0 | I18: =ROUND(ABS(淡江大學_p6_1!I41),0) -> 0 | J18: =ROUND(ABS(淡江大學_p6_1!J41),0) -> 0 | K18: =ROUND(ABS(淡江大學_p6_1!K41),0) -> 0 | ... W18: =ROUND(ABS(淡江大學_p6_1!W41),0) -> 0
B19: 淡江大學 | D19: =ROUND(ABS(淡江大學_p4_2!D41),0) -> 0 | E19: =ROUND(ABS(淡江大學_p4_2!E41),0) -> 0 | F19: =ROUND(ABS(淡江大學_p4_2!F41),0) -> 0 | G19: =ROUND(ABS(淡江大學_p4_2!G41),0) -> 0 | H19: =ROUND(ABS(淡江大學_p4_2!H41),0) -> 0 | I19: =ROUND(ABS(淡江大學_p4_2!I41),0) -> 0 | J19: =ROUND(ABS(淡江大學_p4_2!J41),0) -> 0 | K19: =ROUND(ABS(淡江大學_p4_2!K41),0) -> 0 | ... W19: =ROUND(ABS(淡江大學_p4_2!W41),0) -> 0
B20: 淡江大學 | D20: =ROUND(ABS(淡江大學_p4_1!D41),0) -> 0 | E20: =ROUND(ABS(淡江大學_p4_1!E41),0) -> 0 | F20: =ROUND(ABS(淡江大學_p4_1!F41),0) -> 0 | G20: =ROUND(ABS(淡江大學_p4_1!G41),0) -> 0 | H20: =ROUND(ABS(淡江大學_p4_1!H41),0) -> 0 | I20: =ROUND(ABS(淡江大學_p4_1!I41),0) -> 0 | J20: =ROUND(ABS(淡江大學_p4_1!J41),0) -> 0 | K20: =ROUND(ABS(淡江大學_p4_1!K41),0) -> 0 | ... W20: =ROUND(ABS(淡江大學_p4_1!W41),0) -> 0
B21: 淡江大學 | D21: =ROUND(ABS(淡江大學_p4!D41),0) -> 0 | E21: =ROUND(ABS(淡江大學_p4!E41),0) -> 0 | F21: =ROUND(ABS(淡江大學_p4!F41),0) -> 0 | G21: =ROUND(ABS(淡江大學_p4!G41),0) -> 0 | H21: =ROUND(ABS(淡江大學_p4!H41),0) -> 0 | I21: =ROUND(ABS(淡江大學_p4!I41),0) -> 0 | J21: =ROUND(ABS(淡江大學_p4!J41),0) -> 0 | K21: =ROUND(ABS(淡江大學_p4!K41),0) -> 0 | ... W21: =ROUND(ABS(淡江大學_p4!W41),0) -> 0
B22: 淡江大學 | D22: =ROUND(ABS(淡江大學_p6!D41),0) -> 0 | E22: =ROUND(ABS(淡江大學_p6!E41),0) -> 0 | F22: =ROUND(ABS(淡江大學_p6!F41),0) -> 0 | G22: =ROUND(ABS(淡江大學_p6!G41),0) -> 0 | H22: =ROUND(ABS(淡江大學_p6!H41),0) -> 0 | I22: =ROUND(ABS(淡江大學_p6!I41),0) -> 0 | J22: =ROUND(ABS(淡江大學_p6!J41),0) -> 0 | K22: =ROUND(ABS(淡江大學_p6!K41),0) -> 0 | ... W22: =ROUND(ABS(淡江大學_p6!W41),0) -> 0
B23: 淡江大學 | D23: =ROUND(ABS(淡江大學_p3!D41),0) -> 0 | E23: =ROUND(ABS(淡江大學_p3!E41),0) -> 0 | F23: =ROUND(ABS(淡江大學_p3!F41),0) -> 0 | G23: =ROUND(ABS(淡江大學_p3!G41),0) -> 0 | H23: =ROUND(ABS(淡江大學_p3!H41),0) -> 0 | I23: =ROUND(ABS(淡江大學_p3!I41),0) -> 0 | J23: =ROUND(ABS(淡江大學_p3!J41),0) -> 0 | K23: =ROUND(ABS(淡江大學_p3!K41),0) -> 0 | ... W23: =ROUND(ABS(淡江大學_p3!W41),0) -> 0
B24: 淡江大學 | D24: =ROUND(ABS(淡江大學_p4_3!D41),0) -> 2166128 | E24: =ROUND(ABS(淡江大學_p4_3!E41),0) -> 2157376 | F24: =ROUND(ABS(淡江大學_p4_3!F41),0) -> 2148624 | G24: =ROUND(ABS(淡江大學_p4_3!G41),0) -> 2139872 | H24: =ROUND(ABS(淡江大學_p4_3!H41),0) -> 2131120 | I24: =ROUND(ABS(淡江大學_p4_3!I41),0) -> 2122368 | J24: =ROUND(ABS(淡江大學_p4_3!J41),0) -> 2113616 | K24: =ROUND(ABS(淡江大學_p4_3!K41),0) -> 2104864 | ... W24: =ROUND(ABS(淡江大學_p4_3!W41),0) -> 1999839
B25: 淡江大學 | D25: =ROUND(ABS(淡江大學_p3_1!D41),0) -> 2166128 | E25: =ROUND(ABS(淡江大學_p3_1!E41),0) -> 2157376 | F25: =ROUND(ABS(淡江大學_p3_1!F41),0) -> 2148624 | G25: =ROUND(ABS(淡江大學_p3_1!G41),0) -> 2139872 | H25: =ROUND(ABS(淡江大學_p3_1!H41),0) -> 2131120 | I25: =ROUND(ABS(淡江大學_p3_1!I41),0) -> 2122368 | J25: =ROUND(ABS(淡江大學_p3_1!J41),0) -> 2113616 | K25: =ROUND(ABS(淡江大學_p3_1!K41),0) -> 2104864 | ... W25: =ROUND(ABS(淡江大學_p3_1!W41),0) -> 1999839
B26: 淡江大學 | D26: =ROUND(ABS(淡江大學_p5!D41),0) -> 2166128 | E26: =ROUND(ABS(淡江大學_p5!E41),0) -> 2157376 | F26: =ROUND(ABS(淡江大學_p5!F41),0) -> 2148624 | G26: =ROUND(ABS(淡江大學_p5!G41),0) -> 2139872 | H26: =ROUND(ABS(淡江大學_p5!H41),0) -> 2131120 | I26: =ROUND(ABS(淡江大學_p5!I41),0) -> 2122368 | J26: =ROUND(ABS(淡江大學_p5!J41),0) -> 2113616 | K26: =ROUND(ABS(淡江大學_p5!K41),0) -> 2104864 | ... W26: =ROUND(ABS(淡江大學_p5!W41),0) -> 1999839
C27: 預估收入/年總計 | D27: =SUM(D18:D26) -> 6498384 | E27: =SUM(E18:E26) -> 6472128 | F27: =SUM(F18:F26) -> 6445872 | G27: =SUM(G18:G26) -> 6419616 | H27: =SUM(H18:H26) -> 6393360 | I27: =SUM(I18:I26) -> 6367104 | J27: =SUM(J18:J26) -> 6340848 | K27: =SUM(K18:K26) -> 6314592 | ... W27: =SUM(W18:W26) -> 5999517
C28: 年份 | D28: 2020 | E28: 2021 | F28: 2022 | G28: 2023 | H28: 2024 | I28: 2025 | J28: 2026 | K28: 2027 | L28: 2028 | M28: 2029 | N28: 2030 | O28: 2031 | P28: 2032 | Q28: 2033 | R28: 2034 | S28: 2035 | T28: 2036 | U28: 2037 | V28: 2038 | W28: 2039
C29: 租金
B30: 淡江大學 | D30: =ROUND(ABS(淡江大學_p6_1!D45),0) -> 290201 | E30: =ROUND(ABS(淡江大學_p6_1!E45),0) -> 290201 | F30: =ROUND(ABS(淡江大學_p6_1!F45),0) -> 290201 | G30: =ROUND(ABS(淡江大學_p6_1!G45),0) -> 290201 | H30: =ROUND(ABS(淡江大學_p6_1!H45),0) -> 290201 | I30: =ROUND(ABS(淡江大學_p6_1!I45),0) -> 290201 | J30: =ROUND(ABS(淡江大學_p6_1!J45),0) -> 290201 | K30: =ROUND(ABS(淡江大學_p6_1!K45),0) -> 290201 | ... W30: =ROUND(ABS(淡江大學_p6_1!W45),0) -> 290201
B31: 淡江大學 | D31: =ROUND(ABS(淡江大學_p4_2!D45),0) -> 290201 | E31: =ROUND(ABS(淡江大學_p4_2!E45),0) -> 290201 | F31: =ROUND(ABS(淡江大學_p4_2!F45),0) -> 290201 | G31: =ROUND(ABS(淡江大學_p4_2!G45),0) -> 290201 | H31: =ROUND(ABS(淡江大學_p4_2!H45),0) -> 290201 | I31: =ROUND(ABS(淡江大學_p4_2!I45),0) -> 290201 | J31: =ROUND(ABS(淡江大學_p4_2!J45),0) -> 290201 | K31: =ROUND(ABS(淡江大學_p4_2!K45),0) -> 290201 | ... W31: =ROUND(ABS(淡江大學_p4_2!W45),0) -> 290201
B32: 淡江大學 | D32: =ROUND(ABS(淡江大學_p4_1!D45),0) -> 290201 | E32: =ROUND(ABS(淡江大學_p4_1!E45),0) -> 290201 | F32: =ROUND(ABS(淡江大學_p4_1!F45),0) -> 290201 | G32: =ROUND(ABS(淡江大學_p4_1!G45),0) -> 290201 | H32: =ROUND(ABS(淡江大學_p4_1!H45),0) -> 290201 | I32: =ROUND(ABS(淡江大學_p4_1!I45),0) -> 290201 | J32: =ROUND(ABS(淡江大學_p4_1!J45),0) -> 290201 | K32: =ROUND(ABS(淡江大學_p4_1!K45),0) -> 290201 | ... W32: =ROUND(ABS(淡江大學_p4_1!W45),0) -> 290201
B33: 淡江大學 | D33: =ROUND(ABS(淡江大學_p4!D45),0) -> 290201 | E33: =ROUND(ABS(淡江大學_p4!E45),0) -> 290201 | F33: =ROUND(ABS(淡江大學_p4!F45),0) -> 290201 | G33: =ROUND(ABS(淡江大學_p4!G45),0) -> 290201 | H33: =ROUND(ABS(淡江大學_p4!H45),0) -> 290201 | I33: =ROUND(ABS(淡江大學_p4!I45),0) -> 290201 | J33: =ROUND(ABS(淡江大學_p4!J45),0) -> 290201 | K33: =ROUND(ABS(淡江大學_p4!K45),0) -> 290201 | ... W33: =ROUND(ABS(淡江大學_p4!W45),0) -> 290201
B34: 淡江大學 | D34: =ROUND(ABS(淡江大學_p6!D45),0) -> 290201 | E34: =ROUND(ABS(淡江大學_p6!E45),0) -> 290201 | F34: =ROUND(ABS(淡江大學_p6!F45),0) -> 290201 | G34: =ROUND(ABS(淡江大學_p6!G45),0) -> 290201 | H34: =ROUND(ABS(淡江大學_p6!H45),0) -> 290201 | I34: =ROUND(ABS(淡江大學_p6!I45),0) -> 290201 | J34: =ROUND(ABS(淡江大學_p6!J45),0) -> 290201 | K34: =ROUND(ABS(淡江大學_p6!K45),0) -> 290201 | ... W34: =ROUND(ABS(淡江大學_p6!W45),0) -> 290201
B35: 淡江大學 | D35: =ROUND(ABS(淡江大學_p3!D45),0) -> 290201 | E35: =ROUND(ABS(淡江大學_p3!E45),0) -> 290201 | F35: =ROUND(ABS(淡江大學_p3!F45),0) -> 290201 | G35: =ROUND(ABS(淡江大學_p3!G45),0) -> 290201 | H35: =ROUND(ABS(淡江大學_p3!H45),0) -> 290201 | I35: =ROUND(ABS(淡江大學_p3!I45),0) -> 290201 | J35: =ROUND(ABS(淡江大學_p3!J45),0) -> 290201 | K35: =ROUND(ABS(淡江大學_p3!K45),0) -> 290201 | ... W35: =ROUND(ABS(淡江大學_p3!W45),0) -> 290201
B36: 淡江大學 | D36: =ROUND(ABS(淡江大學_p4_3!D45),0) -> 290201 | E36: =ROUND(ABS(淡江大學_p4_3!E45),0) -> 290201 | F36: =ROUND(ABS(淡江大學_p4_3!F45),0) -> 290201 | G36: =ROUND(ABS(淡江大學_p4_3!G45),0) -> 290201 | H36: =ROUND(ABS(淡江大學_p4_3!H45),0) -> 290201 | I36: =ROUND(ABS(淡江大學_p4_3!I45),0) -> 290201 | J36: =ROUND(ABS(淡江大學_p4_3!J45),0) -> 290201 | K36: =ROUND(ABS(淡江大學_p4_3!K45),0) -> 290201 | ... W36: =ROUND(ABS(淡江大學_p4_3!W45),0) -> 290201
B37: 淡江大學 | D37: =ROUND(ABS(淡江大學_p3_1!D45),0) -> 290201 | E37: =ROUND(ABS(淡江大學_p3_1!E45),0) -> 290201 | F37: =ROUND(ABS(淡江大學_p3_1!F45),0) -> 290201 | G37: =ROUND(ABS(淡江大學_p3_1!G45),0) -> 290201 | H37: =ROUND(ABS(淡江大學_p3_1!H45),0) -> 290201 | I37: =ROUND(ABS(淡江大學_p3_1!I45),0) -> 290201 | J37: =ROUND(ABS(淡江大學_p3_1!J45),0) -> 290201 | K37: =ROUND(ABS(淡江大學_p3_1!K45),0) -> 290201 | ... W37: =ROUND(ABS(淡江大學_p3_1!W45),0) -> 290201
B38: 淡江大學 | D38: =ROUND(ABS(淡江大學_p5!D45),0) -> 290201 | E38: =ROUND(ABS(淡江大學_p5!E45),0) -> 290201 | F38: =ROUND(ABS(淡江大學_p5!F45),0) -> 290201 | G38: =ROUND(ABS(淡江大學_p5!G45),0) -> 290201 | H38: =ROUND(ABS(淡江大學_p5!H45),0) -> 290201 | I38: =ROUND(ABS(淡江大學_p5!I45),0) -> 290201 | J38: =ROUND(ABS(淡江大學_p5!J45),0) -> 290201 | K38: =ROUND(ABS(淡江大學_p5!K45),0) -> 290201 | ... W38: =ROUND(ABS(淡江大學_p5!W45),0) -> 290201
C39: 租金/年總計 | D39: =SUM(D30:D38) -> 2611809 | E39: =SUM(E30:E38) -> 2611809 | F39: =SUM(F30:F38) -> 2611809 | G39: =SUM(G30:G38) -> 2611809 | H39: =SUM(H30:H38) -> 2611809 | I39: =SUM(I30:I38) -> 2611809 | J39: =SUM(J30:J38) -> 2611809 | K39: =SUM(K30:K38) -> 2611809 | ... W39: =SUM(W30:W38) -> 2611809
C40: 年份 | D40: 2020 | E40: 2021 | F40: 2022 | G40: 2023 | H40: 2024 | I40: 2025 | J40: 2026 | K40: 2027 | L40: 2028 | M40: 2029 | N40: 2030 | O40: 2031 | P40: 2032 | Q40: 2033 | R40: 2034 | S40: 2035 | T40: 2036 | U40: 2037 | V40: 2038 | W40: 2039
C41: 運維
B42: 淡江大學 | D42: =ROUND(ABS(淡江大學_p6_1!D48),0) -> 174440 | E42: =ROUND(ABS(淡江大學_p6_1!E48),0) -> 174440 | F42: =ROUND(ABS(淡江大學_p6_1!F48),0) -> 174440 | G42: =ROUND(ABS(淡江大學_p6_1!G48),0) -> 174440 | H42: =ROUND(ABS(淡江大學_p6_1!H48),0) -> 174440 | I42: =ROUND(ABS(淡江大學_p6_1!I48),0) -> 174440 | J42: =ROUND(ABS(淡江大學_p6_1!J48),0) -> 174440 | K42: =ROUND(ABS(淡江大學_p6_1!K48),0) -> 174440 | ... W42: =ROUND(ABS(淡江大學_p6_1!W48),0) -> 174440
B43: 淡江大學 | D43: =ROUND(ABS(淡江大學_p4_2!D48),0) -> 174440 | E43: =ROUND(ABS(淡江大學_p4_2!E48),0) -> 174440 | F43: =ROUND(ABS(淡江大學_p4_2!F48),0) -> 174440 | G43: =ROUND(ABS(淡江大學_p4_2!G48),0) -> 174440 | H43: =ROUND(ABS(淡江大學_p4_2!H48),0) -> 174440 | I43: =ROUND(ABS(淡江大學_p4_2!I48),0) -> 174440 | J43: =ROUND(ABS(淡江大學_p4_2!J48),0) -> 174440 | K43: =ROUND(ABS(淡江大學_p4_2!K48),0) -> 174440 | ... W43: =ROUND(ABS(淡江大學_p4_2!W48),0) -> 174440
...

Sheet 淡江大學_p3
A1: 電站基本資料(請填寫著色處) | E1: 說明 | O1: =1-C11 -> 0.99 | P1: =O1-$C12 -> 0.986 | Q1: =P1-$C12 -> 0.982 | R1: =Q1-$C12 -> 0.978 | S1: =R1-$C12 -> 0.974 | T1: =S1-$C12 -> 0.97 | U1: =T1-$C12 -> 0.966 | V1: =U1-$C12 -> 0.962 | W1: =V1-$C12 -> 0.958 | ... AH1: =AG1-$C12 -> 0.914
A2: 電站名稱 | B2: 淡江大學 | C2: 淡江大學 | D2: - | E2: 填入本案場名稱
A3: 電站壽命 | B3: 20 | C3: 20 | D3: - | E3: 預設 20 年，代表財務評估年期。若合約年限不同可依實際情況修改
A4: 建置量(kWp) | B4: 436.1 | C4: 436.1 | D4: - | E4: 填入裝置容量（kWp），通常由設計圖面或報價書取得 | M4: 情境編號: 3
A5: 起始年度 | B5: 2020 | C5: 2020 | D5: =B5+B3-1 -> 2039 | E5: 2039 | M5: 第2次滾算摘要
M6: 價金: 31000
A7: 綜合損益表(請填寫著色處) | M7: 專案IRR: 3.75
A8: 收入 | M8: 權益法IRR: 8.21
A9: 收支項目 | B9: 相關參數 | C9: 參數數值 | D9: 年限 | E9: 說明 | M9: 利潤率: 30.00%
A10: 電費收入 | B10: 年度AC併網總發電量 | C10: 547002 | D10: 547002 | E10: 20 | M10: 第2次滾算，減少 2000 元 - 現金模式，每次減少 2000 元
B11: 首年衰退率 | C11: 0.01 | E11: 第一年發電衰退比率，請填小數（例：1% → 填 0.01）。一般首年衰退約 1~2%(請參考模組規格書)
B12: 次年衰退率 | C12: 0.004 | E12: 第二年起每年固定衰退比率，請填小數（例：0.4% → 填 0.004）。一般約 0.4~0.7%(請參考模組規格書)
B13: 躉售費率(FIT) / 綠電費率 | C13: 4 | E13: 與台電簽訂的躉購費率或綠電合約費率，單位：元/度。請參考台電公告或合約內容
A14: 支出(請填寫著色處)
A15: 收支項目 | B15: 相關參數 | C15: 參數數值 | D15: 攤提年限 | E15: 說明
A16: 設備費用(價金) | B16: 每kWp設備成本 | C16: 35000 | D16: 31000 | E16: 20
B17: 信邦利潤率(ex:20%填0.2) | C17: 0.3 | E17: 公司在設備費用上加計的利潤比率，請填小數（例：20% → 填 0.2）
B18: 開發費 | C18: 2000 | E18: 前期開發費用（元），含可行性評估、申請規費、地主溝通等。若無則填 0
A19: 租金費用 | B19: 租金計算方式 | C19: 1 | D19: 1 | E19: 0
B20: 【方式1參數】每年相同價格 | C20: 290201 | D20: 290201 | E20: 20
B21: 【方式2參數】抽成比率 | D21: 0 | E21: 0
A22: 運維費用 | B22: 每kw運維成本 | C22: 400 | D22: 400 | E22: 20
A23: 保險費用 | B23: 占整體設備費用比例 | C23: 0.003 | D23: 0.003 | E23: 20
A24: 模組回收費用 | B24: 每kw模組回收成本 | C24: 1000 | D24: 1000 | E24: 10
A25: 利息費用 | B25: 銀行利率 | C25: 0.0256 | D25: 0.0256 | E25: 0
A26: 所得稅 | B26: 所得稅率 | C26: 0.2 | D26: 0.2 | E26: 0
A29: 現金流量表(請填寫著色處)
A30: 金流項目 | B30: 相關參數 | C30: 參數數值 | E30: 說明
A31: 貸款成數 | B31: 占總設備費用比例 | C31: 0.8 | D31: 0.8 | E31: 貸款佔設備總費用比例，填小數（例：80% → 填 0.8）。預設 0.8 代表貸八成、自備二成
A32: 貸款還款 | B32: 攤還期數 | C32: 15 | D32: 15 | E32: 貸款還款年數（年）。預設 15 年，代表分 15 年平均攤還本金
A33: 現金股利 | B33: 股利比率 | C33: 0.9 | D33: 0.9 | E33: 稅後現金流中分配給股東的比例，填小數（例：90% → 填 0.9）
A34: 年底減資 | B34: 攤還期數 | C34: 4 | D34: 4 | E34: 年底減資返還股東的年數。預設 4 年，代表 倒數 4 年進行減資，加速資金返還
D37: 2020 | E37: 2021 | F37: 2022 | G37: 2023 | H37: 2024 | I37: 2025 | J37: 2026 | K37: 2027 | L37: 2028 | M37: 2029 | N37: 2030 | O37: 2031 | P37: 2032 | Q37: 2033 | R37: 2034 | S37: 2035 | T37: 2036 | U37: 2037 | V37: 2038 | W37: 2039
D45: -290201 | E45: -290201 | F45: -290201 | G45: -290201 | H45: -290201 | I45: -290201 | J45: -290201 | K45: -290201 | L45: -290201 | M45: -290201 | N45: -290201 | O45: -290201 | P45: -290201 | Q45: -290201 | R45: -290201 | S45: -290201 | T45: -290201 | U45: -290201 | V45: -290201 | W45: -290201
D48: -174440 | E48: -174440 | F48: -174440 | G48: -174440 | H48: -174440 | I48: -174440 | J48: -174440 | K48: -174440 | L48: -174440 | M48: -174440 | N48: -174440 | O48: -174440 | P48: -174440 | Q48: -174440 | R48: -174440 | S48: -174440 | T48: -174440 | U48: -174440 | V48: -174440 | W48: -174440
D49: -40557.3 | E49: -40557.3 | F49: -40557.3 | G49: -40557.3 | H49: -40557.3 | I49: -40557.3 | J49: -40557.3 | K49: -40557.3 | L49: -40557.3 | M49: -40557.3 | N49: -40557.3 | O49: -40557.3 | P49: -40557.3 | Q49: -40557.3 | R49: -40557.3 | S49: -40557.3 | T49: -40557.3 | U49: -40557.3 | V49: -40557.3 | W49: -40557.3
D50: -43610 | E50: -43610 | F50: -43610 | G50: -43610 | H50: -43610 | I50: -43610 | J50: -43610 | K50: -43610 | L50: -43610 | M50: -43610 | N50: 0 | O50: 0 | P50: 0 | Q50: 0 | R50: 0 | S50: 0 | T50: 0 | U50: 0 | V50: 0 | W50: 0
D54: =D77 -> 0 | E54: =E77 -> 0 | F54: =F77 -> 0 | G54: =G77 -> 0 | H54: =H77 -> 0 | I54: =I77 -> 0 | J54: =J77 -> 0 | K54: =K77 -> 0 | ... W54: =W77 -> 0
D70: 0 | E70: 0 | F70: 0 | G70: 0 | H70: 0 | I70: 0 | J70: 0 | K70: 0 | L70: 0 | M70: 0 | N70: 0 | O70: 0 | P70: 0 | Q70: 0 | R70: 0 | S70: 0 | T70: 0 | U70: 0 | V70: 0 | W70: 0

Sheet 淡江大學_p6
A1: 電站基本資料(請填寫著色處) | E1: 說明 | O1: =1-C11 -> 0.99 | P1: =O1-$C12 -> 0.986 | Q1: =P1-$C12 -> 0.982 | R1: =Q1-$C12 -> 0.978 | S1: =R1-$C12 -> 0.974 | T1: =S1-$C12 -> 0.97 | U1: =T1-$C12 -> 0.966 | V1: =U1-$C12 -> 0.962 | W1: =V1-$C12 -> 0.958 | ... AH1: =AG1-$C12 -> 0.914
A2: 電站名稱 | B2: 淡江大學 | C2: 淡江大學 | D2: - | E2: 填入本案場名稱
A3: 電站壽命 | B3: 20 | C3: 20 | D3: - | E3: 預設 20 年，代表財務評估年期。若合約年限不同可依實際情況修改
A4: 建置量(kWp) | B4: 436.1 | C4: 436.1 | D4: - | E4: 填入裝置容量（kWp），通常由設計圖面或報價書取得 | M4: 情境編號: 6
A5: 起始年度 | B5: 2020 | C5: 2020 | D5: =B5+B3-1 -> 2039 | E5: 2039 | M5: 第5次滾算摘要
M6: 價金: 25000
A7: 綜合損益表(請填寫著色處) | M7: 專案IRR: 5.91
A8: 收入 | M8: 權益法IRR: 17.0
A9: 收支項目 | B9: 相關參數 | C9: 參數數值 | D9: 年限 | E9: 說明 | M9: 利潤率: 30.00%
A10: 電費收入 | B10: 年度AC併網總發電量 | C10: 547002 | D10: 547002 | E10: 20 | M10: 第5次滾算，減少 2000 元 - 現金模式，每次減少 2000 元
B11: 首年衰退率 | C11: 0.01 | E11: 第一年發電衰退比率，請填小數（例：1% → 填 0.01）。一般首年衰退約 1~2%(請參考模組規格書)
B12: 次年衰退率 | C12: 0.004 | E12: 第二年起每年固定衰退比率，請填小數（例：0.4% → 填 0.004）。一般約 0.4~0.7%(請參考模組規格書)
B13: 躉售費率(FIT) / 綠電費率 | C13: 4 | E13: 與台電簽訂的躉購費率或綠電合約費率，單位：元/度。請參考台電公告或合約內容
A14: 支出(請填寫著色處)
A15: 收支項目 | B15: 相關參數 | C15: 參數數值 | D15: 攤提年限 | E15: 說明
A16: 設備費用(價金) | B16: 每kWp設備成本 | C16: 35000 | D16: 25000 | E16: 20
B17: 信邦利潤率(ex:20%填0.2) | C17: 0.3 | E17: 公司在設備費用上加計的利潤比率，請填小數（例：20% → 填 0.2）
B18: 開發費 | C18: 2000 | E18: 前期開發費用（元），含可行性評估、申請規費、地主溝通等。若無則填 0
A19: 租金費用 | B19: 租金計算方式 | C19: 1 | D19: 1 | E19: 0
B20: 【方式1參數】每年相同價格 | C20: 290201 | D20: 290201 | E20: 20
B21: 【方式2參數】抽成比率 | D21: 0 | E21: 0
A22: 運維費用 | B22: 每kw運維成本 | C22: 400 | D22: 400 | E22: 20
A23: 保險費用 | B23: 占整體設備費用比例 | C23: 0.003 | D23: 0.003 | E23: 20
A24: 模組回收費用 | B24: 每kw模組回收成本 | C24: 1000 | D24: 1000 | E24: 10
A25: 利息費用 | B25: 銀行利率 | C25: 0.0256 | D25: 0.0256 | E25: 0
A26: 所得稅 | B26: 所得稅率 | C26: 0.2 | D26: 0.2 | E26: 0
A29: 現金流量表(請填寫著色處)
A30: 金流項目 | B30: 相關參數 | C30: 參數數值 | E30: 說明
A31: 貸款成數 | B31: 占總設備費用比例 | C31: 0.8 | D31: 0.8 | E31: 貸款佔設備總費用比例，填小數（例：80% → 填 0.8）。預設 0.8 代表貸八成、自備二成
A32: 貸款還款 | B32: 攤還期數 | C32: 15 | D32: 15 | E32: 貸款還款年數（年）。預設 15 年，代表分 15 年平均攤還本金
A33: 現金股利 | B33: 股利比率 | C33: 0.9 | D33: 0.9 | E33: 稅後現金流中分配給股東的比例，填小數（例：90% → 填 0.9）
A34: 年底減資 | B34: 攤還期數 | C34: 4 | D34: 4 | E34: 年底減資返還股東的年數。預設 4 年，代表 倒數 4 年進行減資，加速資金返還
D37: 2020 | E37: 2021 | F37: 2022 | G37: 2023 | H37: 2024 | I37: 2025 | J37: 2026 | K37: 2027 | L37: 2028 | M37: 2029 | N37: 2030 | O37: 2031 | P37: 2032 | Q37: 2033 | R37: 2034 | S37: 2035 | T37: 2036 | U37: 2037 | V37: 2038 | W37: 2039
D45: -290201 | E45: -290201 | F45: -290201 | G45: -290201 | H45: -290201 | I45: -290201 | J45: -290201 | K45: -290201 | L45: -290201 | M45: -290201 | N45: -290201 | O45: -290201 | P45: -290201 | Q45: -290201 | R45: -290201 | S45: -290201 | T45: -290201 | U45: -290201 | V45: -290201 | W45: -290201
D48: -174440 | E48: -174440 | F48: -174440 | G48: -174440 | H48: -174440 | I48: -174440 | J48: -174440 | K48: -174440 | L48: -174440 | M48: -174440 | N48: -174440 | O48: -174440 | P48: -174440 | Q48: -174440 | R48: -174440 | S48: -174440 | T48: -174440 | U48: -174440 | V48: -174440 | W48: -174440
D49: -32707.5 | E49: -32707.5 | F49: -32707.5 | G49: -32707.5 | H49: -32707.5 | I49: -32707.5 | J49: -32707.5 | K49: -32707.5 | L49: -32707.5 | M49: -32707.5 | N49: -32707.5 | O49: -32707.5 | P49: -32707.5 | Q49: -32707.5 | R49: -32707.5 | S49: -32707.5 | T49: -32707.5 | U49: -32707.5 | V49: -32707.5 | W49: -32707.5
D50: -43610 | E50: -43610 | F50: -43610 | G50: -43610 | H50: -43610 | I50: -43610 | J50: -43610 | K50: -43610 | L50: -43610 | M50: -43610 | N50: 0 | O50: 0 | P50: 0 | Q50: 0 | R50: 0 | S50: 0 | T50: 0 | U50: 0 | V50: 0 | W50: 0
D54: =D77 -> 0 | E54: =E77 -> 0 | F54: =F77 -> 0 | G54: =G77 -> 0 | H54: =H77 -> 0 | I54: =I77 -> 0 | J54: =J77 -> 0 | K54: =K77 -> 0 | ... W54: =W77 -> 0
D70: 0 | E70: 0 | F70: 0 | G70: 0 | H70: 0 | I70: 0 | J70: 0 | K70: 0 | L70: 0 | M70: 0 | N70: 0 | O70: 0 | P70: 0 | Q70: 0 | R70: 0 | S70: 0 | T70: 0 | U70: 0 | V70: 0 | W70: 0

Sheet 淡江大學_p4
A1: 電站基本資料(請填寫著色處) | E1: 說明 | O1: =1-C11 -> 0.99 | P1: =O1-$C12 -> 0.986 | Q1: =P1-$C12 -> 0.982 | R1: =Q1-$C12 -> 0.978 | S1: =R1-$C12 -> 0.974 | T1: =S1-$C12 -> 0.97 | U1: =T1-$C12 -> 0.966 | V1: =U1-$C12 -> 0.962 | W1: =V1-$C12 -> 0.958 | ... AH1: =AG1-$C12 -> 0.914
A2: 電站名稱 | B2: 淡江大學 | C2: 淡江大學 | D2: - | E2: 填入本案場名稱
A3: 電站壽命 | B3: 20 | C3: 20 | D3: - | E3: 預設 20 年，代表財務評估年期。若合約年限不同可依實際情況修改
A4: 建置量(kWp) | B4: 436.1 | C4: 436.1 | D4: - | E4: 填入裝置容量（kWp），通常由設計圖面或報價書取得 | M4: 情境編號: 4
A5: 起始年度 | B5: 2020 | C5: 2020 | D5: =B5+B3-1 -> 2039 | E5: 2039 | M5: 第3次滾算摘要
M6: 價金: 29000
A7: 綜合損益表(請填寫著色處) | M7: 專案IRR: 4.39
A8: 收入 | M8: 權益法IRR: 10.59
A9: 收支項目 | B9: 相關參數 | C9: 參數數值 | D9: 年限 | E9: 說明 | M9: 利潤率: 30.00%
A10: 電費收入 | B10: 年度AC併網總發電量 | C10: 547002 | D10: 547002 | E10: 20 | M10: 第3次滾算，減少 2000 元 - 現金模式，每次減少 2000 元
B11: 首年衰退率 | C11: 0.01 | E11: 第一年發電衰退比率，請填小數（例：1% → 填 0.01）。一般首年衰退約 1~2%(請參考模組規格書)
B12: 次年衰退率 | C12: 0.004 | E12: 第二年起每年固定衰退比率，請填小數（例：0.4% → 填 0.004）。一般約 0.4~0.7%(請參考模組規格書)
B13: 躉售費率(FIT) / 綠電費率 | C13: 4 | E13: 與台電簽訂的躉購費率或綠電合約費率，單位：元/度。請參考台電公告或合約內容
A14: 支出(請填寫著色處)
A15: 收支項目 | B15: 相關參數 | C15: 參數數值 | D15: 攤提年限 | E15: 說明
A16: 設備費用(價金) | B16: 每kWp設備成本 | C16: 35000 | D16: 29000 | E16: 20
B17: 信邦利潤率(ex:20%填0.2) | C17: 0.3 | E17: 公司在設備費用上加計的利潤比率，請填小數（例：20% → 填 0.2）
B18: 開發費 | C18: 2000 | E18: 前期開發費用（元），含可行性評估、申請規費、地主溝通等。若無則填 0
A19: 租金費用 | B19: 租金計算方式 | C19: 1 | D19: 1 | E19: 0
B20: 【方式1參數】每年相同價格 | C20: 290201 | D20: 290201 | E20: 20
B21: 【方式2參數】抽成比率 | D21: 0 | E21: 0
A22: 運維費用 | B22: 每kw運維成本 | C22: 400 | D22: 400 | E22: 20
A23: 保險費用 | B23: 占整體設備費用比例 | C23: 0.003 | D23: 0.003 | E23: 20
A24: 模組回收費用 | B24: 每kw模組回收成本 | C24: 1000 | D24: 1000 | E24: 10
A25: 利息費用 | B25: 銀行利率 | C25: 0.0256 | D25: 0.0256 | E25: 0
A26: 所得稅 | B26: 所得稅率 | C26: 0.2 | D26: 0.2 | E26: 0
A29: 現金流量表(請填寫著色處)
A30: 金流項目 | B30: 相關參數 | C30: 參數數值 | E30: 說明
A31: 貸款成數 | B31: 占總設備費用比例 | C31: 0.8 | D31: 0.8 | E31: 貸款佔設備總費用比例，填小數（例：80% → 填 0.8）。預設 0.8 代表貸八成、自備二成
A32: 貸款還款 | B32: 攤還期數 | C32: 15 | D32: 15 | E32: 貸款還款年數（年）。預設 15 年，代表分 15 年平均攤還本金
A33: 現金股利 | B33: 股利比率 | C33: 0.9 | D33: 0.9 | E33: 稅後現金流中分配給股東的比例，填小數（例：90% → 填 0.9）
A34: 年底減資 | B34: 攤還期數 | C34: 4 | D34: 4 | E34: 年底減資返還股東的年數。預設 4 年，代表 倒數 4 年進行減資，加速資金返還
D37: 2020 | E37: 2021 | F37: 2022 | G37: 2023 | H37: 2024 | I37: 2025 | J37: 2026 | K37: 2027 | L37: 2028 | M37: 2029 | N37: 2030 | O37: 2031 | P37: 2032 | Q37: 2033 | R37: 2034 | S37: 2035 | T37: 2036 | U37: 2037 | V37: 2038 | W37: 2039
D45: -290201 | E45: -290201 | F45: -290201 | G45: -290201 | H45: -290201 | I45: -290201 | J45: -290201 | K45: -290201 | L45: -290201 | M45: -290201 | N45: -290201 | O45: -290201 | P45: -290201 | Q45: -290201 | R45: -290201 | S45: -290201 | T45: -290201 | U45: -290201 | V45: -290201 | W45: -290201
D48: -174440 | E48: -174440 | F48: -174440 | G48: -174440 | H48: -174440 | I48: -174440 | J48: -174440 | K48: -174440 | L48: -174440 | M48: -174440 | N48: -174440 | O48: -174440 | P48: -174440 | Q48: -174440 | R48: -174440 | S48: -174440 | T48: -174440 | U48: -174440 | V48: -174440 | W48: -174440
D49: -37940.7 | E49: -37940.7 | F49: -37940.7 | G49: -37940.7 | H49: -37940.7 | I49: -37940.7 | J49: -37940.7 | K49: -37940.7 | L49: -37940.7 | M49: -37940.7 | N49: -37940.7 | O49: -37940.7 | P49: -37940.7 | Q49: -37940.7 | R49: -37940.7 | S49: -37940.7 | T49: -37940.7 | U49: -37940.7 | V49: -37940.7 | W49: -37940.7
D50: -43610 | E50: -43610 | F50: -43610 | G50: -43610 | H50: -43610 | I50: -43610 | J50: -43610 | K50: -43610 | L50: -43610 | M50: -43610 | N50: 0 | O50: 0 | P50: 0 | Q50: 0 | R50: 0 | S50: 0 | T50: 0 | U50: 0 | V50: 0 | W50: 0
D54: =D77 -> 0 | E54: =E77 -> 0 | F54: =F77 -> 0 | G54: =G77 -> 0 | H54: =H77 -> 0 | I54: =I77 -> 0 | J54: =J77 -> 0 | K54: =K77 -> 0 | ... W54: =W77 -> 0
D70: 0 | E70: 0 | F70: 0 | G70: 0 | H70: 0 | I70: 0 | J70: 0 | K70: 0 | L70: 0 | M70: 0 | N70: 0 | O70: 0 | P70: 0 | Q70: 0 | R70: 0 | S70: 0 | T70: 0 | U70: 0 | V70: 0 | W70: 0

Sheet 淡江大學_p4_1
A1: 電站基本資料(請填寫著色處) | E1: 說明 | O1: =1-C11 -> 0.99 | P1: =O1-$C12 -> 0.986 | Q1: =P1-$C12 -> 0.982 | R1: =Q1-$C12 -> 0.978 | S1: =R1-$C12 -> 0.974 | T1: =S1-$C12 -> 0.97 | U1: =T1-$C12 -> 0.966 | V1: =U1-$C12 -> 0.962 | W1: =V1-$C12 -> 0.958 | ... AH1: =AG1-$C12 -> 0.914
A2: 電站名稱 | B2: 淡江大學 | C2: 淡江大學 | D2: - | E2: 填入本案場名稱
A3: 電站壽命 | B3: 20 | C3: 20 | D3: - | E3: 預設 20 年，代表財務評估年期。若合約年限不同可依實際情況修改
A4: 建置量(kWp) | B4: 436.1 | C4: 436.1 | D4: - | E4: 填入裝置容量（kWp），通常由設計圖面或報價書取得 | M4: 情境編號: 4
A5: 起始年度 | B5: 2020 | C5: 2020 | D5: =B5+B3-1 -> 2039 | E5: 2039 | M5: 第3次滾算摘要
M6: 價金: 29000
A7: 綜合損益表(請填寫著色處) | M7: 專案IRR: 4.39
A8: 收入 | M8: 權益法IRR: 10.59
A9: 收支項目 | B9: 相關參數 | C9: 參數數值 | D9: 年限 | E9: 說明 | M9: 利潤率: 30.00%
A10: 電費收入 | B10: 年度AC併網總發電量 | C10: 547002 | D10: 547002 | E10: 20 | M10: 第3次滾算，減少 2000 元 - 現金模式，每次減少 2000 元
B11: 首年衰退率 | C11: 0.01 | E11: 第一年發電衰退比率，請填小數（例：1% → 填 0.01）。一般首年衰退約 1~2%(請參考模組規格書)
B12: 次年衰退率 | C12: 0.004 | E12: 第二年起每年固定衰退比率，請填小數（例：0.4% → 填 0.004）。一般約 0.4~0.7%(請參考模組規格書)
B13: 躉售費率(FIT) / 綠電費率 | C13: 4 | E13: 與台電簽訂的躉購費率或綠電合約費率，單位：元/度。請參考台電公告或合約內容
A14: 支出(請填寫著色處)
A15: 收支項目 | B15: 相關參數 | C15: 參數數值 | D15: 攤提年限 | E15: 說明
A16: 設備費用(價金) | B16: 每kWp設備成本 | C16: 35000 | D16: 29000 | E16: 20
B17: 信邦利潤率(ex:20%填0.2) | C17: 0.3 | E17: 公司在設備費用上加計的利潤比率，請填小數（例：20% → 填 0.2）
B18: 開發費 | C18: 2000 | E18: 前期開發費用（元），含可行性評估、申請規費、地主溝通等。若無則填 0
A19: 租金費用 | B19: 租金計算方式 | C19: 1 | D19: 1 | E19: 0
B20: 【方式1參數】每年相同價格 | C20: 290201 | D20: 290201 | E20: 20
B21: 【方式2參數】抽成比率 | D21: 0 | E21: 0
A22: 運維費用 | B22: 每kw運維成本 | C22: 400 | D22: 400 | E22: 20
A23: 保險費用 | B23: 占整體設備費用比例 | C23: 0.003 | D23: 0.003 | E23: 20
A24: 模組回收費用 | B24: 每kw模組回收成本 | C24: 1000 | D24: 1000 | E24: 10
A25: 利息費用 | B25: 銀行利率 | C25: 0.0256 | D25: 0.0256 | E25: 0
A26: 所得稅 | B26: 所得稅率 | C26: 0.2 | D26: 0.2 | E26: 0
A29: 現金流量表(請填寫著色處)
A30: 金流項目 | B30: 相關參數 | C30: 參數數值 | E30: 說明
A31: 貸款成數 | B31: 占總設備費用比例 | C31: 0.8 | D31: 0.8 | E31: 貸款佔設備總費用比例，填小數（例：80% → 填 0.8）。預設 0.8 代表貸八成、自備二成
A32: 貸款還款 | B32: 攤還期數 | C32: 15 | D32: 15 | E32: 貸款還款年數（年）。預設 15 年，代表分 15 年平均攤還本金
A33: 現金股利 | B33: 股利比率 | C33: 0.9 | D33: 0.9 | E33: 稅後現金流中分配給股東的比例，填小數（例：90% → 填 0.9）
A34: 年底減資 | B34: 攤還期數 | C34: 4 | D34: 4 | E34: 年底減資返還股東的年數。預設 4 年，代表 倒數 4 年進行減資，加速資金返還
D37: 2020 | E37: 2021 | F37: 2022 | G37: 2023 | H37: 2024 | I37: 2025 | J37: 2026 | K37: 2027 | L37: 2028 | M37: 2029 | N37: 2030 | O37: 2031 | P37: 2032 | Q37: 2033 | R37: 2034 | S37: 2035 | T37: 2036 | U37: 2037 | V37: 2038 | W37: 2039
D45: -290201 | E45: -290201 | F45: -290201 | G45: -290201 | H45: -290201 | I45: -290201 | J45: -290201 | K45: -290201 | L45: -290201 | M45: -290201 | N45: -290201 | O45: -290201 | P45: -290201 | Q45: -290201 | R45: -290201 | S45: -290201 | T45: -290201 | U45: -290201 | V45: -290201 | W45: -290201
D48: -174440 | E48: -174440 | F48: -174440 | G48: -174440 | H48: -174440 | I48: -174440 | J48: -174440 | K48: -174440 | L48: -174440 | M48: -174440 | N48: -174440 | O48: -174440 | P48: -174440 | Q48: -174440 | R48: -174440 | S48: -174440 | T48: -174440 | U48: -174440 | V48: -174440 | W48: -174440
D49: -37940.7 | E49: -37940.7 | F49: -37940.7 | G49: -37940.7 | H49: -37940.7 | I49: -37940.7 | J49: -37940.7 | K49: -37940.7 | L49: -37940.7 | M49: -37940.7 | N49: -37940.7 | O49: -37940.7 | P49: -37940.7 | Q49: -37940.7 | R49: -37940.7 | S49: -37940.7 | T49: -37940.7 | U49: -37940.7 | V49: -37940.7 | W49: -37940.7
D50: -43610 | E50: -43610 | F50: -43610 | G50: -43610 | H50: -43610 | I50: -43610 | J50: -43610 | K50: -43610 | L50: -43610 | M50: -43610 | N50: 0 | O50: 0 | P50: 0 | Q50: 0 | R50: 0 | S50: 0 | T50: 0 | U50: 0 | V50: 0 | W50: 0
D54: =D77 -> 0 | E54: =E77 -> 0 | F54: =F77 -> 0 | G54: =G77 -> 0 | H54: =H77 -> 0 | I54: =I77 -> 0 | J54: =J77 -> 0 | K54: =K77 -> 0 | ... W54: =W77 -> 0
D70: 0 | E70: 0 | F70: 0 | G70: 0 | H70: 0 | I70: 0 | J70: 0 | K70: 0 | L70: 0 | M70: 0 | N70: 0 | O70: 0 | P70: 0 | Q70: 0 | R70: 0 | S70: 0 | T70: 0 | U70: 0 | V70: 0 | W70: 0

Sheet 淡江大學_p4_2
A1: 電站基本資料(請填寫著色處) | E1: 說明 | O1: =1-C11 -> 0.99 | P1: =O1-$C12 -> 0.986 | Q1: =P1-$C12 -> 0.982 | R1: =Q1-$C12 -> 0.978 | S1: =R1-$C12 -> 0.974 | T1: =S1-$C12 -> 0.97 | U1: =T1-$C12 -> 0.966 | V1: =U1-$C12 -> 0.962 | W1: =V1-$C12 -> 0.958 | ... AH1: =AG1-$C12 -> 0.914
A2: 電站名稱 | B2: 淡江大學 | C2: 淡江大學 | D2: - | E2: 填入本案場名稱
A3: 電站壽命 | B3: 20 | C3: 20 | D3: - | E3: 預設 20 年，代表財務評估年期。若合約年限不同可依實際情況修改
A4: 建置量(kWp) | B4: 436.1 | C4: 436.1 | D4: - | E4: 填入裝置容量（kWp），通常由設計圖面或報價書取得 | M4: 情境編號: 4
A5: 起始年度 | B5: 2020 | C5: 2020 | D5: =B5+B3-1 -> 2039 | E5: 2039 | M5: 第3次滾算摘要
M6: 價金: 29000
A7: 綜合損益表(請填寫著色處) | M7: 專案IRR: 4.39
A8: 收入 | M8: 權益法IRR: 10.59
A9: 收支項目 | B9: 相關參數 | C9: 參數數值 | D9: 年限 | E9: 說明 | M9: 利潤率: 30.00%
A10: 電費收入 | B10: 年度AC併網總發電量 | C10: 547002 | D10: 547002 | E10: 20 | M10: 第3次滾算，減少 2000 元 - 現金模式，每次減少 2000 元
B11: 首年衰退率 | C11: 0.01 | E11: 第一年發電衰退比率，請填小數（例：1% → 填 0.01）。一般首年衰退約 1~2%(請參考模組規格書)
B12: 次年衰退率 | C12: 0.004 | E12: 第二年起每年固定衰退比率，請填小數（例：0.4% → 填 0.004）。一般約 0.4~0.7%(請參考模組規格書)
B13: 躉售費率(FIT) / 綠電費率 | C13: 4 | E13: 與台電簽訂的躉購費率或綠電合約費率，單位：元/度。請參考台電公告或合約內容
A14: 支出(請填寫著色處)
A15: 收支項目 | B15: 相關參數 | C15: 參數數值 | D15: 攤提年限 | E15: 說明
A16: 設備費用(價金) | B16: 每kWp設備成本 | C16: 35000 | D16: 29000 | E16: 20
B17: 信邦利潤率(ex:20%填0.2) | C17: 0.3 | E17: 公司在設備費用上加計的利潤比率，請填小數（例：20% → 填 0.2）
B18: 開發費 | C18: 2000 | E18: 前期開發費用（元），含可行性評估、申請規費、地主溝通等。若無則填 0
A19: 租金費用 | B19: 租金計算方式 | C19: 1 | D19: 1 | E19: 0
B20: 【方式1參數】每年相同價格 | C20: 290201 | D20: 290201 | E20: 20
B21: 【方式2參數】抽成比率 | D21: 0 | E21: 0
A22: 運維費用 | B22: 每kw運維成本 | C22: 400 | D22: 400 | E22: 20
A23: 保險費用 | B23: 占整體設備費用比例 | C23: 0.003 | D23: 0.003 | E23: 20
A24: 模組回收費用 | B24: 每kw模組回收成本 | C24: 1000 | D24: 1000 | E24: 10
A25: 利息費用 | B25: 銀行利率 | C25: 0.0256 | D25: 0.0256 | E25: 0
A26: 所得稅 | B26: 所得稅率 | C26: 0.2 | D26: 0.2 | E26: 0
A29: 現金流量表(請填寫著色處)
A30: 金流項目 | B30: 相關參數 | C30: 參數數值 | E30: 說明
A31: 貸款成數 | B31: 占總設備費用比例 | C31: 0.8 | D31: 0.8 | E31: 貸款佔設備總費用比例，填小數（例：80% → 填 0.8）。預設 0.8 代表貸八成、自備二成
A32: 貸款還款 | B32: 攤還期數 | C32: 15 | D32: 15 | E32: 貸款還款年數（年）。預設 15 年，代表分 15 年平均攤還本金
A33: 現金股利 | B33: 股利比率 | C33: 0.9 | D33: 0.9 | E33: 稅後現金流中分配給股東的比例，填小數（例：90% → 填 0.9）
A34: 年底減資 | B34: 攤還期數 | C34: 4 | D34: 4 | E34: 年底減資返還股東的年數。預設 4 年，代表 倒數 4 年進行減資，加速資金返還
D37: 2020 | E37: 2021 | F37: 2022 | G37: 2023 | H37: 2024 | I37: 2025 | J37: 2026 | K37: 2027 | L37: 2028 | M37: 2029 | N37: 2030 | O37: 2031 | P37: 2032 | Q37: 2033 | R37: 2034 | S37: 2035 | T37: 2036 | U37: 2037 | V37: 2038 | W37: 2039
D45: -290201 | E45: -290201 | F45: -290201 | G45: -290201 | H45: -290201 | I45: -290201 | J45: -290201 | K45: -290201 | L45: -290201 | M45: -290201 | N45: -290201 | O45: -290201 | P45: -290201 | Q45: -290201 | R45: -290201 | S45: -290201 | T45: -290201 | U45: -290201 | V45: -290201 | W45: -290201
D48: -174440 | E48: -174440 | F48: -174440 | G48: -174440 | H48: -174440 | I48: -174440 | J48: -174440 | K48: -174440 | L48: -174440 | M48: -174440 | N48: -174440 | O48: -174440 | P48: -174440 | Q48: -174440 | R48: -174440 | S48: -174440 | T48: -174440 | U48: -174440 | V48: -174440 | W48: -174440
D49: -37940.7 | E49: -37940.7 | F49: -37940.7 | G49: -37940.7 | H49: -37940.7 | I49: -37940.7 | J49: -37940.7 | K49: -37940.7 | L49: -37940.7 | M49: -37940.7 | N49: -37940.7 | O49: -37940.7 | P49: -37940.7 | Q49: -37940.7 | R49: -37940.7 | S49: -37940.7 | T49: -37940.7 | U49: -37940.7 | V49: -37940.7 | W49: -37940.7
D50: -43610 | E50: -43610 | F50: -43610 | G50: -43610 | H50: -43610 | I50: -43610 | J50: -43610 | K50: -43610 | L50: -43610 | M50: -43610 | N50: 0 | O50: 0 | P50: 0 | Q50: 0 | R50: 0 | S50: 0 | T50: 0 | U50: 0 | V50: 0 | W50: 0
D54: =D77 -> 0 | E54: =E77 -> 0 | F54: =F77 -> 0 | G54: =G77 -> 0 | H54: =H77 -> 0 | I54: =I77 -> 0 | J54: =J77 -> 0 | K54: =K77 -> 0 | ... W54: =W77 -> 0
D70: 0 | E70: 0 | F70: 0 | G70: 0 | H70: 0 | I70: 0 | J70: 0 | K70: 0 | L70: 0 | M70: 0 | N70: 0 | O70: 0 | P70: 0 | Q70: 0 | R70: 0 | S70: 0 | T70: 0 | U70: 0 | V70: 0 | W70: 0

Sheet 淡江大學_p6_1
A1: 電站基本資料(請填寫著色處) | E1: 說明 | O1: =1-C11 -> 0.99 | P1: =O1-$C12 -> 0.986 | Q1: =P1-$C12 -> 0.982 | R1: =Q1-$C12 -> 0.978 | S1: =R1-$C12 -> 0.974 | T1: =S1-$C12 -> 0.97 | U1: =T1-$C12 -> 0.966 | V1: =U1-$C12 -> 0.962 | W1: =V1-$C12 -> 0.958 | ... AH1: =AG1-$C12 -> 0.914
A2: 電站名稱 | B2: 淡江大學 | C2: 淡江大學 | D2: - | E2: 填入本案場名稱
A3: 電站壽命 | B3: 20 | C3: 20 | D3: - | E3: 預設 20 年，代表財務評估年期。若合約年限不同可依實際情況修改
A4: 建置量(kWp) | B4: 436.1 | C4: 436.1 | D4: - | E4: 填入裝置容量（kWp），通常由設計圖面或報價書取得 | M4: 情境編號: 6
A5: 起始年度 | B5: 2020 | C5: 2020 | D5: =B5+B3-1 -> 2039 | E5: 2039 | M5: 第5次滾算摘要
M6: 價金: 25000
A7: 綜合損益表(請填寫著色處) | M7: 專案IRR: 5.91
A8: 收入 | M8: 權益法IRR: 17.0
A9: 收支項目 | B9: 相關參數 | C9: 參數數值 | D9: 年限 | E9: 說明 | M9: 利潤率: 30.00%
A10: 電費收入 | B10: 年度AC併網總發電量 | C10: 547002 | D10: 547002 | E10: 20 | M10: 第5次滾算，減少 2000 元 - 現金模式，每次減少 2000 元
B11: 首年衰退率 | C11: 0.01 | E11: 第一年發電衰退比率，請填小數（例：1% → 填 0.01）。一般首年衰退約 1~2%(請參考模組規格書)
B12: 次年衰退率 | C12: 0.004 | E12: 第二年起每年固定衰退比率，請填小數（例：0.4% → 填 0.004）。一般約 0.4~0.7%(請參考模組規格書)
B13: 躉售費率(FIT) / 綠電費率 | C13: 4 | E13: 與台電簽訂的躉購費率或綠電合約費率，單位：元/度。請參考台電公告或合約內容
A14: 支出(請填寫著色處)
A15: 收支項目 | B15: 相關參數 | C15: 參數數值 | D15: 攤提年限 | E15: 說明
A16: 設備費用(價金) | B16: 每kWp設備成本 | C16: 35000 | D16: 25000 | E16: 20
B17: 信邦利潤率(ex:20%填0.2) | C17: 0.3 | E17: 公司在設備費用上加計的利潤比率，請填小數（例：20% → 填 0.2）
B18: 開發費 | C18: 2000 | E18: 前期開發費用（元），含可行性評估、申請規費、地主溝通等。若無則填 0
A19: 租金費用 | B19: 租金計算方式 | C19: 1 | D19: 1 | E19: 0
B20: 【方式1參數】每年相同價格 | C20: 290201 | D20: 290201 | E20: 20
B21: 【方式2參數】抽成比率 | D21: 0 | E21: 0
A22: 運維費用 | B22: 每kw運維成本 | C22: 400 | D22: 400 | E22: 20
A23: 保險費用 | B23: 占整體設備費用比例 | C23: 0.003 | D23: 0.003 | E23: 20
A24: 模組回收費用 | B24: 每kw模組回收成本 | C24: 1000 | D24: 1000 | E24: 10
A25: 利息費用 | B25: 銀行利率 | C25: 0.0256 | D25: 0.0256 | E25: 0
A26: 所得稅 | B26: 所得稅率 | C26: 0.2 | D26: 0.2 | E26: 0
A29: 現金流量表(請填寫著色處)
A30: 金流項目 | B30: 相關參數 | C30: 參數數值 | E30: 說明
A31: 貸款成數 | B31: 占總設備費用比例 | C31: 0.8 | D31: 0.8 | E31: 貸款佔設備總費用比例，填小數（例：80% → 填 0.8）。預設 0.8 代表貸八成、自備二成
A32: 貸款還款 | B32: 攤還期數 | C32: 15 | D32: 15 | E32: 貸款還款年數（年）。預設 15 年，代表分 15 年平均攤還本金
A33: 現金股利 | B33: 股利比率 | C33: 0.9 | D33: 0.9 | E33: 稅後現金流中分配給股東的比例，填小數（例：90% → 填 0.9）
A34: 年底減資 | B34: 攤還期數 | C34: 4 | D34: 4 | E34: 年底減資返還股東的年數。預設 4 年，代表 倒數 4 年進行減資，加速資金返還
D37: 2020 | E37: 2021 | F37: 2022 | G37: 2023 | H37: 2024 | I37: 2025 | J37: 2026 | K37: 2027 | L37: 2028 | M37: 2029 | N37: 2030 | O37: 2031 | P37: 2032 | Q37: 2033 | R37: 2034 | S37: 2035 | T37: 2036 | U37: 2037 | V37: 2038 | W37: 2039
D45: -290201 | E45: -290201 | F45: -290201 | G45: -290201 | H45: -290201 | I45: -290201 | J45: -290201 | K45: -290201 | L45: -290201 | M45: -290201 | N45: -290201 | O45: -290201 | P45: -290201 | Q45: -290201 | R45: -290201 | S45: -290201 | T45: -290201 | U45: -290201 | V45: -290201 | W45: -290201
D48: -174440 | E48: -174440 | F48: -174440 | G48: -174440 | H48: -174440 | I48: -174440 | J48: -174440 | K48: -174440 | L48: -174440 | M48: -174440 | N48: -174440 | O48: -174440 | P48: -174440 | Q48: -174440 | R48: -174440 | S48: -174440 | T48: -174440 | U48: -174440 | V48: -174440 | W48: -174440
D49: -32707.5 | E49: -32707.5 | F49: -32707.5 | G49: -32707.5 | H49: -32707.5 | I49: -32707.5 | J49: -32707.5 | K49: -32707.5 | L49: -32707.5 | M49: -32707.5 | N49: -32707.5 | O49: -32707.5 | P49: -32707.5 | Q49: -32707.5 | R49: -32707.5 | S49: -32707.5 | T49: -32707.5 | U49: -32707.5 | V49: -32707.5 | W49: -32707.5
D50: -43610 | E50: -43610 | F50: -43610 | G50: -43610 | H50: -43610 | I50: -43610 | J50: -43610 | K50: -43610 | L50: -43610 | M50: -43610 | N50: 0 | O50: 0 | P50: 0 | Q50: 0 | R50: 0 | S50: 0 | T50: 0 | U50: 0 | V50: 0 | W50: 0
D54: =D77 -> 0 | E54: =E77 -> 0 | F54: =F77 -> 0 | G54: =G77 -> 0 | H54: =H77 -> 0 | I54: =I77 -> 0 | J54: =J77 -> 0 | K54: =K77 -> 0 | ... W54: =W77 -> 0
D70: 0 | E70: 0 | F70: 0 | G70: 0 | H70: 0 | I70: 0 | J70: 0 | K70: 0 | L70: 0 | M70: 0 | N70: 0 | O70: 0 | P70: 0 | Q70: 0 | R70: 0 | S70: 0 | T70: 0 | U70: 0 | V70: 0 | W70: 0

Sheet 淡江大學_p4_3
B1: 電站基本資料 | F1: 說明 | P1: =1-D11 -> 0.99 | Q1: =P1-$D12 -> 0.986 | R1: =Q1-$D12 -> 0.982 | S1: =R1-$D12 -> 0.978 | T1: =S1-$D12 -> 0.974 | U1: =T1-$D12 -> 0.97 | V1: =U1-$D12 -> 0.966 | W1: =V1-$D12 -> 0.962 | X1: =W1-$D12 -> 0.958 | ... AI1: =AH1-$D12 -> 0.914
B2: 電站名稱 | C2: 淡江大學 | D2: - | E2: - | F2: 填入本案場名稱
B3: 電站壽命 | C3: 20 | D3: - | E3: - | F3: 預設 20 年，代表財務評估年期。若合約年限不同可依實際情況修改
B4: 建置量(kWp) | C4: 436.1 | D4: - | E4: - | F4: 填入裝置容量（kWp），通常由設計圖面或報價書取得 | M4: 情境編號: 4
B5: 起始年度 | C5: 2020 | D5: 結束年度 | E5: 2039 | F5: 填入電站預計掛表的西元年份（例：2025）。結束年度會自動計算 | M5: 第3次滾算摘要
M6: 價金: 29000
B7: 綜合損益表 | M7: 專案IRR: 4.39
B8: 收入 | M8: 權益法IRR: 10.59
B9: 收支項目 | C9: 相關參數 | D9: 參數數值 | E9: 年限 | F9: 說明 | M9: 利潤率: 30.00%
B10: 電費收入 | C10: 年度AC併網總發電量 | D10: 547002 | E10: 20 | F10: 預估年發電量（kWh），通常來自 PVsyst 模擬或估算：裝置容量 × 年日照時數 × 系統效率 | M10: 第3次滾算，減少 2000 元 - 現金模式，每次減少 2000 元
C11: 首年衰退率 | D11: 0.01 | F11: 第一年發電衰退比率，請填小數（例：1% → 填 0.01）。一般首年衰退約 1~2%(請參考模組規格書)
C12: 次年衰退率 | D12: 0.004 | F12: 第二年起每年固定衰退比率，請填小數（例：0.4% → 填 0.004）。一般約 0.4~0.7%(請參考模組規格書)
C13: 躉售費率(FIT) / 綠電費率 | D13: 4 | F13: 與台電簽訂的躉購費率或綠電合約費率，單位：元/度。請參考台電公告或合約內容
B14: 支出
B15: 收支項目 | C15: 相關參數 | D15: 參數數值 | E15: 攤提年限 | F15: 說明
B16: 設備費用(價金) | C16: 每kWp設備成本 | D16: 29000 | E16: 20 | F16: 每峰瓩設備成本（元/kWp），包含模組、逆變器、支架等硬體，不含工程施工費
C17: 信邦利潤率(ex:20%填0.2) | D17: 0.3 | F17: 公司在設備費用上加計的利潤比率，請填小數（例：20% → 填 0.2）
C18: 開發費 | D18: 2000 | F18: 前期開發費用（元），含可行性評估、申請規費、地主溝通等。若無則填 0
B19: 租金費用 | C19: 租金計算方式 | D19: 1 | E19: 20 | F19: 填 1 = 固定年租金（需填方式1參數）；填 2 = 依電費收入抽成（需填方式2參數）
C20: 【方式1參數】每年相同價格 | D20: 290201 | E20: 20 | F20: 租金計算方式選「1」時填寫，固定年租金金額（元/年），套用至整個電站壽命期
C21: 【方式2參數】抽成比率 | D21: 0 | E21: 20 | F21: 租金計算方式選「2」時填寫，請填小數（例：10% → 填 0.1）。租金 = 當年電費收入 × 抽成比率
B22: 運維費用 | C22: 每kw運維成本 | D22: 400 | E22: 20 | F22: 每峰瓩每年運維費用（元/kWp/年），含清洗、巡檢、維修等。
B23: 保險費用 | C23: 占整體設備費用比例 | D23: 0.003 | E23: 20 | F23: 保險費佔設備總費用比率，填小數（例：0.3% → 填 0.003）。預設 0.003，可依投保條件調整
B24: 模組回收費用 | C24: 每kw模組回收成本 | D24: 1000 | E24: 10 | F24: 每峰瓩模組廢棄回收費用（元/kWp），於第 1~10 年計提（攤提 10 年）。
B25: 利息費用 | C25: 銀行利率 | D25: 0.0256 | E25: 20 | F25: 向銀行貸款的年利率，填小數（例：2.56% → 填 0.0256）。請依銀行核准利率填入
B26: 所得稅 | C26: 所得稅率 | D26: 0.2 | E26: 20 | F26: 公司所得稅率，填小數（例：20% → 填 0.2）。預設 0.2，通常不需更改
B29: 現金流量表
B30: 金流項目 | C30: 相關參數 | D30: 參數數值 | F30: 說明
B31: 貸款成數 | C31: 占總設備費用比例 | D31: 0.8 | F31: 貸款佔設備總費用比例，填小數（例：80% → 填 0.8）。預設 0.8 代表貸八成、自備二成
B32: 貸款還款 | C32: 攤還期數 | D32: 15 | F32: 貸款還款年數（年）。預設 15 年，代表分 15 年平均攤還本金
B33: 現金股利 | C33: 股利比率 | D33: 0.9 | F33: 稅後現金流中分配給股東的比例，填小數（例：90% → 填 0.9）
B34: 年底減資 | C34: 攤還期數 | D34: 4 | F34: 年底減資返還股東的年數。預設 4 年，代表 倒數 4 年進行減資，加速資金返還
C37: 年份 | D37: 2020 | E37: 2021 | F37: 2022 | G37: 2023 | H37: 2024 | I37: 2025 | J37: 2026 | K37: 2027 | L37: 2028 | M37: 2029 | N37: 2030 | O37: 2031 | P37: 2032 | Q37: 2033 | R37: 2034 | S37: 2035 | T37: 2036 | U37: 2037 | V37: 2038 | W37: 2039
B38: 0
B39: (Unit : Currency) | C39: 0 | D39: 1 | E39: 2 | F39: 3 | G39: 4 | H39: 5 | I39: 6 | J39: 7 | K39: 8 | L39: 9 | M39: 10 | N39: 11 | O39: 12 | P39: 13 | Q39: 14 | R39: 15 | S39: 16 | T39: 17 | U39: 18 | V39: 19 | W39: 20
B40: 發電度數(KWH) | C40: 0 | D40: =$D$10*P1 -> 541531.98 | E40: =$D$10*Q1 -> 539343.97 | F40: =$D$10*R1 -> 537155.96 | G40: =$D$10*S1 -> 534967.96 | H40: =$D$10*T1 -> 532779.95 | I40: =$D$10*U1 -> 530591.94 | J40: =$D$10*V1 -> 528403.93 | K40: =$D$10*W1 -> 526215.92 | ... W40: =$D$10*AI1 -> 499959.83
B41: Inflow : 電費收入 | C41: - | D41: =D40*$D$13 -> 2166127.9 | E41: =E40*$D$13 -> 2157375.9 | F41: =F40*$D$13 -> 2148623.9 | G41: =G40*$D$13 -> 2139871.8 | H41: =H40*$D$13 -> 2131119.8 | I41: =I40*$D$13 -> 2122367.8 | J41: =J40*$D$13 -> 2113615.7 | K41: =K40*$D$13 -> 2104863.7 | ... W41: =W40*$D$13 -> 1999839.3
B42: Inflow : 政府補助 | C42: - | G42: - | H42: - | I42: - | J42: - | K42: - | L42: - | M42: - | N42: - | O42: - | P42: - | Q42: - | R42: - | S42: - | T42: - | U42: - | V42: - | W42: -
B43: Inflow : 銀行借款
B44: Outflow : 設備費用 | C44: =-(D16/(1-D17)+D18)*C4 -> -18939200
...

Sheet 淡江大學_p3_1
B1: 電站基本資料 | F1: 說明 | P1: =1-D11 -> 0.99 | Q1: =P1-$D12 -> 0.986 | R1: =Q1-$D12 -> 0.982 | S1: =R1-$D12 -> 0.978 | T1: =S1-$D12 -> 0.974 | U1: =T1-$D12 -> 0.97 | V1: =U1-$D12 -> 0.966 | W1: =V1-$D12 -> 0.962 | X1: =W1-$D12 -> 0.958 | ... AI1: =AH1-$D12 -> 0.914
B2: 電站名稱 | C2: 淡江大學 | D2: - | E2: - | F2: 填入本案場名稱
B3: 電站壽命 | C3: 20 | D3: - | E3: - | F3: 預設 20 年，代表財務評估年期。若合約年限不同可依實際情況修改
B4: 建置量(kWp) | C4: 436.1 | D4: - | E4: - | F4: 填入裝置容量（kWp），通常由設計圖面或報價書取得 | M4: 情境編號: 3
B5: 起始年度 | C5: 2020 | D5: 結束年度 | E5: 2039 | F5: 填入電站預計掛表的西元年份（例：2025）。結束年度會自動計算 | M5: 第2次滾算摘要
M6: 價金: 31000
B7: 綜合損益表 | M7: 專案IRR: 3.75
B8: 收入 | M8: 權益法IRR: 8.21
B9: 收支項目 | C9: 相關參數 | D9: 參數數值 | E9: 年限 | F9: 說明 | M9: 利潤率: 30.00%
B10: 電費收入 | C10: 年度AC併網總發電量 | D10: 547002 | E10: 20 | F10: 預估年發電量（kWh），通常來自 PVsyst 模擬或估算：裝置容量 × 年日照時數 × 系統效率 | M10: 第2次滾算，減少 2000 元 - 現金模式，每次減少 2000 元
C11: 首年衰退率 | D11: 0.01 | F11: 第一年發電衰退比率，請填小數（例：1% → 填 0.01）。一般首年衰退約 1~2%(請參考模組規格書)
C12: 次年衰退率 | D12: 0.004 | F12: 第二年起每年固定衰退比率，請填小數（例：0.4% → 填 0.004）。一般約 0.4~0.7%(請參考模組規格書)
C13: 躉售費率(FIT) / 綠電費率 | D13: 4 | F13: 與台電簽訂的躉購費率或綠電合約費率，單位：元/度。請參考台電公告或合約內容
B14: 支出
B15: 收支項目 | C15: 相關參數 | D15: 參數數值 | E15: 攤提年限 | F15: 說明
B16: 設備費用(價金) | C16: 每kWp設備成本 | D16: 31000 | E16: 20 | F16: 每峰瓩設備成本（元/kWp），包含模組、逆變器、支架等硬體，不含工程施工費
C17: 信邦利潤率(ex:20%填0.2) | D17: 0.3 | F17: 公司在設備費用上加計的利潤比率，請填小數（例：20% → 填 0.2）
C18: 開發費 | D18: 2000 | F18: 前期開發費用（元），含可行性評估、申請規費、地主溝通等。若無則填 0
B19: 租金費用 | C19: 租金計算方式 | D19: 1 | E19: 20 | F19: 填 1 = 固定年租金（需填方式1參數）；填 2 = 依電費收入抽成（需填方式2參數）
C20: 【方式1參數】每年相同價格 | D20: 290201 | E20: 20 | F20: 租金計算方式選「1」時填寫，固定年租金金額（元/年），套用至整個電站壽命期
C21: 【方式2參數】抽成比率 | D21: 0 | E21: 20 | F21: 租金計算方式選「2」時填寫，請填小數（例：10% → 填 0.1）。租金 = 當年電費收入 × 抽成比率
B22: 運維費用 | C22: 每kw運維成本 | D22: 400 | E22: 20 | F22: 每峰瓩每年運維費用（元/kWp/年），含清洗、巡檢、維修等。
B23: 保險費用 | C23: 占整體設備費用比例 | D23: 0.003 | E23: 20 | F23: 保險費佔設備總費用比率，填小數（例：0.3% → 填 0.003）。預設 0.003，可依投保條件調整
B24: 模組回收費用 | C24: 每kw模組回收成本 | D24: 1000 | E24: 10 | F24: 每峰瓩模組廢棄回收費用（元/kWp），於第 1~10 年計提（攤提 10 年）。
B25: 利息費用 | C25: 銀行利率 | D25: 0.0256 | E25: 20 | F25: 向銀行貸款的年利率，填小數（例：2.56% → 填 0.0256）。請依銀行核准利率填入
B26: 所得稅 | C26: 所得稅率 | D26: 0.2 | E26: 20 | F26: 公司所得稅率，填小數（例：20% → 填 0.2）。預設 0.2，通常不需更改
B29: 現金流量表
B30: 金流項目 | C30: 相關參數 | D30: 參數數值 | F30: 說明
B31: 貸款成數 | C31: 占總設備費用比例 | D31: 0.8 | F31: 貸款佔設備總費用比例，填小數（例：80% → 填 0.8）。預設 0.8 代表貸八成、自備二成
B32: 貸款還款 | C32: 攤還期數 | D32: 15 | F32: 貸款還款年數（年）。預設 15 年，代表分 15 年平均攤還本金
B33: 現金股利 | C33: 股利比率 | D33: 0.9 | F33: 稅後現金流中分配給股東的比例，填小數（例：90% → 填 0.9）
B34: 年底減資 | C34: 攤還期數 | D34: 4 | F34: 年底減資返還股東的年數。預設 4 年，代表 倒數 4 年進行減資，加速資金返還
C37: 年份 | D37: 2020 | E37: 2021 | F37: 2022 | G37: 2023 | H37: 2024 | I37: 2025 | J37: 2026 | K37: 2027 | L37: 2028 | M37: 2029 | N37: 2030 | O37: 2031 | P37: 2032 | Q37: 2033 | R37: 2034 | S37: 2035 | T37: 2036 | U37: 2037 | V37: 2038 | W37: 2039
B38: 0
B39: (Unit : Currency) | C39: 0 | D39: 1 | E39: 2 | F39: 3 | G39: 4 | H39: 5 | I39: 6 | J39: 7 | K39: 8 | L39: 9 | M39: 10 | N39: 11 | O39: 12 | P39: 13 | Q39: 14 | R39: 15 | S39: 16 | T39: 17 | U39: 18 | V39: 19 | W39: 20
B40: 發電度數(KWH) | C40: 0 | D40: =$D$10*P1 -> 541531.98 | E40: =$D$10*Q1 -> 539343.97 | F40: =$D$10*R1 -> 537155.96 | G40: =$D$10*S1 -> 534967.96 | H40: =$D$10*T1 -> 532779.95 | I40: =$D$10*U1 -> 530591.94 | J40: =$D$10*V1 -> 528403.93 | K40: =$D$10*W1 -> 526215.92 | ... W40: =$D$10*AI1 -> 499959.83
B41: Inflow : 電費收入 | C41: - | D41: =D40*$D$13 -> 2166127.9 | E41: =E40*$D$13 -> 2157375.9 | F41: =F40*$D$13 -> 2148623.9 | G41: =G40*$D$13 -> 2139871.8 | H41: =H40*$D$13 -> 2131119.8 | I41: =I40*$D$13 -> 2122367.8 | J41: =J40*$D$13 -> 2113615.7 | K41: =K40*$D$13 -> 2104863.7 | ... W41: =W40*$D$13 -> 1999839.3
B42: Inflow : 政府補助 | C42: - | G42: - | H42: - | I42: - | J42: - | K42: - | L42: - | M42: - | N42: - | O42: - | P42: - | Q42: - | R42: - | S42: - | T42: - | U42: - | V42: - | W42: -
B43: Inflow : 銀行借款
B44: Outflow : 設備費用 | C44: =-(D16/(1-D17)+D18)*C4 -> -20185200
...

Sheet 淡江大學_p5
B1: 電站基本資料 | F1: 說明 | P1: =1-D11 -> 0.99 | Q1: =P1-$D12 -> 0.986 | R1: =Q1-$D12 -> 0.982 | S1: =R1-$D12 -> 0.978 | T1: =S1-$D12 -> 0.974 | U1: =T1-$D12 -> 0.97 | V1: =U1-$D12 -> 0.966 | W1: =V1-$D12 -> 0.962 | X1: =W1-$D12 -> 0.958 | ... AI1: =AH1-$D12 -> 0.914
B2: 電站名稱 | C2: 淡江大學 | D2: - | E2: - | F2: 填入本案場名稱
B3: 電站壽命 | C3: 20 | D3: - | E3: - | F3: 預設 20 年，代表財務評估年期。若合約年限不同可依實際情況修改
B4: 建置量(kWp) | C4: 436.1 | D4: - | E4: - | F4: 填入裝置容量（kWp），通常由設計圖面或報價書取得 | M4: 情境編號: 5
B5: 起始年度 | C5: 2020 | D5: 結束年度 | E5: 2039 | F5: 填入電站預計掛表的西元年份（例：2025）。結束年度會自動計算 | M5: 第4次滾算摘要
M6: 價金: 27000
B7: 綜合損益表 | M7: 專案IRR: 5.11
B8: 收入 | M8: 權益法IRR: 13.45
B9: 收支項目 | C9: 相關參數 | D9: 參數數值 | E9: 年限 | F9: 說明 | M9: 利潤率: 30.00%
B10: 電費收入 | C10: 年度AC併網總發電量 | D10: 547002 | E10: 20 | F10: 預估年發電量（kWh），通常來自 PVsyst 模擬或估算：裝置容量 × 年日照時數 × 系統效率 | M10: 第4次滾算，減少 2000 元 - 現金模式，每次減少 2000 元
C11: 首年衰退率 | D11: 0.01 | F11: 第一年發電衰退比率，請填小數（例：1% → 填 0.01）。一般首年衰退約 1~2%(請參考模組規格書)
C12: 次年衰退率 | D12: 0.004 | F12: 第二年起每年固定衰退比率，請填小數（例：0.4% → 填 0.004）。一般約 0.4~0.7%(請參考模組規格書)
C13: 躉售費率(FIT) / 綠電費率 | D13: 4 | F13: 與台電簽訂的躉購費率或綠電合約費率，單位：元/度。請參考台電公告或合約內容
B14: 支出
B15: 收支項目 | C15: 相關參數 | D15: 參數數值 | E15: 攤提年限 | F15: 說明
B16: 設備費用(價金) | C16: 每kWp設備成本 | D16: 27000 | E16: 20 | F16: 每峰瓩設備成本（元/kWp），包含模組、逆變器、支架等硬體，不含工程施工費
C17: 信邦利潤率(ex:20%填0.2) | D17: 0.3 | F17: 公司在設備費用上加計的利潤比率，請填小數（例：20% → 填 0.2）
C18: 開發費 | D18: 2000 | F18: 前期開發費用（元），含可行性評估、申請規費、地主溝通等。若無則填 0
B19: 租金費用 | C19: 租金計算方式 | D19: 1 | E19: 20 | F19: 填 1 = 固定年租金（需填方式1參數）；填 2 = 依電費收入抽成（需填方式2參數）
C20: 【方式1參數】每年相同價格 | D20: 290201 | E20: 20 | F20: 租金計算方式選「1」時填寫，固定年租金金額（元/年），套用至整個電站壽命期
C21: 【方式2參數】抽成比率 | D21: 0 | E21: 20 | F21: 租金計算方式選「2」時填寫，請填小數（例：10% → 填 0.1）。租金 = 當年電費收入 × 抽成比率
B22: 運維費用 | C22: 每kw運維成本 | D22: 400 | E22: 20 | F22: 每峰瓩每年運維費用（元/kWp/年），含清洗、巡檢、維修等。
B23: 保險費用 | C23: 占整體設備費用比例 | D23: 0.003 | E23: 20 | F23: 保險費佔設備總費用比率，填小數（例：0.3% → 填 0.003）。預設 0.003，可依投保條件調整
B24: 模組回收費用 | C24: 每kw模組回收成本 | D24: 1000 | E24: 10 | F24: 每峰瓩模組廢棄回收費用（元/kWp），於第 1~10 年計提（攤提 10 年）。
B25: 利息費用 | C25: 銀行利率 | D25: 0.0256 | E25: 20 | F25: 向銀行貸款的年利率，填小數（例：2.56% → 填 0.0256）。請依銀行核准利率填入
B26: 所得稅 | C26: 所得稅率 | D26: 0.2 | E26: 20 | F26: 公司所得稅率，填小數（例：20% → 填 0.2）。預設 0.2，通常不需更改
B29: 現金流量表
B30: 金流項目 | C30: 相關參數 | D30: 參數數值 | F30: 說明
B31: 貸款成數 | C31: 占總設備費用比例 | D31: 0.8 | F31: 貸款佔設備總費用比例，填小數（例：80% → 填 0.8）。預設 0.8 代表貸八成、自備二成
B32: 貸款還款 | C32: 攤還期數 | D32: 15 | F32: 貸款還款年數（年）。預設 15 年，代表分 15 年平均攤還本金
B33: 現金股利 | C33: 股利比率 | D33: 0.9 | F33: 稅後現金流中分配給股東的比例，填小數（例：90% → 填 0.9）
B34: 年底減資 | C34: 攤還期數 | D34: 4 | F34: 年底減資返還股東的年數。預設 4 年，代表 倒數 4 年進行減資，加速資金返還
C37: 年份 | D37: 2020 | E37: 2021 | F37: 2022 | G37: 2023 | H37: 2024 | I37: 2025 | J37: 2026 | K37: 2027 | L37: 2028 | M37: 2029 | N37: 2030 | O37: 2031 | P37: 2032 | Q37: 2033 | R37: 2034 | S37: 2035 | T37: 2036 | U37: 2037 | V37: 2038 | W37: 2039
B38: 0
B39: (Unit : Currency) | C39: 0 | D39: 1 | E39: 2 | F39: 3 | G39: 4 | H39: 5 | I39: 6 | J39: 7 | K39: 8 | L39: 9 | M39: 10 | N39: 11 | O39: 12 | P39: 13 | Q39: 14 | R39: 15 | S39: 16 | T39: 17 | U39: 18 | V39: 19 | W39: 20
B40: 發電度數(KWH) | C40: 0 | D40: =$D$10*P1 -> 541531.98 | E40: =$D$10*Q1 -> 539343.97 | F40: =$D$10*R1 -> 537155.96 | G40: =$D$10*S1 -> 534967.96 | H40: =$D$10*T1 -> 532779.95 | I40: =$D$10*U1 -> 530591.94 | J40: =$D$10*V1 -> 528403.93 | K40: =$D$10*W1 -> 526215.92 | ... W40: =$D$10*AI1 -> 499959.83
B41: Inflow : 電費收入 | C41: - | D41: =D40*$D$13 -> 2166127.9 | E41: =E40*$D$13 -> 2157375.9 | F41: =F40*$D$13 -> 2148623.9 | G41: =G40*$D$13 -> 2139871.8 | H41: =H40*$D$13 -> 2131119.8 | I41: =I40*$D$13 -> 2122367.8 | J41: =J40*$D$13 -> 2113615.7 | K41: =K40*$D$13 -> 2104863.7 | ... W41: =W40*$D$13 -> 1999839.3
B42: Inflow : 政府補助 | C42: - | G42: - | H42: - | I42: - | J42: - | K42: - | L42: - | M42: - | N42: - | O42: - | P42: - | Q42: - | R42: - | S42: - | T42: - | U42: - | V42: - | W42: -
B43: Inflow : 銀行借款
B44: Outflow : 設備費用 | C44: =-(D16/(1-D17)+D18)*C4 -> -17693200
...
