Workbook

Sheet 多站彙整
C4: 年份 | D4: 2020 | E4: 2021 | F4: 2022 | G4: 2023 | H4: 2024 | I4: 2025 | J4: 2026 | K4: 2027 | L4: 2028 | M4: 2029 | N4: 2030 | O4: 2031 | P4: 2032 | Q4: 2033 | R4: 2034 | S4: 2035 | T4: 2036 | U4: 2037 | V4: 2038 | W4: 2039
C5: 預估發電度數
B6: 淡江大學 | D6: =ROUND(ABS(淡江大學_p3!D40),0) -> 541532 | E6: =ROUND(ABS(淡江大學_p3!E40),0) -> 539344 | F6: =ROUND(ABS(淡江大學_p3!F40),0) -> 537156 | G6: =ROUND(ABS(淡江大學_p3!G40),0) -> 534968 | H6: =ROUND(ABS(淡江大學_p3!H40),0) -> 532780 | I6: =ROUND(ABS(淡江大學_p3!I40),0) -> 530592 | J6: =ROUND(ABS(淡江大學_p3!J40),0) -> 528404 | K6: =ROUND(ABS(淡江大學_p3!K40),0) -> 526216 | ... W6: =ROUND(ABS(淡江大學_p3!W40),0) -> 499960
B7: 淡江大學 | D7: =ROUND(ABS(淡江大學_p4!D40),0) -> 541532 | E7: =ROUND(ABS(淡江大學_p4!E40),0) -> 539344 | F7: =ROUND(ABS(淡江大學_p4!F40),0) -> 537156 | G7: =ROUND(ABS(淡江大學_p4!G40),0) -> 534968 | H7: =ROUND(ABS(淡江大學_p4!H40),0) -> 532780 | I7: =ROUND(ABS(淡江大學_p4!I40),0) -> 530592 | J7: =ROUND(ABS(淡江大學_p4!J40),0) -> 528404 | K7: =ROUND(ABS(淡江大學_p4!K40),0) -> 526216 | ... W7: =ROUND(ABS(淡江大學_p4!W40),0) -> 499960
B8: 淡江大學 | D8: =ROUND(ABS(淡江大學_p5!D40),0) -> 541532 | E8: =ROUND(ABS(淡江大學_p5!E40),0) -> 539344 | F8: =ROUND(ABS(淡江大學_p5!F40),0) -> 537156 | G8: =ROUND(ABS(淡江大學_p5!G40),0) -> 534968 | H8: =ROUND(ABS(淡江大學_p5!H40),0) -> 532780 | I8: =ROUND(ABS(淡江大學_p5!I40),0) -> 530592 | J8: =ROUND(ABS(淡江大學_p5!J40),0) -> 528404 | K8: =ROUND(ABS(淡江大學_p5!K40),0) -> 526216 | ... W8: =ROUND(ABS(淡江大學_p5!W40),0) -> 499960
C9: 預估發電度數/年總計 | D9: =SUM(D6:D8) -> 1624596 | E9: =SUM(E6:E8) -> 1618032 | F9: =SUM(F6:F8) -> 1611468 | G9: =SUM(G6:G8) -> 1604904 | H9: =SUM(H6:H8) -> 1598340 | I9: =SUM(I6:I8) -> 1591776 | J9: =SUM(J6:J8) -> 1585212 | K9: =SUM(K6:K8) -> 1578648 | ... W9: =SUM(W6:W8) -> 1499880
C10: 年份 | D10: 2020 | E10: 2021 | F10: 2022 | G10: 2023 | H10: 2024 | I10: 2025 | J10: 2026 | K10: 2027 | L10: 2028 | M10: 2029 | N10: 2030 | O10: 2031 | P10: 2032 | Q10: 2033 | R10: 2034 | S10: 2035 | T10: 2036 | U10: 2037 | V10: 2038 | W10: 2039
C11: 預估收入
B12: 淡江大學 | D12: =ROUND(ABS(淡江大學_p3!D41),0) -> 2166128 | E12: =ROUND(ABS(淡江大學_p3!E41),0) -> 2157376 | F12: =ROUND(ABS(淡江大學_p3!F41),0) -> 2148624 | G12: =ROUND(ABS(淡江大學_p3!G41),0) -> 2139872 | H12: =ROUND(ABS(淡江大學_p3!H41),0) -> 2131120 | I12: =ROUND(ABS(淡江大學_p3!I41),0) -> 2122368 | J12: =ROUND(ABS(淡江大學_p3!J41),0) -> 2113616 | K12: =ROUND(ABS(淡江大學_p3!K41),0) -> 2104864 | ... W12: =ROUND(ABS(淡江大學_p3!W41),0) -> 1999839
B13: 淡江大學 | D13: =ROUND(ABS(淡江大學_p4!D41),0) -> 2166128 | E13: =ROUND(ABS(淡江大學_p4!E41),0) -> 2157376 | F13: =ROUND(ABS(淡江大學_p4!F41),0) -> 2148624 | G13: =ROUND(ABS(淡江大學_p4!G41),0) -> 2139872 | H13: =ROUND(ABS(淡江大學_p4!H41),0) -> 2131120 | I13: =ROUND(ABS(淡江大學_p4!I41),0) -> 2122368 | J13: =ROUND(ABS(淡江大學_p4!J41),0) -> 2113616 | K13: =ROUND(ABS(淡江大學_p4!K41),0) -> 2104864 | ... W13: =ROUND(ABS(淡江大學_p4!W41),0) -> 1999839
B14: 淡江大學 | D14: =ROUND(ABS(淡江大學_p5!D41),0) -> 2166128 | E14: =ROUND(ABS(淡江大學_p5!E41),0) -> 2157376 | F14: =ROUND(ABS(淡江大學_p5!F41),0) -> 2148624 | G14: =ROUND(ABS(淡江大學_p5!G41),0) -> 2139872 | H14: =ROUND(ABS(淡江大學_p5!H41),0) -> 2131120 | I14: =ROUND(ABS(淡江大學_p5!I41),0) -> 2122368 | J14: =ROUND(ABS(淡江大學_p5!J41),0) -> 2113616 | K14: =ROUND(ABS(淡江大學_p5!K41),0) -> 2104864 | ... W14: =ROUND(ABS(淡江大學_p5!W41),0) -> 1999839
C15: 預估收入/年總計 | D15: =SUM(D12:D14) -> 6498384 | E15: =SUM(E12:E14) -> 6472128 | F15: =SUM(F12:F14) -> 6445872 | G15: =SUM(G12:G14) -> 6419616 | H15: =SUM(H12:H14) -> 6393360 | I15: =SUM(I12:I14) -> 6367104 | J15: =SUM(J12:J14) -> 6340848 | K15: =SUM(K12:K14) -> 6314592 | ... W15: =SUM(W12:W14) -> 5999517
C16: 年份 | D16: 2020 | E16: 2021 | F16: 2022 | G16: 2023 | H16: 2024 | I16: 2025 | J16: 2026 | K16: 2027 | L16: 2028 | M16: 2029 | N16: 2030 | O16: 2031 | P16: 2032 | Q16: 2033 | R16: 2034 | S16: 2035 | T16: 2036 | U16: 2037 | V16: 2038 | W16: 2039
C17: 租金
B18: 淡江大學 | D18: =ROUND(ABS(淡江大學_p3!D45),0) -> 290201 | E18: =ROUND(ABS(淡江大學_p3!E45),0) -> 290201 | F18: =ROUND(ABS(淡江大學_p3!F45),0) -> 290201 | G18: =ROUND(ABS(淡江大學_p3!G45),0) -> 290201 | H18: =ROUND(ABS(淡江大學_p3!H45),0) -> 290201 | I18: =ROUND(ABS(淡江大學_p3!I45),0) -> 290201 | J18: =ROUND(ABS(淡江大學_p3!J45),0) -> 290201 | K18: =ROUND(ABS(淡江大學_p3!K45),0) -> 290201 | ... W18: =ROUND(ABS(淡江大學_p3!W45),0) -> 290201
B19: 淡江大學 | D19: =ROUND(ABS(淡江大學_p4!D45),0) -> 290201 | E19: =ROUND(ABS(淡江大學_p4!E45),0) -> 290201 | F19: =ROUND(ABS(淡江大學_p4!F45),0) -> 290201 | G19: =ROUND(ABS(淡江大學_p4!G45),0) -> 290201 | H19: =ROUND(ABS(淡江大學_p4!H45),0) -> 290201 | I19: =ROUND(ABS(淡江大學_p4!I45),0) -> 290201 | J19: =ROUND(ABS(淡江大學_p4!J45),0) -> 290201 | K19: =ROUND(ABS(淡江大學_p4!K45),0) -> 290201 | ... W19: =ROUND(ABS(淡江大學_p4!W45),0) -> 290201
B20: 淡江大學 | D20: =ROUND(ABS(淡江大學_p5!D45),0) -> 290201 | E20: =ROUND(ABS(淡江大學_p5!E45),0) -> 290201 | F20: =ROUND(ABS(淡江大學_p5!F45),0) -> 290201 | G20: =ROUND(ABS(淡江大學_p5!G45),0) -> 290201 | H20: =ROUND(ABS(淡江大學_p5!H45),0) -> 290201 | I20: =ROUND(ABS(淡江大學_p5!I45),0) -> 290201 | J20: =ROUND(ABS(淡江大學_p5!J45),0) -> 290201 | K20: =ROUND(ABS(淡江大學_p5!K45),0) -> 290201 | ... W20: =ROUND(ABS(淡江大學_p5!W45),0) -> 290201
C21: 租金/年總計 | D21: =SUM(D18:D20) -> 870603 | E21: =SUM(E18:E20) -> 870603 | F21: =SUM(F18:F20) -> 870603 | G21: =SUM(G18:G20) -> 870603 | H21: =SUM(H18:H20) -> 870603 | I21: =SUM(I18:I20) -> 870603 | J21: =SUM(J18:J20) -> 870603 | K21: =SUM(K18:K20) -> 870603 | ... W21: =SUM(W18:W20) -> 870603
C22: 年份 | D22: 2020 | E22: 2021 | F22: 2022 | G22: 2023 | H22: 2024 | I22: 2025 | J22: 2026 | K22: 2027 | L22: 2028 | M22: 2029 | N22: 2030 | O22: 2031 | P22: 2032 | Q22: 2033 | R22: 2034 | S22: 2035 | T22: 2036 | U22: 2037 | V22: 2038 | W22: 2039
C23: 運維
B24: 淡江大學 | D24: =ROUND(ABS(淡江大學_p3!D48),0) -> 174440 | E24: =ROUND(ABS(淡江大學_p3!E48),0) -> 174440 | F24: =ROUND(ABS(淡江大學_p3!F48),0) -> 174440 | G24: =ROUND(ABS(淡江大學_p3!G48),0) -> 174440 | H24: =ROUND(ABS(淡江大學_p3!H48),0) -> 174440 | I24: =ROUND(ABS(淡江大學_p3!I48),0) -> 174440 | J24: =ROUND(ABS(淡江大學_p3!J48),0) -> 174440 | K24: =ROUND(ABS(淡江大學_p3!K48),0) -> 174440 | ... W24: =ROUND(ABS(淡江大學_p3!W48),0) -> 174440
B25: 淡江大學 | D25: =ROUND(ABS(淡江大學_p4!D48),0) -> 174440 | E25: =ROUND(ABS(淡江大學_p4!E48),0) -> 174440 | F25: =ROUND(ABS(淡江大學_p4!F48),0) -> 174440 | G25: =ROUND(ABS(淡江大學_p4!G48),0) -> 174440 | H25: =ROUND(ABS(淡江大學_p4!H48),0) -> 174440 | I25: =ROUND(ABS(淡江大學_p4!I48),0) -> 174440 | J25: =ROUND(ABS(淡江大學_p4!J48),0) -> 174440 | K25: =ROUND(ABS(淡江大學_p4!K48),0) -> 174440 | ... W25: =ROUND(ABS(淡江大學_p4!W48),0) -> 174440
B26: 淡江大學 | D26: =ROUND(ABS(淡江大學_p5!D48),0) -> 174440 | E26: =ROUND(ABS(淡江大學_p5!E48),0) -> 174440 | F26: =ROUND(ABS(淡江大學_p5!F48),0) -> 174440 | G26: =ROUND(ABS(淡江大學_p5!G48),0) -> 174440 | H26: =ROUND(ABS(淡江大學_p5!H48),0) -> 174440 | I26: =ROUND(ABS(淡江大學_p5!I48),0) -> 174440 | J26: =ROUND(ABS(淡江大學_p5!J48),0) -> 174440 | K26: =ROUND(ABS(淡江大學_p5!K48),0) -> 174440 | ... W26: =ROUND(ABS(淡江大學_p5!W48),0) -> 174440
C27: 運維/年總計 | D27: =SUM(D24:D26) -> 523320 | E27: =SUM(E24:E26) -> 523320 | F27: =SUM(F24:F26) -> 523320 | G27: =SUM(G24:G26) -> 523320 | H27: =SUM(H24:H26) -> 523320 | I27: =SUM(I24:I26) -> 523320 | J27: =SUM(J24:J26) -> 523320 | K27: =SUM(K24:K26) -> 523320 | ... W27: =SUM(W24:W26) -> 523320
C28: 年份 | D28: 2020 | E28: 2021 | F28: 2022 | G28: 2023 | H28: 2024 | I28: 2025 | J28: 2026 | K28: 2027 | L28: 2028 | M28: 2029 | N28: 2030 | O28: 2031 | P28: 2032 | Q28: 2033 | R28: 2034 | S28: 2035 | T28: 2036 | U28: 2037 | V28: 2038 | W28: 2039
C29: 保險
B30: 淡江大學 | D30: =ROUND(ABS(淡江大學_p3!D49),0) -> 40000 | E30: =ROUND(ABS(淡江大學_p3!E49),0) -> 40000 | F30: =ROUND(ABS(淡江大學_p3!F49),0) -> 40000 | G30: =ROUND(ABS(淡江大學_p3!G49),0) -> 40000 | H30: =ROUND(ABS(淡江大學_p3!H49),0) -> 40000 | I30: =ROUND(ABS(淡江大學_p3!I49),0) -> 40000 | J30: =ROUND(ABS(淡江大學_p3!J49),0) -> 40000 | K30: =ROUND(ABS(淡江大學_p3!K49),0) -> 40000 | ... W30: =ROUND(ABS(淡江大學_p3!W49),0) -> 40000
B31: 淡江大學 | D31: =ROUND(ABS(淡江大學_p4!D49),0) -> 37941 | E31: =ROUND(ABS(淡江大學_p4!E49),0) -> 37941 | F31: =ROUND(ABS(淡江大學_p4!F49),0) -> 37941 | G31: =ROUND(ABS(淡江大學_p4!G49),0) -> 37941 | H31: =ROUND(ABS(淡江大學_p4!H49),0) -> 37941 | I31: =ROUND(ABS(淡江大學_p4!I49),0) -> 37941 | J31: =ROUND(ABS(淡江大學_p4!J49),0) -> 37941 | K31: =ROUND(ABS(淡江大學_p4!K49),0) -> 37941 | ... W31: =ROUND(ABS(淡江大學_p4!W49),0) -> 37941
B32: 淡江大學 | D32: =ROUND(ABS(淡江大學_p5!D49),0) -> 35324 | E32: =ROUND(ABS(淡江大學_p5!E49),0) -> 35324 | F32: =ROUND(ABS(淡江大學_p5!F49),0) -> 35324 | G32: =ROUND(ABS(淡江大學_p5!G49),0) -> 35324 | H32: =ROUND(ABS(淡江大學_p5!H49),0) -> 35324 | I32: =ROUND(ABS(淡江大學_p5!I49),0) -> 35324 | J32: =ROUND(ABS(淡江大學_p5!J49),0) -> 35324 | K32: =ROUND(ABS(淡江大學_p5!K49),0) -> 35324 | ... W32: =ROUND(ABS(淡江大學_p5!W49),0) -> 35324
C33: 保險/年總計 | D33: =SUM(D30:D32) -> 113265 | E33: =SUM(E30:E32) -> 113265 | F33: =SUM(F30:F32) -> 113265 | G33: =SUM(G30:G32) -> 113265 | H33: =SUM(H30:H32) -> 113265 | I33: =SUM(I30:I32) -> 113265 | J33: =SUM(J30:J32) -> 113265 | K33: =SUM(K30:K32) -> 113265 | ... W33: =SUM(W30:W32) -> 113265
C34: 年份 | D34: 2020 | E34: 2021 | F34: 2022 | G34: 2023 | H34: 2024 | I34: 2025 | J34: 2026 | K34: 2027 | L34: 2028 | M34: 2029 | N34: 2030 | O34: 2031 | P34: 2032 | Q34: 2033 | R34: 2034 | S34: 2035 | T34: 2036 | U34: 2037 | V34: 2038 | W34: 2039
C35: 模組回收費
B36: 淡江大學 | D36: =ROUND(ABS(淡江大學_p3!D50),0) -> 43610 | E36: =ROUND(ABS(淡江大學_p3!E50),0) -> 43610 | F36: =ROUND(ABS(淡江大學_p3!F50),0) -> 43610 | G36: =ROUND(ABS(淡江大學_p3!G50),0) -> 43610 | H36: =ROUND(ABS(淡江大學_p3!H50),0) -> 43610 | I36: =ROUND(ABS(淡江大學_p3!I50),0) -> 43610 | J36: =ROUND(ABS(淡江大學_p3!J50),0) -> 43610 | K36: =ROUND(ABS(淡江大學_p3!K50),0) -> 43610 | ... W36: =ROUND(ABS(淡江大學_p3!W50),0) -> 0
B37: 淡江大學 | D37: =ROUND(ABS(淡江大學_p4!D50),0) -> 43610 | E37: =ROUND(ABS(淡江大學_p4!E50),0) -> 43610 | F37: =ROUND(ABS(淡江大學_p4!F50),0) -> 43610 | G37: =ROUND(ABS(淡江大學_p4!G50),0) -> 43610 | H37: =ROUND(ABS(淡江大學_p4!H50),0) -> 43610 | I37: =ROUND(ABS(淡江大學_p4!I50),0) -> 43610 | J37: =ROUND(ABS(淡江大學_p4!J50),0) -> 43610 | K37: =ROUND(ABS(淡江大學_p4!K50),0) -> 43610 | ... W37: =ROUND(ABS(淡江大學_p4!W50),0) -> 0
B38: 淡江大學 | D38: =ROUND(ABS(淡江大學_p5!D50),0) -> 43610 | E38: =ROUND(ABS(淡江大學_p5!E50),0) -> 43610 | F38: =ROUND(ABS(淡江大學_p5!F50),0) -> 43610 | G38: =ROUND(ABS(淡江大學_p5!G50),0) -> 43610 | H38: =ROUND(ABS(淡江大學_p5!H50),0) -> 43610 | I38: =ROUND(ABS(淡江大學_p5!I50),0) -> 43610 | J38: =ROUND(ABS(淡江大學_p5!J50),0) -> 43610 | K38: =ROUND(ABS(淡江大學_p5!K50),0) -> 43610 | ... W38: =ROUND(ABS(淡江大學_p5!W50),0) -> 0
C39: 模組回收費/年總計 | D39: =SUM(D36:D38) -> 130830 | E39: =SUM(E36:E38) -> 130830 | F39: =SUM(F36:F38) -> 130830 | G39: =SUM(G36:G38) -> 130830 | H39: =SUM(H36:H38) -> 130830 | I39: =SUM(I36:I38) -> 130830 | J39: =SUM(J36:J38) -> 130830 | K39: =SUM(K36:K38) -> 130830 | ... W39: =SUM(W36:W38) -> 0
C40: 年份 | D40: 2020 | E40: 2021 | F40: 2022 | G40: 2023 | H40: 2024 | I40: 2025 | J40: 2026 | K40: 2027 | L40: 2028 | M40: 2029 | N40: 2030 | O40: 2031 | P40: 2032 | Q40: 2033 | R40: 2034 | S40: 2035 | T40: 2036 | U40: 2037 | V40: 2038 | W40: 2039
C41: 所得稅
B42: 淡江大學 | D42: =ROUND(ABS(淡江大學_p3!D54),0) -> 179764 | E42: =ROUND(ABS(淡江大學_p3!E54),0) -> 119973 | F42: =ROUND(ABS(淡江大學_p3!F54),0) -> 118223 | G42: =ROUND(ABS(淡江大學_p3!G54),0) -> 116472 | H42: =ROUND(ABS(淡江大學_p3!H54),0) -> 114722 | I42: =ROUND(ABS(淡江大學_p3!I54),0) -> 112971 | J42: =ROUND(ABS(淡江大學_p3!J54),0) -> 111221 | K42: =ROUND(ABS(淡江大學_p3!K54),0) -> 109471 | ... W42: =ROUND(ABS(淡江大學_p3!W54),0) -> 97188
B43: 淡江大學 | D43: =ROUND(ABS(淡江大學_p4!D54),0) -> 192635 | E43: =ROUND(ABS(淡江大學_p4!E54),0) -> 132845 | F43: =ROUND(ABS(淡江大學_p4!F54),0) -> 131094 | G43: =ROUND(ABS(淡江大學_p4!G54),0) -> 129344 | H43: =ROUND(ABS(淡江大學_p4!H54),0) -> 127594 | I43: =ROUND(ABS(淡江大學_p4!I54),0) -> 125843 | J43: =ROUND(ABS(淡江大學_p4!J54),0) -> 124093 | K43: =ROUND(ABS(淡江大學_p4!K54),0) -> 122342 | ... W43: =ROUND(ABS(淡江大學_p4!W54),0) -> 110060
...

Sheet 淡江大學_p3
B1: 電站基本資料 | F1: 說明 | P1: =1-D11 -> 0.99 | Q1: =P1-$D12 -> 0.986 | R1: =Q1-$D12 -> 0.982 | S1: =R1-$D12 -> 0.978 | T1: =S1-$D12 -> 0.974 | U1: =T1-$D12 -> 0.97 | V1: =U1-$D12 -> 0.966 | W1: =V1-$D12 -> 0.962 | X1: =W1-$D12 -> 0.958 | ... AI1: =AH1-$D12 -> 0.914
B2: 電站名稱 | C2: 淡江大學 | D2: - | E2: - | F2: 填入本案場名稱
B3: 電站壽命 | C3: 20 | D3: - | E3: - | F3: 預設 20 年，代表財務評估年期。若合約年限不同可依實際情況修改
B4: 建置量(kWp) | C4: 436.1 | D4: - | E4: - | F4: 填入裝置容量（kWp），通常由設計圖面或報價書取得 | M4: 情境編號: 3
B5: 起始年度 | C5: 2020 | D5: 結束年度 | E5: 2039 | F5: 填入電站預計掛表的西元年份（例：2025）。結束年度會自動計算 | M5: 第2次滾算摘要
M6: 價金: 31000
B7: 綜合損益表 | M7: 專案IRR: 3.75
B8: 收入 | M8: 權益法IRR: 8.21
B9: 收支項目 | C9: 相關參數 | D9: 參數數值 | E9: 年限 | F9: 說明 | M9: 利潤率: 30.00%
B10: 電費收入 | C10: 年度AC併網總發電量 | D10: 547002 | E10: 20 | F10: 預估年發電量（kWh），通常來自 PVsyst 模擬或估算：裝置容量 × 年日照時數 × 系統效率 | M10: 第2次滾算，減少 2000 元 - 現金模式，每次減少 2000 元
C11: 首年衰退率 | D11: 0.01 | F11: 第一年發電衰退比率，請填小數（例：1% → 填 0.01）。一般首年衰退約 1~2%(請參考模組規格書)
C12: 次年衰退率 | D12: 0.004 | F12: 第二年起每年固定衰退比率，請填小數（例：0.4% → 填 0.004）。一般約 0.4~0.7%(請參考模組規格書)
C13: 躉售費率(FIT) / 綠電費率 | D13: 4 | F13: 與台電簽訂的躉購費率或綠電合約費率，單位：元/度。請參考台電公告或合約內容
B14: 支出
B15: 收支項目 | C15: 相關參數 | D15: 參數數值 | E15: 攤提年限 | F15: 說明
B16: 設備費用(價金) | C16: 每kWp設備成本 | D16: 31000 | E16: 20 | F16: 每峰瓩設備成本（元/kWp），包含模組、逆變器、支架等硬體，不含工程施工費
C17: 信邦利潤率(ex:20%填0.2) | D17: 0.3 | F17: 公司在設備費用上加計的利潤比率，請填小數（例：20% → 填 0.2）
C18: 開發費 | D18: 2000 | F18: 前期開發費用（元），含可行性評估、申請規費、地主溝通等。若無則填 0
B19: 租金費用 | C19: 租金計算方式 | D19: 1 | E19: 20 | F19: 填 1 = 固定年租金（需填方式1參數）；填 2 = 依電費收入抽成（需填方式2參數）
C20: 【方式1參數】每年相同價格 | D20: 290201 | E20: 20 | F20: 租金計算方式選「1」時填寫，固定年租金金額（元/年），套用至整個電站壽命期
C21: 【方式2參數】抽成比率 | D21: 0 | E21: 20 | F21: 租金計算方式選「2」時填寫，請填小數（例：10% → 填 0.1）。租金 = 當年電費收入 × 抽成比率
B22: 運維費用 | C22: 每kw運維成本 | D22: 400 | E22: 20 | F22: 每峰瓩每年運維費用（元/kWp/年），含清洗、巡檢、維修等。
B23: 保險費用 | C23: 占整體設備費用比例 | D23: 0.003 | E23: 20 | F23: 保險費佔設備總費用比率，填小數（例：0.3% → 填 0.003）。預設 0.003，可依投保條件調整
B24: 模組回收費用 | C24: 每kw模組回收成本 | D24: 1000 | E24: 10 | F24: 每峰瓩模組廢棄回收費用（元/kWp），於第 1~10 年計提（攤提 10 年）。
B25: 利息費用 | C25: 銀行利率 | D25: 0.0256 | E25: 20 | F25: 向銀行貸款的年利率，填小數（例：2.56% → 填 0.0256）。請依銀行核准利率填入
B26: 所得稅 | C26: 所得稅率 | D26: 0.2 | E26: 20 | F26: 公司所得稅率，填小數（例：20% → 填 0.2）。預設 0.2，通常不需更改
B29: 現金流量表
B30: 金流項目 | C30: 相關參數 | D30: 參數數值 | F30: 說明
B31: 貸款成數 | C31: 占總設備費用比例 | D31: 0.8 | F31: 貸款佔設備總費用比例，填小數（例：80% → 填 0.8）。預設 0.8 代表貸八成、自備二成
B32: 貸款還款 | C32: 攤還期數 | D32: 15 | F32: 貸款還款年數（年）。預設 15 年，代表分 15 年平均攤還本金
B33: 現金股利 | C33: 股利比率 | D33: 0.9 | F33: 稅後現金流中分配給股東的比例，填小數（例：90% → 填 0.9）
B34: 年底減資 | C34: 攤還期數 | D34: 4 | F34: 年底減資返還股東的年數。預設 4 年，代表 倒數 4 年進行減資，加速資金返還
C37: 年份 | D37: 2020 | E37: 2021 | F37: 2022 | G37: 2023 | H37: 2024 | I37: 2025 | J37: 2026 | K37: 2027 | L37: 2028 | M37: 2029 | N37: 2030 | O37: 2031 | P37: 2032 | Q37: 2033 | R37: 2034 | S37: 2035 | T37: 2036 | U37: 2037 | V37: 2038 | W37: 2039
B38: 0
B39: (Unit : Currency) | C39: 0 | D39: 1 | E39: 2 | F39: 3 | G39: 4 | H39: 5 | I39: 6 | J39: 7 | K39: 8 | L39: 9 | M39: 10 | N39: 11 | O39: 12 | P39: 13 | Q39: 14 | R39: 15 | S39: 16 | T39: 17 | U39: 18 | V39: 19 | W39: 20
B40: 發電度數(KWH) | C40: 0 | D40: =$D$10*P1 -> 541531.98 | E40: =$D$10*Q1 -> 539343.97 | F40: =$D$10*R1 -> 537155.96 | G40: =$D$10*S1 -> 534967.96 | H40: =$D$10*T1 -> 532779.95 | I40: =$D$10*U1 -> 530591.94 | J40: =$D$10*V1 -> 528403.93 | K40: =$D$10*W1 -> 526215.92 | ... W40: =$D$10*AI1 -> 499959.83
B41: Inflow : 電費收入 | C41: - | D41: =D40*$D$13 -> 2166127.9 | E41: =E40*$D$13 -> 2157375.9 | F41: =F40*$D$13 -> 2148623.9 | G41: =G40*$D$13 -> 2139871.8 | H41: =H40*$D$13 -> 2131119.8 | I41: =I40*$D$13 -> 2122367.8 | J41: =J40*$D$13 -> 2113615.7 | K41: =K40*$D$13 -> 2104863.7 | ... W41: =W40*$D$13 -> 1999839.3
B42: Inflow : 政府補助 | C42: - | G42: - | H42: - | I42: - | J42: - | K42: - | L42: - | M42: - | N42: - | O42: - | P42: - | Q42: - | R42: - | S42: - | T42: - | U42: - | V42: - | W42: -
B43: Inflow : 銀行借款
B44: Outflow : 設備費用 | C44: =-(D16/(1-D17)+D18)*C4 -> -20185200
...

Sheet 淡江大學_p4
B1: 電站基本資料 | F1: 說明 | P1: =1-D11 -> 0.99 | Q1: =P1-$D12 -> 0.986 | R1: =Q1-$D12 -> 0.982 | S1: =R1-$D12 -> 0.978 | T1: =S1-$D12 -> 0.974 | U1: =T1-$D12 -> 0.97 | V1: =U1-$D12 -> 0.966 | W1: =V1-$D12 -> 0.962 | X1: =W1-$D12 -> 0.958 | ... AI1: =AH1-$D12 -> 0.914
B2: 電站名稱 | C2: 淡江大學 | D2: - | E2: - | F2: 填入本案場名稱
B3: 電站壽命 | C3: 20 | D3: - | E3: - | F3: 預設 20 年，代表財務評估年期。若合約年限不同可依實際情況修改
B4: 建置量(kWp) | C4: 436.1 | D4: - | E4: - | F4: 填入裝置容量（kWp），通常由設計圖面或報價書取得 | M4: 情境編號: 4
B5: 起始年度 | C5: 2020 | D5: 結束年度 | E5: 2039 | F5: 填入電站預計掛表的西元年份（例：2025）。結束年度會自動計算 | M5: 第3次滾算摘要
M6: 價金: 29000
B7: 綜合損益表 | M7: 專案IRR: 4.39
B8: 收入 | M8: 權益法IRR: 10.59
B9: 收支項目 | C9: 相關參數 | D9: 參數數值 | E9: 年限 | F9: 說明 | M9: 利潤率: 30.00%
B10: 電費收入 | C10: 年度AC併網總發電量 | D10: 547002 | E10: 20 | F10: 預估年發電量（kWh），通常來自 PVsyst 模擬或估算：裝置容量 × 年日照時數 × 系統效率 | M10: 第3次滾算，減少 2000 元 - 現金模式，每次減少 2000 元
C11: 首年衰退率 | D11: 0.01 | F11: 第一年發電衰退比率，請填小數（例：1% → 填 0.01）。一般首年衰退約 1~2%(請參考模組規格書)
C12: 次年衰退率 | D12: 0.004 | F12: 第二年起每年固定衰退比率，請填小數（例：0.4% → 填 0.004）。一般約 0.4~0.7%(請參考模組規格書)
C13: 躉售費率(FIT) / 綠電費率 | D13: 4 | F13: 與台電簽訂的躉購費率或綠電合約費率，單位：元/度。請參考台電公告或合約內容
B14: 支出
B15: 收支項目 | C15: 相關參數 | D15: 參數數值 | E15: 攤提年限 | F15: 說明
B16: 設備費用(價金) | C16: 每kWp設備成本 | D16: 29000 | E16: 20 | F16: 每峰瓩設備成本（元/kWp），包含模組、逆變器、支架等硬體，不含工程施工費
C17: 信邦利潤率(ex:20%填0.2) | D17: 0.3 | F17: 公司在設備費用上加計的利潤比率，請填小數（例：20% → 填 0.2）
C18: 開發費 | D18: 2000 | F18: 前期開發費用（元），含可行性評估、申請規費、地主溝通等。若無則填 0
B19: 租金費用 | C19: 租金計算方式 | D19: 1 | E19: 20 | F19: 填 1 = 固定年租金（需填方式1參數）；填 2 = 依電費收入抽成（需填方式2參數）
C20: 【方式1參數】每年相同價格 | D20: 290201 | E20: 20 | F20: 租金計算方式選「1」時填寫，固定年租金金額（元/年），套用至整個電站壽命期
C21: 【方式2參數】抽成比率 | D21: 0 | E21: 20 | F21: 租金計算方式選「2」時填寫，請填小數（例：10% → 填 0.1）。租金 = 當年電費收入 × 抽成比率
B22: 運維費用 | C22: 每kw運維成本 | D22: 400 | E22: 20 | F22: 每峰瓩每年運維費用（元/kWp/年），含清洗、巡檢、維修等。
B23: 保險費用 | C23: 占整體設備費用比例 | D23: 0.003 | E23: 20 | F23: 保險費佔設備總費用比率，填小數（例：0.3% → 填 0.003）。預設 0.003，可依投保條件調整
B24: 模組回收費用 | C24: 每kw模組回收成本 | D24: 1000 | E24: 10 | F24: 每峰瓩模組廢棄回收費用（元/kWp），於第 1~10 年計提（攤提 10 年）。
B25: 利息費用 | C25: 銀行利率 | D25: 0.0256 | E25: 20 | F25: 向銀行貸款的年利率，填小數（例：2.56% → 填 0.0256）。請依銀行核准利率填入
B26: 所得稅 | C26: 所得稅率 | D26: 0.2 | E26: 20 | F26: 公司所得稅率，填小數（例：20% → 填 0.2）。預設 0.2，通常不需更改
B29: 現金流量表
B30: 金流項目 | C30: 相關參數 | D30: 參數數值 | F30: 說明
B31: 貸款成數 | C31: 占總設備費用比例 | D31: 0.8 | F31: 貸款佔設備總費用比例，填小數（例：80% → 填 0.8）。預設 0.8 代表貸八成、自備二成
B32: 貸款還款 | C32: 攤還期數 | D32: 15 | F32: 貸款還款年數（年）。預設 15 年，代表分 15 年平均攤還本金
B33: 現金股利 | C33: 股利比率 | D33: 0.9 | F33: 稅後現金流中分配給股東的比例，填小數（例：90% → 填 0.9）
B34: 年底減資 | C34: 攤還期數 | D34: 4 | F34: 年底減資返還股東的年數。預設 4 年，代表 倒數 4 年進行減資，加速資金返還
C37: 年份 | D37: 2020 | E37: 2021 | F37: 2022 | G37: 2023 | H37: 2024 | I37: 2025 | J37: 2026 | K37: 2027 | L37: 2028 | M37: 2029 | N37: 2030 | O37: 2031 | P37: 2032 | Q37: 2033 | R37: 2034 | S37: 2035 | T37: 2036 | U37: 2037 | V37: 2038 | W37: 2039
B38: 0
B39: (Unit : Currency) | C39: 0 | D39: 1 | E39: 2 | F39: 3 | G39: 4 | H39: 5 | I39: 6 | J39: 7 | K39: 8 | L39: 9 | M39: 10 | N39: 11 | O39: 12 | P39: 13 | Q39: 14 | R39: 15 | S39: 16 | T39: 17 | U39: 18 | V39: 19 | W39: 20
B40: 發電度數(KWH) | C40: 0 | D40: =$D$10*P1 -> 541531.98 | E40: =$D$10*Q1 -> 539343.97 | F40: =$D$10*R1 -> 537155.96 | G40: =$D$10*S1 -> 534967.96 | H40: =$D$10*T1 -> 532779.95 | I40: =$D$10*U1 -> 530591.94 | J40: =$D$10*V1 -> 528403.93 | K40: =$D$10*W1 -> 526215.92 | ... W40: =$D$10*AI1 -> 499959.83
B41: Inflow : 電費收入 | C41: - | D41: =D40*$D$13 -> 2166127.9 | E41: =E40*$D$13 -> 2157375.9 | F41: =F40*$D$13 -> 2148623.9 | G41: =G40*$D$13 -> 2139871.8 | H41: =H40*$D$13 -> 2131119.8 | I41: =I40*$D$13 -> 2122367.8 | J41: =J40*$D$13 -> 2113615.7 | K41: =K40*$D$13 -> 2104863.7 | ... W41: =W40*$D$13 -> 1999839.3
B42: Inflow : 政府補助 | C42: - | G42: - | H42: - | I42: - | J42: - | K42: - | L42: - | M42: - | N42: - | O42: - | P42: - | Q42: - | R42: - | S42: - | T42: - | U42: - | V42: - | W42: -
B43: Inflow : 銀行借款
B44: Outflow : 設備費用 | C44: =-(D16/(1-D17)+D18)*C4 -> -18939200
...

Sheet 淡江大學_p5
B1: 電站基本資料 | F1: 說明 | P1: =1-D11 -> 0.99 | Q1: =P1-$D12 -> 0.986 | R1: =Q1-$D12 -> 0.982 | S1: =R1-$D12 -> 0.978 | T1: =S1-$D12 -> 0.974 | U1: =T1-$D12 -> 0.97 | V1: =U1-$D12 -> 0.966 | W1: =V1-$D12 -> 0.962 | X1: =W1-$D12 -> 0.958 | ... AI1: =AH1-$D12 -> 0.914
B2: 電站名稱 | C2: 淡江大學 | D2: - | E2: - | F2: 填入本案場名稱
B3: 電站壽命 | C3: 20 | D3: - | E3: - | F3: 預設 20 年，代表財務評估年期。若合約年限不同可依實際情況修改
B4: 建置量(kWp) | C4: 436.1 | D4: - | E4: - | F4: 填入裝置容量（kWp），通常由設計圖面或報價書取得 | M4: 情境編號: 5
B5: 起始年度 | C5: 2020 | D5: 結束年度 | E5: 2039 | F5: 填入電站預計掛表的西元年份（例：2025）。結束年度會自動計算 | M5: 第4次滾算摘要
M6: 價金: 27000
B7: 綜合損益表 | M7: 專案IRR: 5.11
B8: 收入 | M8: 權益法IRR: 13.45
B9: 收支項目 | C9: 相關參數 | D9: 參數數值 | E9: 年限 | F9: 說明 | M9: 利潤率: 30.00%
B10: 電費收入 | C10: 年度AC併網總發電量 | D10: 547002 | E10: 20 | F10: 預估年發電量（kWh），通常來自 PVsyst 模擬或估算：裝置容量 × 年日照時數 × 系統效率 | M10: 第4次滾算，減少 2000 元 - 現金模式，每次減少 2000 元
C11: 首年衰退率 | D11: 0.01 | F11: 第一年發電衰退比率，請填小數（例：1% → 填 0.01）。一般首年衰退約 1~2%(請參考模組規格書)
C12: 次年衰退率 | D12: 0.004 | F12: 第二年起每年固定衰退比率，請填小數（例：0.4% → 填 0.004）。一般約 0.4~0.7%(請參考模組規格書)
C13: 躉售費率(FIT) / 綠電費率 | D13: 4 | F13: 與台電簽訂的躉購費率或綠電合約費率，單位：元/度。請參考台電公告或合約內容
B14: 支出
B15: 收支項目 | C15: 相關參數 | D15: 參數數值 | E15: 攤提年限 | F15: 說明
B16: 設備費用(價金) | C16: 每kWp設備成本 | D16: 27000 | E16: 20 | F16: 每峰瓩設備成本（元/kWp），包含模組、逆變器、支架等硬體，不含工程施工費
C17: 信邦利潤率(ex:20%填0.2) | D17: 0.3 | F17: 公司在設備費用上加計的利潤比率，請填小數（例：20% → 填 0.2）
C18: 開發費 | D18: 2000 | F18: 前期開發費用（元），含可行性評估、申請規費、地主溝通等。若無則填 0
B19: 租金費用 | C19: 租金計算方式 | D19: 1 | E19: 20 | F19: 填 1 = 固定年租金（需填方式1參數）；填 2 = 依電費收入抽成（需填方式2參數）
C20: 【方式1參數】每年相同價格 | D20: 290201 | E20: 20 | F20: 租金計算方式選「1」時填寫，固定年租金金額（元/年），套用至整個電站壽命期
C21: 【方式2參數】抽成比率 | D21: 0 | E21: 20 | F21: 租金計算方式選「2」時填寫，請填小數（例：10% → 填 0.1）。租金 = 當年電費收入 × 抽成比率
B22: 運維費用 | C22: 每kw運維成本 | D22: 400 | E22: 20 | F22: 每峰瓩每年運維費用（元/kWp/年），含清洗、巡檢、維修等。
B23: 保險費用 | C23: 占整體設備費用比例 | D23: 0.003 | E23: 20 | F23: 保險費佔設備總費用比率，填小數（例：0.3% → 填 0.003）。預設 0.003，可依投保條件調整
B24: 模組回收費用 | C24: 每kw模組回收成本 | D24: 1000 | E24: 10 | F24: 每峰瓩模組廢棄回收費用（元/kWp），於第 1~10 年計提（攤提 10 年）。
B25: 利息費用 | C25: 銀行利率 | D25: 0.0256 | E25: 20 | F25: 向銀行貸款的年利率，填小數（例：2.56% → 填 0.0256）。請依銀行核准利率填入
B26: 所得稅 | C26: 所得稅率 | D26: 0.2 | E26: 20 | F26: 公司所得稅率，填小數（例：20% → 填 0.2）。預設 0.2，通常不需更改
B29: 現金流量表
B30: 金流項目 | C30: 相關參數 | D30: 參數數值 | F30: 說明
B31: 貸款成數 | C31: 占總設備費用比例 | D31: 0.8 | F31: 貸款佔設備總費用比例，填小數（例：80% → 填 0.8）。預設 0.8 代表貸八成、自備二成
B32: 貸款還款 | C32: 攤還期數 | D32: 15 | F32: 貸款還款年數（年）。預設 15 年，代表分 15 年平均攤還本金
B33: 現金股利 | C33: 股利比率 | D33: 0.9 | F33: 稅後現金流中分配給股東的比例，填小數（例：90% → 填 0.9）
B34: 年底減資 | C34: 攤還期數 | D34: 4 | F34: 年底減資返還股東的年數。預設 4 年，代表 倒數 4 年進行減資，加速資金返還
C37: 年份 | D37: 2020 | E37: 2021 | F37: 2022 | G37: 2023 | H37: 2024 | I37: 2025 | J37: 2026 | K37: 2027 | L37: 2028 | M37: 2029 | N37: 2030 | O37: 2031 | P37: 2032 | Q37: 2033 | R37: 2034 | S37: 2035 | T37: 2036 | U37: 2037 | V37: 2038 | W37: 2039
B38: 0
B39: (Unit : Currency) | C39: 0 | D39: 1 | E39: 2 | F39: 3 | G39: 4 | H39: 5 | I39: 6 | J39: 7 | K39: 8 | L39: 9 | M39: 10 | N39: 11 | O39: 12 | P39: 13 | Q39: 14 | R39: 15 | S39: 16 | T39: 17 | U39: 18 | V39: 19 | W39: 20
B40: 發電度數(KWH) | C40: 0 | D40: =$D$10*P1 -> 541531.98 | E40: =$D$10*Q1 -> 539343.97 | F40: =$D$10*R1 -> 537155.96 | G40: =$D$10*S1 -> 534967.96 | H40: =$D$10*T1 -> 532779.95 | I40: =$D$10*U1 -> 530591.94 | J40: =$D$10*V1 -> 528403.93 | K40: =$D$10*W1 -> 526215.92 | ... W40: =$D$10*AI1 -> 499959.83
B41: Inflow : 電費收入 | C41: - | D41: =D40*$D$13 -> 2166127.9 | E41: =E40*$D$13 -> 2157375.9 | F41: =F40*$D$13 -> 2148623.9 | G41: =G40*$D$13 -> 2139871.8 | H41: =H40*$D$13 -> 2131119.8 | I41: =I40*$D$13 -> 2122367.8 | J41: =J40*$D$13 -> 2113615.7 | K41: =K40*$D$13 -> 2104863.7 | ... W41: =W40*$D$13 -> 1999839.3
B42: Inflow : 政府補助 | C42: - | G42: - | H42: - | I42: - | J42: - | K42: - | L42: - | M42: - | N42: - | O42: - | P42: - | Q42: - | R42: - | S42: - | T42: - | U42: - | V42: - | W42: -
B43: Inflow : 銀行借款
B44: Outflow : 設備費用 | C44: =-(D16/(1-D17)+D18)*C4 -> -17693200
...
